{
 "cells": [
  {
   "cell_type": "markdown",
   "id": "2fdf676f",
   "metadata": {},
   "source": [
    "# EDB: geometry creation"
   ]
  },
  {
   "cell_type": "markdown",
   "id": "33c88515",
   "metadata": {},
   "source": [
    "This example shows how you can use EDB to create a layout.\n",
    "## Final expected project\n",
    "\n",
    "<img src=\"_static/diff_via.png\" width=\"500\">\n",
    "\n",
    "## Import EDB layout object\n",
    "Import the EDB layout object and initialize it on version 2023 R2."
   ]
  },
  {
   "cell_type": "code",
   "execution_count": 1,
   "id": "263d6ae8",
   "metadata": {
    "execution": {
     "iopub.execute_input": "2024-09-04T08:19:19.753915Z",
     "iopub.status.busy": "2024-09-04T08:19:19.753915Z",
     "iopub.status.idle": "2024-09-04T08:19:32.152211Z",
     "shell.execute_reply": "2024-09-04T08:19:32.152211Z"
    }
   },
   "outputs": [
    {
     "name": "stdout",
     "output_type": "stream",
     "text": [
      "AEDB file path: C:\\Users\\ansys\\AppData\\Local\\Temp\\tmp9qtix9bh.ansys\\create_via.aedb\n",
      "EDB version: 2024.2\n"
     ]
    },
    {
     "name": "stdout",
     "output_type": "stream",
     "text": [
      "PyEDB INFO: StdOut is enabled\n"
     ]
    },
    {
     "name": "stdout",
     "output_type": "stream",
     "text": [
      "PyEDB INFO: Logger is initialized in EDB.\n"
     ]
    },
    {
     "name": "stdout",
     "output_type": "stream",
     "text": [
      "PyEDB INFO: legacy v0.26.3\n"
     ]
    },
    {
     "name": "stdout",
     "output_type": "stream",
     "text": [
      "PyEDB INFO: Python version 3.10.11 (tags/v3.10.11:7d4cc5a, Apr  5 2023, 00:38:17) [MSC v.1929 64 bit (AMD64)]\n"
     ]
    },
    {
     "name": "stderr",
     "output_type": "stream",
     "text": [
      "--- Logging error ---\n",
      "Traceback (most recent call last):\n",
      "  File \"C:\\actions-runner\\_work\\_tool\\Python\\3.10.11\\x64\\lib\\logging\\handlers.py\", line 74, in emit\n",
      "    self.doRollover()\n",
      "  File \"C:\\actions-runner\\_work\\_tool\\Python\\3.10.11\\x64\\lib\\logging\\handlers.py\", line 179, in doRollover\n",
      "    self.rotate(self.baseFilename, dfn)\n",
      "  File \"C:\\actions-runner\\_work\\_tool\\Python\\3.10.11\\x64\\lib\\logging\\handlers.py\", line 115, in rotate\n",
      "    os.rename(source, dest)\n",
      "PermissionError: [WinError 32] The process cannot access the file because it is being used by another process: 'C:\\\\Users\\\\ansys\\\\AppData\\\\Local\\\\Temp\\\\pyedb_ansys.log' -> 'C:\\\\Users\\\\ansys\\\\AppData\\\\Local\\\\Temp\\\\pyedb_ansys.log.1'\n",
      "Call stack:\n",
      "  File \"C:\\actions-runner\\_work\\_tool\\Python\\3.10.11\\x64\\lib\\runpy.py\", line 196, in _run_module_as_main\n",
      "    return _run_code(code, main_globals, None,\n",
      "  File \"C:\\actions-runner\\_work\\_tool\\Python\\3.10.11\\x64\\lib\\runpy.py\", line 86, in _run_code\n",
      "    exec(code, run_globals)\n",
      "  File \"C:\\actions-runner\\_work\\pyedb\\pyedb\\.venv\\lib\\site-packages\\ipykernel_launcher.py\", line 18, in <module>\n",
      "    app.launch_new_instance()\n",
      "  File \"C:\\actions-runner\\_work\\pyedb\\pyedb\\.venv\\lib\\site-packages\\traitlets\\config\\application.py\", line 1075, in launch_instance\n",
      "    app.start()\n",
      "  File \"C:\\actions-runner\\_work\\pyedb\\pyedb\\.venv\\lib\\site-packages\\ipykernel\\kernelapp.py\", line 739, in start\n",
      "    self.io_loop.start()\n",
      "  File \"C:\\actions-runner\\_work\\pyedb\\pyedb\\.venv\\lib\\site-packages\\tornado\\platform\\asyncio.py\", line 205, in start\n",
      "    self.asyncio_loop.run_forever()\n",
      "  File \"C:\\actions-runner\\_work\\_tool\\Python\\3.10.11\\x64\\lib\\asyncio\\base_events.py\", line 603, in run_forever\n",
      "    self._run_once()\n",
      "  File \"C:\\actions-runner\\_work\\_tool\\Python\\3.10.11\\x64\\lib\\asyncio\\base_events.py\", line 1909, in _run_once\n",
      "    handle._run()\n",
      "  File \"C:\\actions-runner\\_work\\_tool\\Python\\3.10.11\\x64\\lib\\asyncio\\events.py\", line 80, in _run\n",
      "    self._context.run(self._callback, *self._args)\n",
      "  File \"C:\\actions-runner\\_work\\pyedb\\pyedb\\.venv\\lib\\site-packages\\ipykernel\\kernelbase.py\", line 545, in dispatch_queue\n",
      "    await self.process_one()\n",
      "  File \"C:\\actions-runner\\_work\\pyedb\\pyedb\\.venv\\lib\\site-packages\\ipykernel\\kernelbase.py\", line 534, in process_one\n",
      "    await dispatch(*args)\n",
      "  File \"C:\\actions-runner\\_work\\pyedb\\pyedb\\.venv\\lib\\site-packages\\ipykernel\\kernelbase.py\", line 437, in dispatch_shell\n",
      "    await result\n",
      "  File \"C:\\actions-runner\\_work\\pyedb\\pyedb\\.venv\\lib\\site-packages\\ipykernel\\ipkernel.py\", line 362, in execute_request\n",
      "    await super().execute_request(stream, ident, parent)\n",
      "  File \"C:\\actions-runner\\_work\\pyedb\\pyedb\\.venv\\lib\\site-packages\\ipykernel\\kernelbase.py\", line 778, in execute_request\n",
      "    reply_content = await reply_content\n",
      "  File \"C:\\actions-runner\\_work\\pyedb\\pyedb\\.venv\\lib\\site-packages\\ipykernel\\ipkernel.py\", line 449, in do_execute\n",
      "    res = shell.run_cell(\n",
      "  File \"C:\\actions-runner\\_work\\pyedb\\pyedb\\.venv\\lib\\site-packages\\ipykernel\\zmqshell.py\", line 549, in run_cell\n",
      "    return super().run_cell(*args, **kwargs)\n",
      "  File \"C:\\actions-runner\\_work\\pyedb\\pyedb\\.venv\\lib\\site-packages\\IPython\\core\\interactiveshell.py\", line 3075, in run_cell\n",
      "    result = self._run_cell(\n",
      "  File \"C:\\actions-runner\\_work\\pyedb\\pyedb\\.venv\\lib\\site-packages\\IPython\\core\\interactiveshell.py\", line 3130, in _run_cell\n",
      "    result = runner(coro)\n",
      "  File \"C:\\actions-runner\\_work\\pyedb\\pyedb\\.venv\\lib\\site-packages\\IPython\\core\\async_helpers.py\", line 128, in _pseudo_sync_runner\n",
      "    coro.send(None)\n",
      "  File \"C:\\actions-runner\\_work\\pyedb\\pyedb\\.venv\\lib\\site-packages\\IPython\\core\\interactiveshell.py\", line 3334, in run_cell_async\n",
      "    has_raised = await self.run_ast_nodes(code_ast.body, cell_name,\n",
      "  File \"C:\\actions-runner\\_work\\pyedb\\pyedb\\.venv\\lib\\site-packages\\IPython\\core\\interactiveshell.py\", line 3517, in run_ast_nodes\n",
      "    if await self.run_code(code, result, async_=asy):\n",
      "  File \"C:\\actions-runner\\_work\\pyedb\\pyedb\\.venv\\lib\\site-packages\\IPython\\core\\interactiveshell.py\", line 3577, in run_code\n",
      "    exec(code_obj, self.user_global_ns, self.user_ns)\n",
      "  File \"C:\\Users\\ansys\\AppData\\Local\\Temp\\ipykernel_1556\\450015450.py\", line 14, in <module>\n",
      "    edb = pyedb.Edb(edbpath=aedb_path, edbversion=edb_version)\n",
      "  File \"C:\\actions-runner\\_work\\pyedb\\pyedb\\.venv\\lib\\site-packages\\pyedb\\generic\\design_types.py\", line 110, in Edb\n",
      "    return app(\n",
      "  File \"C:\\actions-runner\\_work\\pyedb\\pyedb\\.venv\\lib\\site-packages\\pyedb\\dotnet\\edb.py\", line 196, in __init__\n",
      "    Database.__init__(self, edbversion=edbversion, student_version=student_version)\n",
      "  File \"C:\\actions-runner\\_work\\pyedb\\pyedb\\.venv\\lib\\site-packages\\pyedb\\dotnet\\edb_core\\dotnet\\database.py\", line 802, in __init__\n",
      "    EdbDotNet.__init__(self, edbversion=edbversion, student_version=student_version)\n",
      "  File \"C:\\actions-runner\\_work\\pyedb\\pyedb\\.venv\\lib\\site-packages\\pyedb\\dotnet\\edb_core\\dotnet\\database.py\", line 703, in __init__\n",
      "    self._logger.enable_stdout_log()\n",
      "  File \"C:\\actions-runner\\_work\\pyedb\\pyedb\\.venv\\lib\\site-packages\\pyedb\\edb_logger.py\", line 318, in enable_stdout_log\n",
      "    self.info(\"StdOut is enabled\")\n",
      "  File \"C:\\actions-runner\\_work\\pyedb\\pyedb\\.venv\\lib\\site-packages\\pyedb\\edb_logger.py\", line 346, in info\n",
      "    return self._log_on_handler(0, msg, *args, **kwargs)\n",
      "  File \"C:\\actions-runner\\_work\\pyedb\\pyedb\\.venv\\lib\\site-packages\\pyedb\\edb_logger.py\", line 293, in _log_on_handler\n",
      "    self._global.info(message_text, *args, **kwargs)\n",
      "Message: 'StdOut is enabled'\n",
      "Arguments: ()\n",
      "--- Logging error ---\n",
      "Traceback (most recent call last):\n",
      "  File \"C:\\actions-runner\\_work\\_tool\\Python\\3.10.11\\x64\\lib\\logging\\handlers.py\", line 74, in emit\n",
      "    self.doRollover()\n",
      "  File \"C:\\actions-runner\\_work\\_tool\\Python\\3.10.11\\x64\\lib\\logging\\handlers.py\", line 179, in doRollover\n",
      "    self.rotate(self.baseFilename, dfn)\n",
      "  File \"C:\\actions-runner\\_work\\_tool\\Python\\3.10.11\\x64\\lib\\logging\\handlers.py\", line 115, in rotate\n",
      "    os.rename(source, dest)\n",
      "PermissionError: [WinError 32] The process cannot access the file because it is being used by another process: 'C:\\\\Users\\\\ansys\\\\AppData\\\\Local\\\\Temp\\\\pyedb_ansys.log' -> 'C:\\\\Users\\\\ansys\\\\AppData\\\\Local\\\\Temp\\\\pyedb_ansys.log.1'\n",
      "Call stack:\n",
      "  File \"C:\\actions-runner\\_work\\_tool\\Python\\3.10.11\\x64\\lib\\runpy.py\", line 196, in _run_module_as_main\n",
      "    return _run_code(code, main_globals, None,\n",
      "  File \"C:\\actions-runner\\_work\\_tool\\Python\\3.10.11\\x64\\lib\\runpy.py\", line 86, in _run_code\n",
      "    exec(code, run_globals)\n",
      "  File \"C:\\actions-runner\\_work\\pyedb\\pyedb\\.venv\\lib\\site-packages\\ipykernel_launcher.py\", line 18, in <module>\n",
      "    app.launch_new_instance()\n",
      "  File \"C:\\actions-runner\\_work\\pyedb\\pyedb\\.venv\\lib\\site-packages\\traitlets\\config\\application.py\", line 1075, in launch_instance\n",
      "    app.start()\n",
      "  File \"C:\\actions-runner\\_work\\pyedb\\pyedb\\.venv\\lib\\site-packages\\ipykernel\\kernelapp.py\", line 739, in start\n",
      "    self.io_loop.start()\n",
      "  File \"C:\\actions-runner\\_work\\pyedb\\pyedb\\.venv\\lib\\site-packages\\tornado\\platform\\asyncio.py\", line 205, in start\n",
      "    self.asyncio_loop.run_forever()\n",
      "  File \"C:\\actions-runner\\_work\\_tool\\Python\\3.10.11\\x64\\lib\\asyncio\\base_events.py\", line 603, in run_forever\n",
      "    self._run_once()\n",
      "  File \"C:\\actions-runner\\_work\\_tool\\Python\\3.10.11\\x64\\lib\\asyncio\\base_events.py\", line 1909, in _run_once\n",
      "    handle._run()\n",
      "  File \"C:\\actions-runner\\_work\\_tool\\Python\\3.10.11\\x64\\lib\\asyncio\\events.py\", line 80, in _run\n",
      "    self._context.run(self._callback, *self._args)\n",
      "  File \"C:\\actions-runner\\_work\\pyedb\\pyedb\\.venv\\lib\\site-packages\\ipykernel\\kernelbase.py\", line 545, in dispatch_queue\n",
      "    await self.process_one()\n",
      "  File \"C:\\actions-runner\\_work\\pyedb\\pyedb\\.venv\\lib\\site-packages\\ipykernel\\kernelbase.py\", line 534, in process_one\n",
      "    await dispatch(*args)\n",
      "  File \"C:\\actions-runner\\_work\\pyedb\\pyedb\\.venv\\lib\\site-packages\\ipykernel\\kernelbase.py\", line 437, in dispatch_shell\n",
      "    await result\n",
      "  File \"C:\\actions-runner\\_work\\pyedb\\pyedb\\.venv\\lib\\site-packages\\ipykernel\\ipkernel.py\", line 362, in execute_request\n",
      "    await super().execute_request(stream, ident, parent)\n",
      "  File \"C:\\actions-runner\\_work\\pyedb\\pyedb\\.venv\\lib\\site-packages\\ipykernel\\kernelbase.py\", line 778, in execute_request\n",
      "    reply_content = await reply_content\n",
      "  File \"C:\\actions-runner\\_work\\pyedb\\pyedb\\.venv\\lib\\site-packages\\ipykernel\\ipkernel.py\", line 449, in do_execute\n",
      "    res = shell.run_cell(\n",
      "  File \"C:\\actions-runner\\_work\\pyedb\\pyedb\\.venv\\lib\\site-packages\\ipykernel\\zmqshell.py\", line 549, in run_cell\n",
      "    return super().run_cell(*args, **kwargs)\n",
      "  File \"C:\\actions-runner\\_work\\pyedb\\pyedb\\.venv\\lib\\site-packages\\IPython\\core\\interactiveshell.py\", line 3075, in run_cell\n",
      "    result = self._run_cell(\n",
      "  File \"C:\\actions-runner\\_work\\pyedb\\pyedb\\.venv\\lib\\site-packages\\IPython\\core\\interactiveshell.py\", line 3130, in _run_cell\n",
      "    result = runner(coro)\n",
      "  File \"C:\\actions-runner\\_work\\pyedb\\pyedb\\.venv\\lib\\site-packages\\IPython\\core\\async_helpers.py\", line 128, in _pseudo_sync_runner\n",
      "    coro.send(None)\n",
      "  File \"C:\\actions-runner\\_work\\pyedb\\pyedb\\.venv\\lib\\site-packages\\IPython\\core\\interactiveshell.py\", line 3334, in run_cell_async\n",
      "    has_raised = await self.run_ast_nodes(code_ast.body, cell_name,\n",
      "  File \"C:\\actions-runner\\_work\\pyedb\\pyedb\\.venv\\lib\\site-packages\\IPython\\core\\interactiveshell.py\", line 3517, in run_ast_nodes\n",
      "    if await self.run_code(code, result, async_=asy):\n",
      "  File \"C:\\actions-runner\\_work\\pyedb\\pyedb\\.venv\\lib\\site-packages\\IPython\\core\\interactiveshell.py\", line 3577, in run_code\n",
      "    exec(code_obj, self.user_global_ns, self.user_ns)\n",
      "  File \"C:\\Users\\ansys\\AppData\\Local\\Temp\\ipykernel_1556\\450015450.py\", line 14, in <module>\n",
      "    edb = pyedb.Edb(edbpath=aedb_path, edbversion=edb_version)\n",
      "  File \"C:\\actions-runner\\_work\\pyedb\\pyedb\\.venv\\lib\\site-packages\\pyedb\\generic\\design_types.py\", line 110, in Edb\n",
      "    return app(\n",
      "  File \"C:\\actions-runner\\_work\\pyedb\\pyedb\\.venv\\lib\\site-packages\\pyedb\\dotnet\\edb.py\", line 196, in __init__\n",
      "    Database.__init__(self, edbversion=edbversion, student_version=student_version)\n",
      "  File \"C:\\actions-runner\\_work\\pyedb\\pyedb\\.venv\\lib\\site-packages\\pyedb\\dotnet\\edb_core\\dotnet\\database.py\", line 802, in __init__\n",
      "    EdbDotNet.__init__(self, edbversion=edbversion, student_version=student_version)\n",
      "  File \"C:\\actions-runner\\_work\\pyedb\\pyedb\\.venv\\lib\\site-packages\\pyedb\\dotnet\\edb_core\\dotnet\\database.py\", line 709, in __init__\n",
      "    self._logger.info(\"Logger is initialized in EDB.\")\n",
      "  File \"C:\\actions-runner\\_work\\pyedb\\pyedb\\.venv\\lib\\site-packages\\pyedb\\edb_logger.py\", line 346, in info\n",
      "    return self._log_on_handler(0, msg, *args, **kwargs)\n",
      "  File \"C:\\actions-runner\\_work\\pyedb\\pyedb\\.venv\\lib\\site-packages\\pyedb\\edb_logger.py\", line 293, in _log_on_handler\n",
      "    self._global.info(message_text, *args, **kwargs)\n",
      "Message: 'Logger is initialized in EDB.'\n",
      "Arguments: ()\n",
      "--- Logging error ---\n",
      "Traceback (most recent call last):\n",
      "  File \"C:\\actions-runner\\_work\\_tool\\Python\\3.10.11\\x64\\lib\\logging\\handlers.py\", line 74, in emit\n",
      "    self.doRollover()\n",
      "  File \"C:\\actions-runner\\_work\\_tool\\Python\\3.10.11\\x64\\lib\\logging\\handlers.py\", line 179, in doRollover\n",
      "    self.rotate(self.baseFilename, dfn)\n",
      "  File \"C:\\actions-runner\\_work\\_tool\\Python\\3.10.11\\x64\\lib\\logging\\handlers.py\", line 115, in rotate\n",
      "    os.rename(source, dest)\n",
      "PermissionError: [WinError 32] The process cannot access the file because it is being used by another process: 'C:\\\\Users\\\\ansys\\\\AppData\\\\Local\\\\Temp\\\\pyedb_ansys.log' -> 'C:\\\\Users\\\\ansys\\\\AppData\\\\Local\\\\Temp\\\\pyedb_ansys.log.1'\n",
      "Call stack:\n",
      "  File \"C:\\actions-runner\\_work\\_tool\\Python\\3.10.11\\x64\\lib\\runpy.py\", line 196, in _run_module_as_main\n",
      "    return _run_code(code, main_globals, None,\n",
      "  File \"C:\\actions-runner\\_work\\_tool\\Python\\3.10.11\\x64\\lib\\runpy.py\", line 86, in _run_code\n",
      "    exec(code, run_globals)\n",
      "  File \"C:\\actions-runner\\_work\\pyedb\\pyedb\\.venv\\lib\\site-packages\\ipykernel_launcher.py\", line 18, in <module>\n",
      "    app.launch_new_instance()\n",
      "  File \"C:\\actions-runner\\_work\\pyedb\\pyedb\\.venv\\lib\\site-packages\\traitlets\\config\\application.py\", line 1075, in launch_instance\n",
      "    app.start()\n",
      "  File \"C:\\actions-runner\\_work\\pyedb\\pyedb\\.venv\\lib\\site-packages\\ipykernel\\kernelapp.py\", line 739, in start\n",
      "    self.io_loop.start()\n",
      "  File \"C:\\actions-runner\\_work\\pyedb\\pyedb\\.venv\\lib\\site-packages\\tornado\\platform\\asyncio.py\", line 205, in start\n",
      "    self.asyncio_loop.run_forever()\n",
      "  File \"C:\\actions-runner\\_work\\_tool\\Python\\3.10.11\\x64\\lib\\asyncio\\base_events.py\", line 603, in run_forever\n",
      "    self._run_once()\n",
      "  File \"C:\\actions-runner\\_work\\_tool\\Python\\3.10.11\\x64\\lib\\asyncio\\base_events.py\", line 1909, in _run_once\n",
      "    handle._run()\n",
      "  File \"C:\\actions-runner\\_work\\_tool\\Python\\3.10.11\\x64\\lib\\asyncio\\events.py\", line 80, in _run\n",
      "    self._context.run(self._callback, *self._args)\n",
      "  File \"C:\\actions-runner\\_work\\pyedb\\pyedb\\.venv\\lib\\site-packages\\ipykernel\\kernelbase.py\", line 545, in dispatch_queue\n",
      "    await self.process_one()\n",
      "  File \"C:\\actions-runner\\_work\\pyedb\\pyedb\\.venv\\lib\\site-packages\\ipykernel\\kernelbase.py\", line 534, in process_one\n",
      "    await dispatch(*args)\n",
      "  File \"C:\\actions-runner\\_work\\pyedb\\pyedb\\.venv\\lib\\site-packages\\ipykernel\\kernelbase.py\", line 437, in dispatch_shell\n",
      "    await result\n",
      "  File \"C:\\actions-runner\\_work\\pyedb\\pyedb\\.venv\\lib\\site-packages\\ipykernel\\ipkernel.py\", line 362, in execute_request\n",
      "    await super().execute_request(stream, ident, parent)\n",
      "  File \"C:\\actions-runner\\_work\\pyedb\\pyedb\\.venv\\lib\\site-packages\\ipykernel\\kernelbase.py\", line 778, in execute_request\n",
      "    reply_content = await reply_content\n",
      "  File \"C:\\actions-runner\\_work\\pyedb\\pyedb\\.venv\\lib\\site-packages\\ipykernel\\ipkernel.py\", line 449, in do_execute\n",
      "    res = shell.run_cell(\n",
      "  File \"C:\\actions-runner\\_work\\pyedb\\pyedb\\.venv\\lib\\site-packages\\ipykernel\\zmqshell.py\", line 549, in run_cell\n",
      "    return super().run_cell(*args, **kwargs)\n",
      "  File \"C:\\actions-runner\\_work\\pyedb\\pyedb\\.venv\\lib\\site-packages\\IPython\\core\\interactiveshell.py\", line 3075, in run_cell\n",
      "    result = self._run_cell(\n",
      "  File \"C:\\actions-runner\\_work\\pyedb\\pyedb\\.venv\\lib\\site-packages\\IPython\\core\\interactiveshell.py\", line 3130, in _run_cell\n",
      "    result = runner(coro)\n",
      "  File \"C:\\actions-runner\\_work\\pyedb\\pyedb\\.venv\\lib\\site-packages\\IPython\\core\\async_helpers.py\", line 128, in _pseudo_sync_runner\n",
      "    coro.send(None)\n",
      "  File \"C:\\actions-runner\\_work\\pyedb\\pyedb\\.venv\\lib\\site-packages\\IPython\\core\\interactiveshell.py\", line 3334, in run_cell_async\n",
      "    has_raised = await self.run_ast_nodes(code_ast.body, cell_name,\n",
      "  File \"C:\\actions-runner\\_work\\pyedb\\pyedb\\.venv\\lib\\site-packages\\IPython\\core\\interactiveshell.py\", line 3517, in run_ast_nodes\n",
      "    if await self.run_code(code, result, async_=asy):\n",
      "  File \"C:\\actions-runner\\_work\\pyedb\\pyedb\\.venv\\lib\\site-packages\\IPython\\core\\interactiveshell.py\", line 3577, in run_code\n",
      "    exec(code_obj, self.user_global_ns, self.user_ns)\n",
      "  File \"C:\\Users\\ansys\\AppData\\Local\\Temp\\ipykernel_1556\\450015450.py\", line 14, in <module>\n",
      "    edb = pyedb.Edb(edbpath=aedb_path, edbversion=edb_version)\n",
      "  File \"C:\\actions-runner\\_work\\pyedb\\pyedb\\.venv\\lib\\site-packages\\pyedb\\generic\\design_types.py\", line 110, in Edb\n",
      "    return app(\n",
      "  File \"C:\\actions-runner\\_work\\pyedb\\pyedb\\.venv\\lib\\site-packages\\pyedb\\dotnet\\edb.py\", line 196, in __init__\n",
      "    Database.__init__(self, edbversion=edbversion, student_version=student_version)\n",
      "  File \"C:\\actions-runner\\_work\\pyedb\\pyedb\\.venv\\lib\\site-packages\\pyedb\\dotnet\\edb_core\\dotnet\\database.py\", line 802, in __init__\n",
      "    EdbDotNet.__init__(self, edbversion=edbversion, student_version=student_version)\n",
      "  File \"C:\\actions-runner\\_work\\pyedb\\pyedb\\.venv\\lib\\site-packages\\pyedb\\dotnet\\edb_core\\dotnet\\database.py\", line 710, in __init__\n",
      "    self._logger.info(\"legacy v%s\", __version__)\n",
      "  File \"C:\\actions-runner\\_work\\pyedb\\pyedb\\.venv\\lib\\site-packages\\pyedb\\edb_logger.py\", line 346, in info\n",
      "    return self._log_on_handler(0, msg, *args, **kwargs)\n",
      "  File \"C:\\actions-runner\\_work\\pyedb\\pyedb\\.venv\\lib\\site-packages\\pyedb\\edb_logger.py\", line 293, in _log_on_handler\n",
      "    self._global.info(message_text, *args, **kwargs)\n",
      "Message: 'legacy v%s'\n",
      "Arguments: ('0.26.3',)\n",
      "--- Logging error ---\n",
      "Traceback (most recent call last):\n",
      "  File \"C:\\actions-runner\\_work\\_tool\\Python\\3.10.11\\x64\\lib\\logging\\handlers.py\", line 74, in emit\n",
      "    self.doRollover()\n",
      "  File \"C:\\actions-runner\\_work\\_tool\\Python\\3.10.11\\x64\\lib\\logging\\handlers.py\", line 179, in doRollover\n",
      "    self.rotate(self.baseFilename, dfn)\n",
      "  File \"C:\\actions-runner\\_work\\_tool\\Python\\3.10.11\\x64\\lib\\logging\\handlers.py\", line 115, in rotate\n",
      "    os.rename(source, dest)\n",
      "PermissionError: [WinError 32] The process cannot access the file because it is being used by another process: 'C:\\\\Users\\\\ansys\\\\AppData\\\\Local\\\\Temp\\\\pyedb_ansys.log' -> 'C:\\\\Users\\\\ansys\\\\AppData\\\\Local\\\\Temp\\\\pyedb_ansys.log.1'\n",
      "Call stack:\n",
      "  File \"C:\\actions-runner\\_work\\_tool\\Python\\3.10.11\\x64\\lib\\runpy.py\", line 196, in _run_module_as_main\n",
      "    return _run_code(code, main_globals, None,\n",
      "  File \"C:\\actions-runner\\_work\\_tool\\Python\\3.10.11\\x64\\lib\\runpy.py\", line 86, in _run_code\n",
      "    exec(code, run_globals)\n",
      "  File \"C:\\actions-runner\\_work\\pyedb\\pyedb\\.venv\\lib\\site-packages\\ipykernel_launcher.py\", line 18, in <module>\n",
      "    app.launch_new_instance()\n",
      "  File \"C:\\actions-runner\\_work\\pyedb\\pyedb\\.venv\\lib\\site-packages\\traitlets\\config\\application.py\", line 1075, in launch_instance\n",
      "    app.start()\n",
      "  File \"C:\\actions-runner\\_work\\pyedb\\pyedb\\.venv\\lib\\site-packages\\ipykernel\\kernelapp.py\", line 739, in start\n",
      "    self.io_loop.start()\n",
      "  File \"C:\\actions-runner\\_work\\pyedb\\pyedb\\.venv\\lib\\site-packages\\tornado\\platform\\asyncio.py\", line 205, in start\n",
      "    self.asyncio_loop.run_forever()\n",
      "  File \"C:\\actions-runner\\_work\\_tool\\Python\\3.10.11\\x64\\lib\\asyncio\\base_events.py\", line 603, in run_forever\n",
      "    self._run_once()\n",
      "  File \"C:\\actions-runner\\_work\\_tool\\Python\\3.10.11\\x64\\lib\\asyncio\\base_events.py\", line 1909, in _run_once\n",
      "    handle._run()\n",
      "  File \"C:\\actions-runner\\_work\\_tool\\Python\\3.10.11\\x64\\lib\\asyncio\\events.py\", line 80, in _run\n",
      "    self._context.run(self._callback, *self._args)\n",
      "  File \"C:\\actions-runner\\_work\\pyedb\\pyedb\\.venv\\lib\\site-packages\\ipykernel\\kernelbase.py\", line 545, in dispatch_queue\n",
      "    await self.process_one()\n",
      "  File \"C:\\actions-runner\\_work\\pyedb\\pyedb\\.venv\\lib\\site-packages\\ipykernel\\kernelbase.py\", line 534, in process_one\n",
      "    await dispatch(*args)\n",
      "  File \"C:\\actions-runner\\_work\\pyedb\\pyedb\\.venv\\lib\\site-packages\\ipykernel\\kernelbase.py\", line 437, in dispatch_shell\n",
      "    await result\n",
      "  File \"C:\\actions-runner\\_work\\pyedb\\pyedb\\.venv\\lib\\site-packages\\ipykernel\\ipkernel.py\", line 362, in execute_request\n",
      "    await super().execute_request(stream, ident, parent)\n",
      "  File \"C:\\actions-runner\\_work\\pyedb\\pyedb\\.venv\\lib\\site-packages\\ipykernel\\kernelbase.py\", line 778, in execute_request\n",
      "    reply_content = await reply_content\n",
      "  File \"C:\\actions-runner\\_work\\pyedb\\pyedb\\.venv\\lib\\site-packages\\ipykernel\\ipkernel.py\", line 449, in do_execute\n",
      "    res = shell.run_cell(\n",
      "  File \"C:\\actions-runner\\_work\\pyedb\\pyedb\\.venv\\lib\\site-packages\\ipykernel\\zmqshell.py\", line 549, in run_cell\n",
      "    return super().run_cell(*args, **kwargs)\n",
      "  File \"C:\\actions-runner\\_work\\pyedb\\pyedb\\.venv\\lib\\site-packages\\IPython\\core\\interactiveshell.py\", line 3075, in run_cell\n",
      "    result = self._run_cell(\n",
      "  File \"C:\\actions-runner\\_work\\pyedb\\pyedb\\.venv\\lib\\site-packages\\IPython\\core\\interactiveshell.py\", line 3130, in _run_cell\n",
      "    result = runner(coro)\n",
      "  File \"C:\\actions-runner\\_work\\pyedb\\pyedb\\.venv\\lib\\site-packages\\IPython\\core\\async_helpers.py\", line 128, in _pseudo_sync_runner\n",
      "    coro.send(None)\n",
      "  File \"C:\\actions-runner\\_work\\pyedb\\pyedb\\.venv\\lib\\site-packages\\IPython\\core\\interactiveshell.py\", line 3334, in run_cell_async\n",
      "    has_raised = await self.run_ast_nodes(code_ast.body, cell_name,\n",
      "  File \"C:\\actions-runner\\_work\\pyedb\\pyedb\\.venv\\lib\\site-packages\\IPython\\core\\interactiveshell.py\", line 3517, in run_ast_nodes\n",
      "    if await self.run_code(code, result, async_=asy):\n",
      "  File \"C:\\actions-runner\\_work\\pyedb\\pyedb\\.venv\\lib\\site-packages\\IPython\\core\\interactiveshell.py\", line 3577, in run_code\n",
      "    exec(code_obj, self.user_global_ns, self.user_ns)\n",
      "  File \"C:\\Users\\ansys\\AppData\\Local\\Temp\\ipykernel_1556\\450015450.py\", line 14, in <module>\n",
      "    edb = pyedb.Edb(edbpath=aedb_path, edbversion=edb_version)\n",
      "  File \"C:\\actions-runner\\_work\\pyedb\\pyedb\\.venv\\lib\\site-packages\\pyedb\\generic\\design_types.py\", line 110, in Edb\n",
      "    return app(\n",
      "  File \"C:\\actions-runner\\_work\\pyedb\\pyedb\\.venv\\lib\\site-packages\\pyedb\\dotnet\\edb.py\", line 196, in __init__\n",
      "    Database.__init__(self, edbversion=edbversion, student_version=student_version)\n",
      "  File \"C:\\actions-runner\\_work\\pyedb\\pyedb\\.venv\\lib\\site-packages\\pyedb\\dotnet\\edb_core\\dotnet\\database.py\", line 802, in __init__\n",
      "    EdbDotNet.__init__(self, edbversion=edbversion, student_version=student_version)\n",
      "  File \"C:\\actions-runner\\_work\\pyedb\\pyedb\\.venv\\lib\\site-packages\\pyedb\\dotnet\\edb_core\\dotnet\\database.py\", line 711, in __init__\n",
      "    self._logger.info(\"Python version %s\", sys.version)\n",
      "  File \"C:\\actions-runner\\_work\\pyedb\\pyedb\\.venv\\lib\\site-packages\\pyedb\\edb_logger.py\", line 346, in info\n",
      "    return self._log_on_handler(0, msg, *args, **kwargs)\n",
      "  File \"C:\\actions-runner\\_work\\pyedb\\pyedb\\.venv\\lib\\site-packages\\pyedb\\edb_logger.py\", line 293, in _log_on_handler\n",
      "    self._global.info(message_text, *args, **kwargs)\n",
      "Message: 'Python version %s'\n",
      "Arguments: ('3.10.11 (tags/v3.10.11:7d4cc5a, Apr  5 2023, 00:38:17) [MSC v.1929 64 bit (AMD64)]',)\n"
     ]
    },
    {
     "name": "stdout",
     "output_type": "stream",
     "text": [
      "PyEDB INFO: EDB C:\\Users\\ansys\\AppData\\Local\\Temp\\tmp9qtix9bh.ansys\\create_via.aedb created correctly.\n"
     ]
    },
    {
     "name": "stdout",
     "output_type": "stream",
     "text": [
      "PyEDB INFO: EDB initialized.\n"
     ]
    },
    {
     "name": "stderr",
     "output_type": "stream",
     "text": [
      "--- Logging error ---\n",
      "Traceback (most recent call last):\n",
      "  File \"C:\\actions-runner\\_work\\_tool\\Python\\3.10.11\\x64\\lib\\logging\\handlers.py\", line 74, in emit\n",
      "    self.doRollover()\n",
      "  File \"C:\\actions-runner\\_work\\_tool\\Python\\3.10.11\\x64\\lib\\logging\\handlers.py\", line 179, in doRollover\n",
      "    self.rotate(self.baseFilename, dfn)\n",
      "  File \"C:\\actions-runner\\_work\\_tool\\Python\\3.10.11\\x64\\lib\\logging\\handlers.py\", line 115, in rotate\n",
      "    os.rename(source, dest)\n",
      "PermissionError: [WinError 32] The process cannot access the file because it is being used by another process: 'C:\\\\Users\\\\ansys\\\\AppData\\\\Local\\\\Temp\\\\pyedb_ansys.log' -> 'C:\\\\Users\\\\ansys\\\\AppData\\\\Local\\\\Temp\\\\pyedb_ansys.log.1'\n",
      "Call stack:\n",
      "  File \"C:\\actions-runner\\_work\\_tool\\Python\\3.10.11\\x64\\lib\\runpy.py\", line 196, in _run_module_as_main\n",
      "    return _run_code(code, main_globals, None,\n",
      "  File \"C:\\actions-runner\\_work\\_tool\\Python\\3.10.11\\x64\\lib\\runpy.py\", line 86, in _run_code\n",
      "    exec(code, run_globals)\n",
      "  File \"C:\\actions-runner\\_work\\pyedb\\pyedb\\.venv\\lib\\site-packages\\ipykernel_launcher.py\", line 18, in <module>\n",
      "    app.launch_new_instance()\n",
      "  File \"C:\\actions-runner\\_work\\pyedb\\pyedb\\.venv\\lib\\site-packages\\traitlets\\config\\application.py\", line 1075, in launch_instance\n",
      "    app.start()\n",
      "  File \"C:\\actions-runner\\_work\\pyedb\\pyedb\\.venv\\lib\\site-packages\\ipykernel\\kernelapp.py\", line 739, in start\n",
      "    self.io_loop.start()\n",
      "  File \"C:\\actions-runner\\_work\\pyedb\\pyedb\\.venv\\lib\\site-packages\\tornado\\platform\\asyncio.py\", line 205, in start\n",
      "    self.asyncio_loop.run_forever()\n",
      "  File \"C:\\actions-runner\\_work\\_tool\\Python\\3.10.11\\x64\\lib\\asyncio\\base_events.py\", line 603, in run_forever\n",
      "    self._run_once()\n",
      "  File \"C:\\actions-runner\\_work\\_tool\\Python\\3.10.11\\x64\\lib\\asyncio\\base_events.py\", line 1909, in _run_once\n",
      "    handle._run()\n",
      "  File \"C:\\actions-runner\\_work\\_tool\\Python\\3.10.11\\x64\\lib\\asyncio\\events.py\", line 80, in _run\n",
      "    self._context.run(self._callback, *self._args)\n",
      "  File \"C:\\actions-runner\\_work\\pyedb\\pyedb\\.venv\\lib\\site-packages\\ipykernel\\kernelbase.py\", line 545, in dispatch_queue\n",
      "    await self.process_one()\n",
      "  File \"C:\\actions-runner\\_work\\pyedb\\pyedb\\.venv\\lib\\site-packages\\ipykernel\\kernelbase.py\", line 534, in process_one\n",
      "    await dispatch(*args)\n",
      "  File \"C:\\actions-runner\\_work\\pyedb\\pyedb\\.venv\\lib\\site-packages\\ipykernel\\kernelbase.py\", line 437, in dispatch_shell\n",
      "    await result\n",
      "  File \"C:\\actions-runner\\_work\\pyedb\\pyedb\\.venv\\lib\\site-packages\\ipykernel\\ipkernel.py\", line 362, in execute_request\n",
      "    await super().execute_request(stream, ident, parent)\n",
      "  File \"C:\\actions-runner\\_work\\pyedb\\pyedb\\.venv\\lib\\site-packages\\ipykernel\\kernelbase.py\", line 778, in execute_request\n",
      "    reply_content = await reply_content\n",
      "  File \"C:\\actions-runner\\_work\\pyedb\\pyedb\\.venv\\lib\\site-packages\\ipykernel\\ipkernel.py\", line 449, in do_execute\n",
      "    res = shell.run_cell(\n",
      "  File \"C:\\actions-runner\\_work\\pyedb\\pyedb\\.venv\\lib\\site-packages\\ipykernel\\zmqshell.py\", line 549, in run_cell\n",
      "    return super().run_cell(*args, **kwargs)\n",
      "  File \"C:\\actions-runner\\_work\\pyedb\\pyedb\\.venv\\lib\\site-packages\\IPython\\core\\interactiveshell.py\", line 3075, in run_cell\n",
      "    result = self._run_cell(\n",
      "  File \"C:\\actions-runner\\_work\\pyedb\\pyedb\\.venv\\lib\\site-packages\\IPython\\core\\interactiveshell.py\", line 3130, in _run_cell\n",
      "    result = runner(coro)\n",
      "  File \"C:\\actions-runner\\_work\\pyedb\\pyedb\\.venv\\lib\\site-packages\\IPython\\core\\async_helpers.py\", line 128, in _pseudo_sync_runner\n",
      "    coro.send(None)\n",
      "  File \"C:\\actions-runner\\_work\\pyedb\\pyedb\\.venv\\lib\\site-packages\\IPython\\core\\interactiveshell.py\", line 3334, in run_cell_async\n",
      "    has_raised = await self.run_ast_nodes(code_ast.body, cell_name,\n",
      "  File \"C:\\actions-runner\\_work\\pyedb\\pyedb\\.venv\\lib\\site-packages\\IPython\\core\\interactiveshell.py\", line 3517, in run_ast_nodes\n",
      "    if await self.run_code(code, result, async_=asy):\n",
      "  File \"C:\\actions-runner\\_work\\pyedb\\pyedb\\.venv\\lib\\site-packages\\IPython\\core\\interactiveshell.py\", line 3577, in run_code\n",
      "    exec(code_obj, self.user_global_ns, self.user_ns)\n",
      "  File \"C:\\Users\\ansys\\AppData\\Local\\Temp\\ipykernel_1556\\450015450.py\", line 14, in <module>\n",
      "    edb = pyedb.Edb(edbpath=aedb_path, edbversion=edb_version)\n",
      "  File \"C:\\actions-runner\\_work\\pyedb\\pyedb\\.venv\\lib\\site-packages\\pyedb\\generic\\design_types.py\", line 110, in Edb\n",
      "    return app(\n",
      "  File \"C:\\actions-runner\\_work\\pyedb\\pyedb\\.venv\\lib\\site-packages\\pyedb\\dotnet\\edb.py\", line 271, in __init__\n",
      "    self.logger.info(\"EDB %s created correctly.\", self.edbpath)\n",
      "  File \"C:\\actions-runner\\_work\\pyedb\\pyedb\\.venv\\lib\\site-packages\\pyedb\\edb_logger.py\", line 346, in info\n",
      "    return self._log_on_handler(0, msg, *args, **kwargs)\n",
      "  File \"C:\\actions-runner\\_work\\pyedb\\pyedb\\.venv\\lib\\site-packages\\pyedb\\edb_logger.py\", line 293, in _log_on_handler\n",
      "    self._global.info(message_text, *args, **kwargs)\n",
      "Message: 'EDB %s created correctly.'\n",
      "Arguments: ('C:\\\\Users\\\\ansys\\\\AppData\\\\Local\\\\Temp\\\\tmp9qtix9bh.ansys\\\\create_via.aedb',)\n",
      "--- Logging error ---\n",
      "Traceback (most recent call last):\n",
      "  File \"C:\\actions-runner\\_work\\_tool\\Python\\3.10.11\\x64\\lib\\logging\\handlers.py\", line 74, in emit\n",
      "    self.doRollover()\n",
      "  File \"C:\\actions-runner\\_work\\_tool\\Python\\3.10.11\\x64\\lib\\logging\\handlers.py\", line 179, in doRollover\n",
      "    self.rotate(self.baseFilename, dfn)\n",
      "  File \"C:\\actions-runner\\_work\\_tool\\Python\\3.10.11\\x64\\lib\\logging\\handlers.py\", line 115, in rotate\n",
      "    os.rename(source, dest)\n",
      "PermissionError: [WinError 32] The process cannot access the file because it is being used by another process: 'C:\\\\Users\\\\ansys\\\\AppData\\\\Local\\\\Temp\\\\pyedb_ansys.log' -> 'C:\\\\Users\\\\ansys\\\\AppData\\\\Local\\\\Temp\\\\pyedb_ansys.log.1'\n",
      "Call stack:\n",
      "  File \"C:\\actions-runner\\_work\\_tool\\Python\\3.10.11\\x64\\lib\\runpy.py\", line 196, in _run_module_as_main\n",
      "    return _run_code(code, main_globals, None,\n",
      "  File \"C:\\actions-runner\\_work\\_tool\\Python\\3.10.11\\x64\\lib\\runpy.py\", line 86, in _run_code\n",
      "    exec(code, run_globals)\n",
      "  File \"C:\\actions-runner\\_work\\pyedb\\pyedb\\.venv\\lib\\site-packages\\ipykernel_launcher.py\", line 18, in <module>\n",
      "    app.launch_new_instance()\n",
      "  File \"C:\\actions-runner\\_work\\pyedb\\pyedb\\.venv\\lib\\site-packages\\traitlets\\config\\application.py\", line 1075, in launch_instance\n",
      "    app.start()\n",
      "  File \"C:\\actions-runner\\_work\\pyedb\\pyedb\\.venv\\lib\\site-packages\\ipykernel\\kernelapp.py\", line 739, in start\n",
      "    self.io_loop.start()\n",
      "  File \"C:\\actions-runner\\_work\\pyedb\\pyedb\\.venv\\lib\\site-packages\\tornado\\platform\\asyncio.py\", line 205, in start\n",
      "    self.asyncio_loop.run_forever()\n",
      "  File \"C:\\actions-runner\\_work\\_tool\\Python\\3.10.11\\x64\\lib\\asyncio\\base_events.py\", line 603, in run_forever\n",
      "    self._run_once()\n",
      "  File \"C:\\actions-runner\\_work\\_tool\\Python\\3.10.11\\x64\\lib\\asyncio\\base_events.py\", line 1909, in _run_once\n",
      "    handle._run()\n",
      "  File \"C:\\actions-runner\\_work\\_tool\\Python\\3.10.11\\x64\\lib\\asyncio\\events.py\", line 80, in _run\n",
      "    self._context.run(self._callback, *self._args)\n",
      "  File \"C:\\actions-runner\\_work\\pyedb\\pyedb\\.venv\\lib\\site-packages\\ipykernel\\kernelbase.py\", line 545, in dispatch_queue\n",
      "    await self.process_one()\n",
      "  File \"C:\\actions-runner\\_work\\pyedb\\pyedb\\.venv\\lib\\site-packages\\ipykernel\\kernelbase.py\", line 534, in process_one\n",
      "    await dispatch(*args)\n",
      "  File \"C:\\actions-runner\\_work\\pyedb\\pyedb\\.venv\\lib\\site-packages\\ipykernel\\kernelbase.py\", line 437, in dispatch_shell\n",
      "    await result\n",
      "  File \"C:\\actions-runner\\_work\\pyedb\\pyedb\\.venv\\lib\\site-packages\\ipykernel\\ipkernel.py\", line 362, in execute_request\n",
      "    await super().execute_request(stream, ident, parent)\n",
      "  File \"C:\\actions-runner\\_work\\pyedb\\pyedb\\.venv\\lib\\site-packages\\ipykernel\\kernelbase.py\", line 778, in execute_request\n",
      "    reply_content = await reply_content\n",
      "  File \"C:\\actions-runner\\_work\\pyedb\\pyedb\\.venv\\lib\\site-packages\\ipykernel\\ipkernel.py\", line 449, in do_execute\n",
      "    res = shell.run_cell(\n",
      "  File \"C:\\actions-runner\\_work\\pyedb\\pyedb\\.venv\\lib\\site-packages\\ipykernel\\zmqshell.py\", line 549, in run_cell\n",
      "    return super().run_cell(*args, **kwargs)\n",
      "  File \"C:\\actions-runner\\_work\\pyedb\\pyedb\\.venv\\lib\\site-packages\\IPython\\core\\interactiveshell.py\", line 3075, in run_cell\n",
      "    result = self._run_cell(\n",
      "  File \"C:\\actions-runner\\_work\\pyedb\\pyedb\\.venv\\lib\\site-packages\\IPython\\core\\interactiveshell.py\", line 3130, in _run_cell\n",
      "    result = runner(coro)\n",
      "  File \"C:\\actions-runner\\_work\\pyedb\\pyedb\\.venv\\lib\\site-packages\\IPython\\core\\async_helpers.py\", line 128, in _pseudo_sync_runner\n",
      "    coro.send(None)\n",
      "  File \"C:\\actions-runner\\_work\\pyedb\\pyedb\\.venv\\lib\\site-packages\\IPython\\core\\interactiveshell.py\", line 3334, in run_cell_async\n",
      "    has_raised = await self.run_ast_nodes(code_ast.body, cell_name,\n",
      "  File \"C:\\actions-runner\\_work\\pyedb\\pyedb\\.venv\\lib\\site-packages\\IPython\\core\\interactiveshell.py\", line 3517, in run_ast_nodes\n",
      "    if await self.run_code(code, result, async_=asy):\n",
      "  File \"C:\\actions-runner\\_work\\pyedb\\pyedb\\.venv\\lib\\site-packages\\IPython\\core\\interactiveshell.py\", line 3577, in run_code\n",
      "    exec(code_obj, self.user_global_ns, self.user_ns)\n",
      "  File \"C:\\Users\\ansys\\AppData\\Local\\Temp\\ipykernel_1556\\450015450.py\", line 14, in <module>\n",
      "    edb = pyedb.Edb(edbpath=aedb_path, edbversion=edb_version)\n",
      "  File \"C:\\actions-runner\\_work\\pyedb\\pyedb\\.venv\\lib\\site-packages\\pyedb\\generic\\design_types.py\", line 110, in Edb\n",
      "    return app(\n",
      "  File \"C:\\actions-runner\\_work\\pyedb\\pyedb\\.venv\\lib\\site-packages\\pyedb\\dotnet\\edb.py\", line 278, in __init__\n",
      "    self.logger.info(\"EDB initialized.\")\n",
      "  File \"C:\\actions-runner\\_work\\pyedb\\pyedb\\.venv\\lib\\site-packages\\pyedb\\edb_logger.py\", line 346, in info\n",
      "    return self._log_on_handler(0, msg, *args, **kwargs)\n",
      "  File \"C:\\actions-runner\\_work\\pyedb\\pyedb\\.venv\\lib\\site-packages\\pyedb\\edb_logger.py\", line 293, in _log_on_handler\n",
      "    self._global.info(message_text, *args, **kwargs)\n",
      "Message: 'EDB initialized.'\n",
      "Arguments: ()\n"
     ]
    }
   ],
   "source": [
    "import os\n",
    "import tempfile\n",
    "\n",
    "import pyedb\n",
    "\n",
    "temp_dir = tempfile.TemporaryDirectory(suffix=\".ansys\")\n",
    "aedb_path = os.path.join(temp_dir.name, \"create_via.aedb\")\n",
    "print(f\"AEDB file path: {aedb_path}\")\n",
    "\n",
    "# Select EDB version (change it manually if needed, e.g. \"2024.2\")\n",
    "edb_version = \"2024.2\"\n",
    "print(f\"EDB version: {edb_version}\")\n",
    "\n",
    "edb = pyedb.Edb(edbpath=aedb_path, edbversion=edb_version)"
   ]
  },
  {
   "cell_type": "markdown",
   "id": "72455d65",
   "metadata": {},
   "source": [
    "## Add stackup layers\n",
    "Add stackup layers.\n",
    "A stackup can be created layer by layer or imported from a CSV file or XML file."
   ]
  },
  {
   "cell_type": "code",
   "execution_count": 2,
   "id": "49dd6ac1",
   "metadata": {
    "execution": {
     "iopub.execute_input": "2024-09-04T08:19:32.152211Z",
     "iopub.status.busy": "2024-09-04T08:19:32.152211Z",
     "iopub.status.idle": "2024-09-04T08:19:32.214661Z",
     "shell.execute_reply": "2024-09-04T08:19:32.214661Z"
    }
   },
   "outputs": [
    {
     "data": {
      "text/plain": [
       "<pyedb.dotnet.edb_core.edb_data.layer_data.StackupLayerEdbClass at 0x26026220cc0>"
      ]
     },
     "execution_count": 2,
     "metadata": {},
     "output_type": "execute_result"
    }
   ],
   "source": [
    "edb.stackup.add_layer(\"GND\")\n",
    "edb.stackup.add_layer(\"Diel\", \"GND\", layer_type=\"dielectric\", thickness=\"0.1mm\", material=\"FR4_epoxy\")\n",
    "edb.stackup.add_layer(\"TOP\", \"Diel\", thickness=\"0.05mm\")"
   ]
  },
  {
   "cell_type": "markdown",
   "id": "914e5011",
   "metadata": {},
   "source": [
    "## Create signal net and ground planes\n",
    "Create a signal net and ground planes."
   ]
  },
  {
   "cell_type": "code",
   "execution_count": 3,
   "id": "6fae17d1",
   "metadata": {
    "execution": {
     "iopub.execute_input": "2024-09-04T08:19:32.214661Z",
     "iopub.status.busy": "2024-09-04T08:19:32.214661Z",
     "iopub.status.idle": "2024-09-04T08:19:32.277162Z",
     "shell.execute_reply": "2024-09-04T08:19:32.277162Z"
    },
    "lines_to_next_cell": 2
   },
   "outputs": [
    {
     "data": {
      "text/plain": [
       "<pyedb.dotnet.edb_core.edb_data.primitives_data.EdbPolygon at 0x26026232d80>"
      ]
     },
     "execution_count": 3,
     "metadata": {},
     "output_type": "execute_result"
    }
   ],
   "source": [
    "points = [[0.0, 0], [100e-3, 0.0]]\n",
    "edb.modeler.create_trace(points, \"TOP\", width=1e-3)\n",
    "points = [[0.0, 1e-3], [0.0, 10e-3], [100e-3, 10e-3], [100e-3, 1e-3], [0.0, 1e-3]]\n",
    "edb.modeler.create_polygon(points, \"TOP\")\n",
    "points = [[0.0, -1e-3], [0.0, -10e-3], [100e-3, -10e-3], [100e-3, -1e-3], [0.0, -1e-3]]\n",
    "edb.modeler.create_polygon(points, \"TOP\")"
   ]
  },
  {
   "cell_type": "markdown",
   "id": "607c6cd9",
   "metadata": {},
   "source": [
    "## Create vias with parametric positions\n",
    "Create vias with parametric positions."
   ]
  },
  {
   "cell_type": "code",
   "execution_count": 4,
   "id": "39027d7a",
   "metadata": {
    "execution": {
     "iopub.execute_input": "2024-09-04T08:19:32.277162Z",
     "iopub.status.busy": "2024-09-04T08:19:32.277162Z",
     "iopub.status.idle": "2024-09-04T08:19:32.402095Z",
     "shell.execute_reply": "2024-09-04T08:19:32.402095Z"
    },
    "lines_to_next_cell": 2
   },
   "outputs": [
    {
     "name": "stdout",
     "output_type": "stream",
     "text": [
      "PyEDB INFO: Padstack MyVia create correctly\n"
     ]
    },
    {
     "name": "stderr",
     "output_type": "stream",
     "text": [
      "--- Logging error ---\n",
      "Traceback (most recent call last):\n",
      "  File \"C:\\actions-runner\\_work\\_tool\\Python\\3.10.11\\x64\\lib\\logging\\handlers.py\", line 74, in emit\n",
      "    self.doRollover()\n",
      "  File \"C:\\actions-runner\\_work\\_tool\\Python\\3.10.11\\x64\\lib\\logging\\handlers.py\", line 179, in doRollover\n",
      "    self.rotate(self.baseFilename, dfn)\n",
      "  File \"C:\\actions-runner\\_work\\_tool\\Python\\3.10.11\\x64\\lib\\logging\\handlers.py\", line 115, in rotate\n",
      "    os.rename(source, dest)\n",
      "PermissionError: [WinError 32] The process cannot access the file because it is being used by another process: 'C:\\\\Users\\\\ansys\\\\AppData\\\\Local\\\\Temp\\\\pyedb_ansys.log' -> 'C:\\\\Users\\\\ansys\\\\AppData\\\\Local\\\\Temp\\\\pyedb_ansys.log.1'\n",
      "Call stack:\n",
      "  File \"C:\\actions-runner\\_work\\_tool\\Python\\3.10.11\\x64\\lib\\runpy.py\", line 196, in _run_module_as_main\n",
      "    return _run_code(code, main_globals, None,\n",
      "  File \"C:\\actions-runner\\_work\\_tool\\Python\\3.10.11\\x64\\lib\\runpy.py\", line 86, in _run_code\n",
      "    exec(code, run_globals)\n",
      "  File \"C:\\actions-runner\\_work\\pyedb\\pyedb\\.venv\\lib\\site-packages\\ipykernel_launcher.py\", line 18, in <module>\n",
      "    app.launch_new_instance()\n",
      "  File \"C:\\actions-runner\\_work\\pyedb\\pyedb\\.venv\\lib\\site-packages\\traitlets\\config\\application.py\", line 1075, in launch_instance\n",
      "    app.start()\n",
      "  File \"C:\\actions-runner\\_work\\pyedb\\pyedb\\.venv\\lib\\site-packages\\ipykernel\\kernelapp.py\", line 739, in start\n",
      "    self.io_loop.start()\n",
      "  File \"C:\\actions-runner\\_work\\pyedb\\pyedb\\.venv\\lib\\site-packages\\tornado\\platform\\asyncio.py\", line 205, in start\n",
      "    self.asyncio_loop.run_forever()\n",
      "  File \"C:\\actions-runner\\_work\\_tool\\Python\\3.10.11\\x64\\lib\\asyncio\\base_events.py\", line 603, in run_forever\n",
      "    self._run_once()\n",
      "  File \"C:\\actions-runner\\_work\\_tool\\Python\\3.10.11\\x64\\lib\\asyncio\\base_events.py\", line 1909, in _run_once\n",
      "    handle._run()\n",
      "  File \"C:\\actions-runner\\_work\\_tool\\Python\\3.10.11\\x64\\lib\\asyncio\\events.py\", line 80, in _run\n",
      "    self._context.run(self._callback, *self._args)\n",
      "  File \"C:\\actions-runner\\_work\\pyedb\\pyedb\\.venv\\lib\\site-packages\\ipykernel\\kernelbase.py\", line 545, in dispatch_queue\n",
      "    await self.process_one()\n",
      "  File \"C:\\actions-runner\\_work\\pyedb\\pyedb\\.venv\\lib\\site-packages\\ipykernel\\kernelbase.py\", line 534, in process_one\n",
      "    await dispatch(*args)\n",
      "  File \"C:\\actions-runner\\_work\\pyedb\\pyedb\\.venv\\lib\\site-packages\\ipykernel\\kernelbase.py\", line 437, in dispatch_shell\n",
      "    await result\n",
      "  File \"C:\\actions-runner\\_work\\pyedb\\pyedb\\.venv\\lib\\site-packages\\ipykernel\\ipkernel.py\", line 362, in execute_request\n",
      "    await super().execute_request(stream, ident, parent)\n",
      "  File \"C:\\actions-runner\\_work\\pyedb\\pyedb\\.venv\\lib\\site-packages\\ipykernel\\kernelbase.py\", line 778, in execute_request\n",
      "    reply_content = await reply_content\n",
      "  File \"C:\\actions-runner\\_work\\pyedb\\pyedb\\.venv\\lib\\site-packages\\ipykernel\\ipkernel.py\", line 449, in do_execute\n",
      "    res = shell.run_cell(\n",
      "  File \"C:\\actions-runner\\_work\\pyedb\\pyedb\\.venv\\lib\\site-packages\\ipykernel\\zmqshell.py\", line 549, in run_cell\n",
      "    return super().run_cell(*args, **kwargs)\n",
      "  File \"C:\\actions-runner\\_work\\pyedb\\pyedb\\.venv\\lib\\site-packages\\IPython\\core\\interactiveshell.py\", line 3075, in run_cell\n",
      "    result = self._run_cell(\n",
      "  File \"C:\\actions-runner\\_work\\pyedb\\pyedb\\.venv\\lib\\site-packages\\IPython\\core\\interactiveshell.py\", line 3130, in _run_cell\n",
      "    result = runner(coro)\n",
      "  File \"C:\\actions-runner\\_work\\pyedb\\pyedb\\.venv\\lib\\site-packages\\IPython\\core\\async_helpers.py\", line 128, in _pseudo_sync_runner\n",
      "    coro.send(None)\n",
      "  File \"C:\\actions-runner\\_work\\pyedb\\pyedb\\.venv\\lib\\site-packages\\IPython\\core\\interactiveshell.py\", line 3334, in run_cell_async\n",
      "    has_raised = await self.run_ast_nodes(code_ast.body, cell_name,\n",
      "  File \"C:\\actions-runner\\_work\\pyedb\\pyedb\\.venv\\lib\\site-packages\\IPython\\core\\interactiveshell.py\", line 3517, in run_ast_nodes\n",
      "    if await self.run_code(code, result, async_=asy):\n",
      "  File \"C:\\actions-runner\\_work\\pyedb\\pyedb\\.venv\\lib\\site-packages\\IPython\\core\\interactiveshell.py\", line 3577, in run_code\n",
      "    exec(code_obj, self.user_global_ns, self.user_ns)\n",
      "  File \"C:\\Users\\ansys\\AppData\\Local\\Temp\\ipykernel_1556\\2951509181.py\", line 1, in <module>\n",
      "    edb.padstacks.create(\"MyVia\")\n",
      "  File \"C:\\actions-runner\\_work\\pyedb\\pyedb\\.venv\\lib\\site-packages\\pyedb\\dotnet\\edb_core\\padstack.py\", line 1074, in create\n",
      "    self._logger.info(\"Padstack %s create correctly\", padstackname)\n",
      "  File \"C:\\actions-runner\\_work\\pyedb\\pyedb\\.venv\\lib\\site-packages\\pyedb\\edb_logger.py\", line 346, in info\n",
      "    return self._log_on_handler(0, msg, *args, **kwargs)\n",
      "  File \"C:\\actions-runner\\_work\\pyedb\\pyedb\\.venv\\lib\\site-packages\\pyedb\\edb_logger.py\", line 293, in _log_on_handler\n",
      "    self._global.info(message_text, *args, **kwargs)\n",
      "Message: 'Padstack %s create correctly'\n",
      "Arguments: ('MyVia',)\n"
     ]
    },
    {
     "data": {
      "text/plain": [
       "<pyedb.dotnet.edb_core.edb_data.padstacks_data.EDBPadstackInstance at 0x26026313a60>"
      ]
     },
     "execution_count": 4,
     "metadata": {},
     "output_type": "execute_result"
    }
   ],
   "source": [
    "edb.padstacks.create(\"MyVia\")\n",
    "edb.padstacks.place([5e-3, 5e-3], \"MyVia\")\n",
    "edb.padstacks.place([15e-3, 5e-3], \"MyVia\")\n",
    "edb.padstacks.place([35e-3, 5e-3], \"MyVia\")\n",
    "edb.padstacks.place([45e-3, 5e-3], \"MyVia\")\n",
    "edb.padstacks.place([5e-3, -5e-3], \"MyVia\")\n",
    "edb.padstacks.place([15e-3, -5e-3], \"MyVia\")\n",
    "edb.padstacks.place([35e-3, -5e-3], \"MyVia\")\n",
    "edb.padstacks.place([45e-3, -5e-3], \"MyVia\")"
   ]
  },
  {
   "cell_type": "markdown",
   "id": "88292b9c",
   "metadata": {},
   "source": [
    "## Generate geometry plot"
   ]
  },
  {
   "cell_type": "code",
   "execution_count": 5,
   "id": "17774e86",
   "metadata": {
    "execution": {
     "iopub.execute_input": "2024-09-04T08:19:32.402095Z",
     "iopub.status.busy": "2024-09-04T08:19:32.402095Z",
     "iopub.status.idle": "2024-09-04T08:19:32.480271Z",
     "shell.execute_reply": "2024-09-04T08:19:32.480271Z"
    }
   },
   "outputs": [
    {
     "name": "stdout",
     "output_type": "stream",
     "text": [
      "PyEDB INFO: Nets Point Generation time 0.031 seconds\n"
     ]
    },
    {
     "name": "stderr",
     "output_type": "stream",
     "text": [
      "--- Logging error ---\n",
      "Traceback (most recent call last):\n",
      "  File \"C:\\actions-runner\\_work\\_tool\\Python\\3.10.11\\x64\\lib\\logging\\handlers.py\", line 74, in emit\n",
      "    self.doRollover()\n",
      "  File \"C:\\actions-runner\\_work\\_tool\\Python\\3.10.11\\x64\\lib\\logging\\handlers.py\", line 179, in doRollover\n",
      "    self.rotate(self.baseFilename, dfn)\n",
      "  File \"C:\\actions-runner\\_work\\_tool\\Python\\3.10.11\\x64\\lib\\logging\\handlers.py\", line 115, in rotate\n",
      "    os.rename(source, dest)\n",
      "PermissionError: [WinError 32] The process cannot access the file because it is being used by another process: 'C:\\\\Users\\\\ansys\\\\AppData\\\\Local\\\\Temp\\\\pyedb_ansys.log' -> 'C:\\\\Users\\\\ansys\\\\AppData\\\\Local\\\\Temp\\\\pyedb_ansys.log.1'\n",
      "Call stack:\n",
      "  File \"C:\\actions-runner\\_work\\_tool\\Python\\3.10.11\\x64\\lib\\runpy.py\", line 196, in _run_module_as_main\n",
      "    return _run_code(code, main_globals, None,\n",
      "  File \"C:\\actions-runner\\_work\\_tool\\Python\\3.10.11\\x64\\lib\\runpy.py\", line 86, in _run_code\n",
      "    exec(code, run_globals)\n",
      "  File \"C:\\actions-runner\\_work\\pyedb\\pyedb\\.venv\\lib\\site-packages\\ipykernel_launcher.py\", line 18, in <module>\n",
      "    app.launch_new_instance()\n",
      "  File \"C:\\actions-runner\\_work\\pyedb\\pyedb\\.venv\\lib\\site-packages\\traitlets\\config\\application.py\", line 1075, in launch_instance\n",
      "    app.start()\n",
      "  File \"C:\\actions-runner\\_work\\pyedb\\pyedb\\.venv\\lib\\site-packages\\ipykernel\\kernelapp.py\", line 739, in start\n",
      "    self.io_loop.start()\n",
      "  File \"C:\\actions-runner\\_work\\pyedb\\pyedb\\.venv\\lib\\site-packages\\tornado\\platform\\asyncio.py\", line 205, in start\n",
      "    self.asyncio_loop.run_forever()\n",
      "  File \"C:\\actions-runner\\_work\\_tool\\Python\\3.10.11\\x64\\lib\\asyncio\\base_events.py\", line 603, in run_forever\n",
      "    self._run_once()\n",
      "  File \"C:\\actions-runner\\_work\\_tool\\Python\\3.10.11\\x64\\lib\\asyncio\\base_events.py\", line 1909, in _run_once\n",
      "    handle._run()\n",
      "  File \"C:\\actions-runner\\_work\\_tool\\Python\\3.10.11\\x64\\lib\\asyncio\\events.py\", line 80, in _run\n",
      "    self._context.run(self._callback, *self._args)\n",
      "  File \"C:\\actions-runner\\_work\\pyedb\\pyedb\\.venv\\lib\\site-packages\\ipykernel\\kernelbase.py\", line 545, in dispatch_queue\n",
      "    await self.process_one()\n",
      "  File \"C:\\actions-runner\\_work\\pyedb\\pyedb\\.venv\\lib\\site-packages\\ipykernel\\kernelbase.py\", line 534, in process_one\n",
      "    await dispatch(*args)\n",
      "  File \"C:\\actions-runner\\_work\\pyedb\\pyedb\\.venv\\lib\\site-packages\\ipykernel\\kernelbase.py\", line 437, in dispatch_shell\n",
      "    await result\n",
      "  File \"C:\\actions-runner\\_work\\pyedb\\pyedb\\.venv\\lib\\site-packages\\ipykernel\\ipkernel.py\", line 362, in execute_request\n",
      "    await super().execute_request(stream, ident, parent)\n",
      "  File \"C:\\actions-runner\\_work\\pyedb\\pyedb\\.venv\\lib\\site-packages\\ipykernel\\kernelbase.py\", line 778, in execute_request\n",
      "    reply_content = await reply_content\n",
      "  File \"C:\\actions-runner\\_work\\pyedb\\pyedb\\.venv\\lib\\site-packages\\ipykernel\\ipkernel.py\", line 449, in do_execute\n",
      "    res = shell.run_cell(\n",
      "  File \"C:\\actions-runner\\_work\\pyedb\\pyedb\\.venv\\lib\\site-packages\\ipykernel\\zmqshell.py\", line 549, in run_cell\n",
      "    return super().run_cell(*args, **kwargs)\n",
      "  File \"C:\\actions-runner\\_work\\pyedb\\pyedb\\.venv\\lib\\site-packages\\IPython\\core\\interactiveshell.py\", line 3075, in run_cell\n",
      "    result = self._run_cell(\n",
      "  File \"C:\\actions-runner\\_work\\pyedb\\pyedb\\.venv\\lib\\site-packages\\IPython\\core\\interactiveshell.py\", line 3130, in _run_cell\n",
      "    result = runner(coro)\n",
      "  File \"C:\\actions-runner\\_work\\pyedb\\pyedb\\.venv\\lib\\site-packages\\IPython\\core\\async_helpers.py\", line 128, in _pseudo_sync_runner\n",
      "    coro.send(None)\n",
      "  File \"C:\\actions-runner\\_work\\pyedb\\pyedb\\.venv\\lib\\site-packages\\IPython\\core\\interactiveshell.py\", line 3334, in run_cell_async\n",
      "    has_raised = await self.run_ast_nodes(code_ast.body, cell_name,\n",
      "  File \"C:\\actions-runner\\_work\\pyedb\\pyedb\\.venv\\lib\\site-packages\\IPython\\core\\interactiveshell.py\", line 3517, in run_ast_nodes\n",
      "    if await self.run_code(code, result, async_=asy):\n",
      "  File \"C:\\actions-runner\\_work\\pyedb\\pyedb\\.venv\\lib\\site-packages\\IPython\\core\\interactiveshell.py\", line 3577, in run_code\n",
      "    exec(code_obj, self.user_global_ns, self.user_ns)\n",
      "  File \"C:\\Users\\ansys\\AppData\\Local\\Temp\\ipykernel_1556\\1442418163.py\", line 1, in <module>\n",
      "    edb.nets.plot(None, color_by_net=True)\n",
      "  File \"C:\\actions-runner\\_work\\pyedb\\pyedb\\.venv\\lib\\site-packages\\pyedb\\dotnet\\edb_core\\nets.py\", line 770, in plot\n",
      "    object_lists = self.get_plot_data(\n",
      "  File \"C:\\actions-runner\\_work\\pyedb\\pyedb\\.venv\\lib\\site-packages\\pyedb\\dotnet\\edb_core\\nets.py\", line 686, in get_plot_data\n",
      "    self._logger.info(\"Nets Point Generation time %s seconds\", round(end_time, 3))\n",
      "  File \"C:\\actions-runner\\_work\\pyedb\\pyedb\\.venv\\lib\\site-packages\\pyedb\\edb_logger.py\", line 346, in info\n",
      "    return self._log_on_handler(0, msg, *args, **kwargs)\n",
      "  File \"C:\\actions-runner\\_work\\pyedb\\pyedb\\.venv\\lib\\site-packages\\pyedb\\edb_logger.py\", line 293, in _log_on_handler\n",
      "    self._global.info(message_text, *args, **kwargs)\n",
      "Message: 'Nets Point Generation time %s seconds'\n",
      "Arguments: (0.031,)\n",
      "C:\\actions-runner\\_work\\pyedb\\pyedb\\.venv\\lib\\site-packages\\pyedb\\generic\\plot.py:144: UserWarning: FigureCanvasAgg is non-interactive, and thus cannot be shown\n",
      "  plt.show()\n"
     ]
    }
   ],
   "source": [
    "edb.nets.plot(None, color_by_net=True)"
   ]
  },
  {
   "cell_type": "markdown",
   "id": "08bedc27",
   "metadata": {},
   "source": [
    "## Generate stackup plot"
   ]
  },
  {
   "cell_type": "code",
   "execution_count": 6,
   "id": "fbb87cd3",
   "metadata": {
    "execution": {
     "iopub.execute_input": "2024-09-04T08:19:32.480271Z",
     "iopub.status.busy": "2024-09-04T08:19:32.480271Z",
     "iopub.status.idle": "2024-09-04T08:19:32.590099Z",
     "shell.execute_reply": "2024-09-04T08:19:32.590099Z"
    }
   },
   "outputs": [
    {
     "name": "stderr",
     "output_type": "stream",
     "text": [
      "C:\\actions-runner\\_work\\pyedb\\pyedb\\.venv\\lib\\site-packages\\pyedb\\dotnet\\edb_core\\stackup.py:2868: UserWarning: FigureCanvasAgg is non-interactive, and thus cannot be shown\n",
      "  plt.show()\n"
     ]
    },
    {
     "data": {
      "text/plain": [
       "<module 'matplotlib.pyplot' from 'C:\\\\actions-runner\\\\_work\\\\pyedb\\\\pyedb\\\\.venv\\\\lib\\\\site-packages\\\\matplotlib\\\\pyplot.py'>"
      ]
     },
     "execution_count": 6,
     "metadata": {},
     "output_type": "execute_result"
    }
   ],
   "source": [
    "edb.stackup.plot(plot_definitions=\"MyVia\")"
   ]
  },
  {
   "cell_type": "markdown",
   "id": "9a0cdc01",
   "metadata": {},
   "source": [
    "## Save and close EDB\n",
    "Save and close EDB."
   ]
  },
  {
   "cell_type": "code",
   "execution_count": 7,
   "id": "203ac63a",
   "metadata": {
    "execution": {
     "iopub.execute_input": "2024-09-04T08:19:32.590099Z",
     "iopub.status.busy": "2024-09-04T08:19:32.590099Z",
     "iopub.status.idle": "2024-09-04T08:19:32.621347Z",
     "shell.execute_reply": "2024-09-04T08:19:32.621347Z"
    }
   },
   "outputs": [
    {
     "name": "stdout",
     "output_type": "stream",
     "text": [
      "PyEDB INFO: EDB file save time: 0.00ms\n"
     ]
    },
    {
     "name": "stdout",
     "output_type": "stream",
     "text": [
      "PyEDB INFO: EDB file release time: 15.56ms\n"
     ]
    },
    {
     "name": "stdout",
     "output_type": "stream",
     "text": [
      "EDB saved correctly to C:\\Users\\ansys\\AppData\\Local\\Temp\\tmp9qtix9bh.ansys\\create_via.aedb. You can import in AEDT.\n"
     ]
    },
    {
     "name": "stderr",
     "output_type": "stream",
     "text": [
      "--- Logging error ---\n",
      "Traceback (most recent call last):\n",
      "  File \"C:\\actions-runner\\_work\\_tool\\Python\\3.10.11\\x64\\lib\\logging\\handlers.py\", line 74, in emit\n",
      "    self.doRollover()\n",
      "  File \"C:\\actions-runner\\_work\\_tool\\Python\\3.10.11\\x64\\lib\\logging\\handlers.py\", line 179, in doRollover\n",
      "    self.rotate(self.baseFilename, dfn)\n",
      "  File \"C:\\actions-runner\\_work\\_tool\\Python\\3.10.11\\x64\\lib\\logging\\handlers.py\", line 115, in rotate\n",
      "    os.rename(source, dest)\n",
      "PermissionError: [WinError 32] The process cannot access the file because it is being used by another process: 'C:\\\\Users\\\\ansys\\\\AppData\\\\Local\\\\Temp\\\\pyedb_ansys.log' -> 'C:\\\\Users\\\\ansys\\\\AppData\\\\Local\\\\Temp\\\\pyedb_ansys.log.1'\n",
      "Call stack:\n",
      "  File \"C:\\actions-runner\\_work\\_tool\\Python\\3.10.11\\x64\\lib\\runpy.py\", line 196, in _run_module_as_main\n",
      "    return _run_code(code, main_globals, None,\n",
      "  File \"C:\\actions-runner\\_work\\_tool\\Python\\3.10.11\\x64\\lib\\runpy.py\", line 86, in _run_code\n",
      "    exec(code, run_globals)\n",
      "  File \"C:\\actions-runner\\_work\\pyedb\\pyedb\\.venv\\lib\\site-packages\\ipykernel_launcher.py\", line 18, in <module>\n",
      "    app.launch_new_instance()\n",
      "  File \"C:\\actions-runner\\_work\\pyedb\\pyedb\\.venv\\lib\\site-packages\\traitlets\\config\\application.py\", line 1075, in launch_instance\n",
      "    app.start()\n",
      "  File \"C:\\actions-runner\\_work\\pyedb\\pyedb\\.venv\\lib\\site-packages\\ipykernel\\kernelapp.py\", line 739, in start\n",
      "    self.io_loop.start()\n",
      "  File \"C:\\actions-runner\\_work\\pyedb\\pyedb\\.venv\\lib\\site-packages\\tornado\\platform\\asyncio.py\", line 205, in start\n",
      "    self.asyncio_loop.run_forever()\n",
      "  File \"C:\\actions-runner\\_work\\_tool\\Python\\3.10.11\\x64\\lib\\asyncio\\base_events.py\", line 603, in run_forever\n",
      "    self._run_once()\n",
      "  File \"C:\\actions-runner\\_work\\_tool\\Python\\3.10.11\\x64\\lib\\asyncio\\base_events.py\", line 1909, in _run_once\n",
      "    handle._run()\n",
      "  File \"C:\\actions-runner\\_work\\_tool\\Python\\3.10.11\\x64\\lib\\asyncio\\events.py\", line 80, in _run\n",
      "    self._context.run(self._callback, *self._args)\n",
      "  File \"C:\\actions-runner\\_work\\pyedb\\pyedb\\.venv\\lib\\site-packages\\ipykernel\\kernelbase.py\", line 545, in dispatch_queue\n",
      "    await self.process_one()\n",
      "  File \"C:\\actions-runner\\_work\\pyedb\\pyedb\\.venv\\lib\\site-packages\\ipykernel\\kernelbase.py\", line 534, in process_one\n",
      "    await dispatch(*args)\n",
      "  File \"C:\\actions-runner\\_work\\pyedb\\pyedb\\.venv\\lib\\site-packages\\ipykernel\\kernelbase.py\", line 437, in dispatch_shell\n",
      "    await result\n",
      "  File \"C:\\actions-runner\\_work\\pyedb\\pyedb\\.venv\\lib\\site-packages\\ipykernel\\ipkernel.py\", line 362, in execute_request\n",
      "    await super().execute_request(stream, ident, parent)\n",
      "  File \"C:\\actions-runner\\_work\\pyedb\\pyedb\\.venv\\lib\\site-packages\\ipykernel\\kernelbase.py\", line 778, in execute_request\n",
      "    reply_content = await reply_content\n",
      "  File \"C:\\actions-runner\\_work\\pyedb\\pyedb\\.venv\\lib\\site-packages\\ipykernel\\ipkernel.py\", line 449, in do_execute\n",
      "    res = shell.run_cell(\n",
      "  File \"C:\\actions-runner\\_work\\pyedb\\pyedb\\.venv\\lib\\site-packages\\ipykernel\\zmqshell.py\", line 549, in run_cell\n",
      "    return super().run_cell(*args, **kwargs)\n",
      "  File \"C:\\actions-runner\\_work\\pyedb\\pyedb\\.venv\\lib\\site-packages\\IPython\\core\\interactiveshell.py\", line 3075, in run_cell\n",
      "    result = self._run_cell(\n",
      "  File \"C:\\actions-runner\\_work\\pyedb\\pyedb\\.venv\\lib\\site-packages\\IPython\\core\\interactiveshell.py\", line 3130, in _run_cell\n",
      "    result = runner(coro)\n",
      "  File \"C:\\actions-runner\\_work\\pyedb\\pyedb\\.venv\\lib\\site-packages\\IPython\\core\\async_helpers.py\", line 128, in _pseudo_sync_runner\n",
      "    coro.send(None)\n",
      "  File \"C:\\actions-runner\\_work\\pyedb\\pyedb\\.venv\\lib\\site-packages\\IPython\\core\\interactiveshell.py\", line 3334, in run_cell_async\n",
      "    has_raised = await self.run_ast_nodes(code_ast.body, cell_name,\n",
      "  File \"C:\\actions-runner\\_work\\pyedb\\pyedb\\.venv\\lib\\site-packages\\IPython\\core\\interactiveshell.py\", line 3517, in run_ast_nodes\n",
      "    if await self.run_code(code, result, async_=asy):\n",
      "  File \"C:\\actions-runner\\_work\\pyedb\\pyedb\\.venv\\lib\\site-packages\\IPython\\core\\interactiveshell.py\", line 3577, in run_code\n",
      "    exec(code_obj, self.user_global_ns, self.user_ns)\n",
      "  File \"C:\\Users\\ansys\\AppData\\Local\\Temp\\ipykernel_1556\\379806575.py\", line 2, in <module>\n",
      "    edb.save_edb()\n",
      "  File \"C:\\actions-runner\\_work\\pyedb\\pyedb\\.venv\\lib\\site-packages\\pyedb\\dotnet\\edb.py\", line 1370, in save_edb\n",
      "    self.logger.info(\"EDB file save time: {0:.2f}ms\".format(elapsed_time * 1000.0))\n",
      "  File \"C:\\actions-runner\\_work\\pyedb\\pyedb\\.venv\\lib\\site-packages\\pyedb\\edb_logger.py\", line 346, in info\n",
      "    return self._log_on_handler(0, msg, *args, **kwargs)\n",
      "  File \"C:\\actions-runner\\_work\\pyedb\\pyedb\\.venv\\lib\\site-packages\\pyedb\\edb_logger.py\", line 293, in _log_on_handler\n",
      "    self._global.info(message_text, *args, **kwargs)\n",
      "Message: 'EDB file save time: 0.00ms'\n",
      "Arguments: ()\n",
      "--- Logging error ---\n",
      "Traceback (most recent call last):\n",
      "  File \"C:\\actions-runner\\_work\\_tool\\Python\\3.10.11\\x64\\lib\\logging\\handlers.py\", line 74, in emit\n",
      "    self.doRollover()\n",
      "  File \"C:\\actions-runner\\_work\\_tool\\Python\\3.10.11\\x64\\lib\\logging\\handlers.py\", line 179, in doRollover\n",
      "    self.rotate(self.baseFilename, dfn)\n",
      "  File \"C:\\actions-runner\\_work\\_tool\\Python\\3.10.11\\x64\\lib\\logging\\handlers.py\", line 115, in rotate\n",
      "    os.rename(source, dest)\n",
      "PermissionError: [WinError 32] The process cannot access the file because it is being used by another process: 'C:\\\\Users\\\\ansys\\\\AppData\\\\Local\\\\Temp\\\\pyedb_ansys.log' -> 'C:\\\\Users\\\\ansys\\\\AppData\\\\Local\\\\Temp\\\\pyedb_ansys.log.1'\n",
      "Call stack:\n",
      "  File \"C:\\actions-runner\\_work\\_tool\\Python\\3.10.11\\x64\\lib\\runpy.py\", line 196, in _run_module_as_main\n",
      "    return _run_code(code, main_globals, None,\n",
      "  File \"C:\\actions-runner\\_work\\_tool\\Python\\3.10.11\\x64\\lib\\runpy.py\", line 86, in _run_code\n",
      "    exec(code, run_globals)\n",
      "  File \"C:\\actions-runner\\_work\\pyedb\\pyedb\\.venv\\lib\\site-packages\\ipykernel_launcher.py\", line 18, in <module>\n",
      "    app.launch_new_instance()\n",
      "  File \"C:\\actions-runner\\_work\\pyedb\\pyedb\\.venv\\lib\\site-packages\\traitlets\\config\\application.py\", line 1075, in launch_instance\n",
      "    app.start()\n",
      "  File \"C:\\actions-runner\\_work\\pyedb\\pyedb\\.venv\\lib\\site-packages\\ipykernel\\kernelapp.py\", line 739, in start\n",
      "    self.io_loop.start()\n",
      "  File \"C:\\actions-runner\\_work\\pyedb\\pyedb\\.venv\\lib\\site-packages\\tornado\\platform\\asyncio.py\", line 205, in start\n",
      "    self.asyncio_loop.run_forever()\n",
      "  File \"C:\\actions-runner\\_work\\_tool\\Python\\3.10.11\\x64\\lib\\asyncio\\base_events.py\", line 603, in run_forever\n",
      "    self._run_once()\n",
      "  File \"C:\\actions-runner\\_work\\_tool\\Python\\3.10.11\\x64\\lib\\asyncio\\base_events.py\", line 1909, in _run_once\n",
      "    handle._run()\n",
      "  File \"C:\\actions-runner\\_work\\_tool\\Python\\3.10.11\\x64\\lib\\asyncio\\events.py\", line 80, in _run\n",
      "    self._context.run(self._callback, *self._args)\n",
      "  File \"C:\\actions-runner\\_work\\pyedb\\pyedb\\.venv\\lib\\site-packages\\ipykernel\\kernelbase.py\", line 545, in dispatch_queue\n",
      "    await self.process_one()\n",
      "  File \"C:\\actions-runner\\_work\\pyedb\\pyedb\\.venv\\lib\\site-packages\\ipykernel\\kernelbase.py\", line 534, in process_one\n",
      "    await dispatch(*args)\n",
      "  File \"C:\\actions-runner\\_work\\pyedb\\pyedb\\.venv\\lib\\site-packages\\ipykernel\\kernelbase.py\", line 437, in dispatch_shell\n",
      "    await result\n",
      "  File \"C:\\actions-runner\\_work\\pyedb\\pyedb\\.venv\\lib\\site-packages\\ipykernel\\ipkernel.py\", line 362, in execute_request\n",
      "    await super().execute_request(stream, ident, parent)\n",
      "  File \"C:\\actions-runner\\_work\\pyedb\\pyedb\\.venv\\lib\\site-packages\\ipykernel\\kernelbase.py\", line 778, in execute_request\n",
      "    reply_content = await reply_content\n",
      "  File \"C:\\actions-runner\\_work\\pyedb\\pyedb\\.venv\\lib\\site-packages\\ipykernel\\ipkernel.py\", line 449, in do_execute\n",
      "    res = shell.run_cell(\n",
      "  File \"C:\\actions-runner\\_work\\pyedb\\pyedb\\.venv\\lib\\site-packages\\ipykernel\\zmqshell.py\", line 549, in run_cell\n",
      "    return super().run_cell(*args, **kwargs)\n",
      "  File \"C:\\actions-runner\\_work\\pyedb\\pyedb\\.venv\\lib\\site-packages\\IPython\\core\\interactiveshell.py\", line 3075, in run_cell\n",
      "    result = self._run_cell(\n",
      "  File \"C:\\actions-runner\\_work\\pyedb\\pyedb\\.venv\\lib\\site-packages\\IPython\\core\\interactiveshell.py\", line 3130, in _run_cell\n",
      "    result = runner(coro)\n",
      "  File \"C:\\actions-runner\\_work\\pyedb\\pyedb\\.venv\\lib\\site-packages\\IPython\\core\\async_helpers.py\", line 128, in _pseudo_sync_runner\n",
      "    coro.send(None)\n",
      "  File \"C:\\actions-runner\\_work\\pyedb\\pyedb\\.venv\\lib\\site-packages\\IPython\\core\\interactiveshell.py\", line 3334, in run_cell_async\n",
      "    has_raised = await self.run_ast_nodes(code_ast.body, cell_name,\n",
      "  File \"C:\\actions-runner\\_work\\pyedb\\pyedb\\.venv\\lib\\site-packages\\IPython\\core\\interactiveshell.py\", line 3517, in run_ast_nodes\n",
      "    if await self.run_code(code, result, async_=asy):\n",
      "  File \"C:\\actions-runner\\_work\\pyedb\\pyedb\\.venv\\lib\\site-packages\\IPython\\core\\interactiveshell.py\", line 3577, in run_code\n",
      "    exec(code_obj, self.user_global_ns, self.user_ns)\n",
      "  File \"C:\\Users\\ansys\\AppData\\Local\\Temp\\ipykernel_1556\\379806575.py\", line 3, in <module>\n",
      "    edb.close_edb()\n",
      "  File \"C:\\actions-runner\\_work\\pyedb\\pyedb\\.venv\\lib\\site-packages\\pyedb\\dotnet\\edb.py\", line 1353, in close_edb\n",
      "    self.logger.info(\"EDB file release time: {0:.2f}ms\".format(elapsed_time * 1000.0))\n",
      "  File \"C:\\actions-runner\\_work\\pyedb\\pyedb\\.venv\\lib\\site-packages\\pyedb\\edb_logger.py\", line 346, in info\n",
      "    return self._log_on_handler(0, msg, *args, **kwargs)\n",
      "  File \"C:\\actions-runner\\_work\\pyedb\\pyedb\\.venv\\lib\\site-packages\\pyedb\\edb_logger.py\", line 293, in _log_on_handler\n",
      "    self._global.info(message_text, *args, **kwargs)\n",
      "Message: 'EDB file release time: 15.56ms'\n",
      "Arguments: ()\n"
     ]
    }
   ],
   "source": [
    "if edb:\n",
    "    edb.save_edb()\n",
    "    edb.close_edb()\n",
    "print(\"EDB saved correctly to {}. You can import in AEDT.\".format(aedb_path))"
   ]
  },
  {
   "cell_type": "markdown",
   "id": "11834f2e",
   "metadata": {},
   "source": [
    "### Clean up temporary directory\n",
    "\n",
    "The following command removes the project and the temporary directory.\n",
    "If you'd like to save this project, save it to a folder of your choice\n",
    "prior to running the following cell."
   ]
  },
  {
   "cell_type": "code",
   "execution_count": 8,
   "id": "2d4476d2",
   "metadata": {
    "execution": {
     "iopub.execute_input": "2024-09-04T08:19:32.621347Z",
     "iopub.status.busy": "2024-09-04T08:19:32.621347Z",
     "iopub.status.idle": "2024-09-04T08:19:32.636975Z",
     "shell.execute_reply": "2024-09-04T08:19:32.636975Z"
    }
   },
   "outputs": [],
   "source": [
    "temp_dir.cleanup()"
   ]
  }
 ],
 "metadata": {
  "jupytext": {
   "cell_metadata_filter": "-all",
   "main_language": "python",
   "notebook_metadata_filter": "-all",
   "text_representation": {
    "extension": ".py",
    "format_name": "light"
   }
  },
  "language_info": {
   "codemirror_mode": {
    "name": "ipython",
    "version": 3
   },
   "file_extension": ".py",
   "mimetype": "text/x-python",
   "name": "python",
   "nbconvert_exporter": "python",
   "pygments_lexer": "ipython3",
   "version": "3.10.11"
  }
 },
 "nbformat": 4,
 "nbformat_minor": 5
}
