{
 "cells": [
  {
   "cell_type": "markdown",
   "id": "40422e2a",
   "metadata": {},
   "source": [
    "# EDB: IPC2581 export\n",
    "\n",
    "This example shows how you can use PyAEDT to export an IPC2581 file.\n",
    "\n",
    "Perform required imports, which includes importing a section."
   ]
  },
  {
   "cell_type": "code",
   "execution_count": 1,
   "id": "ab075c33",
   "metadata": {
    "execution": {
     "iopub.execute_input": "2024-09-17T08:07:39.194168Z",
     "iopub.status.busy": "2024-09-17T08:07:39.194168Z",
     "iopub.status.idle": "2024-09-17T08:07:39.241114Z",
     "shell.execute_reply": "2024-09-17T08:07:39.241114Z"
    }
   },
   "outputs": [],
   "source": [
    "import os\n",
    "import tempfile\n",
    "\n",
    "import pyedb\n",
    "from pyedb.generic.general_methods import generate_unique_name\n",
    "from pyedb.misc.downloads import download_file\n"
   ]
  },
  {
   "cell_type": "markdown",
   "id": "a42a5b11",
   "metadata": {},
   "source": [
    "## Download the AEDB file and copy it in the temporary folder."
   ]
  },
  {
   "cell_type": "code",
   "execution_count": 2,
   "id": "9af7995b",
   "metadata": {
    "execution": {
     "iopub.execute_input": "2024-09-17T08:07:39.241114Z",
     "iopub.status.busy": "2024-09-17T08:07:39.241114Z",
     "iopub.status.idle": "2024-09-17T08:07:40.664119Z",
     "shell.execute_reply": "2024-09-17T08:07:40.664119Z"
    }
   },
   "outputs": [
    {
     "name": "stdout",
     "output_type": "stream",
     "text": [
      "C:\\Users\\ansys\\AppData\\Local\\Temp\\tmpqjhwgcrt.ansys\\edb/ANSYS-HSD_V1.aedb\n"
     ]
    }
   ],
   "source": [
    "temp_dir = tempfile.TemporaryDirectory(suffix=\".ansys\")\n",
    "targetfile = download_file(\"edb/ANSYS-HSD_V1.aedb\", destination=temp_dir.name)\n",
    "ipc2581_file_name = os.path.join(temp_dir.name, \"Ansys_Hsd.xml\")\n",
    "print(targetfile)"
   ]
  },
  {
   "cell_type": "markdown",
   "id": "936ed155",
   "metadata": {},
   "source": [
    "## Launch EDB\n",
    "\n",
    "Launch the `pyedb.Edb` class, using EDB 2023.\n",
    "> Note that length dimensions passed to EDB are in SI units."
   ]
  },
  {
   "cell_type": "code",
   "execution_count": 3,
   "id": "6f1099ad",
   "metadata": {
    "execution": {
     "iopub.execute_input": "2024-09-17T08:07:40.664119Z",
     "iopub.status.busy": "2024-09-17T08:07:40.664119Z",
     "iopub.status.idle": "2024-09-17T08:07:53.982238Z",
     "shell.execute_reply": "2024-09-17T08:07:53.982238Z"
    }
   },
   "outputs": [
    {
     "name": "stdout",
     "output_type": "stream",
     "text": [
      "EDB version: 2024.2\n"
     ]
    },
    {
     "name": "stdout",
     "output_type": "stream",
     "text": [
      "PyEDB INFO: StdOut is enabled\n"
     ]
    },
    {
     "name": "stdout",
     "output_type": "stream",
     "text": [
      "PyEDB INFO: Logger is initialized in EDB.\n"
     ]
    },
    {
     "name": "stdout",
     "output_type": "stream",
     "text": [
      "PyEDB INFO: legacy v0.28.0\n"
     ]
    },
    {
     "name": "stdout",
     "output_type": "stream",
     "text": [
      "PyEDB INFO: Python version 3.10.11 (tags/v3.10.11:7d4cc5a, Apr  5 2023, 00:38:17) [MSC v.1929 64 bit (AMD64)]\n"
     ]
    },
    {
     "name": "stderr",
     "output_type": "stream",
     "text": [
      "--- Logging error ---\n",
      "Traceback (most recent call last):\n",
      "  File \"C:\\actions-runner\\_work\\_tool\\Python\\3.10.11\\x64\\lib\\logging\\handlers.py\", line 74, in emit\n",
      "    self.doRollover()\n",
      "  File \"C:\\actions-runner\\_work\\_tool\\Python\\3.10.11\\x64\\lib\\logging\\handlers.py\", line 179, in doRollover\n",
      "    self.rotate(self.baseFilename, dfn)\n",
      "  File \"C:\\actions-runner\\_work\\_tool\\Python\\3.10.11\\x64\\lib\\logging\\handlers.py\", line 115, in rotate\n",
      "    os.rename(source, dest)\n",
      "PermissionError: [WinError 32] The process cannot access the file because it is being used by another process: 'C:\\\\Users\\\\ansys\\\\AppData\\\\Local\\\\Temp\\\\pyedb_ansys.log' -> 'C:\\\\Users\\\\ansys\\\\AppData\\\\Local\\\\Temp\\\\pyedb_ansys.log.1'\n",
      "Call stack:\n",
      "  File \"C:\\actions-runner\\_work\\_tool\\Python\\3.10.11\\x64\\lib\\runpy.py\", line 196, in _run_module_as_main\n",
      "    return _run_code(code, main_globals, None,\n",
      "  File \"C:\\actions-runner\\_work\\_tool\\Python\\3.10.11\\x64\\lib\\runpy.py\", line 86, in _run_code\n",
      "    exec(code, run_globals)\n",
      "  File \"C:\\actions-runner\\_work\\pyedb\\pyedb\\.venv\\lib\\site-packages\\ipykernel_launcher.py\", line 18, in <module>\n",
      "    app.launch_new_instance()\n",
      "  File \"C:\\actions-runner\\_work\\pyedb\\pyedb\\.venv\\lib\\site-packages\\traitlets\\config\\application.py\", line 1075, in launch_instance\n",
      "    app.start()\n",
      "  File \"C:\\actions-runner\\_work\\pyedb\\pyedb\\.venv\\lib\\site-packages\\ipykernel\\kernelapp.py\", line 739, in start\n",
      "    self.io_loop.start()\n",
      "  File \"C:\\actions-runner\\_work\\pyedb\\pyedb\\.venv\\lib\\site-packages\\tornado\\platform\\asyncio.py\", line 205, in start\n",
      "    self.asyncio_loop.run_forever()\n",
      "  File \"C:\\actions-runner\\_work\\_tool\\Python\\3.10.11\\x64\\lib\\asyncio\\base_events.py\", line 603, in run_forever\n",
      "    self._run_once()\n",
      "  File \"C:\\actions-runner\\_work\\_tool\\Python\\3.10.11\\x64\\lib\\asyncio\\base_events.py\", line 1909, in _run_once\n",
      "    handle._run()\n",
      "  File \"C:\\actions-runner\\_work\\_tool\\Python\\3.10.11\\x64\\lib\\asyncio\\events.py\", line 80, in _run\n",
      "    self._context.run(self._callback, *self._args)\n",
      "  File \"C:\\actions-runner\\_work\\pyedb\\pyedb\\.venv\\lib\\site-packages\\ipykernel\\kernelbase.py\", line 545, in dispatch_queue\n",
      "    await self.process_one()\n",
      "  File \"C:\\actions-runner\\_work\\pyedb\\pyedb\\.venv\\lib\\site-packages\\ipykernel\\kernelbase.py\", line 534, in process_one\n",
      "    await dispatch(*args)\n",
      "  File \"C:\\actions-runner\\_work\\pyedb\\pyedb\\.venv\\lib\\site-packages\\ipykernel\\kernelbase.py\", line 437, in dispatch_shell\n",
      "    await result\n",
      "  File \"C:\\actions-runner\\_work\\pyedb\\pyedb\\.venv\\lib\\site-packages\\ipykernel\\ipkernel.py\", line 362, in execute_request\n",
      "    await super().execute_request(stream, ident, parent)\n",
      "  File \"C:\\actions-runner\\_work\\pyedb\\pyedb\\.venv\\lib\\site-packages\\ipykernel\\kernelbase.py\", line 778, in execute_request\n",
      "    reply_content = await reply_content\n",
      "  File \"C:\\actions-runner\\_work\\pyedb\\pyedb\\.venv\\lib\\site-packages\\ipykernel\\ipkernel.py\", line 449, in do_execute\n",
      "    res = shell.run_cell(\n",
      "  File \"C:\\actions-runner\\_work\\pyedb\\pyedb\\.venv\\lib\\site-packages\\ipykernel\\zmqshell.py\", line 549, in run_cell\n",
      "    return super().run_cell(*args, **kwargs)\n",
      "  File \"C:\\actions-runner\\_work\\pyedb\\pyedb\\.venv\\lib\\site-packages\\IPython\\core\\interactiveshell.py\", line 3075, in run_cell\n",
      "    result = self._run_cell(\n",
      "  File \"C:\\actions-runner\\_work\\pyedb\\pyedb\\.venv\\lib\\site-packages\\IPython\\core\\interactiveshell.py\", line 3130, in _run_cell\n",
      "    result = runner(coro)\n",
      "  File \"C:\\actions-runner\\_work\\pyedb\\pyedb\\.venv\\lib\\site-packages\\IPython\\core\\async_helpers.py\", line 128, in _pseudo_sync_runner\n",
      "    coro.send(None)\n",
      "  File \"C:\\actions-runner\\_work\\pyedb\\pyedb\\.venv\\lib\\site-packages\\IPython\\core\\interactiveshell.py\", line 3334, in run_cell_async\n",
      "    has_raised = await self.run_ast_nodes(code_ast.body, cell_name,\n",
      "  File \"C:\\actions-runner\\_work\\pyedb\\pyedb\\.venv\\lib\\site-packages\\IPython\\core\\interactiveshell.py\", line 3517, in run_ast_nodes\n",
      "    if await self.run_code(code, result, async_=asy):\n",
      "  File \"C:\\actions-runner\\_work\\pyedb\\pyedb\\.venv\\lib\\site-packages\\IPython\\core\\interactiveshell.py\", line 3577, in run_code\n",
      "    exec(code_obj, self.user_global_ns, self.user_ns)\n",
      "  File \"C:\\Users\\ansys\\AppData\\Local\\Temp\\ipykernel_3468\\1057109396.py\", line 5, in <module>\n",
      "    edb = pyedb.Edb(edbpath=targetfile, edbversion=edb_version)\n",
      "  File \"C:\\actions-runner\\_work\\pyedb\\pyedb\\.venv\\lib\\site-packages\\pyedb\\generic\\design_types.py\", line 110, in Edb\n",
      "    return app(\n",
      "  File \"C:\\actions-runner\\_work\\pyedb\\pyedb\\.venv\\lib\\site-packages\\pyedb\\dotnet\\edb.py\", line 196, in __init__\n",
      "    Database.__init__(self, edbversion=edbversion, student_version=student_version)\n",
      "  File \"C:\\actions-runner\\_work\\pyedb\\pyedb\\.venv\\lib\\site-packages\\pyedb\\dotnet\\edb_core\\dotnet\\database.py\", line 802, in __init__\n",
      "    EdbDotNet.__init__(self, edbversion=edbversion, student_version=student_version)\n",
      "  File \"C:\\actions-runner\\_work\\pyedb\\pyedb\\.venv\\lib\\site-packages\\pyedb\\dotnet\\edb_core\\dotnet\\database.py\", line 703, in __init__\n",
      "    self._logger.enable_stdout_log()\n",
      "  File \"C:\\actions-runner\\_work\\pyedb\\pyedb\\.venv\\lib\\site-packages\\pyedb\\edb_logger.py\", line 318, in enable_stdout_log\n",
      "    self.info(\"StdOut is enabled\")\n",
      "  File \"C:\\actions-runner\\_work\\pyedb\\pyedb\\.venv\\lib\\site-packages\\pyedb\\edb_logger.py\", line 346, in info\n",
      "    return self._log_on_handler(0, msg, *args, **kwargs)\n",
      "  File \"C:\\actions-runner\\_work\\pyedb\\pyedb\\.venv\\lib\\site-packages\\pyedb\\edb_logger.py\", line 293, in _log_on_handler\n",
      "    self._global.info(message_text, *args, **kwargs)\n",
      "Message: 'StdOut is enabled'\n",
      "Arguments: ()\n",
      "--- Logging error ---\n",
      "Traceback (most recent call last):\n",
      "  File \"C:\\actions-runner\\_work\\_tool\\Python\\3.10.11\\x64\\lib\\logging\\handlers.py\", line 74, in emit\n",
      "    self.doRollover()\n",
      "  File \"C:\\actions-runner\\_work\\_tool\\Python\\3.10.11\\x64\\lib\\logging\\handlers.py\", line 179, in doRollover\n",
      "    self.rotate(self.baseFilename, dfn)\n",
      "  File \"C:\\actions-runner\\_work\\_tool\\Python\\3.10.11\\x64\\lib\\logging\\handlers.py\", line 115, in rotate\n",
      "    os.rename(source, dest)\n",
      "PermissionError: [WinError 32] The process cannot access the file because it is being used by another process: 'C:\\\\Users\\\\ansys\\\\AppData\\\\Local\\\\Temp\\\\pyedb_ansys.log' -> 'C:\\\\Users\\\\ansys\\\\AppData\\\\Local\\\\Temp\\\\pyedb_ansys.log.1'\n",
      "Call stack:\n",
      "  File \"C:\\actions-runner\\_work\\_tool\\Python\\3.10.11\\x64\\lib\\runpy.py\", line 196, in _run_module_as_main\n",
      "    return _run_code(code, main_globals, None,\n",
      "  File \"C:\\actions-runner\\_work\\_tool\\Python\\3.10.11\\x64\\lib\\runpy.py\", line 86, in _run_code\n",
      "    exec(code, run_globals)\n",
      "  File \"C:\\actions-runner\\_work\\pyedb\\pyedb\\.venv\\lib\\site-packages\\ipykernel_launcher.py\", line 18, in <module>\n",
      "    app.launch_new_instance()\n",
      "  File \"C:\\actions-runner\\_work\\pyedb\\pyedb\\.venv\\lib\\site-packages\\traitlets\\config\\application.py\", line 1075, in launch_instance\n",
      "    app.start()\n",
      "  File \"C:\\actions-runner\\_work\\pyedb\\pyedb\\.venv\\lib\\site-packages\\ipykernel\\kernelapp.py\", line 739, in start\n",
      "    self.io_loop.start()\n",
      "  File \"C:\\actions-runner\\_work\\pyedb\\pyedb\\.venv\\lib\\site-packages\\tornado\\platform\\asyncio.py\", line 205, in start\n",
      "    self.asyncio_loop.run_forever()\n",
      "  File \"C:\\actions-runner\\_work\\_tool\\Python\\3.10.11\\x64\\lib\\asyncio\\base_events.py\", line 603, in run_forever\n",
      "    self._run_once()\n",
      "  File \"C:\\actions-runner\\_work\\_tool\\Python\\3.10.11\\x64\\lib\\asyncio\\base_events.py\", line 1909, in _run_once\n",
      "    handle._run()\n",
      "  File \"C:\\actions-runner\\_work\\_tool\\Python\\3.10.11\\x64\\lib\\asyncio\\events.py\", line 80, in _run\n",
      "    self._context.run(self._callback, *self._args)\n",
      "  File \"C:\\actions-runner\\_work\\pyedb\\pyedb\\.venv\\lib\\site-packages\\ipykernel\\kernelbase.py\", line 545, in dispatch_queue\n",
      "    await self.process_one()\n",
      "  File \"C:\\actions-runner\\_work\\pyedb\\pyedb\\.venv\\lib\\site-packages\\ipykernel\\kernelbase.py\", line 534, in process_one\n",
      "    await dispatch(*args)\n",
      "  File \"C:\\actions-runner\\_work\\pyedb\\pyedb\\.venv\\lib\\site-packages\\ipykernel\\kernelbase.py\", line 437, in dispatch_shell\n",
      "    await result\n",
      "  File \"C:\\actions-runner\\_work\\pyedb\\pyedb\\.venv\\lib\\site-packages\\ipykernel\\ipkernel.py\", line 362, in execute_request\n",
      "    await super().execute_request(stream, ident, parent)\n",
      "  File \"C:\\actions-runner\\_work\\pyedb\\pyedb\\.venv\\lib\\site-packages\\ipykernel\\kernelbase.py\", line 778, in execute_request\n",
      "    reply_content = await reply_content\n",
      "  File \"C:\\actions-runner\\_work\\pyedb\\pyedb\\.venv\\lib\\site-packages\\ipykernel\\ipkernel.py\", line 449, in do_execute\n",
      "    res = shell.run_cell(\n",
      "  File \"C:\\actions-runner\\_work\\pyedb\\pyedb\\.venv\\lib\\site-packages\\ipykernel\\zmqshell.py\", line 549, in run_cell\n",
      "    return super().run_cell(*args, **kwargs)\n",
      "  File \"C:\\actions-runner\\_work\\pyedb\\pyedb\\.venv\\lib\\site-packages\\IPython\\core\\interactiveshell.py\", line 3075, in run_cell\n",
      "    result = self._run_cell(\n",
      "  File \"C:\\actions-runner\\_work\\pyedb\\pyedb\\.venv\\lib\\site-packages\\IPython\\core\\interactiveshell.py\", line 3130, in _run_cell\n",
      "    result = runner(coro)\n",
      "  File \"C:\\actions-runner\\_work\\pyedb\\pyedb\\.venv\\lib\\site-packages\\IPython\\core\\async_helpers.py\", line 128, in _pseudo_sync_runner\n",
      "    coro.send(None)\n",
      "  File \"C:\\actions-runner\\_work\\pyedb\\pyedb\\.venv\\lib\\site-packages\\IPython\\core\\interactiveshell.py\", line 3334, in run_cell_async\n",
      "    has_raised = await self.run_ast_nodes(code_ast.body, cell_name,\n",
      "  File \"C:\\actions-runner\\_work\\pyedb\\pyedb\\.venv\\lib\\site-packages\\IPython\\core\\interactiveshell.py\", line 3517, in run_ast_nodes\n",
      "    if await self.run_code(code, result, async_=asy):\n",
      "  File \"C:\\actions-runner\\_work\\pyedb\\pyedb\\.venv\\lib\\site-packages\\IPython\\core\\interactiveshell.py\", line 3577, in run_code\n",
      "    exec(code_obj, self.user_global_ns, self.user_ns)\n",
      "  File \"C:\\Users\\ansys\\AppData\\Local\\Temp\\ipykernel_3468\\1057109396.py\", line 5, in <module>\n",
      "    edb = pyedb.Edb(edbpath=targetfile, edbversion=edb_version)\n",
      "  File \"C:\\actions-runner\\_work\\pyedb\\pyedb\\.venv\\lib\\site-packages\\pyedb\\generic\\design_types.py\", line 110, in Edb\n",
      "    return app(\n",
      "  File \"C:\\actions-runner\\_work\\pyedb\\pyedb\\.venv\\lib\\site-packages\\pyedb\\dotnet\\edb.py\", line 196, in __init__\n",
      "    Database.__init__(self, edbversion=edbversion, student_version=student_version)\n",
      "  File \"C:\\actions-runner\\_work\\pyedb\\pyedb\\.venv\\lib\\site-packages\\pyedb\\dotnet\\edb_core\\dotnet\\database.py\", line 802, in __init__\n",
      "    EdbDotNet.__init__(self, edbversion=edbversion, student_version=student_version)\n",
      "  File \"C:\\actions-runner\\_work\\pyedb\\pyedb\\.venv\\lib\\site-packages\\pyedb\\dotnet\\edb_core\\dotnet\\database.py\", line 709, in __init__\n",
      "    self._logger.info(\"Logger is initialized in EDB.\")\n",
      "  File \"C:\\actions-runner\\_work\\pyedb\\pyedb\\.venv\\lib\\site-packages\\pyedb\\edb_logger.py\", line 346, in info\n",
      "    return self._log_on_handler(0, msg, *args, **kwargs)\n",
      "  File \"C:\\actions-runner\\_work\\pyedb\\pyedb\\.venv\\lib\\site-packages\\pyedb\\edb_logger.py\", line 293, in _log_on_handler\n",
      "    self._global.info(message_text, *args, **kwargs)\n",
      "Message: 'Logger is initialized in EDB.'\n",
      "Arguments: ()\n",
      "--- Logging error ---\n",
      "Traceback (most recent call last):\n",
      "  File \"C:\\actions-runner\\_work\\_tool\\Python\\3.10.11\\x64\\lib\\logging\\handlers.py\", line 74, in emit\n",
      "    self.doRollover()\n",
      "  File \"C:\\actions-runner\\_work\\_tool\\Python\\3.10.11\\x64\\lib\\logging\\handlers.py\", line 179, in doRollover\n",
      "    self.rotate(self.baseFilename, dfn)\n",
      "  File \"C:\\actions-runner\\_work\\_tool\\Python\\3.10.11\\x64\\lib\\logging\\handlers.py\", line 115, in rotate\n",
      "    os.rename(source, dest)\n",
      "PermissionError: [WinError 32] The process cannot access the file because it is being used by another process: 'C:\\\\Users\\\\ansys\\\\AppData\\\\Local\\\\Temp\\\\pyedb_ansys.log' -> 'C:\\\\Users\\\\ansys\\\\AppData\\\\Local\\\\Temp\\\\pyedb_ansys.log.1'\n",
      "Call stack:\n",
      "  File \"C:\\actions-runner\\_work\\_tool\\Python\\3.10.11\\x64\\lib\\runpy.py\", line 196, in _run_module_as_main\n",
      "    return _run_code(code, main_globals, None,\n",
      "  File \"C:\\actions-runner\\_work\\_tool\\Python\\3.10.11\\x64\\lib\\runpy.py\", line 86, in _run_code\n",
      "    exec(code, run_globals)\n",
      "  File \"C:\\actions-runner\\_work\\pyedb\\pyedb\\.venv\\lib\\site-packages\\ipykernel_launcher.py\", line 18, in <module>\n",
      "    app.launch_new_instance()\n",
      "  File \"C:\\actions-runner\\_work\\pyedb\\pyedb\\.venv\\lib\\site-packages\\traitlets\\config\\application.py\", line 1075, in launch_instance\n",
      "    app.start()\n",
      "  File \"C:\\actions-runner\\_work\\pyedb\\pyedb\\.venv\\lib\\site-packages\\ipykernel\\kernelapp.py\", line 739, in start\n",
      "    self.io_loop.start()\n",
      "  File \"C:\\actions-runner\\_work\\pyedb\\pyedb\\.venv\\lib\\site-packages\\tornado\\platform\\asyncio.py\", line 205, in start\n",
      "    self.asyncio_loop.run_forever()\n",
      "  File \"C:\\actions-runner\\_work\\_tool\\Python\\3.10.11\\x64\\lib\\asyncio\\base_events.py\", line 603, in run_forever\n",
      "    self._run_once()\n",
      "  File \"C:\\actions-runner\\_work\\_tool\\Python\\3.10.11\\x64\\lib\\asyncio\\base_events.py\", line 1909, in _run_once\n",
      "    handle._run()\n",
      "  File \"C:\\actions-runner\\_work\\_tool\\Python\\3.10.11\\x64\\lib\\asyncio\\events.py\", line 80, in _run\n",
      "    self._context.run(self._callback, *self._args)\n",
      "  File \"C:\\actions-runner\\_work\\pyedb\\pyedb\\.venv\\lib\\site-packages\\ipykernel\\kernelbase.py\", line 545, in dispatch_queue\n",
      "    await self.process_one()\n",
      "  File \"C:\\actions-runner\\_work\\pyedb\\pyedb\\.venv\\lib\\site-packages\\ipykernel\\kernelbase.py\", line 534, in process_one\n",
      "    await dispatch(*args)\n",
      "  File \"C:\\actions-runner\\_work\\pyedb\\pyedb\\.venv\\lib\\site-packages\\ipykernel\\kernelbase.py\", line 437, in dispatch_shell\n",
      "    await result\n",
      "  File \"C:\\actions-runner\\_work\\pyedb\\pyedb\\.venv\\lib\\site-packages\\ipykernel\\ipkernel.py\", line 362, in execute_request\n",
      "    await super().execute_request(stream, ident, parent)\n",
      "  File \"C:\\actions-runner\\_work\\pyedb\\pyedb\\.venv\\lib\\site-packages\\ipykernel\\kernelbase.py\", line 778, in execute_request\n",
      "    reply_content = await reply_content\n",
      "  File \"C:\\actions-runner\\_work\\pyedb\\pyedb\\.venv\\lib\\site-packages\\ipykernel\\ipkernel.py\", line 449, in do_execute\n",
      "    res = shell.run_cell(\n",
      "  File \"C:\\actions-runner\\_work\\pyedb\\pyedb\\.venv\\lib\\site-packages\\ipykernel\\zmqshell.py\", line 549, in run_cell\n",
      "    return super().run_cell(*args, **kwargs)\n",
      "  File \"C:\\actions-runner\\_work\\pyedb\\pyedb\\.venv\\lib\\site-packages\\IPython\\core\\interactiveshell.py\", line 3075, in run_cell\n",
      "    result = self._run_cell(\n",
      "  File \"C:\\actions-runner\\_work\\pyedb\\pyedb\\.venv\\lib\\site-packages\\IPython\\core\\interactiveshell.py\", line 3130, in _run_cell\n",
      "    result = runner(coro)\n",
      "  File \"C:\\actions-runner\\_work\\pyedb\\pyedb\\.venv\\lib\\site-packages\\IPython\\core\\async_helpers.py\", line 128, in _pseudo_sync_runner\n",
      "    coro.send(None)\n",
      "  File \"C:\\actions-runner\\_work\\pyedb\\pyedb\\.venv\\lib\\site-packages\\IPython\\core\\interactiveshell.py\", line 3334, in run_cell_async\n",
      "    has_raised = await self.run_ast_nodes(code_ast.body, cell_name,\n",
      "  File \"C:\\actions-runner\\_work\\pyedb\\pyedb\\.venv\\lib\\site-packages\\IPython\\core\\interactiveshell.py\", line 3517, in run_ast_nodes\n",
      "    if await self.run_code(code, result, async_=asy):\n",
      "  File \"C:\\actions-runner\\_work\\pyedb\\pyedb\\.venv\\lib\\site-packages\\IPython\\core\\interactiveshell.py\", line 3577, in run_code\n",
      "    exec(code_obj, self.user_global_ns, self.user_ns)\n",
      "  File \"C:\\Users\\ansys\\AppData\\Local\\Temp\\ipykernel_3468\\1057109396.py\", line 5, in <module>\n",
      "    edb = pyedb.Edb(edbpath=targetfile, edbversion=edb_version)\n",
      "  File \"C:\\actions-runner\\_work\\pyedb\\pyedb\\.venv\\lib\\site-packages\\pyedb\\generic\\design_types.py\", line 110, in Edb\n",
      "    return app(\n",
      "  File \"C:\\actions-runner\\_work\\pyedb\\pyedb\\.venv\\lib\\site-packages\\pyedb\\dotnet\\edb.py\", line 196, in __init__\n",
      "    Database.__init__(self, edbversion=edbversion, student_version=student_version)\n",
      "  File \"C:\\actions-runner\\_work\\pyedb\\pyedb\\.venv\\lib\\site-packages\\pyedb\\dotnet\\edb_core\\dotnet\\database.py\", line 802, in __init__\n",
      "    EdbDotNet.__init__(self, edbversion=edbversion, student_version=student_version)\n",
      "  File \"C:\\actions-runner\\_work\\pyedb\\pyedb\\.venv\\lib\\site-packages\\pyedb\\dotnet\\edb_core\\dotnet\\database.py\", line 710, in __init__\n",
      "    self._logger.info(\"legacy v%s\", __version__)\n",
      "  File \"C:\\actions-runner\\_work\\pyedb\\pyedb\\.venv\\lib\\site-packages\\pyedb\\edb_logger.py\", line 346, in info\n",
      "    return self._log_on_handler(0, msg, *args, **kwargs)\n",
      "  File \"C:\\actions-runner\\_work\\pyedb\\pyedb\\.venv\\lib\\site-packages\\pyedb\\edb_logger.py\", line 293, in _log_on_handler\n",
      "    self._global.info(message_text, *args, **kwargs)\n",
      "Message: 'legacy v%s'\n",
      "Arguments: ('0.28.0',)\n",
      "--- Logging error ---\n",
      "Traceback (most recent call last):\n",
      "  File \"C:\\actions-runner\\_work\\_tool\\Python\\3.10.11\\x64\\lib\\logging\\handlers.py\", line 74, in emit\n",
      "    self.doRollover()\n",
      "  File \"C:\\actions-runner\\_work\\_tool\\Python\\3.10.11\\x64\\lib\\logging\\handlers.py\", line 179, in doRollover\n",
      "    self.rotate(self.baseFilename, dfn)\n",
      "  File \"C:\\actions-runner\\_work\\_tool\\Python\\3.10.11\\x64\\lib\\logging\\handlers.py\", line 115, in rotate\n",
      "    os.rename(source, dest)\n",
      "PermissionError: [WinError 32] The process cannot access the file because it is being used by another process: 'C:\\\\Users\\\\ansys\\\\AppData\\\\Local\\\\Temp\\\\pyedb_ansys.log' -> 'C:\\\\Users\\\\ansys\\\\AppData\\\\Local\\\\Temp\\\\pyedb_ansys.log.1'\n",
      "Call stack:\n",
      "  File \"C:\\actions-runner\\_work\\_tool\\Python\\3.10.11\\x64\\lib\\runpy.py\", line 196, in _run_module_as_main\n",
      "    return _run_code(code, main_globals, None,\n",
      "  File \"C:\\actions-runner\\_work\\_tool\\Python\\3.10.11\\x64\\lib\\runpy.py\", line 86, in _run_code\n",
      "    exec(code, run_globals)\n",
      "  File \"C:\\actions-runner\\_work\\pyedb\\pyedb\\.venv\\lib\\site-packages\\ipykernel_launcher.py\", line 18, in <module>\n",
      "    app.launch_new_instance()\n",
      "  File \"C:\\actions-runner\\_work\\pyedb\\pyedb\\.venv\\lib\\site-packages\\traitlets\\config\\application.py\", line 1075, in launch_instance\n",
      "    app.start()\n",
      "  File \"C:\\actions-runner\\_work\\pyedb\\pyedb\\.venv\\lib\\site-packages\\ipykernel\\kernelapp.py\", line 739, in start\n",
      "    self.io_loop.start()\n",
      "  File \"C:\\actions-runner\\_work\\pyedb\\pyedb\\.venv\\lib\\site-packages\\tornado\\platform\\asyncio.py\", line 205, in start\n",
      "    self.asyncio_loop.run_forever()\n",
      "  File \"C:\\actions-runner\\_work\\_tool\\Python\\3.10.11\\x64\\lib\\asyncio\\base_events.py\", line 603, in run_forever\n",
      "    self._run_once()\n",
      "  File \"C:\\actions-runner\\_work\\_tool\\Python\\3.10.11\\x64\\lib\\asyncio\\base_events.py\", line 1909, in _run_once\n",
      "    handle._run()\n",
      "  File \"C:\\actions-runner\\_work\\_tool\\Python\\3.10.11\\x64\\lib\\asyncio\\events.py\", line 80, in _run\n",
      "    self._context.run(self._callback, *self._args)\n",
      "  File \"C:\\actions-runner\\_work\\pyedb\\pyedb\\.venv\\lib\\site-packages\\ipykernel\\kernelbase.py\", line 545, in dispatch_queue\n",
      "    await self.process_one()\n",
      "  File \"C:\\actions-runner\\_work\\pyedb\\pyedb\\.venv\\lib\\site-packages\\ipykernel\\kernelbase.py\", line 534, in process_one\n",
      "    await dispatch(*args)\n",
      "  File \"C:\\actions-runner\\_work\\pyedb\\pyedb\\.venv\\lib\\site-packages\\ipykernel\\kernelbase.py\", line 437, in dispatch_shell\n",
      "    await result\n",
      "  File \"C:\\actions-runner\\_work\\pyedb\\pyedb\\.venv\\lib\\site-packages\\ipykernel\\ipkernel.py\", line 362, in execute_request\n",
      "    await super().execute_request(stream, ident, parent)\n",
      "  File \"C:\\actions-runner\\_work\\pyedb\\pyedb\\.venv\\lib\\site-packages\\ipykernel\\kernelbase.py\", line 778, in execute_request\n",
      "    reply_content = await reply_content\n",
      "  File \"C:\\actions-runner\\_work\\pyedb\\pyedb\\.venv\\lib\\site-packages\\ipykernel\\ipkernel.py\", line 449, in do_execute\n",
      "    res = shell.run_cell(\n",
      "  File \"C:\\actions-runner\\_work\\pyedb\\pyedb\\.venv\\lib\\site-packages\\ipykernel\\zmqshell.py\", line 549, in run_cell\n",
      "    return super().run_cell(*args, **kwargs)\n",
      "  File \"C:\\actions-runner\\_work\\pyedb\\pyedb\\.venv\\lib\\site-packages\\IPython\\core\\interactiveshell.py\", line 3075, in run_cell\n",
      "    result = self._run_cell(\n",
      "  File \"C:\\actions-runner\\_work\\pyedb\\pyedb\\.venv\\lib\\site-packages\\IPython\\core\\interactiveshell.py\", line 3130, in _run_cell\n",
      "    result = runner(coro)\n",
      "  File \"C:\\actions-runner\\_work\\pyedb\\pyedb\\.venv\\lib\\site-packages\\IPython\\core\\async_helpers.py\", line 128, in _pseudo_sync_runner\n",
      "    coro.send(None)\n",
      "  File \"C:\\actions-runner\\_work\\pyedb\\pyedb\\.venv\\lib\\site-packages\\IPython\\core\\interactiveshell.py\", line 3334, in run_cell_async\n",
      "    has_raised = await self.run_ast_nodes(code_ast.body, cell_name,\n",
      "  File \"C:\\actions-runner\\_work\\pyedb\\pyedb\\.venv\\lib\\site-packages\\IPython\\core\\interactiveshell.py\", line 3517, in run_ast_nodes\n",
      "    if await self.run_code(code, result, async_=asy):\n",
      "  File \"C:\\actions-runner\\_work\\pyedb\\pyedb\\.venv\\lib\\site-packages\\IPython\\core\\interactiveshell.py\", line 3577, in run_code\n",
      "    exec(code_obj, self.user_global_ns, self.user_ns)\n",
      "  File \"C:\\Users\\ansys\\AppData\\Local\\Temp\\ipykernel_3468\\1057109396.py\", line 5, in <module>\n",
      "    edb = pyedb.Edb(edbpath=targetfile, edbversion=edb_version)\n",
      "  File \"C:\\actions-runner\\_work\\pyedb\\pyedb\\.venv\\lib\\site-packages\\pyedb\\generic\\design_types.py\", line 110, in Edb\n",
      "    return app(\n",
      "  File \"C:\\actions-runner\\_work\\pyedb\\pyedb\\.venv\\lib\\site-packages\\pyedb\\dotnet\\edb.py\", line 196, in __init__\n",
      "    Database.__init__(self, edbversion=edbversion, student_version=student_version)\n",
      "  File \"C:\\actions-runner\\_work\\pyedb\\pyedb\\.venv\\lib\\site-packages\\pyedb\\dotnet\\edb_core\\dotnet\\database.py\", line 802, in __init__\n",
      "    EdbDotNet.__init__(self, edbversion=edbversion, student_version=student_version)\n",
      "  File \"C:\\actions-runner\\_work\\pyedb\\pyedb\\.venv\\lib\\site-packages\\pyedb\\dotnet\\edb_core\\dotnet\\database.py\", line 711, in __init__\n",
      "    self._logger.info(\"Python version %s\", sys.version)\n",
      "  File \"C:\\actions-runner\\_work\\pyedb\\pyedb\\.venv\\lib\\site-packages\\pyedb\\edb_logger.py\", line 346, in info\n",
      "    return self._log_on_handler(0, msg, *args, **kwargs)\n",
      "  File \"C:\\actions-runner\\_work\\pyedb\\pyedb\\.venv\\lib\\site-packages\\pyedb\\edb_logger.py\", line 293, in _log_on_handler\n",
      "    self._global.info(message_text, *args, **kwargs)\n",
      "Message: 'Python version %s'\n",
      "Arguments: ('3.10.11 (tags/v3.10.11:7d4cc5a, Apr  5 2023, 00:38:17) [MSC v.1929 64 bit (AMD64)]',)\n"
     ]
    },
    {
     "name": "stdout",
     "output_type": "stream",
     "text": [
      "PyEDB INFO: Database ANSYS-HSD_V1.aedb Opened in 2024.2\n"
     ]
    },
    {
     "name": "stdout",
     "output_type": "stream",
     "text": [
      "PyEDB INFO: Cell main Opened\n"
     ]
    },
    {
     "name": "stderr",
     "output_type": "stream",
     "text": [
      "--- Logging error ---\n",
      "Traceback (most recent call last):\n",
      "  File \"C:\\actions-runner\\_work\\_tool\\Python\\3.10.11\\x64\\lib\\logging\\handlers.py\", line 74, in emit\n",
      "    self.doRollover()\n",
      "  File \"C:\\actions-runner\\_work\\_tool\\Python\\3.10.11\\x64\\lib\\logging\\handlers.py\", line 179, in doRollover\n",
      "    self.rotate(self.baseFilename, dfn)\n",
      "  File \"C:\\actions-runner\\_work\\_tool\\Python\\3.10.11\\x64\\lib\\logging\\handlers.py\", line 115, in rotate\n",
      "    os.rename(source, dest)\n",
      "PermissionError: [WinError 32] The process cannot access the file because it is being used by another process: 'C:\\\\Users\\\\ansys\\\\AppData\\\\Local\\\\Temp\\\\pyedb_ansys.log' -> 'C:\\\\Users\\\\ansys\\\\AppData\\\\Local\\\\Temp\\\\pyedb_ansys.log.1'\n",
      "Call stack:\n",
      "  File \"C:\\actions-runner\\_work\\_tool\\Python\\3.10.11\\x64\\lib\\runpy.py\", line 196, in _run_module_as_main\n",
      "    return _run_code(code, main_globals, None,\n",
      "  File \"C:\\actions-runner\\_work\\_tool\\Python\\3.10.11\\x64\\lib\\runpy.py\", line 86, in _run_code\n",
      "    exec(code, run_globals)\n",
      "  File \"C:\\actions-runner\\_work\\pyedb\\pyedb\\.venv\\lib\\site-packages\\ipykernel_launcher.py\", line 18, in <module>\n",
      "    app.launch_new_instance()\n",
      "  File \"C:\\actions-runner\\_work\\pyedb\\pyedb\\.venv\\lib\\site-packages\\traitlets\\config\\application.py\", line 1075, in launch_instance\n",
      "    app.start()\n",
      "  File \"C:\\actions-runner\\_work\\pyedb\\pyedb\\.venv\\lib\\site-packages\\ipykernel\\kernelapp.py\", line 739, in start\n",
      "    self.io_loop.start()\n",
      "  File \"C:\\actions-runner\\_work\\pyedb\\pyedb\\.venv\\lib\\site-packages\\tornado\\platform\\asyncio.py\", line 205, in start\n",
      "    self.asyncio_loop.run_forever()\n",
      "  File \"C:\\actions-runner\\_work\\_tool\\Python\\3.10.11\\x64\\lib\\asyncio\\base_events.py\", line 603, in run_forever\n",
      "    self._run_once()\n",
      "  File \"C:\\actions-runner\\_work\\_tool\\Python\\3.10.11\\x64\\lib\\asyncio\\base_events.py\", line 1909, in _run_once\n",
      "    handle._run()\n",
      "  File \"C:\\actions-runner\\_work\\_tool\\Python\\3.10.11\\x64\\lib\\asyncio\\events.py\", line 80, in _run\n",
      "    self._context.run(self._callback, *self._args)\n",
      "  File \"C:\\actions-runner\\_work\\pyedb\\pyedb\\.venv\\lib\\site-packages\\ipykernel\\kernelbase.py\", line 545, in dispatch_queue\n",
      "    await self.process_one()\n",
      "  File \"C:\\actions-runner\\_work\\pyedb\\pyedb\\.venv\\lib\\site-packages\\ipykernel\\kernelbase.py\", line 534, in process_one\n",
      "    await dispatch(*args)\n",
      "  File \"C:\\actions-runner\\_work\\pyedb\\pyedb\\.venv\\lib\\site-packages\\ipykernel\\kernelbase.py\", line 437, in dispatch_shell\n",
      "    await result\n",
      "  File \"C:\\actions-runner\\_work\\pyedb\\pyedb\\.venv\\lib\\site-packages\\ipykernel\\ipkernel.py\", line 362, in execute_request\n",
      "    await super().execute_request(stream, ident, parent)\n",
      "  File \"C:\\actions-runner\\_work\\pyedb\\pyedb\\.venv\\lib\\site-packages\\ipykernel\\kernelbase.py\", line 778, in execute_request\n",
      "    reply_content = await reply_content\n",
      "  File \"C:\\actions-runner\\_work\\pyedb\\pyedb\\.venv\\lib\\site-packages\\ipykernel\\ipkernel.py\", line 449, in do_execute\n",
      "    res = shell.run_cell(\n",
      "  File \"C:\\actions-runner\\_work\\pyedb\\pyedb\\.venv\\lib\\site-packages\\ipykernel\\zmqshell.py\", line 549, in run_cell\n",
      "    return super().run_cell(*args, **kwargs)\n",
      "  File \"C:\\actions-runner\\_work\\pyedb\\pyedb\\.venv\\lib\\site-packages\\IPython\\core\\interactiveshell.py\", line 3075, in run_cell\n",
      "    result = self._run_cell(\n",
      "  File \"C:\\actions-runner\\_work\\pyedb\\pyedb\\.venv\\lib\\site-packages\\IPython\\core\\interactiveshell.py\", line 3130, in _run_cell\n",
      "    result = runner(coro)\n",
      "  File \"C:\\actions-runner\\_work\\pyedb\\pyedb\\.venv\\lib\\site-packages\\IPython\\core\\async_helpers.py\", line 128, in _pseudo_sync_runner\n",
      "    coro.send(None)\n",
      "  File \"C:\\actions-runner\\_work\\pyedb\\pyedb\\.venv\\lib\\site-packages\\IPython\\core\\interactiveshell.py\", line 3334, in run_cell_async\n",
      "    has_raised = await self.run_ast_nodes(code_ast.body, cell_name,\n",
      "  File \"C:\\actions-runner\\_work\\pyedb\\pyedb\\.venv\\lib\\site-packages\\IPython\\core\\interactiveshell.py\", line 3517, in run_ast_nodes\n",
      "    if await self.run_code(code, result, async_=asy):\n",
      "  File \"C:\\actions-runner\\_work\\pyedb\\pyedb\\.venv\\lib\\site-packages\\IPython\\core\\interactiveshell.py\", line 3577, in run_code\n",
      "    exec(code_obj, self.user_global_ns, self.user_ns)\n",
      "  File \"C:\\Users\\ansys\\AppData\\Local\\Temp\\ipykernel_3468\\1057109396.py\", line 5, in <module>\n",
      "    edb = pyedb.Edb(edbpath=targetfile, edbversion=edb_version)\n",
      "  File \"C:\\actions-runner\\_work\\pyedb\\pyedb\\.venv\\lib\\site-packages\\pyedb\\generic\\design_types.py\", line 110, in Edb\n",
      "    return app(\n",
      "  File \"C:\\actions-runner\\_work\\pyedb\\pyedb\\.venv\\lib\\site-packages\\pyedb\\dotnet\\edb.py\", line 276, in __init__\n",
      "    self.open_edb()\n",
      "  File \"C:\\actions-runner\\_work\\pyedb\\pyedb\\.venv\\lib\\site-packages\\pyedb\\dotnet\\edb.py\", line 554, in open_edb\n",
      "    self.logger.info(\"Database {} Opened in {}\".format(os.path.split(self.edbpath)[-1], self.edbversion))\n",
      "  File \"C:\\actions-runner\\_work\\pyedb\\pyedb\\.venv\\lib\\site-packages\\pyedb\\edb_logger.py\", line 346, in info\n",
      "    return self._log_on_handler(0, msg, *args, **kwargs)\n",
      "  File \"C:\\actions-runner\\_work\\pyedb\\pyedb\\.venv\\lib\\site-packages\\pyedb\\edb_logger.py\", line 293, in _log_on_handler\n",
      "    self._global.info(message_text, *args, **kwargs)\n",
      "Message: 'Database ANSYS-HSD_V1.aedb Opened in 2024.2'\n",
      "Arguments: ()\n",
      "--- Logging error ---\n",
      "Traceback (most recent call last):\n",
      "  File \"C:\\actions-runner\\_work\\_tool\\Python\\3.10.11\\x64\\lib\\logging\\handlers.py\", line 74, in emit\n",
      "    self.doRollover()\n",
      "  File \"C:\\actions-runner\\_work\\_tool\\Python\\3.10.11\\x64\\lib\\logging\\handlers.py\", line 179, in doRollover\n",
      "    self.rotate(self.baseFilename, dfn)\n",
      "  File \"C:\\actions-runner\\_work\\_tool\\Python\\3.10.11\\x64\\lib\\logging\\handlers.py\", line 115, in rotate\n",
      "    os.rename(source, dest)\n",
      "PermissionError: [WinError 32] The process cannot access the file because it is being used by another process: 'C:\\\\Users\\\\ansys\\\\AppData\\\\Local\\\\Temp\\\\pyedb_ansys.log' -> 'C:\\\\Users\\\\ansys\\\\AppData\\\\Local\\\\Temp\\\\pyedb_ansys.log.1'\n",
      "Call stack:\n",
      "  File \"C:\\actions-runner\\_work\\_tool\\Python\\3.10.11\\x64\\lib\\runpy.py\", line 196, in _run_module_as_main\n",
      "    return _run_code(code, main_globals, None,\n",
      "  File \"C:\\actions-runner\\_work\\_tool\\Python\\3.10.11\\x64\\lib\\runpy.py\", line 86, in _run_code\n",
      "    exec(code, run_globals)\n",
      "  File \"C:\\actions-runner\\_work\\pyedb\\pyedb\\.venv\\lib\\site-packages\\ipykernel_launcher.py\", line 18, in <module>\n",
      "    app.launch_new_instance()\n",
      "  File \"C:\\actions-runner\\_work\\pyedb\\pyedb\\.venv\\lib\\site-packages\\traitlets\\config\\application.py\", line 1075, in launch_instance\n",
      "    app.start()\n",
      "  File \"C:\\actions-runner\\_work\\pyedb\\pyedb\\.venv\\lib\\site-packages\\ipykernel\\kernelapp.py\", line 739, in start\n",
      "    self.io_loop.start()\n",
      "  File \"C:\\actions-runner\\_work\\pyedb\\pyedb\\.venv\\lib\\site-packages\\tornado\\platform\\asyncio.py\", line 205, in start\n",
      "    self.asyncio_loop.run_forever()\n",
      "  File \"C:\\actions-runner\\_work\\_tool\\Python\\3.10.11\\x64\\lib\\asyncio\\base_events.py\", line 603, in run_forever\n",
      "    self._run_once()\n",
      "  File \"C:\\actions-runner\\_work\\_tool\\Python\\3.10.11\\x64\\lib\\asyncio\\base_events.py\", line 1909, in _run_once\n",
      "    handle._run()\n",
      "  File \"C:\\actions-runner\\_work\\_tool\\Python\\3.10.11\\x64\\lib\\asyncio\\events.py\", line 80, in _run\n",
      "    self._context.run(self._callback, *self._args)\n",
      "  File \"C:\\actions-runner\\_work\\pyedb\\pyedb\\.venv\\lib\\site-packages\\ipykernel\\kernelbase.py\", line 545, in dispatch_queue\n",
      "    await self.process_one()\n",
      "  File \"C:\\actions-runner\\_work\\pyedb\\pyedb\\.venv\\lib\\site-packages\\ipykernel\\kernelbase.py\", line 534, in process_one\n",
      "    await dispatch(*args)\n",
      "  File \"C:\\actions-runner\\_work\\pyedb\\pyedb\\.venv\\lib\\site-packages\\ipykernel\\kernelbase.py\", line 437, in dispatch_shell\n",
      "    await result\n",
      "  File \"C:\\actions-runner\\_work\\pyedb\\pyedb\\.venv\\lib\\site-packages\\ipykernel\\ipkernel.py\", line 362, in execute_request\n",
      "    await super().execute_request(stream, ident, parent)\n",
      "  File \"C:\\actions-runner\\_work\\pyedb\\pyedb\\.venv\\lib\\site-packages\\ipykernel\\kernelbase.py\", line 778, in execute_request\n",
      "    reply_content = await reply_content\n",
      "  File \"C:\\actions-runner\\_work\\pyedb\\pyedb\\.venv\\lib\\site-packages\\ipykernel\\ipkernel.py\", line 449, in do_execute\n",
      "    res = shell.run_cell(\n",
      "  File \"C:\\actions-runner\\_work\\pyedb\\pyedb\\.venv\\lib\\site-packages\\ipykernel\\zmqshell.py\", line 549, in run_cell\n",
      "    return super().run_cell(*args, **kwargs)\n",
      "  File \"C:\\actions-runner\\_work\\pyedb\\pyedb\\.venv\\lib\\site-packages\\IPython\\core\\interactiveshell.py\", line 3075, in run_cell\n",
      "    result = self._run_cell(\n",
      "  File \"C:\\actions-runner\\_work\\pyedb\\pyedb\\.venv\\lib\\site-packages\\IPython\\core\\interactiveshell.py\", line 3130, in _run_cell\n",
      "    result = runner(coro)\n",
      "  File \"C:\\actions-runner\\_work\\pyedb\\pyedb\\.venv\\lib\\site-packages\\IPython\\core\\async_helpers.py\", line 128, in _pseudo_sync_runner\n",
      "    coro.send(None)\n",
      "  File \"C:\\actions-runner\\_work\\pyedb\\pyedb\\.venv\\lib\\site-packages\\IPython\\core\\interactiveshell.py\", line 3334, in run_cell_async\n",
      "    has_raised = await self.run_ast_nodes(code_ast.body, cell_name,\n",
      "  File \"C:\\actions-runner\\_work\\pyedb\\pyedb\\.venv\\lib\\site-packages\\IPython\\core\\interactiveshell.py\", line 3517, in run_ast_nodes\n",
      "    if await self.run_code(code, result, async_=asy):\n",
      "  File \"C:\\actions-runner\\_work\\pyedb\\pyedb\\.venv\\lib\\site-packages\\IPython\\core\\interactiveshell.py\", line 3577, in run_code\n",
      "    exec(code_obj, self.user_global_ns, self.user_ns)\n",
      "  File \"C:\\Users\\ansys\\AppData\\Local\\Temp\\ipykernel_3468\\1057109396.py\", line 5, in <module>\n",
      "    edb = pyedb.Edb(edbpath=targetfile, edbversion=edb_version)\n",
      "  File \"C:\\actions-runner\\_work\\pyedb\\pyedb\\.venv\\lib\\site-packages\\pyedb\\generic\\design_types.py\", line 110, in Edb\n",
      "    return app(\n",
      "  File \"C:\\actions-runner\\_work\\pyedb\\pyedb\\.venv\\lib\\site-packages\\pyedb\\dotnet\\edb.py\", line 276, in __init__\n",
      "    self.open_edb()\n",
      "  File \"C:\\actions-runner\\_work\\pyedb\\pyedb\\.venv\\lib\\site-packages\\pyedb\\dotnet\\edb.py\", line 564, in open_edb\n",
      "    self.logger.info(\"Cell %s Opened\", self._active_cell.GetName())\n",
      "  File \"C:\\actions-runner\\_work\\pyedb\\pyedb\\.venv\\lib\\site-packages\\pyedb\\edb_logger.py\", line 346, in info\n",
      "    return self._log_on_handler(0, msg, *args, **kwargs)\n",
      "  File \"C:\\actions-runner\\_work\\pyedb\\pyedb\\.venv\\lib\\site-packages\\pyedb\\edb_logger.py\", line 293, in _log_on_handler\n",
      "    self._global.info(message_text, *args, **kwargs)\n",
      "Message: 'Cell %s Opened'\n",
      "Arguments: ('main',)\n"
     ]
    },
    {
     "name": "stdout",
     "output_type": "stream",
     "text": [
      "PyEDB INFO: Builder was initialized.\n"
     ]
    },
    {
     "name": "stdout",
     "output_type": "stream",
     "text": [
      "PyEDB INFO: EDB initialized.\n"
     ]
    },
    {
     "name": "stderr",
     "output_type": "stream",
     "text": [
      "--- Logging error ---\n",
      "Traceback (most recent call last):\n",
      "  File \"C:\\actions-runner\\_work\\_tool\\Python\\3.10.11\\x64\\lib\\logging\\handlers.py\", line 74, in emit\n",
      "    self.doRollover()\n",
      "  File \"C:\\actions-runner\\_work\\_tool\\Python\\3.10.11\\x64\\lib\\logging\\handlers.py\", line 179, in doRollover\n",
      "    self.rotate(self.baseFilename, dfn)\n",
      "  File \"C:\\actions-runner\\_work\\_tool\\Python\\3.10.11\\x64\\lib\\logging\\handlers.py\", line 115, in rotate\n",
      "    os.rename(source, dest)\n",
      "PermissionError: [WinError 32] The process cannot access the file because it is being used by another process: 'C:\\\\Users\\\\ansys\\\\AppData\\\\Local\\\\Temp\\\\pyedb_ansys.log' -> 'C:\\\\Users\\\\ansys\\\\AppData\\\\Local\\\\Temp\\\\pyedb_ansys.log.1'\n",
      "Call stack:\n",
      "  File \"C:\\actions-runner\\_work\\_tool\\Python\\3.10.11\\x64\\lib\\runpy.py\", line 196, in _run_module_as_main\n",
      "    return _run_code(code, main_globals, None,\n",
      "  File \"C:\\actions-runner\\_work\\_tool\\Python\\3.10.11\\x64\\lib\\runpy.py\", line 86, in _run_code\n",
      "    exec(code, run_globals)\n",
      "  File \"C:\\actions-runner\\_work\\pyedb\\pyedb\\.venv\\lib\\site-packages\\ipykernel_launcher.py\", line 18, in <module>\n",
      "    app.launch_new_instance()\n",
      "  File \"C:\\actions-runner\\_work\\pyedb\\pyedb\\.venv\\lib\\site-packages\\traitlets\\config\\application.py\", line 1075, in launch_instance\n",
      "    app.start()\n",
      "  File \"C:\\actions-runner\\_work\\pyedb\\pyedb\\.venv\\lib\\site-packages\\ipykernel\\kernelapp.py\", line 739, in start\n",
      "    self.io_loop.start()\n",
      "  File \"C:\\actions-runner\\_work\\pyedb\\pyedb\\.venv\\lib\\site-packages\\tornado\\platform\\asyncio.py\", line 205, in start\n",
      "    self.asyncio_loop.run_forever()\n",
      "  File \"C:\\actions-runner\\_work\\_tool\\Python\\3.10.11\\x64\\lib\\asyncio\\base_events.py\", line 603, in run_forever\n",
      "    self._run_once()\n",
      "  File \"C:\\actions-runner\\_work\\_tool\\Python\\3.10.11\\x64\\lib\\asyncio\\base_events.py\", line 1909, in _run_once\n",
      "    handle._run()\n",
      "  File \"C:\\actions-runner\\_work\\_tool\\Python\\3.10.11\\x64\\lib\\asyncio\\events.py\", line 80, in _run\n",
      "    self._context.run(self._callback, *self._args)\n",
      "  File \"C:\\actions-runner\\_work\\pyedb\\pyedb\\.venv\\lib\\site-packages\\ipykernel\\kernelbase.py\", line 545, in dispatch_queue\n",
      "    await self.process_one()\n",
      "  File \"C:\\actions-runner\\_work\\pyedb\\pyedb\\.venv\\lib\\site-packages\\ipykernel\\kernelbase.py\", line 534, in process_one\n",
      "    await dispatch(*args)\n",
      "  File \"C:\\actions-runner\\_work\\pyedb\\pyedb\\.venv\\lib\\site-packages\\ipykernel\\kernelbase.py\", line 437, in dispatch_shell\n",
      "    await result\n",
      "  File \"C:\\actions-runner\\_work\\pyedb\\pyedb\\.venv\\lib\\site-packages\\ipykernel\\ipkernel.py\", line 362, in execute_request\n",
      "    await super().execute_request(stream, ident, parent)\n",
      "  File \"C:\\actions-runner\\_work\\pyedb\\pyedb\\.venv\\lib\\site-packages\\ipykernel\\kernelbase.py\", line 778, in execute_request\n",
      "    reply_content = await reply_content\n",
      "  File \"C:\\actions-runner\\_work\\pyedb\\pyedb\\.venv\\lib\\site-packages\\ipykernel\\ipkernel.py\", line 449, in do_execute\n",
      "    res = shell.run_cell(\n",
      "  File \"C:\\actions-runner\\_work\\pyedb\\pyedb\\.venv\\lib\\site-packages\\ipykernel\\zmqshell.py\", line 549, in run_cell\n",
      "    return super().run_cell(*args, **kwargs)\n",
      "  File \"C:\\actions-runner\\_work\\pyedb\\pyedb\\.venv\\lib\\site-packages\\IPython\\core\\interactiveshell.py\", line 3075, in run_cell\n",
      "    result = self._run_cell(\n",
      "  File \"C:\\actions-runner\\_work\\pyedb\\pyedb\\.venv\\lib\\site-packages\\IPython\\core\\interactiveshell.py\", line 3130, in _run_cell\n",
      "    result = runner(coro)\n",
      "  File \"C:\\actions-runner\\_work\\pyedb\\pyedb\\.venv\\lib\\site-packages\\IPython\\core\\async_helpers.py\", line 128, in _pseudo_sync_runner\n",
      "    coro.send(None)\n",
      "  File \"C:\\actions-runner\\_work\\pyedb\\pyedb\\.venv\\lib\\site-packages\\IPython\\core\\interactiveshell.py\", line 3334, in run_cell_async\n",
      "    has_raised = await self.run_ast_nodes(code_ast.body, cell_name,\n",
      "  File \"C:\\actions-runner\\_work\\pyedb\\pyedb\\.venv\\lib\\site-packages\\IPython\\core\\interactiveshell.py\", line 3517, in run_ast_nodes\n",
      "    if await self.run_code(code, result, async_=asy):\n",
      "  File \"C:\\actions-runner\\_work\\pyedb\\pyedb\\.venv\\lib\\site-packages\\IPython\\core\\interactiveshell.py\", line 3577, in run_code\n",
      "    exec(code_obj, self.user_global_ns, self.user_ns)\n",
      "  File \"C:\\Users\\ansys\\AppData\\Local\\Temp\\ipykernel_3468\\1057109396.py\", line 5, in <module>\n",
      "    edb = pyedb.Edb(edbpath=targetfile, edbversion=edb_version)\n",
      "  File \"C:\\actions-runner\\_work\\pyedb\\pyedb\\.venv\\lib\\site-packages\\pyedb\\generic\\design_types.py\", line 110, in Edb\n",
      "    return app(\n",
      "  File \"C:\\actions-runner\\_work\\pyedb\\pyedb\\.venv\\lib\\site-packages\\pyedb\\dotnet\\edb.py\", line 276, in __init__\n",
      "    self.open_edb()\n",
      "  File \"C:\\actions-runner\\_work\\pyedb\\pyedb\\.venv\\lib\\site-packages\\pyedb\\dotnet\\edb.py\", line 567, in open_edb\n",
      "    self.logger.info(\"Builder was initialized.\")\n",
      "  File \"C:\\actions-runner\\_work\\pyedb\\pyedb\\.venv\\lib\\site-packages\\pyedb\\edb_logger.py\", line 346, in info\n",
      "    return self._log_on_handler(0, msg, *args, **kwargs)\n",
      "  File \"C:\\actions-runner\\_work\\pyedb\\pyedb\\.venv\\lib\\site-packages\\pyedb\\edb_logger.py\", line 293, in _log_on_handler\n",
      "    self._global.info(message_text, *args, **kwargs)\n",
      "Message: 'Builder was initialized.'\n",
      "Arguments: ()\n",
      "--- Logging error ---\n",
      "Traceback (most recent call last):\n",
      "  File \"C:\\actions-runner\\_work\\_tool\\Python\\3.10.11\\x64\\lib\\logging\\handlers.py\", line 74, in emit\n",
      "    self.doRollover()\n",
      "  File \"C:\\actions-runner\\_work\\_tool\\Python\\3.10.11\\x64\\lib\\logging\\handlers.py\", line 179, in doRollover\n",
      "    self.rotate(self.baseFilename, dfn)\n",
      "  File \"C:\\actions-runner\\_work\\_tool\\Python\\3.10.11\\x64\\lib\\logging\\handlers.py\", line 115, in rotate\n",
      "    os.rename(source, dest)\n",
      "PermissionError: [WinError 32] The process cannot access the file because it is being used by another process: 'C:\\\\Users\\\\ansys\\\\AppData\\\\Local\\\\Temp\\\\pyedb_ansys.log' -> 'C:\\\\Users\\\\ansys\\\\AppData\\\\Local\\\\Temp\\\\pyedb_ansys.log.1'\n",
      "Call stack:\n",
      "  File \"C:\\actions-runner\\_work\\_tool\\Python\\3.10.11\\x64\\lib\\runpy.py\", line 196, in _run_module_as_main\n",
      "    return _run_code(code, main_globals, None,\n",
      "  File \"C:\\actions-runner\\_work\\_tool\\Python\\3.10.11\\x64\\lib\\runpy.py\", line 86, in _run_code\n",
      "    exec(code, run_globals)\n",
      "  File \"C:\\actions-runner\\_work\\pyedb\\pyedb\\.venv\\lib\\site-packages\\ipykernel_launcher.py\", line 18, in <module>\n",
      "    app.launch_new_instance()\n",
      "  File \"C:\\actions-runner\\_work\\pyedb\\pyedb\\.venv\\lib\\site-packages\\traitlets\\config\\application.py\", line 1075, in launch_instance\n",
      "    app.start()\n",
      "  File \"C:\\actions-runner\\_work\\pyedb\\pyedb\\.venv\\lib\\site-packages\\ipykernel\\kernelapp.py\", line 739, in start\n",
      "    self.io_loop.start()\n",
      "  File \"C:\\actions-runner\\_work\\pyedb\\pyedb\\.venv\\lib\\site-packages\\tornado\\platform\\asyncio.py\", line 205, in start\n",
      "    self.asyncio_loop.run_forever()\n",
      "  File \"C:\\actions-runner\\_work\\_tool\\Python\\3.10.11\\x64\\lib\\asyncio\\base_events.py\", line 603, in run_forever\n",
      "    self._run_once()\n",
      "  File \"C:\\actions-runner\\_work\\_tool\\Python\\3.10.11\\x64\\lib\\asyncio\\base_events.py\", line 1909, in _run_once\n",
      "    handle._run()\n",
      "  File \"C:\\actions-runner\\_work\\_tool\\Python\\3.10.11\\x64\\lib\\asyncio\\events.py\", line 80, in _run\n",
      "    self._context.run(self._callback, *self._args)\n",
      "  File \"C:\\actions-runner\\_work\\pyedb\\pyedb\\.venv\\lib\\site-packages\\ipykernel\\kernelbase.py\", line 545, in dispatch_queue\n",
      "    await self.process_one()\n",
      "  File \"C:\\actions-runner\\_work\\pyedb\\pyedb\\.venv\\lib\\site-packages\\ipykernel\\kernelbase.py\", line 534, in process_one\n",
      "    await dispatch(*args)\n",
      "  File \"C:\\actions-runner\\_work\\pyedb\\pyedb\\.venv\\lib\\site-packages\\ipykernel\\kernelbase.py\", line 437, in dispatch_shell\n",
      "    await result\n",
      "  File \"C:\\actions-runner\\_work\\pyedb\\pyedb\\.venv\\lib\\site-packages\\ipykernel\\ipkernel.py\", line 362, in execute_request\n",
      "    await super().execute_request(stream, ident, parent)\n",
      "  File \"C:\\actions-runner\\_work\\pyedb\\pyedb\\.venv\\lib\\site-packages\\ipykernel\\kernelbase.py\", line 778, in execute_request\n",
      "    reply_content = await reply_content\n",
      "  File \"C:\\actions-runner\\_work\\pyedb\\pyedb\\.venv\\lib\\site-packages\\ipykernel\\ipkernel.py\", line 449, in do_execute\n",
      "    res = shell.run_cell(\n",
      "  File \"C:\\actions-runner\\_work\\pyedb\\pyedb\\.venv\\lib\\site-packages\\ipykernel\\zmqshell.py\", line 549, in run_cell\n",
      "    return super().run_cell(*args, **kwargs)\n",
      "  File \"C:\\actions-runner\\_work\\pyedb\\pyedb\\.venv\\lib\\site-packages\\IPython\\core\\interactiveshell.py\", line 3075, in run_cell\n",
      "    result = self._run_cell(\n",
      "  File \"C:\\actions-runner\\_work\\pyedb\\pyedb\\.venv\\lib\\site-packages\\IPython\\core\\interactiveshell.py\", line 3130, in _run_cell\n",
      "    result = runner(coro)\n",
      "  File \"C:\\actions-runner\\_work\\pyedb\\pyedb\\.venv\\lib\\site-packages\\IPython\\core\\async_helpers.py\", line 128, in _pseudo_sync_runner\n",
      "    coro.send(None)\n",
      "  File \"C:\\actions-runner\\_work\\pyedb\\pyedb\\.venv\\lib\\site-packages\\IPython\\core\\interactiveshell.py\", line 3334, in run_cell_async\n",
      "    has_raised = await self.run_ast_nodes(code_ast.body, cell_name,\n",
      "  File \"C:\\actions-runner\\_work\\pyedb\\pyedb\\.venv\\lib\\site-packages\\IPython\\core\\interactiveshell.py\", line 3517, in run_ast_nodes\n",
      "    if await self.run_code(code, result, async_=asy):\n",
      "  File \"C:\\actions-runner\\_work\\pyedb\\pyedb\\.venv\\lib\\site-packages\\IPython\\core\\interactiveshell.py\", line 3577, in run_code\n",
      "    exec(code_obj, self.user_global_ns, self.user_ns)\n",
      "  File \"C:\\Users\\ansys\\AppData\\Local\\Temp\\ipykernel_3468\\1057109396.py\", line 5, in <module>\n",
      "    edb = pyedb.Edb(edbpath=targetfile, edbversion=edb_version)\n",
      "  File \"C:\\actions-runner\\_work\\pyedb\\pyedb\\.venv\\lib\\site-packages\\pyedb\\generic\\design_types.py\", line 110, in Edb\n",
      "    return app(\n",
      "  File \"C:\\actions-runner\\_work\\pyedb\\pyedb\\.venv\\lib\\site-packages\\pyedb\\dotnet\\edb.py\", line 278, in __init__\n",
      "    self.logger.info(\"EDB initialized.\")\n",
      "  File \"C:\\actions-runner\\_work\\pyedb\\pyedb\\.venv\\lib\\site-packages\\pyedb\\edb_logger.py\", line 346, in info\n",
      "    return self._log_on_handler(0, msg, *args, **kwargs)\n",
      "  File \"C:\\actions-runner\\_work\\pyedb\\pyedb\\.venv\\lib\\site-packages\\pyedb\\edb_logger.py\", line 293, in _log_on_handler\n",
      "    self._global.info(message_text, *args, **kwargs)\n",
      "Message: 'EDB initialized.'\n",
      "Arguments: ()\n"
     ]
    }
   ],
   "source": [
    "# Select EDB version (change it manually if needed, e.g. \"2024.2\")\n",
    "edb_version = \"2024.2\"\n",
    "print(f\"EDB version: {edb_version}\")\n",
    "\n",
    "edb = pyedb.Edb(edbpath=targetfile, edbversion=edb_version)"
   ]
  },
  {
   "cell_type": "markdown",
   "id": "af5eb354",
   "metadata": {},
   "source": [
    "## Parametrize the width of a trace."
   ]
  },
  {
   "cell_type": "code",
   "execution_count": 4,
   "id": "0ce231ce",
   "metadata": {
    "execution": {
     "iopub.execute_input": "2024-09-17T08:07:53.982238Z",
     "iopub.status.busy": "2024-09-17T08:07:53.982238Z",
     "iopub.status.idle": "2024-09-17T08:07:55.451061Z",
     "shell.execute_reply": "2024-09-17T08:07:55.451061Z"
    }
   },
   "outputs": [
    {
     "data": {
      "text/plain": [
       "True"
      ]
     },
     "execution_count": 4,
     "metadata": {},
     "output_type": "execute_result"
    }
   ],
   "source": [
    "edb.modeler.parametrize_trace_width(\"A0_N\", parameter_name=generate_unique_name(\"Par\"), variable_value=\"0.4321mm\")"
   ]
  },
  {
   "cell_type": "markdown",
   "id": "836f09fa",
   "metadata": {},
   "source": [
    "## Create a cutout and plot it."
   ]
  },
  {
   "cell_type": "code",
   "execution_count": 5,
   "id": "3accbe79",
   "metadata": {
    "execution": {
     "iopub.execute_input": "2024-09-17T08:07:55.451061Z",
     "iopub.status.busy": "2024-09-17T08:07:55.451061Z",
     "iopub.status.idle": "2024-09-17T08:08:05.670321Z",
     "shell.execute_reply": "2024-09-17T08:08:05.670321Z"
    }
   },
   "outputs": [
    {
     "name": "stdout",
     "output_type": "stream",
     "text": [
      "PyEDB INFO: Cutout Multithread started.\n"
     ]
    },
    {
     "name": "stderr",
     "output_type": "stream",
     "text": [
      "--- Logging error ---\n",
      "Traceback (most recent call last):\n",
      "  File \"C:\\actions-runner\\_work\\_tool\\Python\\3.10.11\\x64\\lib\\logging\\handlers.py\", line 74, in emit\n",
      "    self.doRollover()\n",
      "  File \"C:\\actions-runner\\_work\\_tool\\Python\\3.10.11\\x64\\lib\\logging\\handlers.py\", line 179, in doRollover\n",
      "    self.rotate(self.baseFilename, dfn)\n",
      "  File \"C:\\actions-runner\\_work\\_tool\\Python\\3.10.11\\x64\\lib\\logging\\handlers.py\", line 115, in rotate\n",
      "    os.rename(source, dest)\n",
      "PermissionError: [WinError 32] The process cannot access the file because it is being used by another process: 'C:\\\\Users\\\\ansys\\\\AppData\\\\Local\\\\Temp\\\\pyedb_ansys.log' -> 'C:\\\\Users\\\\ansys\\\\AppData\\\\Local\\\\Temp\\\\pyedb_ansys.log.1'\n",
      "Call stack:\n",
      "  File \"C:\\actions-runner\\_work\\_tool\\Python\\3.10.11\\x64\\lib\\runpy.py\", line 196, in _run_module_as_main\n",
      "    return _run_code(code, main_globals, None,\n",
      "  File \"C:\\actions-runner\\_work\\_tool\\Python\\3.10.11\\x64\\lib\\runpy.py\", line 86, in _run_code\n",
      "    exec(code, run_globals)\n",
      "  File \"C:\\actions-runner\\_work\\pyedb\\pyedb\\.venv\\lib\\site-packages\\ipykernel_launcher.py\", line 18, in <module>\n",
      "    app.launch_new_instance()\n",
      "  File \"C:\\actions-runner\\_work\\pyedb\\pyedb\\.venv\\lib\\site-packages\\traitlets\\config\\application.py\", line 1075, in launch_instance\n",
      "    app.start()\n",
      "  File \"C:\\actions-runner\\_work\\pyedb\\pyedb\\.venv\\lib\\site-packages\\ipykernel\\kernelapp.py\", line 739, in start\n",
      "    self.io_loop.start()\n",
      "  File \"C:\\actions-runner\\_work\\pyedb\\pyedb\\.venv\\lib\\site-packages\\tornado\\platform\\asyncio.py\", line 205, in start\n",
      "    self.asyncio_loop.run_forever()\n",
      "  File \"C:\\actions-runner\\_work\\_tool\\Python\\3.10.11\\x64\\lib\\asyncio\\base_events.py\", line 603, in run_forever\n",
      "    self._run_once()\n",
      "  File \"C:\\actions-runner\\_work\\_tool\\Python\\3.10.11\\x64\\lib\\asyncio\\base_events.py\", line 1909, in _run_once\n",
      "    handle._run()\n",
      "  File \"C:\\actions-runner\\_work\\_tool\\Python\\3.10.11\\x64\\lib\\asyncio\\events.py\", line 80, in _run\n",
      "    self._context.run(self._callback, *self._args)\n",
      "  File \"C:\\actions-runner\\_work\\pyedb\\pyedb\\.venv\\lib\\site-packages\\ipykernel\\kernelbase.py\", line 545, in dispatch_queue\n",
      "    await self.process_one()\n",
      "  File \"C:\\actions-runner\\_work\\pyedb\\pyedb\\.venv\\lib\\site-packages\\ipykernel\\kernelbase.py\", line 534, in process_one\n",
      "    await dispatch(*args)\n",
      "  File \"C:\\actions-runner\\_work\\pyedb\\pyedb\\.venv\\lib\\site-packages\\ipykernel\\kernelbase.py\", line 437, in dispatch_shell\n",
      "    await result\n",
      "  File \"C:\\actions-runner\\_work\\pyedb\\pyedb\\.venv\\lib\\site-packages\\ipykernel\\ipkernel.py\", line 362, in execute_request\n",
      "    await super().execute_request(stream, ident, parent)\n",
      "  File \"C:\\actions-runner\\_work\\pyedb\\pyedb\\.venv\\lib\\site-packages\\ipykernel\\kernelbase.py\", line 778, in execute_request\n",
      "    reply_content = await reply_content\n",
      "  File \"C:\\actions-runner\\_work\\pyedb\\pyedb\\.venv\\lib\\site-packages\\ipykernel\\ipkernel.py\", line 449, in do_execute\n",
      "    res = shell.run_cell(\n",
      "  File \"C:\\actions-runner\\_work\\pyedb\\pyedb\\.venv\\lib\\site-packages\\ipykernel\\zmqshell.py\", line 549, in run_cell\n",
      "    return super().run_cell(*args, **kwargs)\n",
      "  File \"C:\\actions-runner\\_work\\pyedb\\pyedb\\.venv\\lib\\site-packages\\IPython\\core\\interactiveshell.py\", line 3075, in run_cell\n",
      "    result = self._run_cell(\n",
      "  File \"C:\\actions-runner\\_work\\pyedb\\pyedb\\.venv\\lib\\site-packages\\IPython\\core\\interactiveshell.py\", line 3130, in _run_cell\n",
      "    result = runner(coro)\n",
      "  File \"C:\\actions-runner\\_work\\pyedb\\pyedb\\.venv\\lib\\site-packages\\IPython\\core\\async_helpers.py\", line 128, in _pseudo_sync_runner\n",
      "    coro.send(None)\n",
      "  File \"C:\\actions-runner\\_work\\pyedb\\pyedb\\.venv\\lib\\site-packages\\IPython\\core\\interactiveshell.py\", line 3334, in run_cell_async\n",
      "    has_raised = await self.run_ast_nodes(code_ast.body, cell_name,\n",
      "  File \"C:\\actions-runner\\_work\\pyedb\\pyedb\\.venv\\lib\\site-packages\\IPython\\core\\interactiveshell.py\", line 3517, in run_ast_nodes\n",
      "    if await self.run_code(code, result, async_=asy):\n",
      "  File \"C:\\actions-runner\\_work\\pyedb\\pyedb\\.venv\\lib\\site-packages\\IPython\\core\\interactiveshell.py\", line 3577, in run_code\n",
      "    exec(code_obj, self.user_global_ns, self.user_ns)\n",
      "  File \"C:\\Users\\ansys\\AppData\\Local\\Temp\\ipykernel_3468\\2999416059.py\", line 6, in <module>\n",
      "    edb.cutout(\n",
      "  File \"C:\\actions-runner\\_work\\pyedb\\pyedb\\.venv\\lib\\site-packages\\pyedb\\dotnet\\edb.py\", line 1951, in cutout\n",
      "    result = self._create_cutout_multithread(\n",
      "  File \"C:\\actions-runner\\_work\\pyedb\\pyedb\\.venv\\lib\\site-packages\\pyedb\\dotnet\\edb.py\", line 2187, in _create_cutout_multithread\n",
      "    self.logger.info(\"Cutout Multithread started.\")\n",
      "  File \"C:\\actions-runner\\_work\\pyedb\\pyedb\\.venv\\lib\\site-packages\\pyedb\\edb_logger.py\", line 346, in info\n",
      "    return self._log_on_handler(0, msg, *args, **kwargs)\n",
      "  File \"C:\\actions-runner\\_work\\pyedb\\pyedb\\.venv\\lib\\site-packages\\pyedb\\edb_logger.py\", line 293, in _log_on_handler\n",
      "    self._global.info(message_text, *args, **kwargs)\n",
      "Message: 'Cutout Multithread started.'\n",
      "Arguments: ()\n"
     ]
    },
    {
     "name": "stdout",
     "output_type": "stream",
     "text": [
      "PyEDB INFO: Net clean up Elapsed time: 0m 4sec\n"
     ]
    },
    {
     "name": "stderr",
     "output_type": "stream",
     "text": [
      "--- Logging error ---\n",
      "Traceback (most recent call last):\n",
      "  File \"C:\\actions-runner\\_work\\_tool\\Python\\3.10.11\\x64\\lib\\logging\\handlers.py\", line 74, in emit\n",
      "    self.doRollover()\n",
      "  File \"C:\\actions-runner\\_work\\_tool\\Python\\3.10.11\\x64\\lib\\logging\\handlers.py\", line 179, in doRollover\n",
      "    self.rotate(self.baseFilename, dfn)\n",
      "  File \"C:\\actions-runner\\_work\\_tool\\Python\\3.10.11\\x64\\lib\\logging\\handlers.py\", line 115, in rotate\n",
      "    os.rename(source, dest)\n",
      "PermissionError: [WinError 32] The process cannot access the file because it is being used by another process: 'C:\\\\Users\\\\ansys\\\\AppData\\\\Local\\\\Temp\\\\pyedb_ansys.log' -> 'C:\\\\Users\\\\ansys\\\\AppData\\\\Local\\\\Temp\\\\pyedb_ansys.log.1'\n",
      "Call stack:\n",
      "  File \"C:\\actions-runner\\_work\\_tool\\Python\\3.10.11\\x64\\lib\\runpy.py\", line 196, in _run_module_as_main\n",
      "    return _run_code(code, main_globals, None,\n",
      "  File \"C:\\actions-runner\\_work\\_tool\\Python\\3.10.11\\x64\\lib\\runpy.py\", line 86, in _run_code\n",
      "    exec(code, run_globals)\n",
      "  File \"C:\\actions-runner\\_work\\pyedb\\pyedb\\.venv\\lib\\site-packages\\ipykernel_launcher.py\", line 18, in <module>\n",
      "    app.launch_new_instance()\n",
      "  File \"C:\\actions-runner\\_work\\pyedb\\pyedb\\.venv\\lib\\site-packages\\traitlets\\config\\application.py\", line 1075, in launch_instance\n",
      "    app.start()\n",
      "  File \"C:\\actions-runner\\_work\\pyedb\\pyedb\\.venv\\lib\\site-packages\\ipykernel\\kernelapp.py\", line 739, in start\n",
      "    self.io_loop.start()\n",
      "  File \"C:\\actions-runner\\_work\\pyedb\\pyedb\\.venv\\lib\\site-packages\\tornado\\platform\\asyncio.py\", line 205, in start\n",
      "    self.asyncio_loop.run_forever()\n",
      "  File \"C:\\actions-runner\\_work\\_tool\\Python\\3.10.11\\x64\\lib\\asyncio\\base_events.py\", line 603, in run_forever\n",
      "    self._run_once()\n",
      "  File \"C:\\actions-runner\\_work\\_tool\\Python\\3.10.11\\x64\\lib\\asyncio\\base_events.py\", line 1909, in _run_once\n",
      "    handle._run()\n",
      "  File \"C:\\actions-runner\\_work\\_tool\\Python\\3.10.11\\x64\\lib\\asyncio\\events.py\", line 80, in _run\n",
      "    self._context.run(self._callback, *self._args)\n",
      "  File \"C:\\actions-runner\\_work\\pyedb\\pyedb\\.venv\\lib\\site-packages\\ipykernel\\kernelbase.py\", line 545, in dispatch_queue\n",
      "    await self.process_one()\n",
      "  File \"C:\\actions-runner\\_work\\pyedb\\pyedb\\.venv\\lib\\site-packages\\ipykernel\\kernelbase.py\", line 534, in process_one\n",
      "    await dispatch(*args)\n",
      "  File \"C:\\actions-runner\\_work\\pyedb\\pyedb\\.venv\\lib\\site-packages\\ipykernel\\kernelbase.py\", line 437, in dispatch_shell\n",
      "    await result\n",
      "  File \"C:\\actions-runner\\_work\\pyedb\\pyedb\\.venv\\lib\\site-packages\\ipykernel\\ipkernel.py\", line 362, in execute_request\n",
      "    await super().execute_request(stream, ident, parent)\n",
      "  File \"C:\\actions-runner\\_work\\pyedb\\pyedb\\.venv\\lib\\site-packages\\ipykernel\\kernelbase.py\", line 778, in execute_request\n",
      "    reply_content = await reply_content\n",
      "  File \"C:\\actions-runner\\_work\\pyedb\\pyedb\\.venv\\lib\\site-packages\\ipykernel\\ipkernel.py\", line 449, in do_execute\n",
      "    res = shell.run_cell(\n",
      "  File \"C:\\actions-runner\\_work\\pyedb\\pyedb\\.venv\\lib\\site-packages\\ipykernel\\zmqshell.py\", line 549, in run_cell\n",
      "    return super().run_cell(*args, **kwargs)\n",
      "  File \"C:\\actions-runner\\_work\\pyedb\\pyedb\\.venv\\lib\\site-packages\\IPython\\core\\interactiveshell.py\", line 3075, in run_cell\n",
      "    result = self._run_cell(\n",
      "  File \"C:\\actions-runner\\_work\\pyedb\\pyedb\\.venv\\lib\\site-packages\\IPython\\core\\interactiveshell.py\", line 3130, in _run_cell\n",
      "    result = runner(coro)\n",
      "  File \"C:\\actions-runner\\_work\\pyedb\\pyedb\\.venv\\lib\\site-packages\\IPython\\core\\async_helpers.py\", line 128, in _pseudo_sync_runner\n",
      "    coro.send(None)\n",
      "  File \"C:\\actions-runner\\_work\\pyedb\\pyedb\\.venv\\lib\\site-packages\\IPython\\core\\interactiveshell.py\", line 3334, in run_cell_async\n",
      "    has_raised = await self.run_ast_nodes(code_ast.body, cell_name,\n",
      "  File \"C:\\actions-runner\\_work\\pyedb\\pyedb\\.venv\\lib\\site-packages\\IPython\\core\\interactiveshell.py\", line 3517, in run_ast_nodes\n",
      "    if await self.run_code(code, result, async_=asy):\n",
      "  File \"C:\\actions-runner\\_work\\pyedb\\pyedb\\.venv\\lib\\site-packages\\IPython\\core\\interactiveshell.py\", line 3577, in run_code\n",
      "    exec(code_obj, self.user_global_ns, self.user_ns)\n",
      "  File \"C:\\Users\\ansys\\AppData\\Local\\Temp\\ipykernel_3468\\2999416059.py\", line 6, in <module>\n",
      "    edb.cutout(\n",
      "  File \"C:\\actions-runner\\_work\\pyedb\\pyedb\\.venv\\lib\\site-packages\\pyedb\\dotnet\\edb.py\", line 1951, in cutout\n",
      "    result = self._create_cutout_multithread(\n",
      "  File \"C:\\actions-runner\\_work\\pyedb\\pyedb\\.venv\\lib\\site-packages\\pyedb\\dotnet\\edb.py\", line 2249, in _create_cutout_multithread\n",
      "    self.logger.info_timer(\"Net clean up\")\n",
      "  File \"C:\\actions-runner\\_work\\pyedb\\pyedb\\.venv\\lib\\site-packages\\pyedb\\edb_logger.py\", line 372, in info_timer\n",
      "    return self._log_on_handler(0, msg, *args, **kwargs)\n",
      "  File \"C:\\actions-runner\\_work\\pyedb\\pyedb\\.venv\\lib\\site-packages\\pyedb\\edb_logger.py\", line 293, in _log_on_handler\n",
      "    self._global.info(message_text, *args, **kwargs)\n",
      "Message: 'Net clean up Elapsed time: 0m 4sec'\n",
      "Arguments: ()\n"
     ]
    },
    {
     "name": "stdout",
     "output_type": "stream",
     "text": [
      "PyEDB INFO: Expanded Net Polygon Creation Elapsed time: 0m 0sec\n"
     ]
    },
    {
     "name": "stderr",
     "output_type": "stream",
     "text": [
      "--- Logging error ---\n",
      "Traceback (most recent call last):\n",
      "  File \"C:\\actions-runner\\_work\\_tool\\Python\\3.10.11\\x64\\lib\\logging\\handlers.py\", line 74, in emit\n",
      "    self.doRollover()\n",
      "  File \"C:\\actions-runner\\_work\\_tool\\Python\\3.10.11\\x64\\lib\\logging\\handlers.py\", line 179, in doRollover\n",
      "    self.rotate(self.baseFilename, dfn)\n",
      "  File \"C:\\actions-runner\\_work\\_tool\\Python\\3.10.11\\x64\\lib\\logging\\handlers.py\", line 115, in rotate\n",
      "    os.rename(source, dest)\n",
      "PermissionError: [WinError 32] The process cannot access the file because it is being used by another process: 'C:\\\\Users\\\\ansys\\\\AppData\\\\Local\\\\Temp\\\\pyedb_ansys.log' -> 'C:\\\\Users\\\\ansys\\\\AppData\\\\Local\\\\Temp\\\\pyedb_ansys.log.1'\n",
      "Call stack:\n",
      "  File \"C:\\actions-runner\\_work\\_tool\\Python\\3.10.11\\x64\\lib\\runpy.py\", line 196, in _run_module_as_main\n",
      "    return _run_code(code, main_globals, None,\n",
      "  File \"C:\\actions-runner\\_work\\_tool\\Python\\3.10.11\\x64\\lib\\runpy.py\", line 86, in _run_code\n",
      "    exec(code, run_globals)\n",
      "  File \"C:\\actions-runner\\_work\\pyedb\\pyedb\\.venv\\lib\\site-packages\\ipykernel_launcher.py\", line 18, in <module>\n",
      "    app.launch_new_instance()\n",
      "  File \"C:\\actions-runner\\_work\\pyedb\\pyedb\\.venv\\lib\\site-packages\\traitlets\\config\\application.py\", line 1075, in launch_instance\n",
      "    app.start()\n",
      "  File \"C:\\actions-runner\\_work\\pyedb\\pyedb\\.venv\\lib\\site-packages\\ipykernel\\kernelapp.py\", line 739, in start\n",
      "    self.io_loop.start()\n",
      "  File \"C:\\actions-runner\\_work\\pyedb\\pyedb\\.venv\\lib\\site-packages\\tornado\\platform\\asyncio.py\", line 205, in start\n",
      "    self.asyncio_loop.run_forever()\n",
      "  File \"C:\\actions-runner\\_work\\_tool\\Python\\3.10.11\\x64\\lib\\asyncio\\base_events.py\", line 603, in run_forever\n",
      "    self._run_once()\n",
      "  File \"C:\\actions-runner\\_work\\_tool\\Python\\3.10.11\\x64\\lib\\asyncio\\base_events.py\", line 1909, in _run_once\n",
      "    handle._run()\n",
      "  File \"C:\\actions-runner\\_work\\_tool\\Python\\3.10.11\\x64\\lib\\asyncio\\events.py\", line 80, in _run\n",
      "    self._context.run(self._callback, *self._args)\n",
      "  File \"C:\\actions-runner\\_work\\pyedb\\pyedb\\.venv\\lib\\site-packages\\ipykernel\\kernelbase.py\", line 545, in dispatch_queue\n",
      "    await self.process_one()\n",
      "  File \"C:\\actions-runner\\_work\\pyedb\\pyedb\\.venv\\lib\\site-packages\\ipykernel\\kernelbase.py\", line 534, in process_one\n",
      "    await dispatch(*args)\n",
      "  File \"C:\\actions-runner\\_work\\pyedb\\pyedb\\.venv\\lib\\site-packages\\ipykernel\\kernelbase.py\", line 437, in dispatch_shell\n",
      "    await result\n",
      "  File \"C:\\actions-runner\\_work\\pyedb\\pyedb\\.venv\\lib\\site-packages\\ipykernel\\ipkernel.py\", line 362, in execute_request\n",
      "    await super().execute_request(stream, ident, parent)\n",
      "  File \"C:\\actions-runner\\_work\\pyedb\\pyedb\\.venv\\lib\\site-packages\\ipykernel\\kernelbase.py\", line 778, in execute_request\n",
      "    reply_content = await reply_content\n",
      "  File \"C:\\actions-runner\\_work\\pyedb\\pyedb\\.venv\\lib\\site-packages\\ipykernel\\ipkernel.py\", line 449, in do_execute\n",
      "    res = shell.run_cell(\n",
      "  File \"C:\\actions-runner\\_work\\pyedb\\pyedb\\.venv\\lib\\site-packages\\ipykernel\\zmqshell.py\", line 549, in run_cell\n",
      "    return super().run_cell(*args, **kwargs)\n",
      "  File \"C:\\actions-runner\\_work\\pyedb\\pyedb\\.venv\\lib\\site-packages\\IPython\\core\\interactiveshell.py\", line 3075, in run_cell\n",
      "    result = self._run_cell(\n",
      "  File \"C:\\actions-runner\\_work\\pyedb\\pyedb\\.venv\\lib\\site-packages\\IPython\\core\\interactiveshell.py\", line 3130, in _run_cell\n",
      "    result = runner(coro)\n",
      "  File \"C:\\actions-runner\\_work\\pyedb\\pyedb\\.venv\\lib\\site-packages\\IPython\\core\\async_helpers.py\", line 128, in _pseudo_sync_runner\n",
      "    coro.send(None)\n",
      "  File \"C:\\actions-runner\\_work\\pyedb\\pyedb\\.venv\\lib\\site-packages\\IPython\\core\\interactiveshell.py\", line 3334, in run_cell_async\n",
      "    has_raised = await self.run_ast_nodes(code_ast.body, cell_name,\n",
      "  File \"C:\\actions-runner\\_work\\pyedb\\pyedb\\.venv\\lib\\site-packages\\IPython\\core\\interactiveshell.py\", line 3517, in run_ast_nodes\n",
      "    if await self.run_code(code, result, async_=asy):\n",
      "  File \"C:\\actions-runner\\_work\\pyedb\\pyedb\\.venv\\lib\\site-packages\\IPython\\core\\interactiveshell.py\", line 3577, in run_code\n",
      "    exec(code_obj, self.user_global_ns, self.user_ns)\n",
      "  File \"C:\\Users\\ansys\\AppData\\Local\\Temp\\ipykernel_3468\\2999416059.py\", line 6, in <module>\n",
      "    edb.cutout(\n",
      "  File \"C:\\actions-runner\\_work\\pyedb\\pyedb\\.venv\\lib\\site-packages\\pyedb\\dotnet\\edb.py\", line 1951, in cutout\n",
      "    result = self._create_cutout_multithread(\n",
      "  File \"C:\\actions-runner\\_work\\pyedb\\pyedb\\.venv\\lib\\site-packages\\pyedb\\dotnet\\edb.py\", line 2293, in _create_cutout_multithread\n",
      "    self.logger.info_timer(\"Expanded Net Polygon Creation\")\n",
      "  File \"C:\\actions-runner\\_work\\pyedb\\pyedb\\.venv\\lib\\site-packages\\pyedb\\edb_logger.py\", line 372, in info_timer\n",
      "    return self._log_on_handler(0, msg, *args, **kwargs)\n",
      "  File \"C:\\actions-runner\\_work\\pyedb\\pyedb\\.venv\\lib\\site-packages\\pyedb\\edb_logger.py\", line 293, in _log_on_handler\n",
      "    self._global.info(message_text, *args, **kwargs)\n",
      "Message: 'Expanded Net Polygon Creation Elapsed time: 0m 0sec'\n",
      "Arguments: ()\n"
     ]
    },
    {
     "name": "stdout",
     "output_type": "stream",
     "text": [
      "PyEDB INFO: Padstack Instances removal completed. 1822 instances removed. Elapsed time: 0m 1sec\n"
     ]
    },
    {
     "name": "stderr",
     "output_type": "stream",
     "text": [
      "--- Logging error ---\n",
      "Traceback (most recent call last):\n",
      "  File \"C:\\actions-runner\\_work\\_tool\\Python\\3.10.11\\x64\\lib\\logging\\handlers.py\", line 74, in emit\n",
      "    self.doRollover()\n",
      "  File \"C:\\actions-runner\\_work\\_tool\\Python\\3.10.11\\x64\\lib\\logging\\handlers.py\", line 179, in doRollover\n",
      "    self.rotate(self.baseFilename, dfn)\n",
      "  File \"C:\\actions-runner\\_work\\_tool\\Python\\3.10.11\\x64\\lib\\logging\\handlers.py\", line 115, in rotate\n",
      "    os.rename(source, dest)\n",
      "PermissionError: [WinError 32] The process cannot access the file because it is being used by another process: 'C:\\\\Users\\\\ansys\\\\AppData\\\\Local\\\\Temp\\\\pyedb_ansys.log' -> 'C:\\\\Users\\\\ansys\\\\AppData\\\\Local\\\\Temp\\\\pyedb_ansys.log.1'\n",
      "Call stack:\n",
      "  File \"C:\\actions-runner\\_work\\_tool\\Python\\3.10.11\\x64\\lib\\runpy.py\", line 196, in _run_module_as_main\n",
      "    return _run_code(code, main_globals, None,\n",
      "  File \"C:\\actions-runner\\_work\\_tool\\Python\\3.10.11\\x64\\lib\\runpy.py\", line 86, in _run_code\n",
      "    exec(code, run_globals)\n",
      "  File \"C:\\actions-runner\\_work\\pyedb\\pyedb\\.venv\\lib\\site-packages\\ipykernel_launcher.py\", line 18, in <module>\n",
      "    app.launch_new_instance()\n",
      "  File \"C:\\actions-runner\\_work\\pyedb\\pyedb\\.venv\\lib\\site-packages\\traitlets\\config\\application.py\", line 1075, in launch_instance\n",
      "    app.start()\n",
      "  File \"C:\\actions-runner\\_work\\pyedb\\pyedb\\.venv\\lib\\site-packages\\ipykernel\\kernelapp.py\", line 739, in start\n",
      "    self.io_loop.start()\n",
      "  File \"C:\\actions-runner\\_work\\pyedb\\pyedb\\.venv\\lib\\site-packages\\tornado\\platform\\asyncio.py\", line 205, in start\n",
      "    self.asyncio_loop.run_forever()\n",
      "  File \"C:\\actions-runner\\_work\\_tool\\Python\\3.10.11\\x64\\lib\\asyncio\\base_events.py\", line 603, in run_forever\n",
      "    self._run_once()\n",
      "  File \"C:\\actions-runner\\_work\\_tool\\Python\\3.10.11\\x64\\lib\\asyncio\\base_events.py\", line 1909, in _run_once\n",
      "    handle._run()\n",
      "  File \"C:\\actions-runner\\_work\\_tool\\Python\\3.10.11\\x64\\lib\\asyncio\\events.py\", line 80, in _run\n",
      "    self._context.run(self._callback, *self._args)\n",
      "  File \"C:\\actions-runner\\_work\\pyedb\\pyedb\\.venv\\lib\\site-packages\\ipykernel\\kernelbase.py\", line 545, in dispatch_queue\n",
      "    await self.process_one()\n",
      "  File \"C:\\actions-runner\\_work\\pyedb\\pyedb\\.venv\\lib\\site-packages\\ipykernel\\kernelbase.py\", line 534, in process_one\n",
      "    await dispatch(*args)\n",
      "  File \"C:\\actions-runner\\_work\\pyedb\\pyedb\\.venv\\lib\\site-packages\\ipykernel\\kernelbase.py\", line 437, in dispatch_shell\n",
      "    await result\n",
      "  File \"C:\\actions-runner\\_work\\pyedb\\pyedb\\.venv\\lib\\site-packages\\ipykernel\\ipkernel.py\", line 362, in execute_request\n",
      "    await super().execute_request(stream, ident, parent)\n",
      "  File \"C:\\actions-runner\\_work\\pyedb\\pyedb\\.venv\\lib\\site-packages\\ipykernel\\kernelbase.py\", line 778, in execute_request\n",
      "    reply_content = await reply_content\n",
      "  File \"C:\\actions-runner\\_work\\pyedb\\pyedb\\.venv\\lib\\site-packages\\ipykernel\\ipkernel.py\", line 449, in do_execute\n",
      "    res = shell.run_cell(\n",
      "  File \"C:\\actions-runner\\_work\\pyedb\\pyedb\\.venv\\lib\\site-packages\\ipykernel\\zmqshell.py\", line 549, in run_cell\n",
      "    return super().run_cell(*args, **kwargs)\n",
      "  File \"C:\\actions-runner\\_work\\pyedb\\pyedb\\.venv\\lib\\site-packages\\IPython\\core\\interactiveshell.py\", line 3075, in run_cell\n",
      "    result = self._run_cell(\n",
      "  File \"C:\\actions-runner\\_work\\pyedb\\pyedb\\.venv\\lib\\site-packages\\IPython\\core\\interactiveshell.py\", line 3130, in _run_cell\n",
      "    result = runner(coro)\n",
      "  File \"C:\\actions-runner\\_work\\pyedb\\pyedb\\.venv\\lib\\site-packages\\IPython\\core\\async_helpers.py\", line 128, in _pseudo_sync_runner\n",
      "    coro.send(None)\n",
      "  File \"C:\\actions-runner\\_work\\pyedb\\pyedb\\.venv\\lib\\site-packages\\IPython\\core\\interactiveshell.py\", line 3334, in run_cell_async\n",
      "    has_raised = await self.run_ast_nodes(code_ast.body, cell_name,\n",
      "  File \"C:\\actions-runner\\_work\\pyedb\\pyedb\\.venv\\lib\\site-packages\\IPython\\core\\interactiveshell.py\", line 3517, in run_ast_nodes\n",
      "    if await self.run_code(code, result, async_=asy):\n",
      "  File \"C:\\actions-runner\\_work\\pyedb\\pyedb\\.venv\\lib\\site-packages\\IPython\\core\\interactiveshell.py\", line 3577, in run_code\n",
      "    exec(code_obj, self.user_global_ns, self.user_ns)\n",
      "  File \"C:\\Users\\ansys\\AppData\\Local\\Temp\\ipykernel_3468\\2999416059.py\", line 6, in <module>\n",
      "    edb.cutout(\n",
      "  File \"C:\\actions-runner\\_work\\pyedb\\pyedb\\.venv\\lib\\site-packages\\pyedb\\dotnet\\edb.py\", line 1951, in cutout\n",
      "    result = self._create_cutout_multithread(\n",
      "  File \"C:\\actions-runner\\_work\\pyedb\\pyedb\\.venv\\lib\\site-packages\\pyedb\\dotnet\\edb.py\", line 2376, in _create_cutout_multithread\n",
      "    self.logger.info_timer(\n",
      "  File \"C:\\actions-runner\\_work\\pyedb\\pyedb\\.venv\\lib\\site-packages\\pyedb\\edb_logger.py\", line 372, in info_timer\n",
      "    return self._log_on_handler(0, msg, *args, **kwargs)\n",
      "  File \"C:\\actions-runner\\_work\\pyedb\\pyedb\\.venv\\lib\\site-packages\\pyedb\\edb_logger.py\", line 293, in _log_on_handler\n",
      "    self._global.info(message_text, *args, **kwargs)\n",
      "Message: 'Padstack Instances removal completed. 1822 instances removed. Elapsed time: 0m 1sec'\n",
      "Arguments: ()\n"
     ]
    },
    {
     "name": "stdout",
     "output_type": "stream",
     "text": [
      "PyEDB INFO: Primitives cleanup completed. 425 primitives deleted. Elapsed time: 0m 4sec\n"
     ]
    },
    {
     "name": "stdout",
     "output_type": "stream",
     "text": [
      "PyEDB INFO: Deleted 928 additional components\n"
     ]
    },
    {
     "name": "stdout",
     "output_type": "stream",
     "text": [
      "PyEDB INFO: Deleted 464 components\n"
     ]
    },
    {
     "name": "stdout",
     "output_type": "stream",
     "text": [
      "PyEDB INFO: Single Pins components deleted Elapsed time: 0m 0sec\n"
     ]
    },
    {
     "name": "stdout",
     "output_type": "stream",
     "text": [
      "PyEDB INFO: Cutout completed. Elapsed time: 0m 9sec\n"
     ]
    },
    {
     "name": "stderr",
     "output_type": "stream",
     "text": [
      "--- Logging error ---\n",
      "Traceback (most recent call last):\n",
      "  File \"C:\\actions-runner\\_work\\_tool\\Python\\3.10.11\\x64\\lib\\logging\\handlers.py\", line 74, in emit\n",
      "    self.doRollover()\n",
      "  File \"C:\\actions-runner\\_work\\_tool\\Python\\3.10.11\\x64\\lib\\logging\\handlers.py\", line 179, in doRollover\n",
      "    self.rotate(self.baseFilename, dfn)\n",
      "  File \"C:\\actions-runner\\_work\\_tool\\Python\\3.10.11\\x64\\lib\\logging\\handlers.py\", line 115, in rotate\n",
      "    os.rename(source, dest)\n",
      "PermissionError: [WinError 32] The process cannot access the file because it is being used by another process: 'C:\\\\Users\\\\ansys\\\\AppData\\\\Local\\\\Temp\\\\pyedb_ansys.log' -> 'C:\\\\Users\\\\ansys\\\\AppData\\\\Local\\\\Temp\\\\pyedb_ansys.log.1'\n",
      "Call stack:\n",
      "  File \"C:\\actions-runner\\_work\\_tool\\Python\\3.10.11\\x64\\lib\\runpy.py\", line 196, in _run_module_as_main\n",
      "    return _run_code(code, main_globals, None,\n",
      "  File \"C:\\actions-runner\\_work\\_tool\\Python\\3.10.11\\x64\\lib\\runpy.py\", line 86, in _run_code\n",
      "    exec(code, run_globals)\n",
      "  File \"C:\\actions-runner\\_work\\pyedb\\pyedb\\.venv\\lib\\site-packages\\ipykernel_launcher.py\", line 18, in <module>\n",
      "    app.launch_new_instance()\n",
      "  File \"C:\\actions-runner\\_work\\pyedb\\pyedb\\.venv\\lib\\site-packages\\traitlets\\config\\application.py\", line 1075, in launch_instance\n",
      "    app.start()\n",
      "  File \"C:\\actions-runner\\_work\\pyedb\\pyedb\\.venv\\lib\\site-packages\\ipykernel\\kernelapp.py\", line 739, in start\n",
      "    self.io_loop.start()\n",
      "  File \"C:\\actions-runner\\_work\\pyedb\\pyedb\\.venv\\lib\\site-packages\\tornado\\platform\\asyncio.py\", line 205, in start\n",
      "    self.asyncio_loop.run_forever()\n",
      "  File \"C:\\actions-runner\\_work\\_tool\\Python\\3.10.11\\x64\\lib\\asyncio\\base_events.py\", line 603, in run_forever\n",
      "    self._run_once()\n",
      "  File \"C:\\actions-runner\\_work\\_tool\\Python\\3.10.11\\x64\\lib\\asyncio\\base_events.py\", line 1909, in _run_once\n",
      "    handle._run()\n",
      "  File \"C:\\actions-runner\\_work\\_tool\\Python\\3.10.11\\x64\\lib\\asyncio\\events.py\", line 80, in _run\n",
      "    self._context.run(self._callback, *self._args)\n",
      "  File \"C:\\actions-runner\\_work\\pyedb\\pyedb\\.venv\\lib\\site-packages\\ipykernel\\kernelbase.py\", line 545, in dispatch_queue\n",
      "    await self.process_one()\n",
      "  File \"C:\\actions-runner\\_work\\pyedb\\pyedb\\.venv\\lib\\site-packages\\ipykernel\\kernelbase.py\", line 534, in process_one\n",
      "    await dispatch(*args)\n",
      "  File \"C:\\actions-runner\\_work\\pyedb\\pyedb\\.venv\\lib\\site-packages\\ipykernel\\kernelbase.py\", line 437, in dispatch_shell\n",
      "    await result\n",
      "  File \"C:\\actions-runner\\_work\\pyedb\\pyedb\\.venv\\lib\\site-packages\\ipykernel\\ipkernel.py\", line 362, in execute_request\n",
      "    await super().execute_request(stream, ident, parent)\n",
      "  File \"C:\\actions-runner\\_work\\pyedb\\pyedb\\.venv\\lib\\site-packages\\ipykernel\\kernelbase.py\", line 778, in execute_request\n",
      "    reply_content = await reply_content\n",
      "  File \"C:\\actions-runner\\_work\\pyedb\\pyedb\\.venv\\lib\\site-packages\\ipykernel\\ipkernel.py\", line 449, in do_execute\n",
      "    res = shell.run_cell(\n",
      "  File \"C:\\actions-runner\\_work\\pyedb\\pyedb\\.venv\\lib\\site-packages\\ipykernel\\zmqshell.py\", line 549, in run_cell\n",
      "    return super().run_cell(*args, **kwargs)\n",
      "  File \"C:\\actions-runner\\_work\\pyedb\\pyedb\\.venv\\lib\\site-packages\\IPython\\core\\interactiveshell.py\", line 3075, in run_cell\n",
      "    result = self._run_cell(\n",
      "  File \"C:\\actions-runner\\_work\\pyedb\\pyedb\\.venv\\lib\\site-packages\\IPython\\core\\interactiveshell.py\", line 3130, in _run_cell\n",
      "    result = runner(coro)\n",
      "  File \"C:\\actions-runner\\_work\\pyedb\\pyedb\\.venv\\lib\\site-packages\\IPython\\core\\async_helpers.py\", line 128, in _pseudo_sync_runner\n",
      "    coro.send(None)\n",
      "  File \"C:\\actions-runner\\_work\\pyedb\\pyedb\\.venv\\lib\\site-packages\\IPython\\core\\interactiveshell.py\", line 3334, in run_cell_async\n",
      "    has_raised = await self.run_ast_nodes(code_ast.body, cell_name,\n",
      "  File \"C:\\actions-runner\\_work\\pyedb\\pyedb\\.venv\\lib\\site-packages\\IPython\\core\\interactiveshell.py\", line 3517, in run_ast_nodes\n",
      "    if await self.run_code(code, result, async_=asy):\n",
      "  File \"C:\\actions-runner\\_work\\pyedb\\pyedb\\.venv\\lib\\site-packages\\IPython\\core\\interactiveshell.py\", line 3577, in run_code\n",
      "    exec(code_obj, self.user_global_ns, self.user_ns)\n",
      "  File \"C:\\Users\\ansys\\AppData\\Local\\Temp\\ipykernel_3468\\2999416059.py\", line 6, in <module>\n",
      "    edb.cutout(\n",
      "  File \"C:\\actions-runner\\_work\\pyedb\\pyedb\\.venv\\lib\\site-packages\\pyedb\\dotnet\\edb.py\", line 1951, in cutout\n",
      "    result = self._create_cutout_multithread(\n",
      "  File \"C:\\actions-runner\\_work\\pyedb\\pyedb\\.venv\\lib\\site-packages\\pyedb\\dotnet\\edb.py\", line 2397, in _create_cutout_multithread\n",
      "    self.logger.info_timer(\"Primitives cleanup completed. {} primitives deleted.\".format(len(prims_to_delete)))\n",
      "  File \"C:\\actions-runner\\_work\\pyedb\\pyedb\\.venv\\lib\\site-packages\\pyedb\\edb_logger.py\", line 372, in info_timer\n",
      "    return self._log_on_handler(0, msg, *args, **kwargs)\n",
      "  File \"C:\\actions-runner\\_work\\pyedb\\pyedb\\.venv\\lib\\site-packages\\pyedb\\edb_logger.py\", line 293, in _log_on_handler\n",
      "    self._global.info(message_text, *args, **kwargs)\n",
      "Message: 'Primitives cleanup completed. 425 primitives deleted. Elapsed time: 0m 4sec'\n",
      "Arguments: ()\n",
      "--- Logging error ---\n",
      "Traceback (most recent call last):\n",
      "  File \"C:\\actions-runner\\_work\\_tool\\Python\\3.10.11\\x64\\lib\\logging\\handlers.py\", line 74, in emit\n",
      "    self.doRollover()\n",
      "  File \"C:\\actions-runner\\_work\\_tool\\Python\\3.10.11\\x64\\lib\\logging\\handlers.py\", line 179, in doRollover\n",
      "    self.rotate(self.baseFilename, dfn)\n",
      "  File \"C:\\actions-runner\\_work\\_tool\\Python\\3.10.11\\x64\\lib\\logging\\handlers.py\", line 115, in rotate\n",
      "    os.rename(source, dest)\n",
      "PermissionError: [WinError 32] The process cannot access the file because it is being used by another process: 'C:\\\\Users\\\\ansys\\\\AppData\\\\Local\\\\Temp\\\\pyedb_ansys.log' -> 'C:\\\\Users\\\\ansys\\\\AppData\\\\Local\\\\Temp\\\\pyedb_ansys.log.1'\n",
      "Call stack:\n",
      "  File \"C:\\actions-runner\\_work\\_tool\\Python\\3.10.11\\x64\\lib\\runpy.py\", line 196, in _run_module_as_main\n",
      "    return _run_code(code, main_globals, None,\n",
      "  File \"C:\\actions-runner\\_work\\_tool\\Python\\3.10.11\\x64\\lib\\runpy.py\", line 86, in _run_code\n",
      "    exec(code, run_globals)\n",
      "  File \"C:\\actions-runner\\_work\\pyedb\\pyedb\\.venv\\lib\\site-packages\\ipykernel_launcher.py\", line 18, in <module>\n",
      "    app.launch_new_instance()\n",
      "  File \"C:\\actions-runner\\_work\\pyedb\\pyedb\\.venv\\lib\\site-packages\\traitlets\\config\\application.py\", line 1075, in launch_instance\n",
      "    app.start()\n",
      "  File \"C:\\actions-runner\\_work\\pyedb\\pyedb\\.venv\\lib\\site-packages\\ipykernel\\kernelapp.py\", line 739, in start\n",
      "    self.io_loop.start()\n",
      "  File \"C:\\actions-runner\\_work\\pyedb\\pyedb\\.venv\\lib\\site-packages\\tornado\\platform\\asyncio.py\", line 205, in start\n",
      "    self.asyncio_loop.run_forever()\n",
      "  File \"C:\\actions-runner\\_work\\_tool\\Python\\3.10.11\\x64\\lib\\asyncio\\base_events.py\", line 603, in run_forever\n",
      "    self._run_once()\n",
      "  File \"C:\\actions-runner\\_work\\_tool\\Python\\3.10.11\\x64\\lib\\asyncio\\base_events.py\", line 1909, in _run_once\n",
      "    handle._run()\n",
      "  File \"C:\\actions-runner\\_work\\_tool\\Python\\3.10.11\\x64\\lib\\asyncio\\events.py\", line 80, in _run\n",
      "    self._context.run(self._callback, *self._args)\n",
      "  File \"C:\\actions-runner\\_work\\pyedb\\pyedb\\.venv\\lib\\site-packages\\ipykernel\\kernelbase.py\", line 545, in dispatch_queue\n",
      "    await self.process_one()\n",
      "  File \"C:\\actions-runner\\_work\\pyedb\\pyedb\\.venv\\lib\\site-packages\\ipykernel\\kernelbase.py\", line 534, in process_one\n",
      "    await dispatch(*args)\n",
      "  File \"C:\\actions-runner\\_work\\pyedb\\pyedb\\.venv\\lib\\site-packages\\ipykernel\\kernelbase.py\", line 437, in dispatch_shell\n",
      "    await result\n",
      "  File \"C:\\actions-runner\\_work\\pyedb\\pyedb\\.venv\\lib\\site-packages\\ipykernel\\ipkernel.py\", line 362, in execute_request\n",
      "    await super().execute_request(stream, ident, parent)\n",
      "  File \"C:\\actions-runner\\_work\\pyedb\\pyedb\\.venv\\lib\\site-packages\\ipykernel\\kernelbase.py\", line 778, in execute_request\n",
      "    reply_content = await reply_content\n",
      "  File \"C:\\actions-runner\\_work\\pyedb\\pyedb\\.venv\\lib\\site-packages\\ipykernel\\ipkernel.py\", line 449, in do_execute\n",
      "    res = shell.run_cell(\n",
      "  File \"C:\\actions-runner\\_work\\pyedb\\pyedb\\.venv\\lib\\site-packages\\ipykernel\\zmqshell.py\", line 549, in run_cell\n",
      "    return super().run_cell(*args, **kwargs)\n",
      "  File \"C:\\actions-runner\\_work\\pyedb\\pyedb\\.venv\\lib\\site-packages\\IPython\\core\\interactiveshell.py\", line 3075, in run_cell\n",
      "    result = self._run_cell(\n",
      "  File \"C:\\actions-runner\\_work\\pyedb\\pyedb\\.venv\\lib\\site-packages\\IPython\\core\\interactiveshell.py\", line 3130, in _run_cell\n",
      "    result = runner(coro)\n",
      "  File \"C:\\actions-runner\\_work\\pyedb\\pyedb\\.venv\\lib\\site-packages\\IPython\\core\\async_helpers.py\", line 128, in _pseudo_sync_runner\n",
      "    coro.send(None)\n",
      "  File \"C:\\actions-runner\\_work\\pyedb\\pyedb\\.venv\\lib\\site-packages\\IPython\\core\\interactiveshell.py\", line 3334, in run_cell_async\n",
      "    has_raised = await self.run_ast_nodes(code_ast.body, cell_name,\n",
      "  File \"C:\\actions-runner\\_work\\pyedb\\pyedb\\.venv\\lib\\site-packages\\IPython\\core\\interactiveshell.py\", line 3517, in run_ast_nodes\n",
      "    if await self.run_code(code, result, async_=asy):\n",
      "  File \"C:\\actions-runner\\_work\\pyedb\\pyedb\\.venv\\lib\\site-packages\\IPython\\core\\interactiveshell.py\", line 3577, in run_code\n",
      "    exec(code_obj, self.user_global_ns, self.user_ns)\n",
      "  File \"C:\\Users\\ansys\\AppData\\Local\\Temp\\ipykernel_3468\\2999416059.py\", line 6, in <module>\n",
      "    edb.cutout(\n",
      "  File \"C:\\actions-runner\\_work\\pyedb\\pyedb\\.venv\\lib\\site-packages\\pyedb\\dotnet\\edb.py\", line 1951, in cutout\n",
      "    result = self._create_cutout_multithread(\n",
      "  File \"C:\\actions-runner\\_work\\pyedb\\pyedb\\.venv\\lib\\site-packages\\pyedb\\dotnet\\edb.py\", line 2406, in _create_cutout_multithread\n",
      "    self.logger.info(\"Deleted {} additional components\".format(i))\n",
      "  File \"C:\\actions-runner\\_work\\pyedb\\pyedb\\.venv\\lib\\site-packages\\pyedb\\edb_logger.py\", line 346, in info\n",
      "    return self._log_on_handler(0, msg, *args, **kwargs)\n",
      "  File \"C:\\actions-runner\\_work\\pyedb\\pyedb\\.venv\\lib\\site-packages\\pyedb\\edb_logger.py\", line 293, in _log_on_handler\n",
      "    self._global.info(message_text, *args, **kwargs)\n",
      "Message: 'Deleted 928 additional components'\n",
      "Arguments: ()\n",
      "--- Logging error ---\n",
      "Traceback (most recent call last):\n",
      "  File \"C:\\actions-runner\\_work\\_tool\\Python\\3.10.11\\x64\\lib\\logging\\handlers.py\", line 74, in emit\n",
      "    self.doRollover()\n",
      "  File \"C:\\actions-runner\\_work\\_tool\\Python\\3.10.11\\x64\\lib\\logging\\handlers.py\", line 179, in doRollover\n",
      "    self.rotate(self.baseFilename, dfn)\n",
      "  File \"C:\\actions-runner\\_work\\_tool\\Python\\3.10.11\\x64\\lib\\logging\\handlers.py\", line 115, in rotate\n",
      "    os.rename(source, dest)\n",
      "PermissionError: [WinError 32] The process cannot access the file because it is being used by another process: 'C:\\\\Users\\\\ansys\\\\AppData\\\\Local\\\\Temp\\\\pyedb_ansys.log' -> 'C:\\\\Users\\\\ansys\\\\AppData\\\\Local\\\\Temp\\\\pyedb_ansys.log.1'\n",
      "Call stack:\n",
      "  File \"C:\\actions-runner\\_work\\_tool\\Python\\3.10.11\\x64\\lib\\runpy.py\", line 196, in _run_module_as_main\n",
      "    return _run_code(code, main_globals, None,\n",
      "  File \"C:\\actions-runner\\_work\\_tool\\Python\\3.10.11\\x64\\lib\\runpy.py\", line 86, in _run_code\n",
      "    exec(code, run_globals)\n",
      "  File \"C:\\actions-runner\\_work\\pyedb\\pyedb\\.venv\\lib\\site-packages\\ipykernel_launcher.py\", line 18, in <module>\n",
      "    app.launch_new_instance()\n",
      "  File \"C:\\actions-runner\\_work\\pyedb\\pyedb\\.venv\\lib\\site-packages\\traitlets\\config\\application.py\", line 1075, in launch_instance\n",
      "    app.start()\n",
      "  File \"C:\\actions-runner\\_work\\pyedb\\pyedb\\.venv\\lib\\site-packages\\ipykernel\\kernelapp.py\", line 739, in start\n",
      "    self.io_loop.start()\n",
      "  File \"C:\\actions-runner\\_work\\pyedb\\pyedb\\.venv\\lib\\site-packages\\tornado\\platform\\asyncio.py\", line 205, in start\n",
      "    self.asyncio_loop.run_forever()\n",
      "  File \"C:\\actions-runner\\_work\\_tool\\Python\\3.10.11\\x64\\lib\\asyncio\\base_events.py\", line 603, in run_forever\n",
      "    self._run_once()\n",
      "  File \"C:\\actions-runner\\_work\\_tool\\Python\\3.10.11\\x64\\lib\\asyncio\\base_events.py\", line 1909, in _run_once\n",
      "    handle._run()\n",
      "  File \"C:\\actions-runner\\_work\\_tool\\Python\\3.10.11\\x64\\lib\\asyncio\\events.py\", line 80, in _run\n",
      "    self._context.run(self._callback, *self._args)\n",
      "  File \"C:\\actions-runner\\_work\\pyedb\\pyedb\\.venv\\lib\\site-packages\\ipykernel\\kernelbase.py\", line 545, in dispatch_queue\n",
      "    await self.process_one()\n",
      "  File \"C:\\actions-runner\\_work\\pyedb\\pyedb\\.venv\\lib\\site-packages\\ipykernel\\kernelbase.py\", line 534, in process_one\n",
      "    await dispatch(*args)\n",
      "  File \"C:\\actions-runner\\_work\\pyedb\\pyedb\\.venv\\lib\\site-packages\\ipykernel\\kernelbase.py\", line 437, in dispatch_shell\n",
      "    await result\n",
      "  File \"C:\\actions-runner\\_work\\pyedb\\pyedb\\.venv\\lib\\site-packages\\ipykernel\\ipkernel.py\", line 362, in execute_request\n",
      "    await super().execute_request(stream, ident, parent)\n",
      "  File \"C:\\actions-runner\\_work\\pyedb\\pyedb\\.venv\\lib\\site-packages\\ipykernel\\kernelbase.py\", line 778, in execute_request\n",
      "    reply_content = await reply_content\n",
      "  File \"C:\\actions-runner\\_work\\pyedb\\pyedb\\.venv\\lib\\site-packages\\ipykernel\\ipkernel.py\", line 449, in do_execute\n",
      "    res = shell.run_cell(\n",
      "  File \"C:\\actions-runner\\_work\\pyedb\\pyedb\\.venv\\lib\\site-packages\\ipykernel\\zmqshell.py\", line 549, in run_cell\n",
      "    return super().run_cell(*args, **kwargs)\n",
      "  File \"C:\\actions-runner\\_work\\pyedb\\pyedb\\.venv\\lib\\site-packages\\IPython\\core\\interactiveshell.py\", line 3075, in run_cell\n",
      "    result = self._run_cell(\n",
      "  File \"C:\\actions-runner\\_work\\pyedb\\pyedb\\.venv\\lib\\site-packages\\IPython\\core\\interactiveshell.py\", line 3130, in _run_cell\n",
      "    result = runner(coro)\n",
      "  File \"C:\\actions-runner\\_work\\pyedb\\pyedb\\.venv\\lib\\site-packages\\IPython\\core\\async_helpers.py\", line 128, in _pseudo_sync_runner\n",
      "    coro.send(None)\n",
      "  File \"C:\\actions-runner\\_work\\pyedb\\pyedb\\.venv\\lib\\site-packages\\IPython\\core\\interactiveshell.py\", line 3334, in run_cell_async\n",
      "    has_raised = await self.run_ast_nodes(code_ast.body, cell_name,\n",
      "  File \"C:\\actions-runner\\_work\\pyedb\\pyedb\\.venv\\lib\\site-packages\\IPython\\core\\interactiveshell.py\", line 3517, in run_ast_nodes\n",
      "    if await self.run_code(code, result, async_=asy):\n",
      "  File \"C:\\actions-runner\\_work\\pyedb\\pyedb\\.venv\\lib\\site-packages\\IPython\\core\\interactiveshell.py\", line 3577, in run_code\n",
      "    exec(code_obj, self.user_global_ns, self.user_ns)\n",
      "  File \"C:\\Users\\ansys\\AppData\\Local\\Temp\\ipykernel_3468\\2999416059.py\", line 6, in <module>\n",
      "    edb.cutout(\n",
      "  File \"C:\\actions-runner\\_work\\pyedb\\pyedb\\.venv\\lib\\site-packages\\pyedb\\dotnet\\edb.py\", line 1951, in cutout\n",
      "    result = self._create_cutout_multithread(\n",
      "  File \"C:\\actions-runner\\_work\\pyedb\\pyedb\\.venv\\lib\\site-packages\\pyedb\\dotnet\\edb.py\", line 2408, in _create_cutout_multithread\n",
      "    self.components.delete_single_pin_rlc()\n",
      "  File \"C:\\actions-runner\\_work\\pyedb\\pyedb\\.venv\\lib\\site-packages\\pyedb\\dotnet\\edb_core\\components.py\", line 1926, in delete_single_pin_rlc\n",
      "    self._pedb._logger.info(\"Deleted {} components\".format(len(deleted_comps)))\n",
      "  File \"C:\\actions-runner\\_work\\pyedb\\pyedb\\.venv\\lib\\site-packages\\pyedb\\edb_logger.py\", line 346, in info\n",
      "    return self._log_on_handler(0, msg, *args, **kwargs)\n",
      "  File \"C:\\actions-runner\\_work\\pyedb\\pyedb\\.venv\\lib\\site-packages\\pyedb\\edb_logger.py\", line 293, in _log_on_handler\n",
      "    self._global.info(message_text, *args, **kwargs)\n",
      "Message: 'Deleted 464 components'\n",
      "Arguments: ()\n",
      "--- Logging error ---\n",
      "Traceback (most recent call last):\n",
      "  File \"C:\\actions-runner\\_work\\_tool\\Python\\3.10.11\\x64\\lib\\logging\\handlers.py\", line 74, in emit\n",
      "    self.doRollover()\n",
      "  File \"C:\\actions-runner\\_work\\_tool\\Python\\3.10.11\\x64\\lib\\logging\\handlers.py\", line 179, in doRollover\n",
      "    self.rotate(self.baseFilename, dfn)\n",
      "  File \"C:\\actions-runner\\_work\\_tool\\Python\\3.10.11\\x64\\lib\\logging\\handlers.py\", line 115, in rotate\n",
      "    os.rename(source, dest)\n",
      "PermissionError: [WinError 32] The process cannot access the file because it is being used by another process: 'C:\\\\Users\\\\ansys\\\\AppData\\\\Local\\\\Temp\\\\pyedb_ansys.log' -> 'C:\\\\Users\\\\ansys\\\\AppData\\\\Local\\\\Temp\\\\pyedb_ansys.log.1'\n",
      "Call stack:\n",
      "  File \"C:\\actions-runner\\_work\\_tool\\Python\\3.10.11\\x64\\lib\\runpy.py\", line 196, in _run_module_as_main\n",
      "    return _run_code(code, main_globals, None,\n",
      "  File \"C:\\actions-runner\\_work\\_tool\\Python\\3.10.11\\x64\\lib\\runpy.py\", line 86, in _run_code\n",
      "    exec(code, run_globals)\n",
      "  File \"C:\\actions-runner\\_work\\pyedb\\pyedb\\.venv\\lib\\site-packages\\ipykernel_launcher.py\", line 18, in <module>\n",
      "    app.launch_new_instance()\n",
      "  File \"C:\\actions-runner\\_work\\pyedb\\pyedb\\.venv\\lib\\site-packages\\traitlets\\config\\application.py\", line 1075, in launch_instance\n",
      "    app.start()\n",
      "  File \"C:\\actions-runner\\_work\\pyedb\\pyedb\\.venv\\lib\\site-packages\\ipykernel\\kernelapp.py\", line 739, in start\n",
      "    self.io_loop.start()\n",
      "  File \"C:\\actions-runner\\_work\\pyedb\\pyedb\\.venv\\lib\\site-packages\\tornado\\platform\\asyncio.py\", line 205, in start\n",
      "    self.asyncio_loop.run_forever()\n",
      "  File \"C:\\actions-runner\\_work\\_tool\\Python\\3.10.11\\x64\\lib\\asyncio\\base_events.py\", line 603, in run_forever\n",
      "    self._run_once()\n",
      "  File \"C:\\actions-runner\\_work\\_tool\\Python\\3.10.11\\x64\\lib\\asyncio\\base_events.py\", line 1909, in _run_once\n",
      "    handle._run()\n",
      "  File \"C:\\actions-runner\\_work\\_tool\\Python\\3.10.11\\x64\\lib\\asyncio\\events.py\", line 80, in _run\n",
      "    self._context.run(self._callback, *self._args)\n",
      "  File \"C:\\actions-runner\\_work\\pyedb\\pyedb\\.venv\\lib\\site-packages\\ipykernel\\kernelbase.py\", line 545, in dispatch_queue\n",
      "    await self.process_one()\n",
      "  File \"C:\\actions-runner\\_work\\pyedb\\pyedb\\.venv\\lib\\site-packages\\ipykernel\\kernelbase.py\", line 534, in process_one\n",
      "    await dispatch(*args)\n",
      "  File \"C:\\actions-runner\\_work\\pyedb\\pyedb\\.venv\\lib\\site-packages\\ipykernel\\kernelbase.py\", line 437, in dispatch_shell\n",
      "    await result\n",
      "  File \"C:\\actions-runner\\_work\\pyedb\\pyedb\\.venv\\lib\\site-packages\\ipykernel\\ipkernel.py\", line 362, in execute_request\n",
      "    await super().execute_request(stream, ident, parent)\n",
      "  File \"C:\\actions-runner\\_work\\pyedb\\pyedb\\.venv\\lib\\site-packages\\ipykernel\\kernelbase.py\", line 778, in execute_request\n",
      "    reply_content = await reply_content\n",
      "  File \"C:\\actions-runner\\_work\\pyedb\\pyedb\\.venv\\lib\\site-packages\\ipykernel\\ipkernel.py\", line 449, in do_execute\n",
      "    res = shell.run_cell(\n",
      "  File \"C:\\actions-runner\\_work\\pyedb\\pyedb\\.venv\\lib\\site-packages\\ipykernel\\zmqshell.py\", line 549, in run_cell\n",
      "    return super().run_cell(*args, **kwargs)\n",
      "  File \"C:\\actions-runner\\_work\\pyedb\\pyedb\\.venv\\lib\\site-packages\\IPython\\core\\interactiveshell.py\", line 3075, in run_cell\n",
      "    result = self._run_cell(\n",
      "  File \"C:\\actions-runner\\_work\\pyedb\\pyedb\\.venv\\lib\\site-packages\\IPython\\core\\interactiveshell.py\", line 3130, in _run_cell\n",
      "    result = runner(coro)\n",
      "  File \"C:\\actions-runner\\_work\\pyedb\\pyedb\\.venv\\lib\\site-packages\\IPython\\core\\async_helpers.py\", line 128, in _pseudo_sync_runner\n",
      "    coro.send(None)\n",
      "  File \"C:\\actions-runner\\_work\\pyedb\\pyedb\\.venv\\lib\\site-packages\\IPython\\core\\interactiveshell.py\", line 3334, in run_cell_async\n",
      "    has_raised = await self.run_ast_nodes(code_ast.body, cell_name,\n",
      "  File \"C:\\actions-runner\\_work\\pyedb\\pyedb\\.venv\\lib\\site-packages\\IPython\\core\\interactiveshell.py\", line 3517, in run_ast_nodes\n",
      "    if await self.run_code(code, result, async_=asy):\n",
      "  File \"C:\\actions-runner\\_work\\pyedb\\pyedb\\.venv\\lib\\site-packages\\IPython\\core\\interactiveshell.py\", line 3577, in run_code\n",
      "    exec(code_obj, self.user_global_ns, self.user_ns)\n",
      "  File \"C:\\Users\\ansys\\AppData\\Local\\Temp\\ipykernel_3468\\2999416059.py\", line 6, in <module>\n",
      "    edb.cutout(\n",
      "  File \"C:\\actions-runner\\_work\\pyedb\\pyedb\\.venv\\lib\\site-packages\\pyedb\\dotnet\\edb.py\", line 1951, in cutout\n",
      "    result = self._create_cutout_multithread(\n",
      "  File \"C:\\actions-runner\\_work\\pyedb\\pyedb\\.venv\\lib\\site-packages\\pyedb\\dotnet\\edb.py\", line 2409, in _create_cutout_multithread\n",
      "    self.logger.info_timer(\"Single Pins components deleted\")\n",
      "  File \"C:\\actions-runner\\_work\\pyedb\\pyedb\\.venv\\lib\\site-packages\\pyedb\\edb_logger.py\", line 372, in info_timer\n",
      "    return self._log_on_handler(0, msg, *args, **kwargs)\n",
      "  File \"C:\\actions-runner\\_work\\pyedb\\pyedb\\.venv\\lib\\site-packages\\pyedb\\edb_logger.py\", line 293, in _log_on_handler\n",
      "    self._global.info(message_text, *args, **kwargs)\n",
      "Message: 'Single Pins components deleted Elapsed time: 0m 0sec'\n",
      "Arguments: ()\n",
      "--- Logging error ---\n",
      "Traceback (most recent call last):\n",
      "  File \"C:\\actions-runner\\_work\\_tool\\Python\\3.10.11\\x64\\lib\\logging\\handlers.py\", line 74, in emit\n",
      "    self.doRollover()\n",
      "  File \"C:\\actions-runner\\_work\\_tool\\Python\\3.10.11\\x64\\lib\\logging\\handlers.py\", line 179, in doRollover\n",
      "    self.rotate(self.baseFilename, dfn)\n",
      "  File \"C:\\actions-runner\\_work\\_tool\\Python\\3.10.11\\x64\\lib\\logging\\handlers.py\", line 115, in rotate\n",
      "    os.rename(source, dest)\n",
      "PermissionError: [WinError 32] The process cannot access the file because it is being used by another process: 'C:\\\\Users\\\\ansys\\\\AppData\\\\Local\\\\Temp\\\\pyedb_ansys.log' -> 'C:\\\\Users\\\\ansys\\\\AppData\\\\Local\\\\Temp\\\\pyedb_ansys.log.1'\n",
      "Call stack:\n",
      "  File \"C:\\actions-runner\\_work\\_tool\\Python\\3.10.11\\x64\\lib\\runpy.py\", line 196, in _run_module_as_main\n",
      "    return _run_code(code, main_globals, None,\n",
      "  File \"C:\\actions-runner\\_work\\_tool\\Python\\3.10.11\\x64\\lib\\runpy.py\", line 86, in _run_code\n",
      "    exec(code, run_globals)\n",
      "  File \"C:\\actions-runner\\_work\\pyedb\\pyedb\\.venv\\lib\\site-packages\\ipykernel_launcher.py\", line 18, in <module>\n",
      "    app.launch_new_instance()\n",
      "  File \"C:\\actions-runner\\_work\\pyedb\\pyedb\\.venv\\lib\\site-packages\\traitlets\\config\\application.py\", line 1075, in launch_instance\n",
      "    app.start()\n",
      "  File \"C:\\actions-runner\\_work\\pyedb\\pyedb\\.venv\\lib\\site-packages\\ipykernel\\kernelapp.py\", line 739, in start\n",
      "    self.io_loop.start()\n",
      "  File \"C:\\actions-runner\\_work\\pyedb\\pyedb\\.venv\\lib\\site-packages\\tornado\\platform\\asyncio.py\", line 205, in start\n",
      "    self.asyncio_loop.run_forever()\n",
      "  File \"C:\\actions-runner\\_work\\_tool\\Python\\3.10.11\\x64\\lib\\asyncio\\base_events.py\", line 603, in run_forever\n",
      "    self._run_once()\n",
      "  File \"C:\\actions-runner\\_work\\_tool\\Python\\3.10.11\\x64\\lib\\asyncio\\base_events.py\", line 1909, in _run_once\n",
      "    handle._run()\n",
      "  File \"C:\\actions-runner\\_work\\_tool\\Python\\3.10.11\\x64\\lib\\asyncio\\events.py\", line 80, in _run\n",
      "    self._context.run(self._callback, *self._args)\n",
      "  File \"C:\\actions-runner\\_work\\pyedb\\pyedb\\.venv\\lib\\site-packages\\ipykernel\\kernelbase.py\", line 545, in dispatch_queue\n",
      "    await self.process_one()\n",
      "  File \"C:\\actions-runner\\_work\\pyedb\\pyedb\\.venv\\lib\\site-packages\\ipykernel\\kernelbase.py\", line 534, in process_one\n",
      "    await dispatch(*args)\n",
      "  File \"C:\\actions-runner\\_work\\pyedb\\pyedb\\.venv\\lib\\site-packages\\ipykernel\\kernelbase.py\", line 437, in dispatch_shell\n",
      "    await result\n",
      "  File \"C:\\actions-runner\\_work\\pyedb\\pyedb\\.venv\\lib\\site-packages\\ipykernel\\ipkernel.py\", line 362, in execute_request\n",
      "    await super().execute_request(stream, ident, parent)\n",
      "  File \"C:\\actions-runner\\_work\\pyedb\\pyedb\\.venv\\lib\\site-packages\\ipykernel\\kernelbase.py\", line 778, in execute_request\n",
      "    reply_content = await reply_content\n",
      "  File \"C:\\actions-runner\\_work\\pyedb\\pyedb\\.venv\\lib\\site-packages\\ipykernel\\ipkernel.py\", line 449, in do_execute\n",
      "    res = shell.run_cell(\n",
      "  File \"C:\\actions-runner\\_work\\pyedb\\pyedb\\.venv\\lib\\site-packages\\ipykernel\\zmqshell.py\", line 549, in run_cell\n",
      "    return super().run_cell(*args, **kwargs)\n",
      "  File \"C:\\actions-runner\\_work\\pyedb\\pyedb\\.venv\\lib\\site-packages\\IPython\\core\\interactiveshell.py\", line 3075, in run_cell\n",
      "    result = self._run_cell(\n",
      "  File \"C:\\actions-runner\\_work\\pyedb\\pyedb\\.venv\\lib\\site-packages\\IPython\\core\\interactiveshell.py\", line 3130, in _run_cell\n",
      "    result = runner(coro)\n",
      "  File \"C:\\actions-runner\\_work\\pyedb\\pyedb\\.venv\\lib\\site-packages\\IPython\\core\\async_helpers.py\", line 128, in _pseudo_sync_runner\n",
      "    coro.send(None)\n",
      "  File \"C:\\actions-runner\\_work\\pyedb\\pyedb\\.venv\\lib\\site-packages\\IPython\\core\\interactiveshell.py\", line 3334, in run_cell_async\n",
      "    has_raised = await self.run_ast_nodes(code_ast.body, cell_name,\n",
      "  File \"C:\\actions-runner\\_work\\pyedb\\pyedb\\.venv\\lib\\site-packages\\IPython\\core\\interactiveshell.py\", line 3517, in run_ast_nodes\n",
      "    if await self.run_code(code, result, async_=asy):\n",
      "  File \"C:\\actions-runner\\_work\\pyedb\\pyedb\\.venv\\lib\\site-packages\\IPython\\core\\interactiveshell.py\", line 3577, in run_code\n",
      "    exec(code_obj, self.user_global_ns, self.user_ns)\n",
      "  File \"C:\\Users\\ansys\\AppData\\Local\\Temp\\ipykernel_3468\\2999416059.py\", line 6, in <module>\n",
      "    edb.cutout(\n",
      "  File \"C:\\actions-runner\\_work\\pyedb\\pyedb\\.venv\\lib\\site-packages\\pyedb\\dotnet\\edb.py\", line 1951, in cutout\n",
      "    result = self._create_cutout_multithread(\n",
      "  File \"C:\\actions-runner\\_work\\pyedb\\pyedb\\.venv\\lib\\site-packages\\pyedb\\dotnet\\edb.py\", line 2414, in _create_cutout_multithread\n",
      "    self.logger.info_timer(\"Cutout completed.\", timer_start)\n",
      "  File \"C:\\actions-runner\\_work\\pyedb\\pyedb\\.venv\\lib\\site-packages\\pyedb\\edb_logger.py\", line 372, in info_timer\n",
      "    return self._log_on_handler(0, msg, *args, **kwargs)\n",
      "  File \"C:\\actions-runner\\_work\\pyedb\\pyedb\\.venv\\lib\\site-packages\\pyedb\\edb_logger.py\", line 293, in _log_on_handler\n",
      "    self._global.info(message_text, *args, **kwargs)\n",
      "Message: 'Cutout completed. Elapsed time: 0m 9sec'\n",
      "Arguments: ()\n"
     ]
    },
    {
     "name": "stdout",
     "output_type": "stream",
     "text": [
      "PyEDB INFO: Nets Point Generation time 0.469 seconds\n"
     ]
    },
    {
     "name": "stderr",
     "output_type": "stream",
     "text": [
      "--- Logging error ---\n",
      "Traceback (most recent call last):\n",
      "  File \"C:\\actions-runner\\_work\\_tool\\Python\\3.10.11\\x64\\lib\\logging\\handlers.py\", line 74, in emit\n",
      "    self.doRollover()\n",
      "  File \"C:\\actions-runner\\_work\\_tool\\Python\\3.10.11\\x64\\lib\\logging\\handlers.py\", line 179, in doRollover\n",
      "    self.rotate(self.baseFilename, dfn)\n",
      "  File \"C:\\actions-runner\\_work\\_tool\\Python\\3.10.11\\x64\\lib\\logging\\handlers.py\", line 115, in rotate\n",
      "    os.rename(source, dest)\n",
      "PermissionError: [WinError 32] The process cannot access the file because it is being used by another process: 'C:\\\\Users\\\\ansys\\\\AppData\\\\Local\\\\Temp\\\\pyedb_ansys.log' -> 'C:\\\\Users\\\\ansys\\\\AppData\\\\Local\\\\Temp\\\\pyedb_ansys.log.1'\n",
      "Call stack:\n",
      "  File \"C:\\actions-runner\\_work\\_tool\\Python\\3.10.11\\x64\\lib\\runpy.py\", line 196, in _run_module_as_main\n",
      "    return _run_code(code, main_globals, None,\n",
      "  File \"C:\\actions-runner\\_work\\_tool\\Python\\3.10.11\\x64\\lib\\runpy.py\", line 86, in _run_code\n",
      "    exec(code, run_globals)\n",
      "  File \"C:\\actions-runner\\_work\\pyedb\\pyedb\\.venv\\lib\\site-packages\\ipykernel_launcher.py\", line 18, in <module>\n",
      "    app.launch_new_instance()\n",
      "  File \"C:\\actions-runner\\_work\\pyedb\\pyedb\\.venv\\lib\\site-packages\\traitlets\\config\\application.py\", line 1075, in launch_instance\n",
      "    app.start()\n",
      "  File \"C:\\actions-runner\\_work\\pyedb\\pyedb\\.venv\\lib\\site-packages\\ipykernel\\kernelapp.py\", line 739, in start\n",
      "    self.io_loop.start()\n",
      "  File \"C:\\actions-runner\\_work\\pyedb\\pyedb\\.venv\\lib\\site-packages\\tornado\\platform\\asyncio.py\", line 205, in start\n",
      "    self.asyncio_loop.run_forever()\n",
      "  File \"C:\\actions-runner\\_work\\_tool\\Python\\3.10.11\\x64\\lib\\asyncio\\base_events.py\", line 603, in run_forever\n",
      "    self._run_once()\n",
      "  File \"C:\\actions-runner\\_work\\_tool\\Python\\3.10.11\\x64\\lib\\asyncio\\base_events.py\", line 1909, in _run_once\n",
      "    handle._run()\n",
      "  File \"C:\\actions-runner\\_work\\_tool\\Python\\3.10.11\\x64\\lib\\asyncio\\events.py\", line 80, in _run\n",
      "    self._context.run(self._callback, *self._args)\n",
      "  File \"C:\\actions-runner\\_work\\pyedb\\pyedb\\.venv\\lib\\site-packages\\ipykernel\\kernelbase.py\", line 545, in dispatch_queue\n",
      "    await self.process_one()\n",
      "  File \"C:\\actions-runner\\_work\\pyedb\\pyedb\\.venv\\lib\\site-packages\\ipykernel\\kernelbase.py\", line 534, in process_one\n",
      "    await dispatch(*args)\n",
      "  File \"C:\\actions-runner\\_work\\pyedb\\pyedb\\.venv\\lib\\site-packages\\ipykernel\\kernelbase.py\", line 437, in dispatch_shell\n",
      "    await result\n",
      "  File \"C:\\actions-runner\\_work\\pyedb\\pyedb\\.venv\\lib\\site-packages\\ipykernel\\ipkernel.py\", line 362, in execute_request\n",
      "    await super().execute_request(stream, ident, parent)\n",
      "  File \"C:\\actions-runner\\_work\\pyedb\\pyedb\\.venv\\lib\\site-packages\\ipykernel\\kernelbase.py\", line 778, in execute_request\n",
      "    reply_content = await reply_content\n",
      "  File \"C:\\actions-runner\\_work\\pyedb\\pyedb\\.venv\\lib\\site-packages\\ipykernel\\ipkernel.py\", line 449, in do_execute\n",
      "    res = shell.run_cell(\n",
      "  File \"C:\\actions-runner\\_work\\pyedb\\pyedb\\.venv\\lib\\site-packages\\ipykernel\\zmqshell.py\", line 549, in run_cell\n",
      "    return super().run_cell(*args, **kwargs)\n",
      "  File \"C:\\actions-runner\\_work\\pyedb\\pyedb\\.venv\\lib\\site-packages\\IPython\\core\\interactiveshell.py\", line 3075, in run_cell\n",
      "    result = self._run_cell(\n",
      "  File \"C:\\actions-runner\\_work\\pyedb\\pyedb\\.venv\\lib\\site-packages\\IPython\\core\\interactiveshell.py\", line 3130, in _run_cell\n",
      "    result = runner(coro)\n",
      "  File \"C:\\actions-runner\\_work\\pyedb\\pyedb\\.venv\\lib\\site-packages\\IPython\\core\\async_helpers.py\", line 128, in _pseudo_sync_runner\n",
      "    coro.send(None)\n",
      "  File \"C:\\actions-runner\\_work\\pyedb\\pyedb\\.venv\\lib\\site-packages\\IPython\\core\\interactiveshell.py\", line 3334, in run_cell_async\n",
      "    has_raised = await self.run_ast_nodes(code_ast.body, cell_name,\n",
      "  File \"C:\\actions-runner\\_work\\pyedb\\pyedb\\.venv\\lib\\site-packages\\IPython\\core\\interactiveshell.py\", line 3517, in run_ast_nodes\n",
      "    if await self.run_code(code, result, async_=asy):\n",
      "  File \"C:\\actions-runner\\_work\\pyedb\\pyedb\\.venv\\lib\\site-packages\\IPython\\core\\interactiveshell.py\", line 3577, in run_code\n",
      "    exec(code_obj, self.user_global_ns, self.user_ns)\n",
      "  File \"C:\\Users\\ansys\\AppData\\Local\\Temp\\ipykernel_3468\\2999416059.py\", line 17, in <module>\n",
      "    edb.nets.plot(None, None, color_by_net=True)\n",
      "  File \"C:\\actions-runner\\_work\\pyedb\\pyedb\\.venv\\lib\\site-packages\\pyedb\\dotnet\\edb_core\\nets.py\", line 770, in plot\n",
      "    object_lists = self.get_plot_data(\n",
      "  File \"C:\\actions-runner\\_work\\pyedb\\pyedb\\.venv\\lib\\site-packages\\pyedb\\dotnet\\edb_core\\nets.py\", line 686, in get_plot_data\n",
      "    self._logger.info(\"Nets Point Generation time %s seconds\", round(end_time, 3))\n",
      "  File \"C:\\actions-runner\\_work\\pyedb\\pyedb\\.venv\\lib\\site-packages\\pyedb\\edb_logger.py\", line 346, in info\n",
      "    return self._log_on_handler(0, msg, *args, **kwargs)\n",
      "  File \"C:\\actions-runner\\_work\\pyedb\\pyedb\\.venv\\lib\\site-packages\\pyedb\\edb_logger.py\", line 293, in _log_on_handler\n",
      "    self._global.info(message_text, *args, **kwargs)\n",
      "Message: 'Nets Point Generation time %s seconds'\n",
      "Arguments: (0.469,)\n"
     ]
    },
    {
     "name": "stderr",
     "output_type": "stream",
     "text": [
      "C:\\actions-runner\\_work\\pyedb\\pyedb\\.venv\\lib\\site-packages\\pyedb\\generic\\plot.py:144: UserWarning: FigureCanvasAgg is non-interactive, and thus cannot be shown\n",
      "  plt.show()\n"
     ]
    }
   ],
   "source": [
    "signal_list = []\n",
    "for net in edb.nets.netlist:\n",
    "    if \"PCIe\" in net:\n",
    "        signal_list.append(net)\n",
    "power_list = [\"GND\"]\n",
    "edb.cutout(\n",
    "    signal_list=signal_list,\n",
    "    reference_list=power_list,\n",
    "    extent_type=\"ConvexHull\",\n",
    "    expansion_size=0.002,\n",
    "    use_round_corner=False,\n",
    "    number_of_threads=4,\n",
    "    remove_single_pin_components=True,\n",
    "    use_pyaedt_extent_computing=True,\n",
    "    extent_defeature=0,\n",
    ")\n",
    "edb.nets.plot(None, None, color_by_net=True)"
   ]
  },
  {
   "cell_type": "markdown",
   "id": "51b4a7d5",
   "metadata": {},
   "source": [
    "## Export the EDB to an IPC2581 file."
   ]
  },
  {
   "cell_type": "code",
   "execution_count": 6,
   "id": "d704d870",
   "metadata": {
    "execution": {
     "iopub.execute_input": "2024-09-17T08:08:05.670321Z",
     "iopub.status.busy": "2024-09-17T08:08:05.670321Z",
     "iopub.status.idle": "2024-09-17T08:08:09.529748Z",
     "shell.execute_reply": "2024-09-17T08:08:09.529748Z"
    }
   },
   "outputs": [
    {
     "name": "stdout",
     "output_type": "stream",
     "text": [
      "PyEDB INFO: Export IPC 2581 is starting. This operation can take a while.\n"
     ]
    },
    {
     "name": "stdout",
     "output_type": "stream",
     "text": [
      "PyEDB INFO: Parsing Layers...\n"
     ]
    },
    {
     "name": "stderr",
     "output_type": "stream",
     "text": [
      "--- Logging error ---\n",
      "Traceback (most recent call last):\n",
      "  File \"C:\\actions-runner\\_work\\_tool\\Python\\3.10.11\\x64\\lib\\logging\\handlers.py\", line 74, in emit\n",
      "    self.doRollover()\n",
      "  File \"C:\\actions-runner\\_work\\_tool\\Python\\3.10.11\\x64\\lib\\logging\\handlers.py\", line 179, in doRollover\n",
      "    self.rotate(self.baseFilename, dfn)\n",
      "  File \"C:\\actions-runner\\_work\\_tool\\Python\\3.10.11\\x64\\lib\\logging\\handlers.py\", line 115, in rotate\n",
      "    os.rename(source, dest)\n",
      "PermissionError: [WinError 32] The process cannot access the file because it is being used by another process: 'C:\\\\Users\\\\ansys\\\\AppData\\\\Local\\\\Temp\\\\pyedb_ansys.log' -> 'C:\\\\Users\\\\ansys\\\\AppData\\\\Local\\\\Temp\\\\pyedb_ansys.log.1'\n",
      "Call stack:\n",
      "  File \"C:\\actions-runner\\_work\\_tool\\Python\\3.10.11\\x64\\lib\\runpy.py\", line 196, in _run_module_as_main\n",
      "    return _run_code(code, main_globals, None,\n",
      "  File \"C:\\actions-runner\\_work\\_tool\\Python\\3.10.11\\x64\\lib\\runpy.py\", line 86, in _run_code\n",
      "    exec(code, run_globals)\n",
      "  File \"C:\\actions-runner\\_work\\pyedb\\pyedb\\.venv\\lib\\site-packages\\ipykernel_launcher.py\", line 18, in <module>\n",
      "    app.launch_new_instance()\n",
      "  File \"C:\\actions-runner\\_work\\pyedb\\pyedb\\.venv\\lib\\site-packages\\traitlets\\config\\application.py\", line 1075, in launch_instance\n",
      "    app.start()\n",
      "  File \"C:\\actions-runner\\_work\\pyedb\\pyedb\\.venv\\lib\\site-packages\\ipykernel\\kernelapp.py\", line 739, in start\n",
      "    self.io_loop.start()\n",
      "  File \"C:\\actions-runner\\_work\\pyedb\\pyedb\\.venv\\lib\\site-packages\\tornado\\platform\\asyncio.py\", line 205, in start\n",
      "    self.asyncio_loop.run_forever()\n",
      "  File \"C:\\actions-runner\\_work\\_tool\\Python\\3.10.11\\x64\\lib\\asyncio\\base_events.py\", line 603, in run_forever\n",
      "    self._run_once()\n",
      "  File \"C:\\actions-runner\\_work\\_tool\\Python\\3.10.11\\x64\\lib\\asyncio\\base_events.py\", line 1909, in _run_once\n",
      "    handle._run()\n",
      "  File \"C:\\actions-runner\\_work\\_tool\\Python\\3.10.11\\x64\\lib\\asyncio\\events.py\", line 80, in _run\n",
      "    self._context.run(self._callback, *self._args)\n",
      "  File \"C:\\actions-runner\\_work\\pyedb\\pyedb\\.venv\\lib\\site-packages\\ipykernel\\kernelbase.py\", line 545, in dispatch_queue\n",
      "    await self.process_one()\n",
      "  File \"C:\\actions-runner\\_work\\pyedb\\pyedb\\.venv\\lib\\site-packages\\ipykernel\\kernelbase.py\", line 534, in process_one\n",
      "    await dispatch(*args)\n",
      "  File \"C:\\actions-runner\\_work\\pyedb\\pyedb\\.venv\\lib\\site-packages\\ipykernel\\kernelbase.py\", line 437, in dispatch_shell\n",
      "    await result\n",
      "  File \"C:\\actions-runner\\_work\\pyedb\\pyedb\\.venv\\lib\\site-packages\\ipykernel\\ipkernel.py\", line 362, in execute_request\n",
      "    await super().execute_request(stream, ident, parent)\n",
      "  File \"C:\\actions-runner\\_work\\pyedb\\pyedb\\.venv\\lib\\site-packages\\ipykernel\\kernelbase.py\", line 778, in execute_request\n",
      "    reply_content = await reply_content\n",
      "  File \"C:\\actions-runner\\_work\\pyedb\\pyedb\\.venv\\lib\\site-packages\\ipykernel\\ipkernel.py\", line 449, in do_execute\n",
      "    res = shell.run_cell(\n",
      "  File \"C:\\actions-runner\\_work\\pyedb\\pyedb\\.venv\\lib\\site-packages\\ipykernel\\zmqshell.py\", line 549, in run_cell\n",
      "    return super().run_cell(*args, **kwargs)\n",
      "  File \"C:\\actions-runner\\_work\\pyedb\\pyedb\\.venv\\lib\\site-packages\\IPython\\core\\interactiveshell.py\", line 3075, in run_cell\n",
      "    result = self._run_cell(\n",
      "  File \"C:\\actions-runner\\_work\\pyedb\\pyedb\\.venv\\lib\\site-packages\\IPython\\core\\interactiveshell.py\", line 3130, in _run_cell\n",
      "    result = runner(coro)\n",
      "  File \"C:\\actions-runner\\_work\\pyedb\\pyedb\\.venv\\lib\\site-packages\\IPython\\core\\async_helpers.py\", line 128, in _pseudo_sync_runner\n",
      "    coro.send(None)\n",
      "  File \"C:\\actions-runner\\_work\\pyedb\\pyedb\\.venv\\lib\\site-packages\\IPython\\core\\interactiveshell.py\", line 3334, in run_cell_async\n",
      "    has_raised = await self.run_ast_nodes(code_ast.body, cell_name,\n",
      "  File \"C:\\actions-runner\\_work\\pyedb\\pyedb\\.venv\\lib\\site-packages\\IPython\\core\\interactiveshell.py\", line 3517, in run_ast_nodes\n",
      "    if await self.run_code(code, result, async_=asy):\n",
      "  File \"C:\\actions-runner\\_work\\pyedb\\pyedb\\.venv\\lib\\site-packages\\IPython\\core\\interactiveshell.py\", line 3577, in run_code\n",
      "    exec(code_obj, self.user_global_ns, self.user_ns)\n",
      "  File \"C:\\Users\\ansys\\AppData\\Local\\Temp\\ipykernel_3468\\359427503.py\", line 1, in <module>\n",
      "    edb.export_to_ipc2581(ipc2581_file_name, \"inch\")\n",
      "  File \"C:\\actions-runner\\_work\\pyedb\\pyedb\\.venv\\lib\\site-packages\\pyedb\\dotnet\\edb.py\", line 703, in export_to_ipc2581\n",
      "    self.logger.info(\"Export IPC 2581 is starting. This operation can take a while.\")\n",
      "  File \"C:\\actions-runner\\_work\\pyedb\\pyedb\\.venv\\lib\\site-packages\\pyedb\\edb_logger.py\", line 346, in info\n",
      "    return self._log_on_handler(0, msg, *args, **kwargs)\n",
      "  File \"C:\\actions-runner\\_work\\pyedb\\pyedb\\.venv\\lib\\site-packages\\pyedb\\edb_logger.py\", line 293, in _log_on_handler\n",
      "    self._global.info(message_text, *args, **kwargs)\n",
      "Message: 'Export IPC 2581 is starting. This operation can take a while.'\n",
      "Arguments: ()\n",
      "--- Logging error ---\n",
      "Traceback (most recent call last):\n",
      "  File \"C:\\actions-runner\\_work\\_tool\\Python\\3.10.11\\x64\\lib\\logging\\handlers.py\", line 74, in emit\n",
      "    self.doRollover()\n",
      "  File \"C:\\actions-runner\\_work\\_tool\\Python\\3.10.11\\x64\\lib\\logging\\handlers.py\", line 179, in doRollover\n",
      "    self.rotate(self.baseFilename, dfn)\n",
      "  File \"C:\\actions-runner\\_work\\_tool\\Python\\3.10.11\\x64\\lib\\logging\\handlers.py\", line 115, in rotate\n",
      "    os.rename(source, dest)\n",
      "PermissionError: [WinError 32] The process cannot access the file because it is being used by another process: 'C:\\\\Users\\\\ansys\\\\AppData\\\\Local\\\\Temp\\\\pyedb_ansys.log' -> 'C:\\\\Users\\\\ansys\\\\AppData\\\\Local\\\\Temp\\\\pyedb_ansys.log.1'\n",
      "Call stack:\n",
      "  File \"C:\\actions-runner\\_work\\_tool\\Python\\3.10.11\\x64\\lib\\runpy.py\", line 196, in _run_module_as_main\n",
      "    return _run_code(code, main_globals, None,\n",
      "  File \"C:\\actions-runner\\_work\\_tool\\Python\\3.10.11\\x64\\lib\\runpy.py\", line 86, in _run_code\n",
      "    exec(code, run_globals)\n",
      "  File \"C:\\actions-runner\\_work\\pyedb\\pyedb\\.venv\\lib\\site-packages\\ipykernel_launcher.py\", line 18, in <module>\n",
      "    app.launch_new_instance()\n",
      "  File \"C:\\actions-runner\\_work\\pyedb\\pyedb\\.venv\\lib\\site-packages\\traitlets\\config\\application.py\", line 1075, in launch_instance\n",
      "    app.start()\n",
      "  File \"C:\\actions-runner\\_work\\pyedb\\pyedb\\.venv\\lib\\site-packages\\ipykernel\\kernelapp.py\", line 739, in start\n",
      "    self.io_loop.start()\n",
      "  File \"C:\\actions-runner\\_work\\pyedb\\pyedb\\.venv\\lib\\site-packages\\tornado\\platform\\asyncio.py\", line 205, in start\n",
      "    self.asyncio_loop.run_forever()\n",
      "  File \"C:\\actions-runner\\_work\\_tool\\Python\\3.10.11\\x64\\lib\\asyncio\\base_events.py\", line 603, in run_forever\n",
      "    self._run_once()\n",
      "  File \"C:\\actions-runner\\_work\\_tool\\Python\\3.10.11\\x64\\lib\\asyncio\\base_events.py\", line 1909, in _run_once\n",
      "    handle._run()\n",
      "  File \"C:\\actions-runner\\_work\\_tool\\Python\\3.10.11\\x64\\lib\\asyncio\\events.py\", line 80, in _run\n",
      "    self._context.run(self._callback, *self._args)\n",
      "  File \"C:\\actions-runner\\_work\\pyedb\\pyedb\\.venv\\lib\\site-packages\\ipykernel\\kernelbase.py\", line 545, in dispatch_queue\n",
      "    await self.process_one()\n",
      "  File \"C:\\actions-runner\\_work\\pyedb\\pyedb\\.venv\\lib\\site-packages\\ipykernel\\kernelbase.py\", line 534, in process_one\n",
      "    await dispatch(*args)\n",
      "  File \"C:\\actions-runner\\_work\\pyedb\\pyedb\\.venv\\lib\\site-packages\\ipykernel\\kernelbase.py\", line 437, in dispatch_shell\n",
      "    await result\n",
      "  File \"C:\\actions-runner\\_work\\pyedb\\pyedb\\.venv\\lib\\site-packages\\ipykernel\\ipkernel.py\", line 362, in execute_request\n",
      "    await super().execute_request(stream, ident, parent)\n",
      "  File \"C:\\actions-runner\\_work\\pyedb\\pyedb\\.venv\\lib\\site-packages\\ipykernel\\kernelbase.py\", line 778, in execute_request\n",
      "    reply_content = await reply_content\n",
      "  File \"C:\\actions-runner\\_work\\pyedb\\pyedb\\.venv\\lib\\site-packages\\ipykernel\\ipkernel.py\", line 449, in do_execute\n",
      "    res = shell.run_cell(\n",
      "  File \"C:\\actions-runner\\_work\\pyedb\\pyedb\\.venv\\lib\\site-packages\\ipykernel\\zmqshell.py\", line 549, in run_cell\n",
      "    return super().run_cell(*args, **kwargs)\n",
      "  File \"C:\\actions-runner\\_work\\pyedb\\pyedb\\.venv\\lib\\site-packages\\IPython\\core\\interactiveshell.py\", line 3075, in run_cell\n",
      "    result = self._run_cell(\n",
      "  File \"C:\\actions-runner\\_work\\pyedb\\pyedb\\.venv\\lib\\site-packages\\IPython\\core\\interactiveshell.py\", line 3130, in _run_cell\n",
      "    result = runner(coro)\n",
      "  File \"C:\\actions-runner\\_work\\pyedb\\pyedb\\.venv\\lib\\site-packages\\IPython\\core\\async_helpers.py\", line 128, in _pseudo_sync_runner\n",
      "    coro.send(None)\n",
      "  File \"C:\\actions-runner\\_work\\pyedb\\pyedb\\.venv\\lib\\site-packages\\IPython\\core\\interactiveshell.py\", line 3334, in run_cell_async\n",
      "    has_raised = await self.run_ast_nodes(code_ast.body, cell_name,\n",
      "  File \"C:\\actions-runner\\_work\\pyedb\\pyedb\\.venv\\lib\\site-packages\\IPython\\core\\interactiveshell.py\", line 3517, in run_ast_nodes\n",
      "    if await self.run_code(code, result, async_=asy):\n",
      "  File \"C:\\actions-runner\\_work\\pyedb\\pyedb\\.venv\\lib\\site-packages\\IPython\\core\\interactiveshell.py\", line 3577, in run_code\n",
      "    exec(code_obj, self.user_global_ns, self.user_ns)\n",
      "  File \"C:\\Users\\ansys\\AppData\\Local\\Temp\\ipykernel_3468\\359427503.py\", line 1, in <module>\n",
      "    edb.export_to_ipc2581(ipc2581_file_name, \"inch\")\n",
      "  File \"C:\\actions-runner\\_work\\pyedb\\pyedb\\.venv\\lib\\site-packages\\pyedb\\dotnet\\edb.py\", line 706, in export_to_ipc2581\n",
      "    ipc.load_ipc_model()\n",
      "  File \"C:\\actions-runner\\_work\\pyedb\\pyedb\\.venv\\lib\\site-packages\\pyedb\\ipc2581\\ipc2581.py\", line 54, in load_ipc_model\n",
      "    self._pedb.logger.info(\"Parsing Layers...\")\n",
      "  File \"C:\\actions-runner\\_work\\pyedb\\pyedb\\.venv\\lib\\site-packages\\pyedb\\edb_logger.py\", line 346, in info\n",
      "    return self._log_on_handler(0, msg, *args, **kwargs)\n",
      "  File \"C:\\actions-runner\\_work\\pyedb\\pyedb\\.venv\\lib\\site-packages\\pyedb\\edb_logger.py\", line 293, in _log_on_handler\n",
      "    self._global.info(message_text, *args, **kwargs)\n",
      "Message: 'Parsing Layers...'\n",
      "Arguments: ()\n"
     ]
    },
    {
     "name": "stdout",
     "output_type": "stream",
     "text": [
      "PyEDB INFO: Parsing BOM...\n"
     ]
    },
    {
     "name": "stdout",
     "output_type": "stream",
     "text": [
      "PyEDB INFO: Parsing Padstack Definitions...\n"
     ]
    },
    {
     "name": "stderr",
     "output_type": "stream",
     "text": [
      "--- Logging error ---\n",
      "Traceback (most recent call last):\n",
      "  File \"C:\\actions-runner\\_work\\_tool\\Python\\3.10.11\\x64\\lib\\logging\\handlers.py\", line 74, in emit\n",
      "    self.doRollover()\n",
      "  File \"C:\\actions-runner\\_work\\_tool\\Python\\3.10.11\\x64\\lib\\logging\\handlers.py\", line 179, in doRollover\n",
      "    self.rotate(self.baseFilename, dfn)\n",
      "  File \"C:\\actions-runner\\_work\\_tool\\Python\\3.10.11\\x64\\lib\\logging\\handlers.py\", line 115, in rotate\n",
      "    os.rename(source, dest)\n",
      "PermissionError: [WinError 32] The process cannot access the file because it is being used by another process: 'C:\\\\Users\\\\ansys\\\\AppData\\\\Local\\\\Temp\\\\pyedb_ansys.log' -> 'C:\\\\Users\\\\ansys\\\\AppData\\\\Local\\\\Temp\\\\pyedb_ansys.log.1'\n",
      "Call stack:\n",
      "  File \"C:\\actions-runner\\_work\\_tool\\Python\\3.10.11\\x64\\lib\\runpy.py\", line 196, in _run_module_as_main\n",
      "    return _run_code(code, main_globals, None,\n",
      "  File \"C:\\actions-runner\\_work\\_tool\\Python\\3.10.11\\x64\\lib\\runpy.py\", line 86, in _run_code\n",
      "    exec(code, run_globals)\n",
      "  File \"C:\\actions-runner\\_work\\pyedb\\pyedb\\.venv\\lib\\site-packages\\ipykernel_launcher.py\", line 18, in <module>\n",
      "    app.launch_new_instance()\n",
      "  File \"C:\\actions-runner\\_work\\pyedb\\pyedb\\.venv\\lib\\site-packages\\traitlets\\config\\application.py\", line 1075, in launch_instance\n",
      "    app.start()\n",
      "  File \"C:\\actions-runner\\_work\\pyedb\\pyedb\\.venv\\lib\\site-packages\\ipykernel\\kernelapp.py\", line 739, in start\n",
      "    self.io_loop.start()\n",
      "  File \"C:\\actions-runner\\_work\\pyedb\\pyedb\\.venv\\lib\\site-packages\\tornado\\platform\\asyncio.py\", line 205, in start\n",
      "    self.asyncio_loop.run_forever()\n",
      "  File \"C:\\actions-runner\\_work\\_tool\\Python\\3.10.11\\x64\\lib\\asyncio\\base_events.py\", line 603, in run_forever\n",
      "    self._run_once()\n",
      "  File \"C:\\actions-runner\\_work\\_tool\\Python\\3.10.11\\x64\\lib\\asyncio\\base_events.py\", line 1909, in _run_once\n",
      "    handle._run()\n",
      "  File \"C:\\actions-runner\\_work\\_tool\\Python\\3.10.11\\x64\\lib\\asyncio\\events.py\", line 80, in _run\n",
      "    self._context.run(self._callback, *self._args)\n",
      "  File \"C:\\actions-runner\\_work\\pyedb\\pyedb\\.venv\\lib\\site-packages\\ipykernel\\kernelbase.py\", line 545, in dispatch_queue\n",
      "    await self.process_one()\n",
      "  File \"C:\\actions-runner\\_work\\pyedb\\pyedb\\.venv\\lib\\site-packages\\ipykernel\\kernelbase.py\", line 534, in process_one\n",
      "    await dispatch(*args)\n",
      "  File \"C:\\actions-runner\\_work\\pyedb\\pyedb\\.venv\\lib\\site-packages\\ipykernel\\kernelbase.py\", line 437, in dispatch_shell\n",
      "    await result\n",
      "  File \"C:\\actions-runner\\_work\\pyedb\\pyedb\\.venv\\lib\\site-packages\\ipykernel\\ipkernel.py\", line 362, in execute_request\n",
      "    await super().execute_request(stream, ident, parent)\n",
      "  File \"C:\\actions-runner\\_work\\pyedb\\pyedb\\.venv\\lib\\site-packages\\ipykernel\\kernelbase.py\", line 778, in execute_request\n",
      "    reply_content = await reply_content\n",
      "  File \"C:\\actions-runner\\_work\\pyedb\\pyedb\\.venv\\lib\\site-packages\\ipykernel\\ipkernel.py\", line 449, in do_execute\n",
      "    res = shell.run_cell(\n",
      "  File \"C:\\actions-runner\\_work\\pyedb\\pyedb\\.venv\\lib\\site-packages\\ipykernel\\zmqshell.py\", line 549, in run_cell\n",
      "    return super().run_cell(*args, **kwargs)\n",
      "  File \"C:\\actions-runner\\_work\\pyedb\\pyedb\\.venv\\lib\\site-packages\\IPython\\core\\interactiveshell.py\", line 3075, in run_cell\n",
      "    result = self._run_cell(\n",
      "  File \"C:\\actions-runner\\_work\\pyedb\\pyedb\\.venv\\lib\\site-packages\\IPython\\core\\interactiveshell.py\", line 3130, in _run_cell\n",
      "    result = runner(coro)\n",
      "  File \"C:\\actions-runner\\_work\\pyedb\\pyedb\\.venv\\lib\\site-packages\\IPython\\core\\async_helpers.py\", line 128, in _pseudo_sync_runner\n",
      "    coro.send(None)\n",
      "  File \"C:\\actions-runner\\_work\\pyedb\\pyedb\\.venv\\lib\\site-packages\\IPython\\core\\interactiveshell.py\", line 3334, in run_cell_async\n",
      "    has_raised = await self.run_ast_nodes(code_ast.body, cell_name,\n",
      "  File \"C:\\actions-runner\\_work\\pyedb\\pyedb\\.venv\\lib\\site-packages\\IPython\\core\\interactiveshell.py\", line 3517, in run_ast_nodes\n",
      "    if await self.run_code(code, result, async_=asy):\n",
      "  File \"C:\\actions-runner\\_work\\pyedb\\pyedb\\.venv\\lib\\site-packages\\IPython\\core\\interactiveshell.py\", line 3577, in run_code\n",
      "    exec(code_obj, self.user_global_ns, self.user_ns)\n",
      "  File \"C:\\Users\\ansys\\AppData\\Local\\Temp\\ipykernel_3468\\359427503.py\", line 1, in <module>\n",
      "    edb.export_to_ipc2581(ipc2581_file_name, \"inch\")\n",
      "  File \"C:\\actions-runner\\_work\\pyedb\\pyedb\\.venv\\lib\\site-packages\\pyedb\\dotnet\\edb.py\", line 706, in export_to_ipc2581\n",
      "    ipc.load_ipc_model()\n",
      "  File \"C:\\actions-runner\\_work\\pyedb\\pyedb\\.venv\\lib\\site-packages\\pyedb\\ipc2581\\ipc2581.py\", line 56, in load_ipc_model\n",
      "    self._pedb.logger.info(\"Parsing BOM...\")\n",
      "  File \"C:\\actions-runner\\_work\\pyedb\\pyedb\\.venv\\lib\\site-packages\\pyedb\\edb_logger.py\", line 346, in info\n",
      "    return self._log_on_handler(0, msg, *args, **kwargs)\n",
      "  File \"C:\\actions-runner\\_work\\pyedb\\pyedb\\.venv\\lib\\site-packages\\pyedb\\edb_logger.py\", line 293, in _log_on_handler\n",
      "    self._global.info(message_text, *args, **kwargs)\n",
      "Message: 'Parsing BOM...'\n",
      "Arguments: ()\n",
      "--- Logging error ---\n",
      "Traceback (most recent call last):\n",
      "  File \"C:\\actions-runner\\_work\\_tool\\Python\\3.10.11\\x64\\lib\\logging\\handlers.py\", line 74, in emit\n",
      "    self.doRollover()\n",
      "  File \"C:\\actions-runner\\_work\\_tool\\Python\\3.10.11\\x64\\lib\\logging\\handlers.py\", line 179, in doRollover\n",
      "    self.rotate(self.baseFilename, dfn)\n",
      "  File \"C:\\actions-runner\\_work\\_tool\\Python\\3.10.11\\x64\\lib\\logging\\handlers.py\", line 115, in rotate\n",
      "    os.rename(source, dest)\n",
      "PermissionError: [WinError 32] The process cannot access the file because it is being used by another process: 'C:\\\\Users\\\\ansys\\\\AppData\\\\Local\\\\Temp\\\\pyedb_ansys.log' -> 'C:\\\\Users\\\\ansys\\\\AppData\\\\Local\\\\Temp\\\\pyedb_ansys.log.1'\n",
      "Call stack:\n",
      "  File \"C:\\actions-runner\\_work\\_tool\\Python\\3.10.11\\x64\\lib\\runpy.py\", line 196, in _run_module_as_main\n",
      "    return _run_code(code, main_globals, None,\n",
      "  File \"C:\\actions-runner\\_work\\_tool\\Python\\3.10.11\\x64\\lib\\runpy.py\", line 86, in _run_code\n",
      "    exec(code, run_globals)\n",
      "  File \"C:\\actions-runner\\_work\\pyedb\\pyedb\\.venv\\lib\\site-packages\\ipykernel_launcher.py\", line 18, in <module>\n",
      "    app.launch_new_instance()\n",
      "  File \"C:\\actions-runner\\_work\\pyedb\\pyedb\\.venv\\lib\\site-packages\\traitlets\\config\\application.py\", line 1075, in launch_instance\n",
      "    app.start()\n",
      "  File \"C:\\actions-runner\\_work\\pyedb\\pyedb\\.venv\\lib\\site-packages\\ipykernel\\kernelapp.py\", line 739, in start\n",
      "    self.io_loop.start()\n",
      "  File \"C:\\actions-runner\\_work\\pyedb\\pyedb\\.venv\\lib\\site-packages\\tornado\\platform\\asyncio.py\", line 205, in start\n",
      "    self.asyncio_loop.run_forever()\n",
      "  File \"C:\\actions-runner\\_work\\_tool\\Python\\3.10.11\\x64\\lib\\asyncio\\base_events.py\", line 603, in run_forever\n",
      "    self._run_once()\n",
      "  File \"C:\\actions-runner\\_work\\_tool\\Python\\3.10.11\\x64\\lib\\asyncio\\base_events.py\", line 1909, in _run_once\n",
      "    handle._run()\n",
      "  File \"C:\\actions-runner\\_work\\_tool\\Python\\3.10.11\\x64\\lib\\asyncio\\events.py\", line 80, in _run\n",
      "    self._context.run(self._callback, *self._args)\n",
      "  File \"C:\\actions-runner\\_work\\pyedb\\pyedb\\.venv\\lib\\site-packages\\ipykernel\\kernelbase.py\", line 545, in dispatch_queue\n",
      "    await self.process_one()\n",
      "  File \"C:\\actions-runner\\_work\\pyedb\\pyedb\\.venv\\lib\\site-packages\\ipykernel\\kernelbase.py\", line 534, in process_one\n",
      "    await dispatch(*args)\n",
      "  File \"C:\\actions-runner\\_work\\pyedb\\pyedb\\.venv\\lib\\site-packages\\ipykernel\\kernelbase.py\", line 437, in dispatch_shell\n",
      "    await result\n",
      "  File \"C:\\actions-runner\\_work\\pyedb\\pyedb\\.venv\\lib\\site-packages\\ipykernel\\ipkernel.py\", line 362, in execute_request\n",
      "    await super().execute_request(stream, ident, parent)\n",
      "  File \"C:\\actions-runner\\_work\\pyedb\\pyedb\\.venv\\lib\\site-packages\\ipykernel\\kernelbase.py\", line 778, in execute_request\n",
      "    reply_content = await reply_content\n",
      "  File \"C:\\actions-runner\\_work\\pyedb\\pyedb\\.venv\\lib\\site-packages\\ipykernel\\ipkernel.py\", line 449, in do_execute\n",
      "    res = shell.run_cell(\n",
      "  File \"C:\\actions-runner\\_work\\pyedb\\pyedb\\.venv\\lib\\site-packages\\ipykernel\\zmqshell.py\", line 549, in run_cell\n",
      "    return super().run_cell(*args, **kwargs)\n",
      "  File \"C:\\actions-runner\\_work\\pyedb\\pyedb\\.venv\\lib\\site-packages\\IPython\\core\\interactiveshell.py\", line 3075, in run_cell\n",
      "    result = self._run_cell(\n",
      "  File \"C:\\actions-runner\\_work\\pyedb\\pyedb\\.venv\\lib\\site-packages\\IPython\\core\\interactiveshell.py\", line 3130, in _run_cell\n",
      "    result = runner(coro)\n",
      "  File \"C:\\actions-runner\\_work\\pyedb\\pyedb\\.venv\\lib\\site-packages\\IPython\\core\\async_helpers.py\", line 128, in _pseudo_sync_runner\n",
      "    coro.send(None)\n",
      "  File \"C:\\actions-runner\\_work\\pyedb\\pyedb\\.venv\\lib\\site-packages\\IPython\\core\\interactiveshell.py\", line 3334, in run_cell_async\n",
      "    has_raised = await self.run_ast_nodes(code_ast.body, cell_name,\n",
      "  File \"C:\\actions-runner\\_work\\pyedb\\pyedb\\.venv\\lib\\site-packages\\IPython\\core\\interactiveshell.py\", line 3517, in run_ast_nodes\n",
      "    if await self.run_code(code, result, async_=asy):\n",
      "  File \"C:\\actions-runner\\_work\\pyedb\\pyedb\\.venv\\lib\\site-packages\\IPython\\core\\interactiveshell.py\", line 3577, in run_code\n",
      "    exec(code_obj, self.user_global_ns, self.user_ns)\n",
      "  File \"C:\\Users\\ansys\\AppData\\Local\\Temp\\ipykernel_3468\\359427503.py\", line 1, in <module>\n",
      "    edb.export_to_ipc2581(ipc2581_file_name, \"inch\")\n",
      "  File \"C:\\actions-runner\\_work\\pyedb\\pyedb\\.venv\\lib\\site-packages\\pyedb\\dotnet\\edb.py\", line 706, in export_to_ipc2581\n",
      "    ipc.load_ipc_model()\n",
      "  File \"C:\\actions-runner\\_work\\pyedb\\pyedb\\.venv\\lib\\site-packages\\pyedb\\ipc2581\\ipc2581.py\", line 58, in load_ipc_model\n",
      "    self._pedb.logger.info(\"Parsing Padstack Definitions...\")\n",
      "  File \"C:\\actions-runner\\_work\\pyedb\\pyedb\\.venv\\lib\\site-packages\\pyedb\\edb_logger.py\", line 346, in info\n",
      "    return self._log_on_handler(0, msg, *args, **kwargs)\n",
      "  File \"C:\\actions-runner\\_work\\pyedb\\pyedb\\.venv\\lib\\site-packages\\pyedb\\edb_logger.py\", line 293, in _log_on_handler\n",
      "    self._global.info(message_text, *args, **kwargs)\n",
      "Message: 'Parsing Padstack Definitions...'\n",
      "Arguments: ()\n"
     ]
    },
    {
     "name": "stdout",
     "output_type": "stream",
     "text": [
      "PyEDB INFO: Parsing Components...\n"
     ]
    },
    {
     "name": "stderr",
     "output_type": "stream",
     "text": [
      "--- Logging error ---\n",
      "Traceback (most recent call last):\n",
      "  File \"C:\\actions-runner\\_work\\_tool\\Python\\3.10.11\\x64\\lib\\logging\\handlers.py\", line 74, in emit\n",
      "    self.doRollover()\n",
      "  File \"C:\\actions-runner\\_work\\_tool\\Python\\3.10.11\\x64\\lib\\logging\\handlers.py\", line 179, in doRollover\n",
      "    self.rotate(self.baseFilename, dfn)\n",
      "  File \"C:\\actions-runner\\_work\\_tool\\Python\\3.10.11\\x64\\lib\\logging\\handlers.py\", line 115, in rotate\n",
      "    os.rename(source, dest)\n",
      "PermissionError: [WinError 32] The process cannot access the file because it is being used by another process: 'C:\\\\Users\\\\ansys\\\\AppData\\\\Local\\\\Temp\\\\pyedb_ansys.log' -> 'C:\\\\Users\\\\ansys\\\\AppData\\\\Local\\\\Temp\\\\pyedb_ansys.log.1'\n",
      "Call stack:\n",
      "  File \"C:\\actions-runner\\_work\\_tool\\Python\\3.10.11\\x64\\lib\\runpy.py\", line 196, in _run_module_as_main\n",
      "    return _run_code(code, main_globals, None,\n",
      "  File \"C:\\actions-runner\\_work\\_tool\\Python\\3.10.11\\x64\\lib\\runpy.py\", line 86, in _run_code\n",
      "    exec(code, run_globals)\n",
      "  File \"C:\\actions-runner\\_work\\pyedb\\pyedb\\.venv\\lib\\site-packages\\ipykernel_launcher.py\", line 18, in <module>\n",
      "    app.launch_new_instance()\n",
      "  File \"C:\\actions-runner\\_work\\pyedb\\pyedb\\.venv\\lib\\site-packages\\traitlets\\config\\application.py\", line 1075, in launch_instance\n",
      "    app.start()\n",
      "  File \"C:\\actions-runner\\_work\\pyedb\\pyedb\\.venv\\lib\\site-packages\\ipykernel\\kernelapp.py\", line 739, in start\n",
      "    self.io_loop.start()\n",
      "  File \"C:\\actions-runner\\_work\\pyedb\\pyedb\\.venv\\lib\\site-packages\\tornado\\platform\\asyncio.py\", line 205, in start\n",
      "    self.asyncio_loop.run_forever()\n",
      "  File \"C:\\actions-runner\\_work\\_tool\\Python\\3.10.11\\x64\\lib\\asyncio\\base_events.py\", line 603, in run_forever\n",
      "    self._run_once()\n",
      "  File \"C:\\actions-runner\\_work\\_tool\\Python\\3.10.11\\x64\\lib\\asyncio\\base_events.py\", line 1909, in _run_once\n",
      "    handle._run()\n",
      "  File \"C:\\actions-runner\\_work\\_tool\\Python\\3.10.11\\x64\\lib\\asyncio\\events.py\", line 80, in _run\n",
      "    self._context.run(self._callback, *self._args)\n",
      "  File \"C:\\actions-runner\\_work\\pyedb\\pyedb\\.venv\\lib\\site-packages\\ipykernel\\kernelbase.py\", line 545, in dispatch_queue\n",
      "    await self.process_one()\n",
      "  File \"C:\\actions-runner\\_work\\pyedb\\pyedb\\.venv\\lib\\site-packages\\ipykernel\\kernelbase.py\", line 534, in process_one\n",
      "    await dispatch(*args)\n",
      "  File \"C:\\actions-runner\\_work\\pyedb\\pyedb\\.venv\\lib\\site-packages\\ipykernel\\kernelbase.py\", line 437, in dispatch_shell\n",
      "    await result\n",
      "  File \"C:\\actions-runner\\_work\\pyedb\\pyedb\\.venv\\lib\\site-packages\\ipykernel\\ipkernel.py\", line 362, in execute_request\n",
      "    await super().execute_request(stream, ident, parent)\n",
      "  File \"C:\\actions-runner\\_work\\pyedb\\pyedb\\.venv\\lib\\site-packages\\ipykernel\\kernelbase.py\", line 778, in execute_request\n",
      "    reply_content = await reply_content\n",
      "  File \"C:\\actions-runner\\_work\\pyedb\\pyedb\\.venv\\lib\\site-packages\\ipykernel\\ipkernel.py\", line 449, in do_execute\n",
      "    res = shell.run_cell(\n",
      "  File \"C:\\actions-runner\\_work\\pyedb\\pyedb\\.venv\\lib\\site-packages\\ipykernel\\zmqshell.py\", line 549, in run_cell\n",
      "    return super().run_cell(*args, **kwargs)\n",
      "  File \"C:\\actions-runner\\_work\\pyedb\\pyedb\\.venv\\lib\\site-packages\\IPython\\core\\interactiveshell.py\", line 3075, in run_cell\n",
      "    result = self._run_cell(\n",
      "  File \"C:\\actions-runner\\_work\\pyedb\\pyedb\\.venv\\lib\\site-packages\\IPython\\core\\interactiveshell.py\", line 3130, in _run_cell\n",
      "    result = runner(coro)\n",
      "  File \"C:\\actions-runner\\_work\\pyedb\\pyedb\\.venv\\lib\\site-packages\\IPython\\core\\async_helpers.py\", line 128, in _pseudo_sync_runner\n",
      "    coro.send(None)\n",
      "  File \"C:\\actions-runner\\_work\\pyedb\\pyedb\\.venv\\lib\\site-packages\\IPython\\core\\interactiveshell.py\", line 3334, in run_cell_async\n",
      "    has_raised = await self.run_ast_nodes(code_ast.body, cell_name,\n",
      "  File \"C:\\actions-runner\\_work\\pyedb\\pyedb\\.venv\\lib\\site-packages\\IPython\\core\\interactiveshell.py\", line 3517, in run_ast_nodes\n",
      "    if await self.run_code(code, result, async_=asy):\n",
      "  File \"C:\\actions-runner\\_work\\pyedb\\pyedb\\.venv\\lib\\site-packages\\IPython\\core\\interactiveshell.py\", line 3577, in run_code\n",
      "    exec(code_obj, self.user_global_ns, self.user_ns)\n",
      "  File \"C:\\Users\\ansys\\AppData\\Local\\Temp\\ipykernel_3468\\359427503.py\", line 1, in <module>\n",
      "    edb.export_to_ipc2581(ipc2581_file_name, \"inch\")\n",
      "  File \"C:\\actions-runner\\_work\\pyedb\\pyedb\\.venv\\lib\\site-packages\\pyedb\\dotnet\\edb.py\", line 706, in export_to_ipc2581\n",
      "    ipc.load_ipc_model()\n",
      "  File \"C:\\actions-runner\\_work\\pyedb\\pyedb\\.venv\\lib\\site-packages\\pyedb\\ipc2581\\ipc2581.py\", line 61, in load_ipc_model\n",
      "    self._pedb.logger.info(\"Parsing Components...\")\n",
      "  File \"C:\\actions-runner\\_work\\pyedb\\pyedb\\.venv\\lib\\site-packages\\pyedb\\edb_logger.py\", line 346, in info\n",
      "    return self._log_on_handler(0, msg, *args, **kwargs)\n",
      "  File \"C:\\actions-runner\\_work\\pyedb\\pyedb\\.venv\\lib\\site-packages\\pyedb\\edb_logger.py\", line 293, in _log_on_handler\n",
      "    self._global.info(message_text, *args, **kwargs)\n",
      "Message: 'Parsing Components...'\n",
      "Arguments: ()\n"
     ]
    },
    {
     "name": "stdout",
     "output_type": "stream",
     "text": [
      "PyEDB INFO: Parsing Logical Nets...\n"
     ]
    },
    {
     "name": "stdout",
     "output_type": "stream",
     "text": [
      "PyEDB INFO: Parsing Layout Primitives...\n"
     ]
    },
    {
     "name": "stderr",
     "output_type": "stream",
     "text": [
      "--- Logging error ---\n",
      "Traceback (most recent call last):\n",
      "  File \"C:\\actions-runner\\_work\\_tool\\Python\\3.10.11\\x64\\lib\\logging\\handlers.py\", line 74, in emit\n",
      "    self.doRollover()\n",
      "  File \"C:\\actions-runner\\_work\\_tool\\Python\\3.10.11\\x64\\lib\\logging\\handlers.py\", line 179, in doRollover\n",
      "    self.rotate(self.baseFilename, dfn)\n",
      "  File \"C:\\actions-runner\\_work\\_tool\\Python\\3.10.11\\x64\\lib\\logging\\handlers.py\", line 115, in rotate\n",
      "    os.rename(source, dest)\n",
      "PermissionError: [WinError 32] The process cannot access the file because it is being used by another process: 'C:\\\\Users\\\\ansys\\\\AppData\\\\Local\\\\Temp\\\\pyedb_ansys.log' -> 'C:\\\\Users\\\\ansys\\\\AppData\\\\Local\\\\Temp\\\\pyedb_ansys.log.1'\n",
      "Call stack:\n",
      "  File \"C:\\actions-runner\\_work\\_tool\\Python\\3.10.11\\x64\\lib\\runpy.py\", line 196, in _run_module_as_main\n",
      "    return _run_code(code, main_globals, None,\n",
      "  File \"C:\\actions-runner\\_work\\_tool\\Python\\3.10.11\\x64\\lib\\runpy.py\", line 86, in _run_code\n",
      "    exec(code, run_globals)\n",
      "  File \"C:\\actions-runner\\_work\\pyedb\\pyedb\\.venv\\lib\\site-packages\\ipykernel_launcher.py\", line 18, in <module>\n",
      "    app.launch_new_instance()\n",
      "  File \"C:\\actions-runner\\_work\\pyedb\\pyedb\\.venv\\lib\\site-packages\\traitlets\\config\\application.py\", line 1075, in launch_instance\n",
      "    app.start()\n",
      "  File \"C:\\actions-runner\\_work\\pyedb\\pyedb\\.venv\\lib\\site-packages\\ipykernel\\kernelapp.py\", line 739, in start\n",
      "    self.io_loop.start()\n",
      "  File \"C:\\actions-runner\\_work\\pyedb\\pyedb\\.venv\\lib\\site-packages\\tornado\\platform\\asyncio.py\", line 205, in start\n",
      "    self.asyncio_loop.run_forever()\n",
      "  File \"C:\\actions-runner\\_work\\_tool\\Python\\3.10.11\\x64\\lib\\asyncio\\base_events.py\", line 603, in run_forever\n",
      "    self._run_once()\n",
      "  File \"C:\\actions-runner\\_work\\_tool\\Python\\3.10.11\\x64\\lib\\asyncio\\base_events.py\", line 1909, in _run_once\n",
      "    handle._run()\n",
      "  File \"C:\\actions-runner\\_work\\_tool\\Python\\3.10.11\\x64\\lib\\asyncio\\events.py\", line 80, in _run\n",
      "    self._context.run(self._callback, *self._args)\n",
      "  File \"C:\\actions-runner\\_work\\pyedb\\pyedb\\.venv\\lib\\site-packages\\ipykernel\\kernelbase.py\", line 545, in dispatch_queue\n",
      "    await self.process_one()\n",
      "  File \"C:\\actions-runner\\_work\\pyedb\\pyedb\\.venv\\lib\\site-packages\\ipykernel\\kernelbase.py\", line 534, in process_one\n",
      "    await dispatch(*args)\n",
      "  File \"C:\\actions-runner\\_work\\pyedb\\pyedb\\.venv\\lib\\site-packages\\ipykernel\\kernelbase.py\", line 437, in dispatch_shell\n",
      "    await result\n",
      "  File \"C:\\actions-runner\\_work\\pyedb\\pyedb\\.venv\\lib\\site-packages\\ipykernel\\ipkernel.py\", line 362, in execute_request\n",
      "    await super().execute_request(stream, ident, parent)\n",
      "  File \"C:\\actions-runner\\_work\\pyedb\\pyedb\\.venv\\lib\\site-packages\\ipykernel\\kernelbase.py\", line 778, in execute_request\n",
      "    reply_content = await reply_content\n",
      "  File \"C:\\actions-runner\\_work\\pyedb\\pyedb\\.venv\\lib\\site-packages\\ipykernel\\ipkernel.py\", line 449, in do_execute\n",
      "    res = shell.run_cell(\n",
      "  File \"C:\\actions-runner\\_work\\pyedb\\pyedb\\.venv\\lib\\site-packages\\ipykernel\\zmqshell.py\", line 549, in run_cell\n",
      "    return super().run_cell(*args, **kwargs)\n",
      "  File \"C:\\actions-runner\\_work\\pyedb\\pyedb\\.venv\\lib\\site-packages\\IPython\\core\\interactiveshell.py\", line 3075, in run_cell\n",
      "    result = self._run_cell(\n",
      "  File \"C:\\actions-runner\\_work\\pyedb\\pyedb\\.venv\\lib\\site-packages\\IPython\\core\\interactiveshell.py\", line 3130, in _run_cell\n",
      "    result = runner(coro)\n",
      "  File \"C:\\actions-runner\\_work\\pyedb\\pyedb\\.venv\\lib\\site-packages\\IPython\\core\\async_helpers.py\", line 128, in _pseudo_sync_runner\n",
      "    coro.send(None)\n",
      "  File \"C:\\actions-runner\\_work\\pyedb\\pyedb\\.venv\\lib\\site-packages\\IPython\\core\\interactiveshell.py\", line 3334, in run_cell_async\n",
      "    has_raised = await self.run_ast_nodes(code_ast.body, cell_name,\n",
      "  File \"C:\\actions-runner\\_work\\pyedb\\pyedb\\.venv\\lib\\site-packages\\IPython\\core\\interactiveshell.py\", line 3517, in run_ast_nodes\n",
      "    if await self.run_code(code, result, async_=asy):\n",
      "  File \"C:\\actions-runner\\_work\\pyedb\\pyedb\\.venv\\lib\\site-packages\\IPython\\core\\interactiveshell.py\", line 3577, in run_code\n",
      "    exec(code_obj, self.user_global_ns, self.user_ns)\n",
      "  File \"C:\\Users\\ansys\\AppData\\Local\\Temp\\ipykernel_3468\\359427503.py\", line 1, in <module>\n",
      "    edb.export_to_ipc2581(ipc2581_file_name, \"inch\")\n",
      "  File \"C:\\actions-runner\\_work\\pyedb\\pyedb\\.venv\\lib\\site-packages\\pyedb\\dotnet\\edb.py\", line 706, in export_to_ipc2581\n",
      "    ipc.load_ipc_model()\n",
      "  File \"C:\\actions-runner\\_work\\pyedb\\pyedb\\.venv\\lib\\site-packages\\pyedb\\ipc2581\\ipc2581.py\", line 63, in load_ipc_model\n",
      "    self._pedb.logger.info(\"Parsing Logical Nets...\")\n",
      "  File \"C:\\actions-runner\\_work\\pyedb\\pyedb\\.venv\\lib\\site-packages\\pyedb\\edb_logger.py\", line 346, in info\n",
      "    return self._log_on_handler(0, msg, *args, **kwargs)\n",
      "  File \"C:\\actions-runner\\_work\\pyedb\\pyedb\\.venv\\lib\\site-packages\\pyedb\\edb_logger.py\", line 293, in _log_on_handler\n",
      "    self._global.info(message_text, *args, **kwargs)\n",
      "Message: 'Parsing Logical Nets...'\n",
      "Arguments: ()\n",
      "--- Logging error ---\n",
      "Traceback (most recent call last):\n",
      "  File \"C:\\actions-runner\\_work\\_tool\\Python\\3.10.11\\x64\\lib\\logging\\handlers.py\", line 74, in emit\n",
      "    self.doRollover()\n",
      "  File \"C:\\actions-runner\\_work\\_tool\\Python\\3.10.11\\x64\\lib\\logging\\handlers.py\", line 179, in doRollover\n",
      "    self.rotate(self.baseFilename, dfn)\n",
      "  File \"C:\\actions-runner\\_work\\_tool\\Python\\3.10.11\\x64\\lib\\logging\\handlers.py\", line 115, in rotate\n",
      "    os.rename(source, dest)\n",
      "PermissionError: [WinError 32] The process cannot access the file because it is being used by another process: 'C:\\\\Users\\\\ansys\\\\AppData\\\\Local\\\\Temp\\\\pyedb_ansys.log' -> 'C:\\\\Users\\\\ansys\\\\AppData\\\\Local\\\\Temp\\\\pyedb_ansys.log.1'\n",
      "Call stack:\n",
      "  File \"C:\\actions-runner\\_work\\_tool\\Python\\3.10.11\\x64\\lib\\runpy.py\", line 196, in _run_module_as_main\n",
      "    return _run_code(code, main_globals, None,\n",
      "  File \"C:\\actions-runner\\_work\\_tool\\Python\\3.10.11\\x64\\lib\\runpy.py\", line 86, in _run_code\n",
      "    exec(code, run_globals)\n",
      "  File \"C:\\actions-runner\\_work\\pyedb\\pyedb\\.venv\\lib\\site-packages\\ipykernel_launcher.py\", line 18, in <module>\n",
      "    app.launch_new_instance()\n",
      "  File \"C:\\actions-runner\\_work\\pyedb\\pyedb\\.venv\\lib\\site-packages\\traitlets\\config\\application.py\", line 1075, in launch_instance\n",
      "    app.start()\n",
      "  File \"C:\\actions-runner\\_work\\pyedb\\pyedb\\.venv\\lib\\site-packages\\ipykernel\\kernelapp.py\", line 739, in start\n",
      "    self.io_loop.start()\n",
      "  File \"C:\\actions-runner\\_work\\pyedb\\pyedb\\.venv\\lib\\site-packages\\tornado\\platform\\asyncio.py\", line 205, in start\n",
      "    self.asyncio_loop.run_forever()\n",
      "  File \"C:\\actions-runner\\_work\\_tool\\Python\\3.10.11\\x64\\lib\\asyncio\\base_events.py\", line 603, in run_forever\n",
      "    self._run_once()\n",
      "  File \"C:\\actions-runner\\_work\\_tool\\Python\\3.10.11\\x64\\lib\\asyncio\\base_events.py\", line 1909, in _run_once\n",
      "    handle._run()\n",
      "  File \"C:\\actions-runner\\_work\\_tool\\Python\\3.10.11\\x64\\lib\\asyncio\\events.py\", line 80, in _run\n",
      "    self._context.run(self._callback, *self._args)\n",
      "  File \"C:\\actions-runner\\_work\\pyedb\\pyedb\\.venv\\lib\\site-packages\\ipykernel\\kernelbase.py\", line 545, in dispatch_queue\n",
      "    await self.process_one()\n",
      "  File \"C:\\actions-runner\\_work\\pyedb\\pyedb\\.venv\\lib\\site-packages\\ipykernel\\kernelbase.py\", line 534, in process_one\n",
      "    await dispatch(*args)\n",
      "  File \"C:\\actions-runner\\_work\\pyedb\\pyedb\\.venv\\lib\\site-packages\\ipykernel\\kernelbase.py\", line 437, in dispatch_shell\n",
      "    await result\n",
      "  File \"C:\\actions-runner\\_work\\pyedb\\pyedb\\.venv\\lib\\site-packages\\ipykernel\\ipkernel.py\", line 362, in execute_request\n",
      "    await super().execute_request(stream, ident, parent)\n",
      "  File \"C:\\actions-runner\\_work\\pyedb\\pyedb\\.venv\\lib\\site-packages\\ipykernel\\kernelbase.py\", line 778, in execute_request\n",
      "    reply_content = await reply_content\n",
      "  File \"C:\\actions-runner\\_work\\pyedb\\pyedb\\.venv\\lib\\site-packages\\ipykernel\\ipkernel.py\", line 449, in do_execute\n",
      "    res = shell.run_cell(\n",
      "  File \"C:\\actions-runner\\_work\\pyedb\\pyedb\\.venv\\lib\\site-packages\\ipykernel\\zmqshell.py\", line 549, in run_cell\n",
      "    return super().run_cell(*args, **kwargs)\n",
      "  File \"C:\\actions-runner\\_work\\pyedb\\pyedb\\.venv\\lib\\site-packages\\IPython\\core\\interactiveshell.py\", line 3075, in run_cell\n",
      "    result = self._run_cell(\n",
      "  File \"C:\\actions-runner\\_work\\pyedb\\pyedb\\.venv\\lib\\site-packages\\IPython\\core\\interactiveshell.py\", line 3130, in _run_cell\n",
      "    result = runner(coro)\n",
      "  File \"C:\\actions-runner\\_work\\pyedb\\pyedb\\.venv\\lib\\site-packages\\IPython\\core\\async_helpers.py\", line 128, in _pseudo_sync_runner\n",
      "    coro.send(None)\n",
      "  File \"C:\\actions-runner\\_work\\pyedb\\pyedb\\.venv\\lib\\site-packages\\IPython\\core\\interactiveshell.py\", line 3334, in run_cell_async\n",
      "    has_raised = await self.run_ast_nodes(code_ast.body, cell_name,\n",
      "  File \"C:\\actions-runner\\_work\\pyedb\\pyedb\\.venv\\lib\\site-packages\\IPython\\core\\interactiveshell.py\", line 3517, in run_ast_nodes\n",
      "    if await self.run_code(code, result, async_=asy):\n",
      "  File \"C:\\actions-runner\\_work\\pyedb\\pyedb\\.venv\\lib\\site-packages\\IPython\\core\\interactiveshell.py\", line 3577, in run_code\n",
      "    exec(code_obj, self.user_global_ns, self.user_ns)\n",
      "  File \"C:\\Users\\ansys\\AppData\\Local\\Temp\\ipykernel_3468\\359427503.py\", line 1, in <module>\n",
      "    edb.export_to_ipc2581(ipc2581_file_name, \"inch\")\n",
      "  File \"C:\\actions-runner\\_work\\pyedb\\pyedb\\.venv\\lib\\site-packages\\pyedb\\dotnet\\edb.py\", line 706, in export_to_ipc2581\n",
      "    ipc.load_ipc_model()\n",
      "  File \"C:\\actions-runner\\_work\\pyedb\\pyedb\\.venv\\lib\\site-packages\\pyedb\\ipc2581\\ipc2581.py\", line 65, in load_ipc_model\n",
      "    self._pedb.logger.info(\"Parsing Layout Primitives...\")\n",
      "  File \"C:\\actions-runner\\_work\\pyedb\\pyedb\\.venv\\lib\\site-packages\\pyedb\\edb_logger.py\", line 346, in info\n",
      "    return self._log_on_handler(0, msg, *args, **kwargs)\n",
      "  File \"C:\\actions-runner\\_work\\pyedb\\pyedb\\.venv\\lib\\site-packages\\pyedb\\edb_logger.py\", line 293, in _log_on_handler\n",
      "    self._global.info(message_text, *args, **kwargs)\n",
      "Message: 'Parsing Layout Primitives...'\n",
      "Arguments: ()\n"
     ]
    },
    {
     "name": "stdout",
     "output_type": "stream",
     "text": [
      "PyEDB INFO: Parsing Drills...\n"
     ]
    },
    {
     "name": "stderr",
     "output_type": "stream",
     "text": [
      "--- Logging error ---\n",
      "Traceback (most recent call last):\n",
      "  File \"C:\\actions-runner\\_work\\_tool\\Python\\3.10.11\\x64\\lib\\logging\\handlers.py\", line 74, in emit\n",
      "    self.doRollover()\n",
      "  File \"C:\\actions-runner\\_work\\_tool\\Python\\3.10.11\\x64\\lib\\logging\\handlers.py\", line 179, in doRollover\n",
      "    self.rotate(self.baseFilename, dfn)\n",
      "  File \"C:\\actions-runner\\_work\\_tool\\Python\\3.10.11\\x64\\lib\\logging\\handlers.py\", line 115, in rotate\n",
      "    os.rename(source, dest)\n",
      "PermissionError: [WinError 32] The process cannot access the file because it is being used by another process: 'C:\\\\Users\\\\ansys\\\\AppData\\\\Local\\\\Temp\\\\pyedb_ansys.log' -> 'C:\\\\Users\\\\ansys\\\\AppData\\\\Local\\\\Temp\\\\pyedb_ansys.log.1'\n",
      "Call stack:\n",
      "  File \"C:\\actions-runner\\_work\\_tool\\Python\\3.10.11\\x64\\lib\\runpy.py\", line 196, in _run_module_as_main\n",
      "    return _run_code(code, main_globals, None,\n",
      "  File \"C:\\actions-runner\\_work\\_tool\\Python\\3.10.11\\x64\\lib\\runpy.py\", line 86, in _run_code\n",
      "    exec(code, run_globals)\n",
      "  File \"C:\\actions-runner\\_work\\pyedb\\pyedb\\.venv\\lib\\site-packages\\ipykernel_launcher.py\", line 18, in <module>\n",
      "    app.launch_new_instance()\n",
      "  File \"C:\\actions-runner\\_work\\pyedb\\pyedb\\.venv\\lib\\site-packages\\traitlets\\config\\application.py\", line 1075, in launch_instance\n",
      "    app.start()\n",
      "  File \"C:\\actions-runner\\_work\\pyedb\\pyedb\\.venv\\lib\\site-packages\\ipykernel\\kernelapp.py\", line 739, in start\n",
      "    self.io_loop.start()\n",
      "  File \"C:\\actions-runner\\_work\\pyedb\\pyedb\\.venv\\lib\\site-packages\\tornado\\platform\\asyncio.py\", line 205, in start\n",
      "    self.asyncio_loop.run_forever()\n",
      "  File \"C:\\actions-runner\\_work\\_tool\\Python\\3.10.11\\x64\\lib\\asyncio\\base_events.py\", line 603, in run_forever\n",
      "    self._run_once()\n",
      "  File \"C:\\actions-runner\\_work\\_tool\\Python\\3.10.11\\x64\\lib\\asyncio\\base_events.py\", line 1909, in _run_once\n",
      "    handle._run()\n",
      "  File \"C:\\actions-runner\\_work\\_tool\\Python\\3.10.11\\x64\\lib\\asyncio\\events.py\", line 80, in _run\n",
      "    self._context.run(self._callback, *self._args)\n",
      "  File \"C:\\actions-runner\\_work\\pyedb\\pyedb\\.venv\\lib\\site-packages\\ipykernel\\kernelbase.py\", line 545, in dispatch_queue\n",
      "    await self.process_one()\n",
      "  File \"C:\\actions-runner\\_work\\pyedb\\pyedb\\.venv\\lib\\site-packages\\ipykernel\\kernelbase.py\", line 534, in process_one\n",
      "    await dispatch(*args)\n",
      "  File \"C:\\actions-runner\\_work\\pyedb\\pyedb\\.venv\\lib\\site-packages\\ipykernel\\kernelbase.py\", line 437, in dispatch_shell\n",
      "    await result\n",
      "  File \"C:\\actions-runner\\_work\\pyedb\\pyedb\\.venv\\lib\\site-packages\\ipykernel\\ipkernel.py\", line 362, in execute_request\n",
      "    await super().execute_request(stream, ident, parent)\n",
      "  File \"C:\\actions-runner\\_work\\pyedb\\pyedb\\.venv\\lib\\site-packages\\ipykernel\\kernelbase.py\", line 778, in execute_request\n",
      "    reply_content = await reply_content\n",
      "  File \"C:\\actions-runner\\_work\\pyedb\\pyedb\\.venv\\lib\\site-packages\\ipykernel\\ipkernel.py\", line 449, in do_execute\n",
      "    res = shell.run_cell(\n",
      "  File \"C:\\actions-runner\\_work\\pyedb\\pyedb\\.venv\\lib\\site-packages\\ipykernel\\zmqshell.py\", line 549, in run_cell\n",
      "    return super().run_cell(*args, **kwargs)\n",
      "  File \"C:\\actions-runner\\_work\\pyedb\\pyedb\\.venv\\lib\\site-packages\\IPython\\core\\interactiveshell.py\", line 3075, in run_cell\n",
      "    result = self._run_cell(\n",
      "  File \"C:\\actions-runner\\_work\\pyedb\\pyedb\\.venv\\lib\\site-packages\\IPython\\core\\interactiveshell.py\", line 3130, in _run_cell\n",
      "    result = runner(coro)\n",
      "  File \"C:\\actions-runner\\_work\\pyedb\\pyedb\\.venv\\lib\\site-packages\\IPython\\core\\async_helpers.py\", line 128, in _pseudo_sync_runner\n",
      "    coro.send(None)\n",
      "  File \"C:\\actions-runner\\_work\\pyedb\\pyedb\\.venv\\lib\\site-packages\\IPython\\core\\interactiveshell.py\", line 3334, in run_cell_async\n",
      "    has_raised = await self.run_ast_nodes(code_ast.body, cell_name,\n",
      "  File \"C:\\actions-runner\\_work\\pyedb\\pyedb\\.venv\\lib\\site-packages\\IPython\\core\\interactiveshell.py\", line 3517, in run_ast_nodes\n",
      "    if await self.run_code(code, result, async_=asy):\n",
      "  File \"C:\\actions-runner\\_work\\pyedb\\pyedb\\.venv\\lib\\site-packages\\IPython\\core\\interactiveshell.py\", line 3577, in run_code\n",
      "    exec(code_obj, self.user_global_ns, self.user_ns)\n",
      "  File \"C:\\Users\\ansys\\AppData\\Local\\Temp\\ipykernel_3468\\359427503.py\", line 1, in <module>\n",
      "    edb.export_to_ipc2581(ipc2581_file_name, \"inch\")\n",
      "  File \"C:\\actions-runner\\_work\\pyedb\\pyedb\\.venv\\lib\\site-packages\\pyedb\\dotnet\\edb.py\", line 706, in export_to_ipc2581\n",
      "    ipc.load_ipc_model()\n",
      "  File \"C:\\actions-runner\\_work\\pyedb\\pyedb\\.venv\\lib\\site-packages\\pyedb\\ipc2581\\ipc2581.py\", line 67, in load_ipc_model\n",
      "    self._pedb.logger.info(\"Parsing Drills...\")\n",
      "  File \"C:\\actions-runner\\_work\\pyedb\\pyedb\\.venv\\lib\\site-packages\\pyedb\\edb_logger.py\", line 346, in info\n",
      "    return self._log_on_handler(0, msg, *args, **kwargs)\n",
      "  File \"C:\\actions-runner\\_work\\pyedb\\pyedb\\.venv\\lib\\site-packages\\pyedb\\edb_logger.py\", line 293, in _log_on_handler\n",
      "    self._global.info(message_text, *args, **kwargs)\n",
      "Message: 'Parsing Drills...'\n",
      "Arguments: ()\n"
     ]
    },
    {
     "name": "stdout",
     "output_type": "stream",
     "text": [
      "PyEDB INFO: Parsing EDB Completed!\n"
     ]
    },
    {
     "name": "stdout",
     "output_type": "stream",
     "text": [
      "PyEDB INFO: Export IPC 2581 completed. Elapsed time: 0m 4sec\n"
     ]
    },
    {
     "name": "stdout",
     "output_type": "stream",
     "text": [
      "PyEDB INFO: File saved as C:\\Users\\ansys\\AppData\\Local\\Temp\\tmpqjhwgcrt.ansys\\Ansys_Hsd.xml\n"
     ]
    },
    {
     "name": "stdout",
     "output_type": "stream",
     "text": [
      "IPC2581 File has been saved to C:\\Users\\ansys\\AppData\\Local\\Temp\\tmpqjhwgcrt.ansys\\Ansys_Hsd.xml\n"
     ]
    },
    {
     "name": "stderr",
     "output_type": "stream",
     "text": [
      "--- Logging error ---\n",
      "Traceback (most recent call last):\n",
      "  File \"C:\\actions-runner\\_work\\_tool\\Python\\3.10.11\\x64\\lib\\logging\\handlers.py\", line 74, in emit\n",
      "    self.doRollover()\n",
      "  File \"C:\\actions-runner\\_work\\_tool\\Python\\3.10.11\\x64\\lib\\logging\\handlers.py\", line 179, in doRollover\n",
      "    self.rotate(self.baseFilename, dfn)\n",
      "  File \"C:\\actions-runner\\_work\\_tool\\Python\\3.10.11\\x64\\lib\\logging\\handlers.py\", line 115, in rotate\n",
      "    os.rename(source, dest)\n",
      "PermissionError: [WinError 32] The process cannot access the file because it is being used by another process: 'C:\\\\Users\\\\ansys\\\\AppData\\\\Local\\\\Temp\\\\pyedb_ansys.log' -> 'C:\\\\Users\\\\ansys\\\\AppData\\\\Local\\\\Temp\\\\pyedb_ansys.log.1'\n",
      "Call stack:\n",
      "  File \"C:\\actions-runner\\_work\\_tool\\Python\\3.10.11\\x64\\lib\\runpy.py\", line 196, in _run_module_as_main\n",
      "    return _run_code(code, main_globals, None,\n",
      "  File \"C:\\actions-runner\\_work\\_tool\\Python\\3.10.11\\x64\\lib\\runpy.py\", line 86, in _run_code\n",
      "    exec(code, run_globals)\n",
      "  File \"C:\\actions-runner\\_work\\pyedb\\pyedb\\.venv\\lib\\site-packages\\ipykernel_launcher.py\", line 18, in <module>\n",
      "    app.launch_new_instance()\n",
      "  File \"C:\\actions-runner\\_work\\pyedb\\pyedb\\.venv\\lib\\site-packages\\traitlets\\config\\application.py\", line 1075, in launch_instance\n",
      "    app.start()\n",
      "  File \"C:\\actions-runner\\_work\\pyedb\\pyedb\\.venv\\lib\\site-packages\\ipykernel\\kernelapp.py\", line 739, in start\n",
      "    self.io_loop.start()\n",
      "  File \"C:\\actions-runner\\_work\\pyedb\\pyedb\\.venv\\lib\\site-packages\\tornado\\platform\\asyncio.py\", line 205, in start\n",
      "    self.asyncio_loop.run_forever()\n",
      "  File \"C:\\actions-runner\\_work\\_tool\\Python\\3.10.11\\x64\\lib\\asyncio\\base_events.py\", line 603, in run_forever\n",
      "    self._run_once()\n",
      "  File \"C:\\actions-runner\\_work\\_tool\\Python\\3.10.11\\x64\\lib\\asyncio\\base_events.py\", line 1909, in _run_once\n",
      "    handle._run()\n",
      "  File \"C:\\actions-runner\\_work\\_tool\\Python\\3.10.11\\x64\\lib\\asyncio\\events.py\", line 80, in _run\n",
      "    self._context.run(self._callback, *self._args)\n",
      "  File \"C:\\actions-runner\\_work\\pyedb\\pyedb\\.venv\\lib\\site-packages\\ipykernel\\kernelbase.py\", line 545, in dispatch_queue\n",
      "    await self.process_one()\n",
      "  File \"C:\\actions-runner\\_work\\pyedb\\pyedb\\.venv\\lib\\site-packages\\ipykernel\\kernelbase.py\", line 534, in process_one\n",
      "    await dispatch(*args)\n",
      "  File \"C:\\actions-runner\\_work\\pyedb\\pyedb\\.venv\\lib\\site-packages\\ipykernel\\kernelbase.py\", line 437, in dispatch_shell\n",
      "    await result\n",
      "  File \"C:\\actions-runner\\_work\\pyedb\\pyedb\\.venv\\lib\\site-packages\\ipykernel\\ipkernel.py\", line 362, in execute_request\n",
      "    await super().execute_request(stream, ident, parent)\n",
      "  File \"C:\\actions-runner\\_work\\pyedb\\pyedb\\.venv\\lib\\site-packages\\ipykernel\\kernelbase.py\", line 778, in execute_request\n",
      "    reply_content = await reply_content\n",
      "  File \"C:\\actions-runner\\_work\\pyedb\\pyedb\\.venv\\lib\\site-packages\\ipykernel\\ipkernel.py\", line 449, in do_execute\n",
      "    res = shell.run_cell(\n",
      "  File \"C:\\actions-runner\\_work\\pyedb\\pyedb\\.venv\\lib\\site-packages\\ipykernel\\zmqshell.py\", line 549, in run_cell\n",
      "    return super().run_cell(*args, **kwargs)\n",
      "  File \"C:\\actions-runner\\_work\\pyedb\\pyedb\\.venv\\lib\\site-packages\\IPython\\core\\interactiveshell.py\", line 3075, in run_cell\n",
      "    result = self._run_cell(\n",
      "  File \"C:\\actions-runner\\_work\\pyedb\\pyedb\\.venv\\lib\\site-packages\\IPython\\core\\interactiveshell.py\", line 3130, in _run_cell\n",
      "    result = runner(coro)\n",
      "  File \"C:\\actions-runner\\_work\\pyedb\\pyedb\\.venv\\lib\\site-packages\\IPython\\core\\async_helpers.py\", line 128, in _pseudo_sync_runner\n",
      "    coro.send(None)\n",
      "  File \"C:\\actions-runner\\_work\\pyedb\\pyedb\\.venv\\lib\\site-packages\\IPython\\core\\interactiveshell.py\", line 3334, in run_cell_async\n",
      "    has_raised = await self.run_ast_nodes(code_ast.body, cell_name,\n",
      "  File \"C:\\actions-runner\\_work\\pyedb\\pyedb\\.venv\\lib\\site-packages\\IPython\\core\\interactiveshell.py\", line 3517, in run_ast_nodes\n",
      "    if await self.run_code(code, result, async_=asy):\n",
      "  File \"C:\\actions-runner\\_work\\pyedb\\pyedb\\.venv\\lib\\site-packages\\IPython\\core\\interactiveshell.py\", line 3577, in run_code\n",
      "    exec(code_obj, self.user_global_ns, self.user_ns)\n",
      "  File \"C:\\Users\\ansys\\AppData\\Local\\Temp\\ipykernel_3468\\359427503.py\", line 1, in <module>\n",
      "    edb.export_to_ipc2581(ipc2581_file_name, \"inch\")\n",
      "  File \"C:\\actions-runner\\_work\\pyedb\\pyedb\\.venv\\lib\\site-packages\\pyedb\\dotnet\\edb.py\", line 706, in export_to_ipc2581\n",
      "    ipc.load_ipc_model()\n",
      "  File \"C:\\actions-runner\\_work\\pyedb\\pyedb\\.venv\\lib\\site-packages\\pyedb\\ipc2581\\ipc2581.py\", line 69, in load_ipc_model\n",
      "    self._pedb.logger.info(\"Parsing EDB Completed!\")\n",
      "  File \"C:\\actions-runner\\_work\\pyedb\\pyedb\\.venv\\lib\\site-packages\\pyedb\\edb_logger.py\", line 346, in info\n",
      "    return self._log_on_handler(0, msg, *args, **kwargs)\n",
      "  File \"C:\\actions-runner\\_work\\pyedb\\pyedb\\.venv\\lib\\site-packages\\pyedb\\edb_logger.py\", line 293, in _log_on_handler\n",
      "    self._global.info(message_text, *args, **kwargs)\n",
      "Message: 'Parsing EDB Completed!'\n",
      "Arguments: ()\n",
      "--- Logging error ---\n",
      "Traceback (most recent call last):\n",
      "  File \"C:\\actions-runner\\_work\\_tool\\Python\\3.10.11\\x64\\lib\\logging\\handlers.py\", line 74, in emit\n",
      "    self.doRollover()\n",
      "  File \"C:\\actions-runner\\_work\\_tool\\Python\\3.10.11\\x64\\lib\\logging\\handlers.py\", line 179, in doRollover\n",
      "    self.rotate(self.baseFilename, dfn)\n",
      "  File \"C:\\actions-runner\\_work\\_tool\\Python\\3.10.11\\x64\\lib\\logging\\handlers.py\", line 115, in rotate\n",
      "    os.rename(source, dest)\n",
      "PermissionError: [WinError 32] The process cannot access the file because it is being used by another process: 'C:\\\\Users\\\\ansys\\\\AppData\\\\Local\\\\Temp\\\\pyedb_ansys.log' -> 'C:\\\\Users\\\\ansys\\\\AppData\\\\Local\\\\Temp\\\\pyedb_ansys.log.1'\n",
      "Call stack:\n",
      "  File \"C:\\actions-runner\\_work\\_tool\\Python\\3.10.11\\x64\\lib\\runpy.py\", line 196, in _run_module_as_main\n",
      "    return _run_code(code, main_globals, None,\n",
      "  File \"C:\\actions-runner\\_work\\_tool\\Python\\3.10.11\\x64\\lib\\runpy.py\", line 86, in _run_code\n",
      "    exec(code, run_globals)\n",
      "  File \"C:\\actions-runner\\_work\\pyedb\\pyedb\\.venv\\lib\\site-packages\\ipykernel_launcher.py\", line 18, in <module>\n",
      "    app.launch_new_instance()\n",
      "  File \"C:\\actions-runner\\_work\\pyedb\\pyedb\\.venv\\lib\\site-packages\\traitlets\\config\\application.py\", line 1075, in launch_instance\n",
      "    app.start()\n",
      "  File \"C:\\actions-runner\\_work\\pyedb\\pyedb\\.venv\\lib\\site-packages\\ipykernel\\kernelapp.py\", line 739, in start\n",
      "    self.io_loop.start()\n",
      "  File \"C:\\actions-runner\\_work\\pyedb\\pyedb\\.venv\\lib\\site-packages\\tornado\\platform\\asyncio.py\", line 205, in start\n",
      "    self.asyncio_loop.run_forever()\n",
      "  File \"C:\\actions-runner\\_work\\_tool\\Python\\3.10.11\\x64\\lib\\asyncio\\base_events.py\", line 603, in run_forever\n",
      "    self._run_once()\n",
      "  File \"C:\\actions-runner\\_work\\_tool\\Python\\3.10.11\\x64\\lib\\asyncio\\base_events.py\", line 1909, in _run_once\n",
      "    handle._run()\n",
      "  File \"C:\\actions-runner\\_work\\_tool\\Python\\3.10.11\\x64\\lib\\asyncio\\events.py\", line 80, in _run\n",
      "    self._context.run(self._callback, *self._args)\n",
      "  File \"C:\\actions-runner\\_work\\pyedb\\pyedb\\.venv\\lib\\site-packages\\ipykernel\\kernelbase.py\", line 545, in dispatch_queue\n",
      "    await self.process_one()\n",
      "  File \"C:\\actions-runner\\_work\\pyedb\\pyedb\\.venv\\lib\\site-packages\\ipykernel\\kernelbase.py\", line 534, in process_one\n",
      "    await dispatch(*args)\n",
      "  File \"C:\\actions-runner\\_work\\pyedb\\pyedb\\.venv\\lib\\site-packages\\ipykernel\\kernelbase.py\", line 437, in dispatch_shell\n",
      "    await result\n",
      "  File \"C:\\actions-runner\\_work\\pyedb\\pyedb\\.venv\\lib\\site-packages\\ipykernel\\ipkernel.py\", line 362, in execute_request\n",
      "    await super().execute_request(stream, ident, parent)\n",
      "  File \"C:\\actions-runner\\_work\\pyedb\\pyedb\\.venv\\lib\\site-packages\\ipykernel\\kernelbase.py\", line 778, in execute_request\n",
      "    reply_content = await reply_content\n",
      "  File \"C:\\actions-runner\\_work\\pyedb\\pyedb\\.venv\\lib\\site-packages\\ipykernel\\ipkernel.py\", line 449, in do_execute\n",
      "    res = shell.run_cell(\n",
      "  File \"C:\\actions-runner\\_work\\pyedb\\pyedb\\.venv\\lib\\site-packages\\ipykernel\\zmqshell.py\", line 549, in run_cell\n",
      "    return super().run_cell(*args, **kwargs)\n",
      "  File \"C:\\actions-runner\\_work\\pyedb\\pyedb\\.venv\\lib\\site-packages\\IPython\\core\\interactiveshell.py\", line 3075, in run_cell\n",
      "    result = self._run_cell(\n",
      "  File \"C:\\actions-runner\\_work\\pyedb\\pyedb\\.venv\\lib\\site-packages\\IPython\\core\\interactiveshell.py\", line 3130, in _run_cell\n",
      "    result = runner(coro)\n",
      "  File \"C:\\actions-runner\\_work\\pyedb\\pyedb\\.venv\\lib\\site-packages\\IPython\\core\\async_helpers.py\", line 128, in _pseudo_sync_runner\n",
      "    coro.send(None)\n",
      "  File \"C:\\actions-runner\\_work\\pyedb\\pyedb\\.venv\\lib\\site-packages\\IPython\\core\\interactiveshell.py\", line 3334, in run_cell_async\n",
      "    has_raised = await self.run_ast_nodes(code_ast.body, cell_name,\n",
      "  File \"C:\\actions-runner\\_work\\pyedb\\pyedb\\.venv\\lib\\site-packages\\IPython\\core\\interactiveshell.py\", line 3517, in run_ast_nodes\n",
      "    if await self.run_code(code, result, async_=asy):\n",
      "  File \"C:\\actions-runner\\_work\\pyedb\\pyedb\\.venv\\lib\\site-packages\\IPython\\core\\interactiveshell.py\", line 3577, in run_code\n",
      "    exec(code_obj, self.user_global_ns, self.user_ns)\n",
      "  File \"C:\\Users\\ansys\\AppData\\Local\\Temp\\ipykernel_3468\\359427503.py\", line 1, in <module>\n",
      "    edb.export_to_ipc2581(ipc2581_file_name, \"inch\")\n",
      "  File \"C:\\actions-runner\\_work\\pyedb\\pyedb\\.venv\\lib\\site-packages\\pyedb\\dotnet\\edb.py\", line 711, in export_to_ipc2581\n",
      "    self.logger.info_timer(\"Export IPC 2581 completed.\", start)\n",
      "  File \"C:\\actions-runner\\_work\\pyedb\\pyedb\\.venv\\lib\\site-packages\\pyedb\\edb_logger.py\", line 372, in info_timer\n",
      "    return self._log_on_handler(0, msg, *args, **kwargs)\n",
      "  File \"C:\\actions-runner\\_work\\pyedb\\pyedb\\.venv\\lib\\site-packages\\pyedb\\edb_logger.py\", line 293, in _log_on_handler\n",
      "    self._global.info(message_text, *args, **kwargs)\n",
      "Message: 'Export IPC 2581 completed. Elapsed time: 0m 4sec'\n",
      "Arguments: ()\n",
      "--- Logging error ---\n",
      "Traceback (most recent call last):\n",
      "  File \"C:\\actions-runner\\_work\\_tool\\Python\\3.10.11\\x64\\lib\\logging\\handlers.py\", line 74, in emit\n",
      "    self.doRollover()\n",
      "  File \"C:\\actions-runner\\_work\\_tool\\Python\\3.10.11\\x64\\lib\\logging\\handlers.py\", line 179, in doRollover\n",
      "    self.rotate(self.baseFilename, dfn)\n",
      "  File \"C:\\actions-runner\\_work\\_tool\\Python\\3.10.11\\x64\\lib\\logging\\handlers.py\", line 115, in rotate\n",
      "    os.rename(source, dest)\n",
      "PermissionError: [WinError 32] The process cannot access the file because it is being used by another process: 'C:\\\\Users\\\\ansys\\\\AppData\\\\Local\\\\Temp\\\\pyedb_ansys.log' -> 'C:\\\\Users\\\\ansys\\\\AppData\\\\Local\\\\Temp\\\\pyedb_ansys.log.1'\n",
      "Call stack:\n",
      "  File \"C:\\actions-runner\\_work\\_tool\\Python\\3.10.11\\x64\\lib\\runpy.py\", line 196, in _run_module_as_main\n",
      "    return _run_code(code, main_globals, None,\n",
      "  File \"C:\\actions-runner\\_work\\_tool\\Python\\3.10.11\\x64\\lib\\runpy.py\", line 86, in _run_code\n",
      "    exec(code, run_globals)\n",
      "  File \"C:\\actions-runner\\_work\\pyedb\\pyedb\\.venv\\lib\\site-packages\\ipykernel_launcher.py\", line 18, in <module>\n",
      "    app.launch_new_instance()\n",
      "  File \"C:\\actions-runner\\_work\\pyedb\\pyedb\\.venv\\lib\\site-packages\\traitlets\\config\\application.py\", line 1075, in launch_instance\n",
      "    app.start()\n",
      "  File \"C:\\actions-runner\\_work\\pyedb\\pyedb\\.venv\\lib\\site-packages\\ipykernel\\kernelapp.py\", line 739, in start\n",
      "    self.io_loop.start()\n",
      "  File \"C:\\actions-runner\\_work\\pyedb\\pyedb\\.venv\\lib\\site-packages\\tornado\\platform\\asyncio.py\", line 205, in start\n",
      "    self.asyncio_loop.run_forever()\n",
      "  File \"C:\\actions-runner\\_work\\_tool\\Python\\3.10.11\\x64\\lib\\asyncio\\base_events.py\", line 603, in run_forever\n",
      "    self._run_once()\n",
      "  File \"C:\\actions-runner\\_work\\_tool\\Python\\3.10.11\\x64\\lib\\asyncio\\base_events.py\", line 1909, in _run_once\n",
      "    handle._run()\n",
      "  File \"C:\\actions-runner\\_work\\_tool\\Python\\3.10.11\\x64\\lib\\asyncio\\events.py\", line 80, in _run\n",
      "    self._context.run(self._callback, *self._args)\n",
      "  File \"C:\\actions-runner\\_work\\pyedb\\pyedb\\.venv\\lib\\site-packages\\ipykernel\\kernelbase.py\", line 545, in dispatch_queue\n",
      "    await self.process_one()\n",
      "  File \"C:\\actions-runner\\_work\\pyedb\\pyedb\\.venv\\lib\\site-packages\\ipykernel\\kernelbase.py\", line 534, in process_one\n",
      "    await dispatch(*args)\n",
      "  File \"C:\\actions-runner\\_work\\pyedb\\pyedb\\.venv\\lib\\site-packages\\ipykernel\\kernelbase.py\", line 437, in dispatch_shell\n",
      "    await result\n",
      "  File \"C:\\actions-runner\\_work\\pyedb\\pyedb\\.venv\\lib\\site-packages\\ipykernel\\ipkernel.py\", line 362, in execute_request\n",
      "    await super().execute_request(stream, ident, parent)\n",
      "  File \"C:\\actions-runner\\_work\\pyedb\\pyedb\\.venv\\lib\\site-packages\\ipykernel\\kernelbase.py\", line 778, in execute_request\n",
      "    reply_content = await reply_content\n",
      "  File \"C:\\actions-runner\\_work\\pyedb\\pyedb\\.venv\\lib\\site-packages\\ipykernel\\ipkernel.py\", line 449, in do_execute\n",
      "    res = shell.run_cell(\n",
      "  File \"C:\\actions-runner\\_work\\pyedb\\pyedb\\.venv\\lib\\site-packages\\ipykernel\\zmqshell.py\", line 549, in run_cell\n",
      "    return super().run_cell(*args, **kwargs)\n",
      "  File \"C:\\actions-runner\\_work\\pyedb\\pyedb\\.venv\\lib\\site-packages\\IPython\\core\\interactiveshell.py\", line 3075, in run_cell\n",
      "    result = self._run_cell(\n",
      "  File \"C:\\actions-runner\\_work\\pyedb\\pyedb\\.venv\\lib\\site-packages\\IPython\\core\\interactiveshell.py\", line 3130, in _run_cell\n",
      "    result = runner(coro)\n",
      "  File \"C:\\actions-runner\\_work\\pyedb\\pyedb\\.venv\\lib\\site-packages\\IPython\\core\\async_helpers.py\", line 128, in _pseudo_sync_runner\n",
      "    coro.send(None)\n",
      "  File \"C:\\actions-runner\\_work\\pyedb\\pyedb\\.venv\\lib\\site-packages\\IPython\\core\\interactiveshell.py\", line 3334, in run_cell_async\n",
      "    has_raised = await self.run_ast_nodes(code_ast.body, cell_name,\n",
      "  File \"C:\\actions-runner\\_work\\pyedb\\pyedb\\.venv\\lib\\site-packages\\IPython\\core\\interactiveshell.py\", line 3517, in run_ast_nodes\n",
      "    if await self.run_code(code, result, async_=asy):\n",
      "  File \"C:\\actions-runner\\_work\\pyedb\\pyedb\\.venv\\lib\\site-packages\\IPython\\core\\interactiveshell.py\", line 3577, in run_code\n",
      "    exec(code_obj, self.user_global_ns, self.user_ns)\n",
      "  File \"C:\\Users\\ansys\\AppData\\Local\\Temp\\ipykernel_3468\\359427503.py\", line 1, in <module>\n",
      "    edb.export_to_ipc2581(ipc2581_file_name, \"inch\")\n",
      "  File \"C:\\actions-runner\\_work\\pyedb\\pyedb\\.venv\\lib\\site-packages\\pyedb\\dotnet\\edb.py\", line 712, in export_to_ipc2581\n",
      "    self.logger.info(\"File saved as %s\", ipc_path)\n",
      "  File \"C:\\actions-runner\\_work\\pyedb\\pyedb\\.venv\\lib\\site-packages\\pyedb\\edb_logger.py\", line 346, in info\n",
      "    return self._log_on_handler(0, msg, *args, **kwargs)\n",
      "  File \"C:\\actions-runner\\_work\\pyedb\\pyedb\\.venv\\lib\\site-packages\\pyedb\\edb_logger.py\", line 293, in _log_on_handler\n",
      "    self._global.info(message_text, *args, **kwargs)\n",
      "Message: 'File saved as %s'\n",
      "Arguments: ('C:\\\\Users\\\\ansys\\\\AppData\\\\Local\\\\Temp\\\\tmpqjhwgcrt.ansys\\\\Ansys_Hsd.xml',)\n"
     ]
    }
   ],
   "source": [
    "edb.export_to_ipc2581(ipc2581_file_name, \"inch\")\n",
    "print(\"IPC2581 File has been saved to {}\".format(ipc2581_file_name))"
   ]
  },
  {
   "cell_type": "markdown",
   "id": "561b4076",
   "metadata": {},
   "source": [
    "## Close EDB"
   ]
  },
  {
   "cell_type": "code",
   "execution_count": 7,
   "id": "70097c1d",
   "metadata": {
    "execution": {
     "iopub.execute_input": "2024-09-17T08:08:09.529748Z",
     "iopub.status.busy": "2024-09-17T08:08:09.529748Z",
     "iopub.status.idle": "2024-09-17T08:08:09.686001Z",
     "shell.execute_reply": "2024-09-17T08:08:09.686001Z"
    }
   },
   "outputs": [
    {
     "name": "stdout",
     "output_type": "stream",
     "text": [
      "PyEDB INFO: EDB file release time: 0.00ms\n"
     ]
    },
    {
     "name": "stderr",
     "output_type": "stream",
     "text": [
      "--- Logging error ---\n",
      "Traceback (most recent call last):\n",
      "  File \"C:\\actions-runner\\_work\\_tool\\Python\\3.10.11\\x64\\lib\\logging\\handlers.py\", line 74, in emit\n",
      "    self.doRollover()\n",
      "  File \"C:\\actions-runner\\_work\\_tool\\Python\\3.10.11\\x64\\lib\\logging\\handlers.py\", line 179, in doRollover\n",
      "    self.rotate(self.baseFilename, dfn)\n",
      "  File \"C:\\actions-runner\\_work\\_tool\\Python\\3.10.11\\x64\\lib\\logging\\handlers.py\", line 115, in rotate\n",
      "    os.rename(source, dest)\n",
      "PermissionError: [WinError 32] The process cannot access the file because it is being used by another process: 'C:\\\\Users\\\\ansys\\\\AppData\\\\Local\\\\Temp\\\\pyedb_ansys.log' -> 'C:\\\\Users\\\\ansys\\\\AppData\\\\Local\\\\Temp\\\\pyedb_ansys.log.1'\n",
      "Call stack:\n",
      "  File \"C:\\actions-runner\\_work\\_tool\\Python\\3.10.11\\x64\\lib\\runpy.py\", line 196, in _run_module_as_main\n",
      "    return _run_code(code, main_globals, None,\n",
      "  File \"C:\\actions-runner\\_work\\_tool\\Python\\3.10.11\\x64\\lib\\runpy.py\", line 86, in _run_code\n",
      "    exec(code, run_globals)\n",
      "  File \"C:\\actions-runner\\_work\\pyedb\\pyedb\\.venv\\lib\\site-packages\\ipykernel_launcher.py\", line 18, in <module>\n",
      "    app.launch_new_instance()\n",
      "  File \"C:\\actions-runner\\_work\\pyedb\\pyedb\\.venv\\lib\\site-packages\\traitlets\\config\\application.py\", line 1075, in launch_instance\n",
      "    app.start()\n",
      "  File \"C:\\actions-runner\\_work\\pyedb\\pyedb\\.venv\\lib\\site-packages\\ipykernel\\kernelapp.py\", line 739, in start\n",
      "    self.io_loop.start()\n",
      "  File \"C:\\actions-runner\\_work\\pyedb\\pyedb\\.venv\\lib\\site-packages\\tornado\\platform\\asyncio.py\", line 205, in start\n",
      "    self.asyncio_loop.run_forever()\n",
      "  File \"C:\\actions-runner\\_work\\_tool\\Python\\3.10.11\\x64\\lib\\asyncio\\base_events.py\", line 603, in run_forever\n",
      "    self._run_once()\n",
      "  File \"C:\\actions-runner\\_work\\_tool\\Python\\3.10.11\\x64\\lib\\asyncio\\base_events.py\", line 1909, in _run_once\n",
      "    handle._run()\n",
      "  File \"C:\\actions-runner\\_work\\_tool\\Python\\3.10.11\\x64\\lib\\asyncio\\events.py\", line 80, in _run\n",
      "    self._context.run(self._callback, *self._args)\n",
      "  File \"C:\\actions-runner\\_work\\pyedb\\pyedb\\.venv\\lib\\site-packages\\ipykernel\\kernelbase.py\", line 545, in dispatch_queue\n",
      "    await self.process_one()\n",
      "  File \"C:\\actions-runner\\_work\\pyedb\\pyedb\\.venv\\lib\\site-packages\\ipykernel\\kernelbase.py\", line 534, in process_one\n",
      "    await dispatch(*args)\n",
      "  File \"C:\\actions-runner\\_work\\pyedb\\pyedb\\.venv\\lib\\site-packages\\ipykernel\\kernelbase.py\", line 437, in dispatch_shell\n",
      "    await result\n",
      "  File \"C:\\actions-runner\\_work\\pyedb\\pyedb\\.venv\\lib\\site-packages\\ipykernel\\ipkernel.py\", line 362, in execute_request\n",
      "    await super().execute_request(stream, ident, parent)\n",
      "  File \"C:\\actions-runner\\_work\\pyedb\\pyedb\\.venv\\lib\\site-packages\\ipykernel\\kernelbase.py\", line 778, in execute_request\n",
      "    reply_content = await reply_content\n",
      "  File \"C:\\actions-runner\\_work\\pyedb\\pyedb\\.venv\\lib\\site-packages\\ipykernel\\ipkernel.py\", line 449, in do_execute\n",
      "    res = shell.run_cell(\n",
      "  File \"C:\\actions-runner\\_work\\pyedb\\pyedb\\.venv\\lib\\site-packages\\ipykernel\\zmqshell.py\", line 549, in run_cell\n",
      "    return super().run_cell(*args, **kwargs)\n",
      "  File \"C:\\actions-runner\\_work\\pyedb\\pyedb\\.venv\\lib\\site-packages\\IPython\\core\\interactiveshell.py\", line 3075, in run_cell\n",
      "    result = self._run_cell(\n",
      "  File \"C:\\actions-runner\\_work\\pyedb\\pyedb\\.venv\\lib\\site-packages\\IPython\\core\\interactiveshell.py\", line 3130, in _run_cell\n",
      "    result = runner(coro)\n",
      "  File \"C:\\actions-runner\\_work\\pyedb\\pyedb\\.venv\\lib\\site-packages\\IPython\\core\\async_helpers.py\", line 128, in _pseudo_sync_runner\n",
      "    coro.send(None)\n",
      "  File \"C:\\actions-runner\\_work\\pyedb\\pyedb\\.venv\\lib\\site-packages\\IPython\\core\\interactiveshell.py\", line 3334, in run_cell_async\n",
      "    has_raised = await self.run_ast_nodes(code_ast.body, cell_name,\n",
      "  File \"C:\\actions-runner\\_work\\pyedb\\pyedb\\.venv\\lib\\site-packages\\IPython\\core\\interactiveshell.py\", line 3517, in run_ast_nodes\n",
      "    if await self.run_code(code, result, async_=asy):\n",
      "  File \"C:\\actions-runner\\_work\\pyedb\\pyedb\\.venv\\lib\\site-packages\\IPython\\core\\interactiveshell.py\", line 3577, in run_code\n",
      "    exec(code_obj, self.user_global_ns, self.user_ns)\n",
      "  File \"C:\\Users\\ansys\\AppData\\Local\\Temp\\ipykernel_3468\\3588321624.py\", line 1, in <module>\n",
      "    edb.close_edb()\n",
      "  File \"C:\\actions-runner\\_work\\pyedb\\pyedb\\.venv\\lib\\site-packages\\pyedb\\dotnet\\edb.py\", line 1353, in close_edb\n",
      "    self.logger.info(\"EDB file release time: {0:.2f}ms\".format(elapsed_time * 1000.0))\n",
      "  File \"C:\\actions-runner\\_work\\pyedb\\pyedb\\.venv\\lib\\site-packages\\pyedb\\edb_logger.py\", line 346, in info\n",
      "    return self._log_on_handler(0, msg, *args, **kwargs)\n",
      "  File \"C:\\actions-runner\\_work\\pyedb\\pyedb\\.venv\\lib\\site-packages\\pyedb\\edb_logger.py\", line 293, in _log_on_handler\n",
      "    self._global.info(message_text, *args, **kwargs)\n",
      "Message: 'EDB file release time: 0.00ms'\n",
      "Arguments: ()\n"
     ]
    },
    {
     "data": {
      "text/plain": [
       "True"
      ]
     },
     "execution_count": 7,
     "metadata": {},
     "output_type": "execute_result"
    }
   ],
   "source": [
    "edb.close_edb()"
   ]
  },
  {
   "cell_type": "markdown",
   "id": "d360b948",
   "metadata": {},
   "source": [
    "## Clean up the temporary directory"
   ]
  },
  {
   "cell_type": "code",
   "execution_count": 8,
   "id": "691d7129",
   "metadata": {
    "execution": {
     "iopub.execute_input": "2024-09-17T08:08:09.686001Z",
     "iopub.status.busy": "2024-09-17T08:08:09.686001Z",
     "iopub.status.idle": "2024-09-17T08:08:09.701677Z",
     "shell.execute_reply": "2024-09-17T08:08:09.701677Z"
    }
   },
   "outputs": [],
   "source": [
    "temp_dir.cleanup()"
   ]
  }
 ],
 "metadata": {
  "jupytext": {
   "cell_metadata_filter": "-all",
   "main_language": "python",
   "notebook_metadata_filter": "-all",
   "text_representation": {
    "extension": ".py",
    "format_name": "light"
   }
  },
  "language_info": {
   "codemirror_mode": {
    "name": "ipython",
    "version": 3
   },
   "file_extension": ".py",
   "mimetype": "text/x-python",
   "name": "python",
   "nbconvert_exporter": "python",
   "pygments_lexer": "ipython3",
   "version": "3.10.11"
  }
 },
 "nbformat": 4,
 "nbformat_minor": 5
}
