{
 "cells": [
  {
   "cell_type": "markdown",
   "id": "6b1d8bb9",
   "metadata": {},
   "source": [
    "# EDB: plot nets with Matplotlib\n",
    "\n",
    "This example shows how to use the ``Edb`` class to view nets, layers and\n",
    "via geometry directly in Python. The methods demonstrated in this example\n",
    "rely on\n",
    "[matplotlib](https://matplotlib.org/cheatsheets/_images/cheatsheets-1.png)."
   ]
  },
  {
   "cell_type": "markdown",
   "id": "87c88d20",
   "metadata": {},
   "source": [
    "## Perform required imports\n",
    "\n",
    "Perform required imports, which includes importing a section."
   ]
  },
  {
   "cell_type": "code",
   "execution_count": 1,
   "id": "cedf9aa1",
   "metadata": {
    "execution": {
     "iopub.execute_input": "2024-07-30T16:41:03.165353Z",
     "iopub.status.busy": "2024-07-30T16:41:03.165353Z",
     "iopub.status.idle": "2024-07-30T16:41:03.196599Z",
     "shell.execute_reply": "2024-07-30T16:41:03.196599Z"
    }
   },
   "outputs": [],
   "source": [
    "import tempfile\n",
    "\n",
    "import pyedb\n",
    "from pyedb.misc.downloads import download_file\n"
   ]
  },
  {
   "cell_type": "markdown",
   "id": "e39ab774",
   "metadata": {},
   "source": [
    "## Download the EDB and copy it into the temporary folder."
   ]
  },
  {
   "cell_type": "code",
   "execution_count": 2,
   "id": "699eb5d3",
   "metadata": {
    "execution": {
     "iopub.execute_input": "2024-07-30T16:41:03.196599Z",
     "iopub.status.busy": "2024-07-30T16:41:03.196599Z",
     "iopub.status.idle": "2024-07-30T16:41:04.009059Z",
     "shell.execute_reply": "2024-07-30T16:41:04.009059Z"
    }
   },
   "outputs": [],
   "source": [
    "temp_dir = tempfile.TemporaryDirectory(suffix=\".ansys\")\n",
    "targetfolder = download_file(\"edb/ANSYS-HSD_V1.aedb\", destination=temp_dir.name)"
   ]
  },
  {
   "cell_type": "markdown",
   "id": "7b113654",
   "metadata": {},
   "source": [
    "## Create an instance of the Electronics Database using the `pyedb.Edb` class.\n",
    "\n",
    "> Note that units are SI."
   ]
  },
  {
   "cell_type": "code",
   "execution_count": 3,
   "id": "6e05c02b",
   "metadata": {
    "execution": {
     "iopub.execute_input": "2024-07-30T16:41:04.009059Z",
     "iopub.status.busy": "2024-07-30T16:41:04.009059Z",
     "iopub.status.idle": "2024-07-30T16:41:16.730205Z",
     "shell.execute_reply": "2024-07-30T16:41:16.730205Z"
    }
   },
   "outputs": [
    {
     "name": "stdout",
     "output_type": "stream",
     "text": [
      "EDB version: 2024.1\n"
     ]
    },
    {
     "name": "stdout",
     "output_type": "stream",
     "text": [
      "PyEDB INFO: StdOut is enabled\n"
     ]
    },
    {
     "name": "stdout",
     "output_type": "stream",
     "text": [
      "PyEDB INFO: Logger is initialized in EDB.\n"
     ]
    },
    {
     "name": "stdout",
     "output_type": "stream",
     "text": [
      "PyEDB INFO: legacy v0.23.0\n"
     ]
    },
    {
     "name": "stdout",
     "output_type": "stream",
     "text": [
      "PyEDB INFO: Python version 3.10.11 (tags/v3.10.11:7d4cc5a, Apr  5 2023, 00:38:17) [MSC v.1929 64 bit (AMD64)]\n"
     ]
    },
    {
     "name": "stderr",
     "output_type": "stream",
     "text": [
      "--- Logging error ---\n",
      "Traceback (most recent call last):\n",
      "  File \"C:\\actions-runner\\_work\\_tool\\Python\\3.10.11\\x64\\lib\\logging\\handlers.py\", line 74, in emit\n",
      "    self.doRollover()\n",
      "  File \"C:\\actions-runner\\_work\\_tool\\Python\\3.10.11\\x64\\lib\\logging\\handlers.py\", line 179, in doRollover\n",
      "    self.rotate(self.baseFilename, dfn)\n",
      "  File \"C:\\actions-runner\\_work\\_tool\\Python\\3.10.11\\x64\\lib\\logging\\handlers.py\", line 115, in rotate\n",
      "    os.rename(source, dest)\n",
      "PermissionError: [WinError 32] The process cannot access the file because it is being used by another process: 'C:\\\\Users\\\\ansys\\\\AppData\\\\Local\\\\Temp\\\\pyedb_ansys.log' -> 'C:\\\\Users\\\\ansys\\\\AppData\\\\Local\\\\Temp\\\\pyedb_ansys.log.1'\n",
      "Call stack:\n",
      "  File \"C:\\actions-runner\\_work\\_tool\\Python\\3.10.11\\x64\\lib\\runpy.py\", line 196, in _run_module_as_main\n",
      "    return _run_code(code, main_globals, None,\n",
      "  File \"C:\\actions-runner\\_work\\_tool\\Python\\3.10.11\\x64\\lib\\runpy.py\", line 86, in _run_code\n",
      "    exec(code, run_globals)\n",
      "  File \"C:\\actions-runner\\_work\\pyedb\\pyedb\\.venv\\lib\\site-packages\\ipykernel_launcher.py\", line 18, in <module>\n",
      "    app.launch_new_instance()\n",
      "  File \"C:\\actions-runner\\_work\\pyedb\\pyedb\\.venv\\lib\\site-packages\\traitlets\\config\\application.py\", line 1075, in launch_instance\n",
      "    app.start()\n",
      "  File \"C:\\actions-runner\\_work\\pyedb\\pyedb\\.venv\\lib\\site-packages\\ipykernel\\kernelapp.py\", line 739, in start\n",
      "    self.io_loop.start()\n",
      "  File \"C:\\actions-runner\\_work\\pyedb\\pyedb\\.venv\\lib\\site-packages\\tornado\\platform\\asyncio.py\", line 205, in start\n",
      "    self.asyncio_loop.run_forever()\n",
      "  File \"C:\\actions-runner\\_work\\_tool\\Python\\3.10.11\\x64\\lib\\asyncio\\base_events.py\", line 603, in run_forever\n",
      "    self._run_once()\n",
      "  File \"C:\\actions-runner\\_work\\_tool\\Python\\3.10.11\\x64\\lib\\asyncio\\base_events.py\", line 1909, in _run_once\n",
      "    handle._run()\n",
      "  File \"C:\\actions-runner\\_work\\_tool\\Python\\3.10.11\\x64\\lib\\asyncio\\events.py\", line 80, in _run\n",
      "    self._context.run(self._callback, *self._args)\n",
      "  File \"C:\\actions-runner\\_work\\pyedb\\pyedb\\.venv\\lib\\site-packages\\ipykernel\\kernelbase.py\", line 545, in dispatch_queue\n",
      "    await self.process_one()\n",
      "  File \"C:\\actions-runner\\_work\\pyedb\\pyedb\\.venv\\lib\\site-packages\\ipykernel\\kernelbase.py\", line 534, in process_one\n",
      "    await dispatch(*args)\n",
      "  File \"C:\\actions-runner\\_work\\pyedb\\pyedb\\.venv\\lib\\site-packages\\ipykernel\\kernelbase.py\", line 437, in dispatch_shell\n",
      "    await result\n",
      "  File \"C:\\actions-runner\\_work\\pyedb\\pyedb\\.venv\\lib\\site-packages\\ipykernel\\ipkernel.py\", line 362, in execute_request\n",
      "    await super().execute_request(stream, ident, parent)\n",
      "  File \"C:\\actions-runner\\_work\\pyedb\\pyedb\\.venv\\lib\\site-packages\\ipykernel\\kernelbase.py\", line 778, in execute_request\n",
      "    reply_content = await reply_content\n",
      "  File \"C:\\actions-runner\\_work\\pyedb\\pyedb\\.venv\\lib\\site-packages\\ipykernel\\ipkernel.py\", line 449, in do_execute\n",
      "    res = shell.run_cell(\n",
      "  File \"C:\\actions-runner\\_work\\pyedb\\pyedb\\.venv\\lib\\site-packages\\ipykernel\\zmqshell.py\", line 549, in run_cell\n",
      "    return super().run_cell(*args, **kwargs)\n",
      "  File \"C:\\actions-runner\\_work\\pyedb\\pyedb\\.venv\\lib\\site-packages\\IPython\\core\\interactiveshell.py\", line 3075, in run_cell\n",
      "    result = self._run_cell(\n",
      "  File \"C:\\actions-runner\\_work\\pyedb\\pyedb\\.venv\\lib\\site-packages\\IPython\\core\\interactiveshell.py\", line 3130, in _run_cell\n",
      "    result = runner(coro)\n",
      "  File \"C:\\actions-runner\\_work\\pyedb\\pyedb\\.venv\\lib\\site-packages\\IPython\\core\\async_helpers.py\", line 128, in _pseudo_sync_runner\n",
      "    coro.send(None)\n",
      "  File \"C:\\actions-runner\\_work\\pyedb\\pyedb\\.venv\\lib\\site-packages\\IPython\\core\\interactiveshell.py\", line 3334, in run_cell_async\n",
      "    has_raised = await self.run_ast_nodes(code_ast.body, cell_name,\n",
      "  File \"C:\\actions-runner\\_work\\pyedb\\pyedb\\.venv\\lib\\site-packages\\IPython\\core\\interactiveshell.py\", line 3517, in run_ast_nodes\n",
      "    if await self.run_code(code, result, async_=asy):\n",
      "  File \"C:\\actions-runner\\_work\\pyedb\\pyedb\\.venv\\lib\\site-packages\\IPython\\core\\interactiveshell.py\", line 3577, in run_code\n",
      "    exec(code_obj, self.user_global_ns, self.user_ns)\n",
      "  File \"C:\\Users\\ansys\\AppData\\Local\\Temp\\ipykernel_8532\\2300580511.py\", line 5, in <module>\n",
      "    edb = pyedb.Edb(edbpath=targetfolder, edbversion=edb_version)\n",
      "  File \"C:\\actions-runner\\_work\\pyedb\\pyedb\\.venv\\lib\\site-packages\\pyedb\\generic\\design_types.py\", line 110, in Edb\n",
      "    return app(\n",
      "  File \"C:\\actions-runner\\_work\\pyedb\\pyedb\\.venv\\lib\\site-packages\\pyedb\\dotnet\\edb.py\", line 196, in __init__\n",
      "    Database.__init__(self, edbversion=edbversion, student_version=student_version)\n",
      "  File \"C:\\actions-runner\\_work\\pyedb\\pyedb\\.venv\\lib\\site-packages\\pyedb\\dotnet\\edb_core\\dotnet\\database.py\", line 824, in __init__\n",
      "    EdbDotNet.__init__(self, edbversion=edbversion, student_version=student_version)\n",
      "  File \"C:\\actions-runner\\_work\\pyedb\\pyedb\\.venv\\lib\\site-packages\\pyedb\\dotnet\\edb_core\\dotnet\\database.py\", line 725, in __init__\n",
      "    self._logger.enable_stdout_log()\n",
      "  File \"C:\\actions-runner\\_work\\pyedb\\pyedb\\.venv\\lib\\site-packages\\pyedb\\edb_logger.py\", line 318, in enable_stdout_log\n",
      "    self.info(\"StdOut is enabled\")\n",
      "  File \"C:\\actions-runner\\_work\\pyedb\\pyedb\\.venv\\lib\\site-packages\\pyedb\\edb_logger.py\", line 346, in info\n",
      "    return self._log_on_handler(0, msg, *args, **kwargs)\n",
      "  File \"C:\\actions-runner\\_work\\pyedb\\pyedb\\.venv\\lib\\site-packages\\pyedb\\edb_logger.py\", line 293, in _log_on_handler\n",
      "    self._global.info(message_text, *args, **kwargs)\n",
      "Message: 'StdOut is enabled'\n",
      "Arguments: ()\n",
      "--- Logging error ---\n",
      "Traceback (most recent call last):\n",
      "  File \"C:\\actions-runner\\_work\\_tool\\Python\\3.10.11\\x64\\lib\\logging\\handlers.py\", line 74, in emit\n",
      "    self.doRollover()\n",
      "  File \"C:\\actions-runner\\_work\\_tool\\Python\\3.10.11\\x64\\lib\\logging\\handlers.py\", line 179, in doRollover\n",
      "    self.rotate(self.baseFilename, dfn)\n",
      "  File \"C:\\actions-runner\\_work\\_tool\\Python\\3.10.11\\x64\\lib\\logging\\handlers.py\", line 115, in rotate\n",
      "    os.rename(source, dest)\n",
      "PermissionError: [WinError 32] The process cannot access the file because it is being used by another process: 'C:\\\\Users\\\\ansys\\\\AppData\\\\Local\\\\Temp\\\\pyedb_ansys.log' -> 'C:\\\\Users\\\\ansys\\\\AppData\\\\Local\\\\Temp\\\\pyedb_ansys.log.1'\n",
      "Call stack:\n",
      "  File \"C:\\actions-runner\\_work\\_tool\\Python\\3.10.11\\x64\\lib\\runpy.py\", line 196, in _run_module_as_main\n",
      "    return _run_code(code, main_globals, None,\n",
      "  File \"C:\\actions-runner\\_work\\_tool\\Python\\3.10.11\\x64\\lib\\runpy.py\", line 86, in _run_code\n",
      "    exec(code, run_globals)\n",
      "  File \"C:\\actions-runner\\_work\\pyedb\\pyedb\\.venv\\lib\\site-packages\\ipykernel_launcher.py\", line 18, in <module>\n",
      "    app.launch_new_instance()\n",
      "  File \"C:\\actions-runner\\_work\\pyedb\\pyedb\\.venv\\lib\\site-packages\\traitlets\\config\\application.py\", line 1075, in launch_instance\n",
      "    app.start()\n",
      "  File \"C:\\actions-runner\\_work\\pyedb\\pyedb\\.venv\\lib\\site-packages\\ipykernel\\kernelapp.py\", line 739, in start\n",
      "    self.io_loop.start()\n",
      "  File \"C:\\actions-runner\\_work\\pyedb\\pyedb\\.venv\\lib\\site-packages\\tornado\\platform\\asyncio.py\", line 205, in start\n",
      "    self.asyncio_loop.run_forever()\n",
      "  File \"C:\\actions-runner\\_work\\_tool\\Python\\3.10.11\\x64\\lib\\asyncio\\base_events.py\", line 603, in run_forever\n",
      "    self._run_once()\n",
      "  File \"C:\\actions-runner\\_work\\_tool\\Python\\3.10.11\\x64\\lib\\asyncio\\base_events.py\", line 1909, in _run_once\n",
      "    handle._run()\n",
      "  File \"C:\\actions-runner\\_work\\_tool\\Python\\3.10.11\\x64\\lib\\asyncio\\events.py\", line 80, in _run\n",
      "    self._context.run(self._callback, *self._args)\n",
      "  File \"C:\\actions-runner\\_work\\pyedb\\pyedb\\.venv\\lib\\site-packages\\ipykernel\\kernelbase.py\", line 545, in dispatch_queue\n",
      "    await self.process_one()\n",
      "  File \"C:\\actions-runner\\_work\\pyedb\\pyedb\\.venv\\lib\\site-packages\\ipykernel\\kernelbase.py\", line 534, in process_one\n",
      "    await dispatch(*args)\n",
      "  File \"C:\\actions-runner\\_work\\pyedb\\pyedb\\.venv\\lib\\site-packages\\ipykernel\\kernelbase.py\", line 437, in dispatch_shell\n",
      "    await result\n",
      "  File \"C:\\actions-runner\\_work\\pyedb\\pyedb\\.venv\\lib\\site-packages\\ipykernel\\ipkernel.py\", line 362, in execute_request\n",
      "    await super().execute_request(stream, ident, parent)\n",
      "  File \"C:\\actions-runner\\_work\\pyedb\\pyedb\\.venv\\lib\\site-packages\\ipykernel\\kernelbase.py\", line 778, in execute_request\n",
      "    reply_content = await reply_content\n",
      "  File \"C:\\actions-runner\\_work\\pyedb\\pyedb\\.venv\\lib\\site-packages\\ipykernel\\ipkernel.py\", line 449, in do_execute\n",
      "    res = shell.run_cell(\n",
      "  File \"C:\\actions-runner\\_work\\pyedb\\pyedb\\.venv\\lib\\site-packages\\ipykernel\\zmqshell.py\", line 549, in run_cell\n",
      "    return super().run_cell(*args, **kwargs)\n",
      "  File \"C:\\actions-runner\\_work\\pyedb\\pyedb\\.venv\\lib\\site-packages\\IPython\\core\\interactiveshell.py\", line 3075, in run_cell\n",
      "    result = self._run_cell(\n",
      "  File \"C:\\actions-runner\\_work\\pyedb\\pyedb\\.venv\\lib\\site-packages\\IPython\\core\\interactiveshell.py\", line 3130, in _run_cell\n",
      "    result = runner(coro)\n",
      "  File \"C:\\actions-runner\\_work\\pyedb\\pyedb\\.venv\\lib\\site-packages\\IPython\\core\\async_helpers.py\", line 128, in _pseudo_sync_runner\n",
      "    coro.send(None)\n",
      "  File \"C:\\actions-runner\\_work\\pyedb\\pyedb\\.venv\\lib\\site-packages\\IPython\\core\\interactiveshell.py\", line 3334, in run_cell_async\n",
      "    has_raised = await self.run_ast_nodes(code_ast.body, cell_name,\n",
      "  File \"C:\\actions-runner\\_work\\pyedb\\pyedb\\.venv\\lib\\site-packages\\IPython\\core\\interactiveshell.py\", line 3517, in run_ast_nodes\n",
      "    if await self.run_code(code, result, async_=asy):\n",
      "  File \"C:\\actions-runner\\_work\\pyedb\\pyedb\\.venv\\lib\\site-packages\\IPython\\core\\interactiveshell.py\", line 3577, in run_code\n",
      "    exec(code_obj, self.user_global_ns, self.user_ns)\n",
      "  File \"C:\\Users\\ansys\\AppData\\Local\\Temp\\ipykernel_8532\\2300580511.py\", line 5, in <module>\n",
      "    edb = pyedb.Edb(edbpath=targetfolder, edbversion=edb_version)\n",
      "  File \"C:\\actions-runner\\_work\\pyedb\\pyedb\\.venv\\lib\\site-packages\\pyedb\\generic\\design_types.py\", line 110, in Edb\n",
      "    return app(\n",
      "  File \"C:\\actions-runner\\_work\\pyedb\\pyedb\\.venv\\lib\\site-packages\\pyedb\\dotnet\\edb.py\", line 196, in __init__\n",
      "    Database.__init__(self, edbversion=edbversion, student_version=student_version)\n",
      "  File \"C:\\actions-runner\\_work\\pyedb\\pyedb\\.venv\\lib\\site-packages\\pyedb\\dotnet\\edb_core\\dotnet\\database.py\", line 824, in __init__\n",
      "    EdbDotNet.__init__(self, edbversion=edbversion, student_version=student_version)\n",
      "  File \"C:\\actions-runner\\_work\\pyedb\\pyedb\\.venv\\lib\\site-packages\\pyedb\\dotnet\\edb_core\\dotnet\\database.py\", line 731, in __init__\n",
      "    self._logger.info(\"Logger is initialized in EDB.\")\n",
      "  File \"C:\\actions-runner\\_work\\pyedb\\pyedb\\.venv\\lib\\site-packages\\pyedb\\edb_logger.py\", line 346, in info\n",
      "    return self._log_on_handler(0, msg, *args, **kwargs)\n",
      "  File \"C:\\actions-runner\\_work\\pyedb\\pyedb\\.venv\\lib\\site-packages\\pyedb\\edb_logger.py\", line 293, in _log_on_handler\n",
      "    self._global.info(message_text, *args, **kwargs)\n",
      "Message: 'Logger is initialized in EDB.'\n",
      "Arguments: ()\n",
      "--- Logging error ---\n",
      "Traceback (most recent call last):\n",
      "  File \"C:\\actions-runner\\_work\\_tool\\Python\\3.10.11\\x64\\lib\\logging\\handlers.py\", line 74, in emit\n",
      "    self.doRollover()\n",
      "  File \"C:\\actions-runner\\_work\\_tool\\Python\\3.10.11\\x64\\lib\\logging\\handlers.py\", line 179, in doRollover\n",
      "    self.rotate(self.baseFilename, dfn)\n",
      "  File \"C:\\actions-runner\\_work\\_tool\\Python\\3.10.11\\x64\\lib\\logging\\handlers.py\", line 115, in rotate\n",
      "    os.rename(source, dest)\n",
      "PermissionError: [WinError 32] The process cannot access the file because it is being used by another process: 'C:\\\\Users\\\\ansys\\\\AppData\\\\Local\\\\Temp\\\\pyedb_ansys.log' -> 'C:\\\\Users\\\\ansys\\\\AppData\\\\Local\\\\Temp\\\\pyedb_ansys.log.1'\n",
      "Call stack:\n",
      "  File \"C:\\actions-runner\\_work\\_tool\\Python\\3.10.11\\x64\\lib\\runpy.py\", line 196, in _run_module_as_main\n",
      "    return _run_code(code, main_globals, None,\n",
      "  File \"C:\\actions-runner\\_work\\_tool\\Python\\3.10.11\\x64\\lib\\runpy.py\", line 86, in _run_code\n",
      "    exec(code, run_globals)\n",
      "  File \"C:\\actions-runner\\_work\\pyedb\\pyedb\\.venv\\lib\\site-packages\\ipykernel_launcher.py\", line 18, in <module>\n",
      "    app.launch_new_instance()\n",
      "  File \"C:\\actions-runner\\_work\\pyedb\\pyedb\\.venv\\lib\\site-packages\\traitlets\\config\\application.py\", line 1075, in launch_instance\n",
      "    app.start()\n",
      "  File \"C:\\actions-runner\\_work\\pyedb\\pyedb\\.venv\\lib\\site-packages\\ipykernel\\kernelapp.py\", line 739, in start\n",
      "    self.io_loop.start()\n",
      "  File \"C:\\actions-runner\\_work\\pyedb\\pyedb\\.venv\\lib\\site-packages\\tornado\\platform\\asyncio.py\", line 205, in start\n",
      "    self.asyncio_loop.run_forever()\n",
      "  File \"C:\\actions-runner\\_work\\_tool\\Python\\3.10.11\\x64\\lib\\asyncio\\base_events.py\", line 603, in run_forever\n",
      "    self._run_once()\n",
      "  File \"C:\\actions-runner\\_work\\_tool\\Python\\3.10.11\\x64\\lib\\asyncio\\base_events.py\", line 1909, in _run_once\n",
      "    handle._run()\n",
      "  File \"C:\\actions-runner\\_work\\_tool\\Python\\3.10.11\\x64\\lib\\asyncio\\events.py\", line 80, in _run\n",
      "    self._context.run(self._callback, *self._args)\n",
      "  File \"C:\\actions-runner\\_work\\pyedb\\pyedb\\.venv\\lib\\site-packages\\ipykernel\\kernelbase.py\", line 545, in dispatch_queue\n",
      "    await self.process_one()\n",
      "  File \"C:\\actions-runner\\_work\\pyedb\\pyedb\\.venv\\lib\\site-packages\\ipykernel\\kernelbase.py\", line 534, in process_one\n",
      "    await dispatch(*args)\n",
      "  File \"C:\\actions-runner\\_work\\pyedb\\pyedb\\.venv\\lib\\site-packages\\ipykernel\\kernelbase.py\", line 437, in dispatch_shell\n",
      "    await result\n",
      "  File \"C:\\actions-runner\\_work\\pyedb\\pyedb\\.venv\\lib\\site-packages\\ipykernel\\ipkernel.py\", line 362, in execute_request\n",
      "    await super().execute_request(stream, ident, parent)\n",
      "  File \"C:\\actions-runner\\_work\\pyedb\\pyedb\\.venv\\lib\\site-packages\\ipykernel\\kernelbase.py\", line 778, in execute_request\n",
      "    reply_content = await reply_content\n",
      "  File \"C:\\actions-runner\\_work\\pyedb\\pyedb\\.venv\\lib\\site-packages\\ipykernel\\ipkernel.py\", line 449, in do_execute\n",
      "    res = shell.run_cell(\n",
      "  File \"C:\\actions-runner\\_work\\pyedb\\pyedb\\.venv\\lib\\site-packages\\ipykernel\\zmqshell.py\", line 549, in run_cell\n",
      "    return super().run_cell(*args, **kwargs)\n",
      "  File \"C:\\actions-runner\\_work\\pyedb\\pyedb\\.venv\\lib\\site-packages\\IPython\\core\\interactiveshell.py\", line 3075, in run_cell\n",
      "    result = self._run_cell(\n",
      "  File \"C:\\actions-runner\\_work\\pyedb\\pyedb\\.venv\\lib\\site-packages\\IPython\\core\\interactiveshell.py\", line 3130, in _run_cell\n",
      "    result = runner(coro)\n",
      "  File \"C:\\actions-runner\\_work\\pyedb\\pyedb\\.venv\\lib\\site-packages\\IPython\\core\\async_helpers.py\", line 128, in _pseudo_sync_runner\n",
      "    coro.send(None)\n",
      "  File \"C:\\actions-runner\\_work\\pyedb\\pyedb\\.venv\\lib\\site-packages\\IPython\\core\\interactiveshell.py\", line 3334, in run_cell_async\n",
      "    has_raised = await self.run_ast_nodes(code_ast.body, cell_name,\n",
      "  File \"C:\\actions-runner\\_work\\pyedb\\pyedb\\.venv\\lib\\site-packages\\IPython\\core\\interactiveshell.py\", line 3517, in run_ast_nodes\n",
      "    if await self.run_code(code, result, async_=asy):\n",
      "  File \"C:\\actions-runner\\_work\\pyedb\\pyedb\\.venv\\lib\\site-packages\\IPython\\core\\interactiveshell.py\", line 3577, in run_code\n",
      "    exec(code_obj, self.user_global_ns, self.user_ns)\n",
      "  File \"C:\\Users\\ansys\\AppData\\Local\\Temp\\ipykernel_8532\\2300580511.py\", line 5, in <module>\n",
      "    edb = pyedb.Edb(edbpath=targetfolder, edbversion=edb_version)\n",
      "  File \"C:\\actions-runner\\_work\\pyedb\\pyedb\\.venv\\lib\\site-packages\\pyedb\\generic\\design_types.py\", line 110, in Edb\n",
      "    return app(\n",
      "  File \"C:\\actions-runner\\_work\\pyedb\\pyedb\\.venv\\lib\\site-packages\\pyedb\\dotnet\\edb.py\", line 196, in __init__\n",
      "    Database.__init__(self, edbversion=edbversion, student_version=student_version)\n",
      "  File \"C:\\actions-runner\\_work\\pyedb\\pyedb\\.venv\\lib\\site-packages\\pyedb\\dotnet\\edb_core\\dotnet\\database.py\", line 824, in __init__\n",
      "    EdbDotNet.__init__(self, edbversion=edbversion, student_version=student_version)\n",
      "  File \"C:\\actions-runner\\_work\\pyedb\\pyedb\\.venv\\lib\\site-packages\\pyedb\\dotnet\\edb_core\\dotnet\\database.py\", line 732, in __init__\n",
      "    self._logger.info(\"legacy v%s\", __version__)\n",
      "  File \"C:\\actions-runner\\_work\\pyedb\\pyedb\\.venv\\lib\\site-packages\\pyedb\\edb_logger.py\", line 346, in info\n",
      "    return self._log_on_handler(0, msg, *args, **kwargs)\n",
      "  File \"C:\\actions-runner\\_work\\pyedb\\pyedb\\.venv\\lib\\site-packages\\pyedb\\edb_logger.py\", line 293, in _log_on_handler\n",
      "    self._global.info(message_text, *args, **kwargs)\n",
      "Message: 'legacy v%s'\n",
      "Arguments: ('0.23.0',)\n",
      "--- Logging error ---\n",
      "Traceback (most recent call last):\n",
      "  File \"C:\\actions-runner\\_work\\_tool\\Python\\3.10.11\\x64\\lib\\logging\\handlers.py\", line 74, in emit\n",
      "    self.doRollover()\n",
      "  File \"C:\\actions-runner\\_work\\_tool\\Python\\3.10.11\\x64\\lib\\logging\\handlers.py\", line 179, in doRollover\n",
      "    self.rotate(self.baseFilename, dfn)\n",
      "  File \"C:\\actions-runner\\_work\\_tool\\Python\\3.10.11\\x64\\lib\\logging\\handlers.py\", line 115, in rotate\n",
      "    os.rename(source, dest)\n",
      "PermissionError: [WinError 32] The process cannot access the file because it is being used by another process: 'C:\\\\Users\\\\ansys\\\\AppData\\\\Local\\\\Temp\\\\pyedb_ansys.log' -> 'C:\\\\Users\\\\ansys\\\\AppData\\\\Local\\\\Temp\\\\pyedb_ansys.log.1'\n",
      "Call stack:\n",
      "  File \"C:\\actions-runner\\_work\\_tool\\Python\\3.10.11\\x64\\lib\\runpy.py\", line 196, in _run_module_as_main\n",
      "    return _run_code(code, main_globals, None,\n",
      "  File \"C:\\actions-runner\\_work\\_tool\\Python\\3.10.11\\x64\\lib\\runpy.py\", line 86, in _run_code\n",
      "    exec(code, run_globals)\n",
      "  File \"C:\\actions-runner\\_work\\pyedb\\pyedb\\.venv\\lib\\site-packages\\ipykernel_launcher.py\", line 18, in <module>\n",
      "    app.launch_new_instance()\n",
      "  File \"C:\\actions-runner\\_work\\pyedb\\pyedb\\.venv\\lib\\site-packages\\traitlets\\config\\application.py\", line 1075, in launch_instance\n",
      "    app.start()\n",
      "  File \"C:\\actions-runner\\_work\\pyedb\\pyedb\\.venv\\lib\\site-packages\\ipykernel\\kernelapp.py\", line 739, in start\n",
      "    self.io_loop.start()\n",
      "  File \"C:\\actions-runner\\_work\\pyedb\\pyedb\\.venv\\lib\\site-packages\\tornado\\platform\\asyncio.py\", line 205, in start\n",
      "    self.asyncio_loop.run_forever()\n",
      "  File \"C:\\actions-runner\\_work\\_tool\\Python\\3.10.11\\x64\\lib\\asyncio\\base_events.py\", line 603, in run_forever\n",
      "    self._run_once()\n",
      "  File \"C:\\actions-runner\\_work\\_tool\\Python\\3.10.11\\x64\\lib\\asyncio\\base_events.py\", line 1909, in _run_once\n",
      "    handle._run()\n",
      "  File \"C:\\actions-runner\\_work\\_tool\\Python\\3.10.11\\x64\\lib\\asyncio\\events.py\", line 80, in _run\n",
      "    self._context.run(self._callback, *self._args)\n",
      "  File \"C:\\actions-runner\\_work\\pyedb\\pyedb\\.venv\\lib\\site-packages\\ipykernel\\kernelbase.py\", line 545, in dispatch_queue\n",
      "    await self.process_one()\n",
      "  File \"C:\\actions-runner\\_work\\pyedb\\pyedb\\.venv\\lib\\site-packages\\ipykernel\\kernelbase.py\", line 534, in process_one\n",
      "    await dispatch(*args)\n",
      "  File \"C:\\actions-runner\\_work\\pyedb\\pyedb\\.venv\\lib\\site-packages\\ipykernel\\kernelbase.py\", line 437, in dispatch_shell\n",
      "    await result\n",
      "  File \"C:\\actions-runner\\_work\\pyedb\\pyedb\\.venv\\lib\\site-packages\\ipykernel\\ipkernel.py\", line 362, in execute_request\n",
      "    await super().execute_request(stream, ident, parent)\n",
      "  File \"C:\\actions-runner\\_work\\pyedb\\pyedb\\.venv\\lib\\site-packages\\ipykernel\\kernelbase.py\", line 778, in execute_request\n",
      "    reply_content = await reply_content\n",
      "  File \"C:\\actions-runner\\_work\\pyedb\\pyedb\\.venv\\lib\\site-packages\\ipykernel\\ipkernel.py\", line 449, in do_execute\n",
      "    res = shell.run_cell(\n",
      "  File \"C:\\actions-runner\\_work\\pyedb\\pyedb\\.venv\\lib\\site-packages\\ipykernel\\zmqshell.py\", line 549, in run_cell\n",
      "    return super().run_cell(*args, **kwargs)\n",
      "  File \"C:\\actions-runner\\_work\\pyedb\\pyedb\\.venv\\lib\\site-packages\\IPython\\core\\interactiveshell.py\", line 3075, in run_cell\n",
      "    result = self._run_cell(\n",
      "  File \"C:\\actions-runner\\_work\\pyedb\\pyedb\\.venv\\lib\\site-packages\\IPython\\core\\interactiveshell.py\", line 3130, in _run_cell\n",
      "    result = runner(coro)\n",
      "  File \"C:\\actions-runner\\_work\\pyedb\\pyedb\\.venv\\lib\\site-packages\\IPython\\core\\async_helpers.py\", line 128, in _pseudo_sync_runner\n",
      "    coro.send(None)\n",
      "  File \"C:\\actions-runner\\_work\\pyedb\\pyedb\\.venv\\lib\\site-packages\\IPython\\core\\interactiveshell.py\", line 3334, in run_cell_async\n",
      "    has_raised = await self.run_ast_nodes(code_ast.body, cell_name,\n",
      "  File \"C:\\actions-runner\\_work\\pyedb\\pyedb\\.venv\\lib\\site-packages\\IPython\\core\\interactiveshell.py\", line 3517, in run_ast_nodes\n",
      "    if await self.run_code(code, result, async_=asy):\n",
      "  File \"C:\\actions-runner\\_work\\pyedb\\pyedb\\.venv\\lib\\site-packages\\IPython\\core\\interactiveshell.py\", line 3577, in run_code\n",
      "    exec(code_obj, self.user_global_ns, self.user_ns)\n",
      "  File \"C:\\Users\\ansys\\AppData\\Local\\Temp\\ipykernel_8532\\2300580511.py\", line 5, in <module>\n",
      "    edb = pyedb.Edb(edbpath=targetfolder, edbversion=edb_version)\n",
      "  File \"C:\\actions-runner\\_work\\pyedb\\pyedb\\.venv\\lib\\site-packages\\pyedb\\generic\\design_types.py\", line 110, in Edb\n",
      "    return app(\n",
      "  File \"C:\\actions-runner\\_work\\pyedb\\pyedb\\.venv\\lib\\site-packages\\pyedb\\dotnet\\edb.py\", line 196, in __init__\n",
      "    Database.__init__(self, edbversion=edbversion, student_version=student_version)\n",
      "  File \"C:\\actions-runner\\_work\\pyedb\\pyedb\\.venv\\lib\\site-packages\\pyedb\\dotnet\\edb_core\\dotnet\\database.py\", line 824, in __init__\n",
      "    EdbDotNet.__init__(self, edbversion=edbversion, student_version=student_version)\n",
      "  File \"C:\\actions-runner\\_work\\pyedb\\pyedb\\.venv\\lib\\site-packages\\pyedb\\dotnet\\edb_core\\dotnet\\database.py\", line 733, in __init__\n",
      "    self._logger.info(\"Python version %s\", sys.version)\n",
      "  File \"C:\\actions-runner\\_work\\pyedb\\pyedb\\.venv\\lib\\site-packages\\pyedb\\edb_logger.py\", line 346, in info\n",
      "    return self._log_on_handler(0, msg, *args, **kwargs)\n",
      "  File \"C:\\actions-runner\\_work\\pyedb\\pyedb\\.venv\\lib\\site-packages\\pyedb\\edb_logger.py\", line 293, in _log_on_handler\n",
      "    self._global.info(message_text, *args, **kwargs)\n",
      "Message: 'Python version %s'\n",
      "Arguments: ('3.10.11 (tags/v3.10.11:7d4cc5a, Apr  5 2023, 00:38:17) [MSC v.1929 64 bit (AMD64)]',)\n"
     ]
    },
    {
     "name": "stdout",
     "output_type": "stream",
     "text": [
      "PyEDB INFO: Database ANSYS-HSD_V1.aedb Opened in 2024.1\n"
     ]
    },
    {
     "name": "stdout",
     "output_type": "stream",
     "text": [
      "PyEDB INFO: Cell main Opened\n"
     ]
    },
    {
     "name": "stderr",
     "output_type": "stream",
     "text": [
      "--- Logging error ---\n",
      "Traceback (most recent call last):\n",
      "  File \"C:\\actions-runner\\_work\\_tool\\Python\\3.10.11\\x64\\lib\\logging\\handlers.py\", line 74, in emit\n",
      "    self.doRollover()\n",
      "  File \"C:\\actions-runner\\_work\\_tool\\Python\\3.10.11\\x64\\lib\\logging\\handlers.py\", line 179, in doRollover\n",
      "    self.rotate(self.baseFilename, dfn)\n",
      "  File \"C:\\actions-runner\\_work\\_tool\\Python\\3.10.11\\x64\\lib\\logging\\handlers.py\", line 115, in rotate\n",
      "    os.rename(source, dest)\n",
      "PermissionError: [WinError 32] The process cannot access the file because it is being used by another process: 'C:\\\\Users\\\\ansys\\\\AppData\\\\Local\\\\Temp\\\\pyedb_ansys.log' -> 'C:\\\\Users\\\\ansys\\\\AppData\\\\Local\\\\Temp\\\\pyedb_ansys.log.1'\n",
      "Call stack:\n",
      "  File \"C:\\actions-runner\\_work\\_tool\\Python\\3.10.11\\x64\\lib\\runpy.py\", line 196, in _run_module_as_main\n",
      "    return _run_code(code, main_globals, None,\n",
      "  File \"C:\\actions-runner\\_work\\_tool\\Python\\3.10.11\\x64\\lib\\runpy.py\", line 86, in _run_code\n",
      "    exec(code, run_globals)\n",
      "  File \"C:\\actions-runner\\_work\\pyedb\\pyedb\\.venv\\lib\\site-packages\\ipykernel_launcher.py\", line 18, in <module>\n",
      "    app.launch_new_instance()\n",
      "  File \"C:\\actions-runner\\_work\\pyedb\\pyedb\\.venv\\lib\\site-packages\\traitlets\\config\\application.py\", line 1075, in launch_instance\n",
      "    app.start()\n",
      "  File \"C:\\actions-runner\\_work\\pyedb\\pyedb\\.venv\\lib\\site-packages\\ipykernel\\kernelapp.py\", line 739, in start\n",
      "    self.io_loop.start()\n",
      "  File \"C:\\actions-runner\\_work\\pyedb\\pyedb\\.venv\\lib\\site-packages\\tornado\\platform\\asyncio.py\", line 205, in start\n",
      "    self.asyncio_loop.run_forever()\n",
      "  File \"C:\\actions-runner\\_work\\_tool\\Python\\3.10.11\\x64\\lib\\asyncio\\base_events.py\", line 603, in run_forever\n",
      "    self._run_once()\n",
      "  File \"C:\\actions-runner\\_work\\_tool\\Python\\3.10.11\\x64\\lib\\asyncio\\base_events.py\", line 1909, in _run_once\n",
      "    handle._run()\n",
      "  File \"C:\\actions-runner\\_work\\_tool\\Python\\3.10.11\\x64\\lib\\asyncio\\events.py\", line 80, in _run\n",
      "    self._context.run(self._callback, *self._args)\n",
      "  File \"C:\\actions-runner\\_work\\pyedb\\pyedb\\.venv\\lib\\site-packages\\ipykernel\\kernelbase.py\", line 545, in dispatch_queue\n",
      "    await self.process_one()\n",
      "  File \"C:\\actions-runner\\_work\\pyedb\\pyedb\\.venv\\lib\\site-packages\\ipykernel\\kernelbase.py\", line 534, in process_one\n",
      "    await dispatch(*args)\n",
      "  File \"C:\\actions-runner\\_work\\pyedb\\pyedb\\.venv\\lib\\site-packages\\ipykernel\\kernelbase.py\", line 437, in dispatch_shell\n",
      "    await result\n",
      "  File \"C:\\actions-runner\\_work\\pyedb\\pyedb\\.venv\\lib\\site-packages\\ipykernel\\ipkernel.py\", line 362, in execute_request\n",
      "    await super().execute_request(stream, ident, parent)\n",
      "  File \"C:\\actions-runner\\_work\\pyedb\\pyedb\\.venv\\lib\\site-packages\\ipykernel\\kernelbase.py\", line 778, in execute_request\n",
      "    reply_content = await reply_content\n",
      "  File \"C:\\actions-runner\\_work\\pyedb\\pyedb\\.venv\\lib\\site-packages\\ipykernel\\ipkernel.py\", line 449, in do_execute\n",
      "    res = shell.run_cell(\n",
      "  File \"C:\\actions-runner\\_work\\pyedb\\pyedb\\.venv\\lib\\site-packages\\ipykernel\\zmqshell.py\", line 549, in run_cell\n",
      "    return super().run_cell(*args, **kwargs)\n",
      "  File \"C:\\actions-runner\\_work\\pyedb\\pyedb\\.venv\\lib\\site-packages\\IPython\\core\\interactiveshell.py\", line 3075, in run_cell\n",
      "    result = self._run_cell(\n",
      "  File \"C:\\actions-runner\\_work\\pyedb\\pyedb\\.venv\\lib\\site-packages\\IPython\\core\\interactiveshell.py\", line 3130, in _run_cell\n",
      "    result = runner(coro)\n",
      "  File \"C:\\actions-runner\\_work\\pyedb\\pyedb\\.venv\\lib\\site-packages\\IPython\\core\\async_helpers.py\", line 128, in _pseudo_sync_runner\n",
      "    coro.send(None)\n",
      "  File \"C:\\actions-runner\\_work\\pyedb\\pyedb\\.venv\\lib\\site-packages\\IPython\\core\\interactiveshell.py\", line 3334, in run_cell_async\n",
      "    has_raised = await self.run_ast_nodes(code_ast.body, cell_name,\n",
      "  File \"C:\\actions-runner\\_work\\pyedb\\pyedb\\.venv\\lib\\site-packages\\IPython\\core\\interactiveshell.py\", line 3517, in run_ast_nodes\n",
      "    if await self.run_code(code, result, async_=asy):\n",
      "  File \"C:\\actions-runner\\_work\\pyedb\\pyedb\\.venv\\lib\\site-packages\\IPython\\core\\interactiveshell.py\", line 3577, in run_code\n",
      "    exec(code_obj, self.user_global_ns, self.user_ns)\n",
      "  File \"C:\\Users\\ansys\\AppData\\Local\\Temp\\ipykernel_8532\\2300580511.py\", line 5, in <module>\n",
      "    edb = pyedb.Edb(edbpath=targetfolder, edbversion=edb_version)\n",
      "  File \"C:\\actions-runner\\_work\\pyedb\\pyedb\\.venv\\lib\\site-packages\\pyedb\\generic\\design_types.py\", line 110, in Edb\n",
      "    return app(\n",
      "  File \"C:\\actions-runner\\_work\\pyedb\\pyedb\\.venv\\lib\\site-packages\\pyedb\\dotnet\\edb.py\", line 276, in __init__\n",
      "    self.open_edb()\n",
      "  File \"C:\\actions-runner\\_work\\pyedb\\pyedb\\.venv\\lib\\site-packages\\pyedb\\dotnet\\edb.py\", line 554, in open_edb\n",
      "    self.logger.info(\"Database {} Opened in {}\".format(os.path.split(self.edbpath)[-1], self.edbversion))\n",
      "  File \"C:\\actions-runner\\_work\\pyedb\\pyedb\\.venv\\lib\\site-packages\\pyedb\\edb_logger.py\", line 346, in info\n",
      "    return self._log_on_handler(0, msg, *args, **kwargs)\n",
      "  File \"C:\\actions-runner\\_work\\pyedb\\pyedb\\.venv\\lib\\site-packages\\pyedb\\edb_logger.py\", line 293, in _log_on_handler\n",
      "    self._global.info(message_text, *args, **kwargs)\n",
      "Message: 'Database ANSYS-HSD_V1.aedb Opened in 2024.1'\n",
      "Arguments: ()\n",
      "--- Logging error ---\n",
      "Traceback (most recent call last):\n",
      "  File \"C:\\actions-runner\\_work\\_tool\\Python\\3.10.11\\x64\\lib\\logging\\handlers.py\", line 74, in emit\n",
      "    self.doRollover()\n",
      "  File \"C:\\actions-runner\\_work\\_tool\\Python\\3.10.11\\x64\\lib\\logging\\handlers.py\", line 179, in doRollover\n",
      "    self.rotate(self.baseFilename, dfn)\n",
      "  File \"C:\\actions-runner\\_work\\_tool\\Python\\3.10.11\\x64\\lib\\logging\\handlers.py\", line 115, in rotate\n",
      "    os.rename(source, dest)\n",
      "PermissionError: [WinError 32] The process cannot access the file because it is being used by another process: 'C:\\\\Users\\\\ansys\\\\AppData\\\\Local\\\\Temp\\\\pyedb_ansys.log' -> 'C:\\\\Users\\\\ansys\\\\AppData\\\\Local\\\\Temp\\\\pyedb_ansys.log.1'\n",
      "Call stack:\n",
      "  File \"C:\\actions-runner\\_work\\_tool\\Python\\3.10.11\\x64\\lib\\runpy.py\", line 196, in _run_module_as_main\n",
      "    return _run_code(code, main_globals, None,\n",
      "  File \"C:\\actions-runner\\_work\\_tool\\Python\\3.10.11\\x64\\lib\\runpy.py\", line 86, in _run_code\n",
      "    exec(code, run_globals)\n",
      "  File \"C:\\actions-runner\\_work\\pyedb\\pyedb\\.venv\\lib\\site-packages\\ipykernel_launcher.py\", line 18, in <module>\n",
      "    app.launch_new_instance()\n",
      "  File \"C:\\actions-runner\\_work\\pyedb\\pyedb\\.venv\\lib\\site-packages\\traitlets\\config\\application.py\", line 1075, in launch_instance\n",
      "    app.start()\n",
      "  File \"C:\\actions-runner\\_work\\pyedb\\pyedb\\.venv\\lib\\site-packages\\ipykernel\\kernelapp.py\", line 739, in start\n",
      "    self.io_loop.start()\n",
      "  File \"C:\\actions-runner\\_work\\pyedb\\pyedb\\.venv\\lib\\site-packages\\tornado\\platform\\asyncio.py\", line 205, in start\n",
      "    self.asyncio_loop.run_forever()\n",
      "  File \"C:\\actions-runner\\_work\\_tool\\Python\\3.10.11\\x64\\lib\\asyncio\\base_events.py\", line 603, in run_forever\n",
      "    self._run_once()\n",
      "  File \"C:\\actions-runner\\_work\\_tool\\Python\\3.10.11\\x64\\lib\\asyncio\\base_events.py\", line 1909, in _run_once\n",
      "    handle._run()\n",
      "  File \"C:\\actions-runner\\_work\\_tool\\Python\\3.10.11\\x64\\lib\\asyncio\\events.py\", line 80, in _run\n",
      "    self._context.run(self._callback, *self._args)\n",
      "  File \"C:\\actions-runner\\_work\\pyedb\\pyedb\\.venv\\lib\\site-packages\\ipykernel\\kernelbase.py\", line 545, in dispatch_queue\n",
      "    await self.process_one()\n",
      "  File \"C:\\actions-runner\\_work\\pyedb\\pyedb\\.venv\\lib\\site-packages\\ipykernel\\kernelbase.py\", line 534, in process_one\n",
      "    await dispatch(*args)\n",
      "  File \"C:\\actions-runner\\_work\\pyedb\\pyedb\\.venv\\lib\\site-packages\\ipykernel\\kernelbase.py\", line 437, in dispatch_shell\n",
      "    await result\n",
      "  File \"C:\\actions-runner\\_work\\pyedb\\pyedb\\.venv\\lib\\site-packages\\ipykernel\\ipkernel.py\", line 362, in execute_request\n",
      "    await super().execute_request(stream, ident, parent)\n",
      "  File \"C:\\actions-runner\\_work\\pyedb\\pyedb\\.venv\\lib\\site-packages\\ipykernel\\kernelbase.py\", line 778, in execute_request\n",
      "    reply_content = await reply_content\n",
      "  File \"C:\\actions-runner\\_work\\pyedb\\pyedb\\.venv\\lib\\site-packages\\ipykernel\\ipkernel.py\", line 449, in do_execute\n",
      "    res = shell.run_cell(\n",
      "  File \"C:\\actions-runner\\_work\\pyedb\\pyedb\\.venv\\lib\\site-packages\\ipykernel\\zmqshell.py\", line 549, in run_cell\n",
      "    return super().run_cell(*args, **kwargs)\n",
      "  File \"C:\\actions-runner\\_work\\pyedb\\pyedb\\.venv\\lib\\site-packages\\IPython\\core\\interactiveshell.py\", line 3075, in run_cell\n",
      "    result = self._run_cell(\n",
      "  File \"C:\\actions-runner\\_work\\pyedb\\pyedb\\.venv\\lib\\site-packages\\IPython\\core\\interactiveshell.py\", line 3130, in _run_cell\n",
      "    result = runner(coro)\n",
      "  File \"C:\\actions-runner\\_work\\pyedb\\pyedb\\.venv\\lib\\site-packages\\IPython\\core\\async_helpers.py\", line 128, in _pseudo_sync_runner\n",
      "    coro.send(None)\n",
      "  File \"C:\\actions-runner\\_work\\pyedb\\pyedb\\.venv\\lib\\site-packages\\IPython\\core\\interactiveshell.py\", line 3334, in run_cell_async\n",
      "    has_raised = await self.run_ast_nodes(code_ast.body, cell_name,\n",
      "  File \"C:\\actions-runner\\_work\\pyedb\\pyedb\\.venv\\lib\\site-packages\\IPython\\core\\interactiveshell.py\", line 3517, in run_ast_nodes\n",
      "    if await self.run_code(code, result, async_=asy):\n",
      "  File \"C:\\actions-runner\\_work\\pyedb\\pyedb\\.venv\\lib\\site-packages\\IPython\\core\\interactiveshell.py\", line 3577, in run_code\n",
      "    exec(code_obj, self.user_global_ns, self.user_ns)\n",
      "  File \"C:\\Users\\ansys\\AppData\\Local\\Temp\\ipykernel_8532\\2300580511.py\", line 5, in <module>\n",
      "    edb = pyedb.Edb(edbpath=targetfolder, edbversion=edb_version)\n",
      "  File \"C:\\actions-runner\\_work\\pyedb\\pyedb\\.venv\\lib\\site-packages\\pyedb\\generic\\design_types.py\", line 110, in Edb\n",
      "    return app(\n",
      "  File \"C:\\actions-runner\\_work\\pyedb\\pyedb\\.venv\\lib\\site-packages\\pyedb\\dotnet\\edb.py\", line 276, in __init__\n",
      "    self.open_edb()\n",
      "  File \"C:\\actions-runner\\_work\\pyedb\\pyedb\\.venv\\lib\\site-packages\\pyedb\\dotnet\\edb.py\", line 564, in open_edb\n",
      "    self.logger.info(\"Cell %s Opened\", self._active_cell.GetName())\n",
      "  File \"C:\\actions-runner\\_work\\pyedb\\pyedb\\.venv\\lib\\site-packages\\pyedb\\edb_logger.py\", line 346, in info\n",
      "    return self._log_on_handler(0, msg, *args, **kwargs)\n",
      "  File \"C:\\actions-runner\\_work\\pyedb\\pyedb\\.venv\\lib\\site-packages\\pyedb\\edb_logger.py\", line 293, in _log_on_handler\n",
      "    self._global.info(message_text, *args, **kwargs)\n",
      "Message: 'Cell %s Opened'\n",
      "Arguments: ('main',)\n"
     ]
    },
    {
     "name": "stdout",
     "output_type": "stream",
     "text": [
      "PyEDB INFO: Builder was initialized.\n"
     ]
    },
    {
     "name": "stdout",
     "output_type": "stream",
     "text": [
      "PyEDB INFO: EDB initialized.\n"
     ]
    },
    {
     "name": "stderr",
     "output_type": "stream",
     "text": [
      "--- Logging error ---\n",
      "Traceback (most recent call last):\n",
      "  File \"C:\\actions-runner\\_work\\_tool\\Python\\3.10.11\\x64\\lib\\logging\\handlers.py\", line 74, in emit\n",
      "    self.doRollover()\n",
      "  File \"C:\\actions-runner\\_work\\_tool\\Python\\3.10.11\\x64\\lib\\logging\\handlers.py\", line 179, in doRollover\n",
      "    self.rotate(self.baseFilename, dfn)\n",
      "  File \"C:\\actions-runner\\_work\\_tool\\Python\\3.10.11\\x64\\lib\\logging\\handlers.py\", line 115, in rotate\n",
      "    os.rename(source, dest)\n",
      "PermissionError: [WinError 32] The process cannot access the file because it is being used by another process: 'C:\\\\Users\\\\ansys\\\\AppData\\\\Local\\\\Temp\\\\pyedb_ansys.log' -> 'C:\\\\Users\\\\ansys\\\\AppData\\\\Local\\\\Temp\\\\pyedb_ansys.log.1'\n",
      "Call stack:\n",
      "  File \"C:\\actions-runner\\_work\\_tool\\Python\\3.10.11\\x64\\lib\\runpy.py\", line 196, in _run_module_as_main\n",
      "    return _run_code(code, main_globals, None,\n",
      "  File \"C:\\actions-runner\\_work\\_tool\\Python\\3.10.11\\x64\\lib\\runpy.py\", line 86, in _run_code\n",
      "    exec(code, run_globals)\n",
      "  File \"C:\\actions-runner\\_work\\pyedb\\pyedb\\.venv\\lib\\site-packages\\ipykernel_launcher.py\", line 18, in <module>\n",
      "    app.launch_new_instance()\n",
      "  File \"C:\\actions-runner\\_work\\pyedb\\pyedb\\.venv\\lib\\site-packages\\traitlets\\config\\application.py\", line 1075, in launch_instance\n",
      "    app.start()\n",
      "  File \"C:\\actions-runner\\_work\\pyedb\\pyedb\\.venv\\lib\\site-packages\\ipykernel\\kernelapp.py\", line 739, in start\n",
      "    self.io_loop.start()\n",
      "  File \"C:\\actions-runner\\_work\\pyedb\\pyedb\\.venv\\lib\\site-packages\\tornado\\platform\\asyncio.py\", line 205, in start\n",
      "    self.asyncio_loop.run_forever()\n",
      "  File \"C:\\actions-runner\\_work\\_tool\\Python\\3.10.11\\x64\\lib\\asyncio\\base_events.py\", line 603, in run_forever\n",
      "    self._run_once()\n",
      "  File \"C:\\actions-runner\\_work\\_tool\\Python\\3.10.11\\x64\\lib\\asyncio\\base_events.py\", line 1909, in _run_once\n",
      "    handle._run()\n",
      "  File \"C:\\actions-runner\\_work\\_tool\\Python\\3.10.11\\x64\\lib\\asyncio\\events.py\", line 80, in _run\n",
      "    self._context.run(self._callback, *self._args)\n",
      "  File \"C:\\actions-runner\\_work\\pyedb\\pyedb\\.venv\\lib\\site-packages\\ipykernel\\kernelbase.py\", line 545, in dispatch_queue\n",
      "    await self.process_one()\n",
      "  File \"C:\\actions-runner\\_work\\pyedb\\pyedb\\.venv\\lib\\site-packages\\ipykernel\\kernelbase.py\", line 534, in process_one\n",
      "    await dispatch(*args)\n",
      "  File \"C:\\actions-runner\\_work\\pyedb\\pyedb\\.venv\\lib\\site-packages\\ipykernel\\kernelbase.py\", line 437, in dispatch_shell\n",
      "    await result\n",
      "  File \"C:\\actions-runner\\_work\\pyedb\\pyedb\\.venv\\lib\\site-packages\\ipykernel\\ipkernel.py\", line 362, in execute_request\n",
      "    await super().execute_request(stream, ident, parent)\n",
      "  File \"C:\\actions-runner\\_work\\pyedb\\pyedb\\.venv\\lib\\site-packages\\ipykernel\\kernelbase.py\", line 778, in execute_request\n",
      "    reply_content = await reply_content\n",
      "  File \"C:\\actions-runner\\_work\\pyedb\\pyedb\\.venv\\lib\\site-packages\\ipykernel\\ipkernel.py\", line 449, in do_execute\n",
      "    res = shell.run_cell(\n",
      "  File \"C:\\actions-runner\\_work\\pyedb\\pyedb\\.venv\\lib\\site-packages\\ipykernel\\zmqshell.py\", line 549, in run_cell\n",
      "    return super().run_cell(*args, **kwargs)\n",
      "  File \"C:\\actions-runner\\_work\\pyedb\\pyedb\\.venv\\lib\\site-packages\\IPython\\core\\interactiveshell.py\", line 3075, in run_cell\n",
      "    result = self._run_cell(\n",
      "  File \"C:\\actions-runner\\_work\\pyedb\\pyedb\\.venv\\lib\\site-packages\\IPython\\core\\interactiveshell.py\", line 3130, in _run_cell\n",
      "    result = runner(coro)\n",
      "  File \"C:\\actions-runner\\_work\\pyedb\\pyedb\\.venv\\lib\\site-packages\\IPython\\core\\async_helpers.py\", line 128, in _pseudo_sync_runner\n",
      "    coro.send(None)\n",
      "  File \"C:\\actions-runner\\_work\\pyedb\\pyedb\\.venv\\lib\\site-packages\\IPython\\core\\interactiveshell.py\", line 3334, in run_cell_async\n",
      "    has_raised = await self.run_ast_nodes(code_ast.body, cell_name,\n",
      "  File \"C:\\actions-runner\\_work\\pyedb\\pyedb\\.venv\\lib\\site-packages\\IPython\\core\\interactiveshell.py\", line 3517, in run_ast_nodes\n",
      "    if await self.run_code(code, result, async_=asy):\n",
      "  File \"C:\\actions-runner\\_work\\pyedb\\pyedb\\.venv\\lib\\site-packages\\IPython\\core\\interactiveshell.py\", line 3577, in run_code\n",
      "    exec(code_obj, self.user_global_ns, self.user_ns)\n",
      "  File \"C:\\Users\\ansys\\AppData\\Local\\Temp\\ipykernel_8532\\2300580511.py\", line 5, in <module>\n",
      "    edb = pyedb.Edb(edbpath=targetfolder, edbversion=edb_version)\n",
      "  File \"C:\\actions-runner\\_work\\pyedb\\pyedb\\.venv\\lib\\site-packages\\pyedb\\generic\\design_types.py\", line 110, in Edb\n",
      "    return app(\n",
      "  File \"C:\\actions-runner\\_work\\pyedb\\pyedb\\.venv\\lib\\site-packages\\pyedb\\dotnet\\edb.py\", line 276, in __init__\n",
      "    self.open_edb()\n",
      "  File \"C:\\actions-runner\\_work\\pyedb\\pyedb\\.venv\\lib\\site-packages\\pyedb\\dotnet\\edb.py\", line 567, in open_edb\n",
      "    self.logger.info(\"Builder was initialized.\")\n",
      "  File \"C:\\actions-runner\\_work\\pyedb\\pyedb\\.venv\\lib\\site-packages\\pyedb\\edb_logger.py\", line 346, in info\n",
      "    return self._log_on_handler(0, msg, *args, **kwargs)\n",
      "  File \"C:\\actions-runner\\_work\\pyedb\\pyedb\\.venv\\lib\\site-packages\\pyedb\\edb_logger.py\", line 293, in _log_on_handler\n",
      "    self._global.info(message_text, *args, **kwargs)\n",
      "Message: 'Builder was initialized.'\n",
      "Arguments: ()\n",
      "--- Logging error ---\n",
      "Traceback (most recent call last):\n",
      "  File \"C:\\actions-runner\\_work\\_tool\\Python\\3.10.11\\x64\\lib\\logging\\handlers.py\", line 74, in emit\n",
      "    self.doRollover()\n",
      "  File \"C:\\actions-runner\\_work\\_tool\\Python\\3.10.11\\x64\\lib\\logging\\handlers.py\", line 179, in doRollover\n",
      "    self.rotate(self.baseFilename, dfn)\n",
      "  File \"C:\\actions-runner\\_work\\_tool\\Python\\3.10.11\\x64\\lib\\logging\\handlers.py\", line 115, in rotate\n",
      "    os.rename(source, dest)\n",
      "PermissionError: [WinError 32] The process cannot access the file because it is being used by another process: 'C:\\\\Users\\\\ansys\\\\AppData\\\\Local\\\\Temp\\\\pyedb_ansys.log' -> 'C:\\\\Users\\\\ansys\\\\AppData\\\\Local\\\\Temp\\\\pyedb_ansys.log.1'\n",
      "Call stack:\n",
      "  File \"C:\\actions-runner\\_work\\_tool\\Python\\3.10.11\\x64\\lib\\runpy.py\", line 196, in _run_module_as_main\n",
      "    return _run_code(code, main_globals, None,\n",
      "  File \"C:\\actions-runner\\_work\\_tool\\Python\\3.10.11\\x64\\lib\\runpy.py\", line 86, in _run_code\n",
      "    exec(code, run_globals)\n",
      "  File \"C:\\actions-runner\\_work\\pyedb\\pyedb\\.venv\\lib\\site-packages\\ipykernel_launcher.py\", line 18, in <module>\n",
      "    app.launch_new_instance()\n",
      "  File \"C:\\actions-runner\\_work\\pyedb\\pyedb\\.venv\\lib\\site-packages\\traitlets\\config\\application.py\", line 1075, in launch_instance\n",
      "    app.start()\n",
      "  File \"C:\\actions-runner\\_work\\pyedb\\pyedb\\.venv\\lib\\site-packages\\ipykernel\\kernelapp.py\", line 739, in start\n",
      "    self.io_loop.start()\n",
      "  File \"C:\\actions-runner\\_work\\pyedb\\pyedb\\.venv\\lib\\site-packages\\tornado\\platform\\asyncio.py\", line 205, in start\n",
      "    self.asyncio_loop.run_forever()\n",
      "  File \"C:\\actions-runner\\_work\\_tool\\Python\\3.10.11\\x64\\lib\\asyncio\\base_events.py\", line 603, in run_forever\n",
      "    self._run_once()\n",
      "  File \"C:\\actions-runner\\_work\\_tool\\Python\\3.10.11\\x64\\lib\\asyncio\\base_events.py\", line 1909, in _run_once\n",
      "    handle._run()\n",
      "  File \"C:\\actions-runner\\_work\\_tool\\Python\\3.10.11\\x64\\lib\\asyncio\\events.py\", line 80, in _run\n",
      "    self._context.run(self._callback, *self._args)\n",
      "  File \"C:\\actions-runner\\_work\\pyedb\\pyedb\\.venv\\lib\\site-packages\\ipykernel\\kernelbase.py\", line 545, in dispatch_queue\n",
      "    await self.process_one()\n",
      "  File \"C:\\actions-runner\\_work\\pyedb\\pyedb\\.venv\\lib\\site-packages\\ipykernel\\kernelbase.py\", line 534, in process_one\n",
      "    await dispatch(*args)\n",
      "  File \"C:\\actions-runner\\_work\\pyedb\\pyedb\\.venv\\lib\\site-packages\\ipykernel\\kernelbase.py\", line 437, in dispatch_shell\n",
      "    await result\n",
      "  File \"C:\\actions-runner\\_work\\pyedb\\pyedb\\.venv\\lib\\site-packages\\ipykernel\\ipkernel.py\", line 362, in execute_request\n",
      "    await super().execute_request(stream, ident, parent)\n",
      "  File \"C:\\actions-runner\\_work\\pyedb\\pyedb\\.venv\\lib\\site-packages\\ipykernel\\kernelbase.py\", line 778, in execute_request\n",
      "    reply_content = await reply_content\n",
      "  File \"C:\\actions-runner\\_work\\pyedb\\pyedb\\.venv\\lib\\site-packages\\ipykernel\\ipkernel.py\", line 449, in do_execute\n",
      "    res = shell.run_cell(\n",
      "  File \"C:\\actions-runner\\_work\\pyedb\\pyedb\\.venv\\lib\\site-packages\\ipykernel\\zmqshell.py\", line 549, in run_cell\n",
      "    return super().run_cell(*args, **kwargs)\n",
      "  File \"C:\\actions-runner\\_work\\pyedb\\pyedb\\.venv\\lib\\site-packages\\IPython\\core\\interactiveshell.py\", line 3075, in run_cell\n",
      "    result = self._run_cell(\n",
      "  File \"C:\\actions-runner\\_work\\pyedb\\pyedb\\.venv\\lib\\site-packages\\IPython\\core\\interactiveshell.py\", line 3130, in _run_cell\n",
      "    result = runner(coro)\n",
      "  File \"C:\\actions-runner\\_work\\pyedb\\pyedb\\.venv\\lib\\site-packages\\IPython\\core\\async_helpers.py\", line 128, in _pseudo_sync_runner\n",
      "    coro.send(None)\n",
      "  File \"C:\\actions-runner\\_work\\pyedb\\pyedb\\.venv\\lib\\site-packages\\IPython\\core\\interactiveshell.py\", line 3334, in run_cell_async\n",
      "    has_raised = await self.run_ast_nodes(code_ast.body, cell_name,\n",
      "  File \"C:\\actions-runner\\_work\\pyedb\\pyedb\\.venv\\lib\\site-packages\\IPython\\core\\interactiveshell.py\", line 3517, in run_ast_nodes\n",
      "    if await self.run_code(code, result, async_=asy):\n",
      "  File \"C:\\actions-runner\\_work\\pyedb\\pyedb\\.venv\\lib\\site-packages\\IPython\\core\\interactiveshell.py\", line 3577, in run_code\n",
      "    exec(code_obj, self.user_global_ns, self.user_ns)\n",
      "  File \"C:\\Users\\ansys\\AppData\\Local\\Temp\\ipykernel_8532\\2300580511.py\", line 5, in <module>\n",
      "    edb = pyedb.Edb(edbpath=targetfolder, edbversion=edb_version)\n",
      "  File \"C:\\actions-runner\\_work\\pyedb\\pyedb\\.venv\\lib\\site-packages\\pyedb\\generic\\design_types.py\", line 110, in Edb\n",
      "    return app(\n",
      "  File \"C:\\actions-runner\\_work\\pyedb\\pyedb\\.venv\\lib\\site-packages\\pyedb\\dotnet\\edb.py\", line 278, in __init__\n",
      "    self.logger.info(\"EDB initialized.\")\n",
      "  File \"C:\\actions-runner\\_work\\pyedb\\pyedb\\.venv\\lib\\site-packages\\pyedb\\edb_logger.py\", line 346, in info\n",
      "    return self._log_on_handler(0, msg, *args, **kwargs)\n",
      "  File \"C:\\actions-runner\\_work\\pyedb\\pyedb\\.venv\\lib\\site-packages\\pyedb\\edb_logger.py\", line 293, in _log_on_handler\n",
      "    self._global.info(message_text, *args, **kwargs)\n",
      "Message: 'EDB initialized.'\n",
      "Arguments: ()\n"
     ]
    }
   ],
   "source": [
    "# Select EDB version (change it manually if needed, e.g. \"2024.1\")\n",
    "edb_version = \"2024.1\"\n",
    "print(f\"EDB version: {edb_version}\")\n",
    "\n",
    "edb = pyedb.Edb(edbpath=targetfolder, edbversion=edb_version)"
   ]
  },
  {
   "cell_type": "markdown",
   "id": "d386d450",
   "metadata": {},
   "source": [
    "Display the nets on a layer. You can display the net geometry directly in Python using\n",
    "``matplotlib`` from the ``pyedb.Edb`` class."
   ]
  },
  {
   "cell_type": "code",
   "execution_count": 4,
   "id": "74725f18",
   "metadata": {
    "execution": {
     "iopub.execute_input": "2024-07-30T16:41:16.730205Z",
     "iopub.status.busy": "2024-07-30T16:41:16.730205Z",
     "iopub.status.idle": "2024-07-30T16:41:34.011722Z",
     "shell.execute_reply": "2024-07-30T16:41:34.011722Z"
    }
   },
   "outputs": [
    {
     "name": "stdout",
     "output_type": "stream",
     "text": [
      "PyEDB INFO: Nets Point Generation time 16.969 seconds\n"
     ]
    },
    {
     "name": "stderr",
     "output_type": "stream",
     "text": [
      "--- Logging error ---\n",
      "Traceback (most recent call last):\n",
      "  File \"C:\\actions-runner\\_work\\_tool\\Python\\3.10.11\\x64\\lib\\logging\\handlers.py\", line 74, in emit\n",
      "    self.doRollover()\n",
      "  File \"C:\\actions-runner\\_work\\_tool\\Python\\3.10.11\\x64\\lib\\logging\\handlers.py\", line 179, in doRollover\n",
      "    self.rotate(self.baseFilename, dfn)\n",
      "  File \"C:\\actions-runner\\_work\\_tool\\Python\\3.10.11\\x64\\lib\\logging\\handlers.py\", line 115, in rotate\n",
      "    os.rename(source, dest)\n",
      "PermissionError: [WinError 32] The process cannot access the file because it is being used by another process: 'C:\\\\Users\\\\ansys\\\\AppData\\\\Local\\\\Temp\\\\pyedb_ansys.log' -> 'C:\\\\Users\\\\ansys\\\\AppData\\\\Local\\\\Temp\\\\pyedb_ansys.log.1'\n",
      "Call stack:\n",
      "  File \"C:\\actions-runner\\_work\\_tool\\Python\\3.10.11\\x64\\lib\\runpy.py\", line 196, in _run_module_as_main\n",
      "    return _run_code(code, main_globals, None,\n",
      "  File \"C:\\actions-runner\\_work\\_tool\\Python\\3.10.11\\x64\\lib\\runpy.py\", line 86, in _run_code\n",
      "    exec(code, run_globals)\n",
      "  File \"C:\\actions-runner\\_work\\pyedb\\pyedb\\.venv\\lib\\site-packages\\ipykernel_launcher.py\", line 18, in <module>\n",
      "    app.launch_new_instance()\n",
      "  File \"C:\\actions-runner\\_work\\pyedb\\pyedb\\.venv\\lib\\site-packages\\traitlets\\config\\application.py\", line 1075, in launch_instance\n",
      "    app.start()\n",
      "  File \"C:\\actions-runner\\_work\\pyedb\\pyedb\\.venv\\lib\\site-packages\\ipykernel\\kernelapp.py\", line 739, in start\n",
      "    self.io_loop.start()\n",
      "  File \"C:\\actions-runner\\_work\\pyedb\\pyedb\\.venv\\lib\\site-packages\\tornado\\platform\\asyncio.py\", line 205, in start\n",
      "    self.asyncio_loop.run_forever()\n",
      "  File \"C:\\actions-runner\\_work\\_tool\\Python\\3.10.11\\x64\\lib\\asyncio\\base_events.py\", line 603, in run_forever\n",
      "    self._run_once()\n",
      "  File \"C:\\actions-runner\\_work\\_tool\\Python\\3.10.11\\x64\\lib\\asyncio\\base_events.py\", line 1909, in _run_once\n",
      "    handle._run()\n",
      "  File \"C:\\actions-runner\\_work\\_tool\\Python\\3.10.11\\x64\\lib\\asyncio\\events.py\", line 80, in _run\n",
      "    self._context.run(self._callback, *self._args)\n",
      "  File \"C:\\actions-runner\\_work\\pyedb\\pyedb\\.venv\\lib\\site-packages\\ipykernel\\kernelbase.py\", line 545, in dispatch_queue\n",
      "    await self.process_one()\n",
      "  File \"C:\\actions-runner\\_work\\pyedb\\pyedb\\.venv\\lib\\site-packages\\ipykernel\\kernelbase.py\", line 534, in process_one\n",
      "    await dispatch(*args)\n",
      "  File \"C:\\actions-runner\\_work\\pyedb\\pyedb\\.venv\\lib\\site-packages\\ipykernel\\kernelbase.py\", line 437, in dispatch_shell\n",
      "    await result\n",
      "  File \"C:\\actions-runner\\_work\\pyedb\\pyedb\\.venv\\lib\\site-packages\\ipykernel\\ipkernel.py\", line 362, in execute_request\n",
      "    await super().execute_request(stream, ident, parent)\n",
      "  File \"C:\\actions-runner\\_work\\pyedb\\pyedb\\.venv\\lib\\site-packages\\ipykernel\\kernelbase.py\", line 778, in execute_request\n",
      "    reply_content = await reply_content\n",
      "  File \"C:\\actions-runner\\_work\\pyedb\\pyedb\\.venv\\lib\\site-packages\\ipykernel\\ipkernel.py\", line 449, in do_execute\n",
      "    res = shell.run_cell(\n",
      "  File \"C:\\actions-runner\\_work\\pyedb\\pyedb\\.venv\\lib\\site-packages\\ipykernel\\zmqshell.py\", line 549, in run_cell\n",
      "    return super().run_cell(*args, **kwargs)\n",
      "  File \"C:\\actions-runner\\_work\\pyedb\\pyedb\\.venv\\lib\\site-packages\\IPython\\core\\interactiveshell.py\", line 3075, in run_cell\n",
      "    result = self._run_cell(\n",
      "  File \"C:\\actions-runner\\_work\\pyedb\\pyedb\\.venv\\lib\\site-packages\\IPython\\core\\interactiveshell.py\", line 3130, in _run_cell\n",
      "    result = runner(coro)\n",
      "  File \"C:\\actions-runner\\_work\\pyedb\\pyedb\\.venv\\lib\\site-packages\\IPython\\core\\async_helpers.py\", line 128, in _pseudo_sync_runner\n",
      "    coro.send(None)\n",
      "  File \"C:\\actions-runner\\_work\\pyedb\\pyedb\\.venv\\lib\\site-packages\\IPython\\core\\interactiveshell.py\", line 3334, in run_cell_async\n",
      "    has_raised = await self.run_ast_nodes(code_ast.body, cell_name,\n",
      "  File \"C:\\actions-runner\\_work\\pyedb\\pyedb\\.venv\\lib\\site-packages\\IPython\\core\\interactiveshell.py\", line 3517, in run_ast_nodes\n",
      "    if await self.run_code(code, result, async_=asy):\n",
      "  File \"C:\\actions-runner\\_work\\pyedb\\pyedb\\.venv\\lib\\site-packages\\IPython\\core\\interactiveshell.py\", line 3577, in run_code\n",
      "    exec(code_obj, self.user_global_ns, self.user_ns)\n",
      "  File \"C:\\Users\\ansys\\AppData\\Local\\Temp\\ipykernel_8532\\1189763028.py\", line 1, in <module>\n",
      "    edb.nets.plot(\"AVCC_1V3\")\n",
      "  File \"C:\\actions-runner\\_work\\pyedb\\pyedb\\.venv\\lib\\site-packages\\pyedb\\dotnet\\edb_core\\nets.py\", line 843, in plot\n",
      "    object_lists = self.get_plot_data(\n",
      "  File \"C:\\actions-runner\\_work\\pyedb\\pyedb\\.venv\\lib\\site-packages\\pyedb\\dotnet\\edb_core\\nets.py\", line 759, in get_plot_data\n",
      "    self._logger.info(\"Nets Point Generation time %s seconds\", round(end_time, 3))\n",
      "  File \"C:\\actions-runner\\_work\\pyedb\\pyedb\\.venv\\lib\\site-packages\\pyedb\\edb_logger.py\", line 346, in info\n",
      "    return self._log_on_handler(0, msg, *args, **kwargs)\n",
      "  File \"C:\\actions-runner\\_work\\pyedb\\pyedb\\.venv\\lib\\site-packages\\pyedb\\edb_logger.py\", line 293, in _log_on_handler\n",
      "    self._global.info(message_text, *args, **kwargs)\n",
      "Message: 'Nets Point Generation time %s seconds'\n",
      "Arguments: (16.969,)\n"
     ]
    },
    {
     "name": "stderr",
     "output_type": "stream",
     "text": [
      "C:\\actions-runner\\_work\\pyedb\\pyedb\\.venv\\lib\\site-packages\\pyedb\\generic\\plot.py:144: UserWarning: FigureCanvasAgg is non-interactive, and thus cannot be shown\n",
      "  plt.show()\n"
     ]
    }
   ],
   "source": [
    "edb.nets.plot(\"AVCC_1V3\")"
   ]
  },
  {
   "cell_type": "markdown",
   "id": "e95c8efe",
   "metadata": {},
   "source": [
    "You can view multiple nets by passing a list containing the net\n",
    "names to the ``plot()`` method."
   ]
  },
  {
   "cell_type": "code",
   "execution_count": 5,
   "id": "1b9f8b9b",
   "metadata": {
    "execution": {
     "iopub.execute_input": "2024-07-30T16:41:34.011722Z",
     "iopub.status.busy": "2024-07-30T16:41:34.011722Z",
     "iopub.status.idle": "2024-07-30T16:41:52.980757Z",
     "shell.execute_reply": "2024-07-30T16:41:52.980757Z"
    }
   },
   "outputs": [
    {
     "name": "stdout",
     "output_type": "stream",
     "text": [
      "PyEDB INFO: Nets Point Generation time 16.766 seconds\n"
     ]
    },
    {
     "name": "stderr",
     "output_type": "stream",
     "text": [
      "--- Logging error ---\n",
      "Traceback (most recent call last):\n",
      "  File \"C:\\actions-runner\\_work\\_tool\\Python\\3.10.11\\x64\\lib\\logging\\handlers.py\", line 74, in emit\n",
      "    self.doRollover()\n",
      "  File \"C:\\actions-runner\\_work\\_tool\\Python\\3.10.11\\x64\\lib\\logging\\handlers.py\", line 179, in doRollover\n",
      "    self.rotate(self.baseFilename, dfn)\n",
      "  File \"C:\\actions-runner\\_work\\_tool\\Python\\3.10.11\\x64\\lib\\logging\\handlers.py\", line 115, in rotate\n",
      "    os.rename(source, dest)\n",
      "PermissionError: [WinError 32] The process cannot access the file because it is being used by another process: 'C:\\\\Users\\\\ansys\\\\AppData\\\\Local\\\\Temp\\\\pyedb_ansys.log' -> 'C:\\\\Users\\\\ansys\\\\AppData\\\\Local\\\\Temp\\\\pyedb_ansys.log.1'\n",
      "Call stack:\n",
      "  File \"C:\\actions-runner\\_work\\_tool\\Python\\3.10.11\\x64\\lib\\runpy.py\", line 196, in _run_module_as_main\n",
      "    return _run_code(code, main_globals, None,\n",
      "  File \"C:\\actions-runner\\_work\\_tool\\Python\\3.10.11\\x64\\lib\\runpy.py\", line 86, in _run_code\n",
      "    exec(code, run_globals)\n",
      "  File \"C:\\actions-runner\\_work\\pyedb\\pyedb\\.venv\\lib\\site-packages\\ipykernel_launcher.py\", line 18, in <module>\n",
      "    app.launch_new_instance()\n",
      "  File \"C:\\actions-runner\\_work\\pyedb\\pyedb\\.venv\\lib\\site-packages\\traitlets\\config\\application.py\", line 1075, in launch_instance\n",
      "    app.start()\n",
      "  File \"C:\\actions-runner\\_work\\pyedb\\pyedb\\.venv\\lib\\site-packages\\ipykernel\\kernelapp.py\", line 739, in start\n",
      "    self.io_loop.start()\n",
      "  File \"C:\\actions-runner\\_work\\pyedb\\pyedb\\.venv\\lib\\site-packages\\tornado\\platform\\asyncio.py\", line 205, in start\n",
      "    self.asyncio_loop.run_forever()\n",
      "  File \"C:\\actions-runner\\_work\\_tool\\Python\\3.10.11\\x64\\lib\\asyncio\\base_events.py\", line 603, in run_forever\n",
      "    self._run_once()\n",
      "  File \"C:\\actions-runner\\_work\\_tool\\Python\\3.10.11\\x64\\lib\\asyncio\\base_events.py\", line 1909, in _run_once\n",
      "    handle._run()\n",
      "  File \"C:\\actions-runner\\_work\\_tool\\Python\\3.10.11\\x64\\lib\\asyncio\\events.py\", line 80, in _run\n",
      "    self._context.run(self._callback, *self._args)\n",
      "  File \"C:\\actions-runner\\_work\\pyedb\\pyedb\\.venv\\lib\\site-packages\\ipykernel\\kernelbase.py\", line 545, in dispatch_queue\n",
      "    await self.process_one()\n",
      "  File \"C:\\actions-runner\\_work\\pyedb\\pyedb\\.venv\\lib\\site-packages\\ipykernel\\kernelbase.py\", line 534, in process_one\n",
      "    await dispatch(*args)\n",
      "  File \"C:\\actions-runner\\_work\\pyedb\\pyedb\\.venv\\lib\\site-packages\\ipykernel\\kernelbase.py\", line 437, in dispatch_shell\n",
      "    await result\n",
      "  File \"C:\\actions-runner\\_work\\pyedb\\pyedb\\.venv\\lib\\site-packages\\ipykernel\\ipkernel.py\", line 362, in execute_request\n",
      "    await super().execute_request(stream, ident, parent)\n",
      "  File \"C:\\actions-runner\\_work\\pyedb\\pyedb\\.venv\\lib\\site-packages\\ipykernel\\kernelbase.py\", line 778, in execute_request\n",
      "    reply_content = await reply_content\n",
      "  File \"C:\\actions-runner\\_work\\pyedb\\pyedb\\.venv\\lib\\site-packages\\ipykernel\\ipkernel.py\", line 449, in do_execute\n",
      "    res = shell.run_cell(\n",
      "  File \"C:\\actions-runner\\_work\\pyedb\\pyedb\\.venv\\lib\\site-packages\\ipykernel\\zmqshell.py\", line 549, in run_cell\n",
      "    return super().run_cell(*args, **kwargs)\n",
      "  File \"C:\\actions-runner\\_work\\pyedb\\pyedb\\.venv\\lib\\site-packages\\IPython\\core\\interactiveshell.py\", line 3075, in run_cell\n",
      "    result = self._run_cell(\n",
      "  File \"C:\\actions-runner\\_work\\pyedb\\pyedb\\.venv\\lib\\site-packages\\IPython\\core\\interactiveshell.py\", line 3130, in _run_cell\n",
      "    result = runner(coro)\n",
      "  File \"C:\\actions-runner\\_work\\pyedb\\pyedb\\.venv\\lib\\site-packages\\IPython\\core\\async_helpers.py\", line 128, in _pseudo_sync_runner\n",
      "    coro.send(None)\n",
      "  File \"C:\\actions-runner\\_work\\pyedb\\pyedb\\.venv\\lib\\site-packages\\IPython\\core\\interactiveshell.py\", line 3334, in run_cell_async\n",
      "    has_raised = await self.run_ast_nodes(code_ast.body, cell_name,\n",
      "  File \"C:\\actions-runner\\_work\\pyedb\\pyedb\\.venv\\lib\\site-packages\\IPython\\core\\interactiveshell.py\", line 3517, in run_ast_nodes\n",
      "    if await self.run_code(code, result, async_=asy):\n",
      "  File \"C:\\actions-runner\\_work\\pyedb\\pyedb\\.venv\\lib\\site-packages\\IPython\\core\\interactiveshell.py\", line 3577, in run_code\n",
      "    exec(code_obj, self.user_global_ns, self.user_ns)\n",
      "  File \"C:\\Users\\ansys\\AppData\\Local\\Temp\\ipykernel_8532\\863075063.py\", line 1, in <module>\n",
      "    edb.nets.plot([\"GND\", \"GND_DP\", \"AVCC_1V3\"], color_by_net=True)\n",
      "  File \"C:\\actions-runner\\_work\\pyedb\\pyedb\\.venv\\lib\\site-packages\\pyedb\\dotnet\\edb_core\\nets.py\", line 843, in plot\n",
      "    object_lists = self.get_plot_data(\n",
      "  File \"C:\\actions-runner\\_work\\pyedb\\pyedb\\.venv\\lib\\site-packages\\pyedb\\dotnet\\edb_core\\nets.py\", line 759, in get_plot_data\n",
      "    self._logger.info(\"Nets Point Generation time %s seconds\", round(end_time, 3))\n",
      "  File \"C:\\actions-runner\\_work\\pyedb\\pyedb\\.venv\\lib\\site-packages\\pyedb\\edb_logger.py\", line 346, in info\n",
      "    return self._log_on_handler(0, msg, *args, **kwargs)\n",
      "  File \"C:\\actions-runner\\_work\\pyedb\\pyedb\\.venv\\lib\\site-packages\\pyedb\\edb_logger.py\", line 293, in _log_on_handler\n",
      "    self._global.info(message_text, *args, **kwargs)\n",
      "Message: 'Nets Point Generation time %s seconds'\n",
      "Arguments: (16.766,)\n"
     ]
    }
   ],
   "source": [
    "edb.nets.plot([\"GND\", \"GND_DP\", \"AVCC_1V3\"], color_by_net=True)"
   ]
  },
  {
   "cell_type": "markdown",
   "id": "a3c3acff",
   "metadata": {},
   "source": [
    "You can display all copper on a single layer by passing ``None``\n",
    "as the first argument. The second argument is a list\n",
    "of layers to plot. In this case, only one\n",
    "layer is to be displayed."
   ]
  },
  {
   "cell_type": "code",
   "execution_count": 6,
   "id": "ac499188",
   "metadata": {
    "execution": {
     "iopub.execute_input": "2024-07-30T16:41:52.980757Z",
     "iopub.status.busy": "2024-07-30T16:41:52.980757Z",
     "iopub.status.idle": "2024-07-30T16:42:12.590485Z",
     "shell.execute_reply": "2024-07-30T16:42:12.590485Z"
    }
   },
   "outputs": [
    {
     "name": "stdout",
     "output_type": "stream",
     "text": [
      "PyEDB INFO: Nets Point Generation time 17.25 seconds\n"
     ]
    },
    {
     "name": "stderr",
     "output_type": "stream",
     "text": [
      "--- Logging error ---\n",
      "Traceback (most recent call last):\n",
      "  File \"C:\\actions-runner\\_work\\_tool\\Python\\3.10.11\\x64\\lib\\logging\\handlers.py\", line 74, in emit\n",
      "    self.doRollover()\n",
      "  File \"C:\\actions-runner\\_work\\_tool\\Python\\3.10.11\\x64\\lib\\logging\\handlers.py\", line 179, in doRollover\n",
      "    self.rotate(self.baseFilename, dfn)\n",
      "  File \"C:\\actions-runner\\_work\\_tool\\Python\\3.10.11\\x64\\lib\\logging\\handlers.py\", line 115, in rotate\n",
      "    os.rename(source, dest)\n",
      "PermissionError: [WinError 32] The process cannot access the file because it is being used by another process: 'C:\\\\Users\\\\ansys\\\\AppData\\\\Local\\\\Temp\\\\pyedb_ansys.log' -> 'C:\\\\Users\\\\ansys\\\\AppData\\\\Local\\\\Temp\\\\pyedb_ansys.log.1'\n",
      "Call stack:\n",
      "  File \"C:\\actions-runner\\_work\\_tool\\Python\\3.10.11\\x64\\lib\\runpy.py\", line 196, in _run_module_as_main\n",
      "    return _run_code(code, main_globals, None,\n",
      "  File \"C:\\actions-runner\\_work\\_tool\\Python\\3.10.11\\x64\\lib\\runpy.py\", line 86, in _run_code\n",
      "    exec(code, run_globals)\n",
      "  File \"C:\\actions-runner\\_work\\pyedb\\pyedb\\.venv\\lib\\site-packages\\ipykernel_launcher.py\", line 18, in <module>\n",
      "    app.launch_new_instance()\n",
      "  File \"C:\\actions-runner\\_work\\pyedb\\pyedb\\.venv\\lib\\site-packages\\traitlets\\config\\application.py\", line 1075, in launch_instance\n",
      "    app.start()\n",
      "  File \"C:\\actions-runner\\_work\\pyedb\\pyedb\\.venv\\lib\\site-packages\\ipykernel\\kernelapp.py\", line 739, in start\n",
      "    self.io_loop.start()\n",
      "  File \"C:\\actions-runner\\_work\\pyedb\\pyedb\\.venv\\lib\\site-packages\\tornado\\platform\\asyncio.py\", line 205, in start\n",
      "    self.asyncio_loop.run_forever()\n",
      "  File \"C:\\actions-runner\\_work\\_tool\\Python\\3.10.11\\x64\\lib\\asyncio\\base_events.py\", line 603, in run_forever\n",
      "    self._run_once()\n",
      "  File \"C:\\actions-runner\\_work\\_tool\\Python\\3.10.11\\x64\\lib\\asyncio\\base_events.py\", line 1909, in _run_once\n",
      "    handle._run()\n",
      "  File \"C:\\actions-runner\\_work\\_tool\\Python\\3.10.11\\x64\\lib\\asyncio\\events.py\", line 80, in _run\n",
      "    self._context.run(self._callback, *self._args)\n",
      "  File \"C:\\actions-runner\\_work\\pyedb\\pyedb\\.venv\\lib\\site-packages\\ipykernel\\kernelbase.py\", line 545, in dispatch_queue\n",
      "    await self.process_one()\n",
      "  File \"C:\\actions-runner\\_work\\pyedb\\pyedb\\.venv\\lib\\site-packages\\ipykernel\\kernelbase.py\", line 534, in process_one\n",
      "    await dispatch(*args)\n",
      "  File \"C:\\actions-runner\\_work\\pyedb\\pyedb\\.venv\\lib\\site-packages\\ipykernel\\kernelbase.py\", line 437, in dispatch_shell\n",
      "    await result\n",
      "  File \"C:\\actions-runner\\_work\\pyedb\\pyedb\\.venv\\lib\\site-packages\\ipykernel\\ipkernel.py\", line 362, in execute_request\n",
      "    await super().execute_request(stream, ident, parent)\n",
      "  File \"C:\\actions-runner\\_work\\pyedb\\pyedb\\.venv\\lib\\site-packages\\ipykernel\\kernelbase.py\", line 778, in execute_request\n",
      "    reply_content = await reply_content\n",
      "  File \"C:\\actions-runner\\_work\\pyedb\\pyedb\\.venv\\lib\\site-packages\\ipykernel\\ipkernel.py\", line 449, in do_execute\n",
      "    res = shell.run_cell(\n",
      "  File \"C:\\actions-runner\\_work\\pyedb\\pyedb\\.venv\\lib\\site-packages\\ipykernel\\zmqshell.py\", line 549, in run_cell\n",
      "    return super().run_cell(*args, **kwargs)\n",
      "  File \"C:\\actions-runner\\_work\\pyedb\\pyedb\\.venv\\lib\\site-packages\\IPython\\core\\interactiveshell.py\", line 3075, in run_cell\n",
      "    result = self._run_cell(\n",
      "  File \"C:\\actions-runner\\_work\\pyedb\\pyedb\\.venv\\lib\\site-packages\\IPython\\core\\interactiveshell.py\", line 3130, in _run_cell\n",
      "    result = runner(coro)\n",
      "  File \"C:\\actions-runner\\_work\\pyedb\\pyedb\\.venv\\lib\\site-packages\\IPython\\core\\async_helpers.py\", line 128, in _pseudo_sync_runner\n",
      "    coro.send(None)\n",
      "  File \"C:\\actions-runner\\_work\\pyedb\\pyedb\\.venv\\lib\\site-packages\\IPython\\core\\interactiveshell.py\", line 3334, in run_cell_async\n",
      "    has_raised = await self.run_ast_nodes(code_ast.body, cell_name,\n",
      "  File \"C:\\actions-runner\\_work\\pyedb\\pyedb\\.venv\\lib\\site-packages\\IPython\\core\\interactiveshell.py\", line 3517, in run_ast_nodes\n",
      "    if await self.run_code(code, result, async_=asy):\n",
      "  File \"C:\\actions-runner\\_work\\pyedb\\pyedb\\.venv\\lib\\site-packages\\IPython\\core\\interactiveshell.py\", line 3577, in run_code\n",
      "    exec(code_obj, self.user_global_ns, self.user_ns)\n",
      "  File \"C:\\Users\\ansys\\AppData\\Local\\Temp\\ipykernel_8532\\1537379181.py\", line 1, in <module>\n",
      "    edb.nets.plot(None, [\"1_Top\"], color_by_net=True, plot_components_on_top=True)\n",
      "  File \"C:\\actions-runner\\_work\\pyedb\\pyedb\\.venv\\lib\\site-packages\\pyedb\\dotnet\\edb_core\\nets.py\", line 843, in plot\n",
      "    object_lists = self.get_plot_data(\n",
      "  File \"C:\\actions-runner\\_work\\pyedb\\pyedb\\.venv\\lib\\site-packages\\pyedb\\dotnet\\edb_core\\nets.py\", line 759, in get_plot_data\n",
      "    self._logger.info(\"Nets Point Generation time %s seconds\", round(end_time, 3))\n",
      "  File \"C:\\actions-runner\\_work\\pyedb\\pyedb\\.venv\\lib\\site-packages\\pyedb\\edb_logger.py\", line 346, in info\n",
      "    return self._log_on_handler(0, msg, *args, **kwargs)\n",
      "  File \"C:\\actions-runner\\_work\\pyedb\\pyedb\\.venv\\lib\\site-packages\\pyedb\\edb_logger.py\", line 293, in _log_on_handler\n",
      "    self._global.info(message_text, *args, **kwargs)\n",
      "Message: 'Nets Point Generation time %s seconds'\n",
      "Arguments: (17.25,)\n"
     ]
    }
   ],
   "source": [
    "edb.nets.plot(None, [\"1_Top\"], color_by_net=True, plot_components_on_top=True)"
   ]
  },
  {
   "cell_type": "markdown",
   "id": "e0245faf",
   "metadata": {},
   "source": [
    "Display a side view of the layers and padstack geometry using the\n",
    "``Edb.stackup.plot()`` method."
   ]
  },
  {
   "cell_type": "code",
   "execution_count": 7,
   "id": "e166cf9f",
   "metadata": {
    "execution": {
     "iopub.execute_input": "2024-07-30T16:42:12.590485Z",
     "iopub.status.busy": "2024-07-30T16:42:12.590485Z",
     "iopub.status.idle": "2024-07-30T16:42:12.871708Z",
     "shell.execute_reply": "2024-07-30T16:42:12.871708Z"
    }
   },
   "outputs": [
    {
     "name": "stderr",
     "output_type": "stream",
     "text": [
      "C:\\actions-runner\\_work\\pyedb\\pyedb\\.venv\\lib\\site-packages\\pyedb\\dotnet\\edb_core\\stackup.py:2862: UserWarning: FigureCanvasAgg is non-interactive, and thus cannot be shown\n",
      "  plt.show()\n"
     ]
    },
    {
     "data": {
      "text/plain": [
       "<module 'matplotlib.pyplot' from 'C:\\\\actions-runner\\\\_work\\\\pyedb\\\\pyedb\\\\.venv\\\\lib\\\\site-packages\\\\matplotlib\\\\pyplot.py'>"
      ]
     },
     "execution_count": 7,
     "metadata": {},
     "output_type": "execute_result"
    }
   ],
   "source": [
    "edb.stackup.plot(scale_elevation=False, plot_definitions=[\"c100hn140\", \"c35\"])"
   ]
  },
  {
   "cell_type": "markdown",
   "id": "1f507c85",
   "metadata": {},
   "source": [
    "Close the EDB."
   ]
  },
  {
   "cell_type": "code",
   "execution_count": 8,
   "id": "71db5480",
   "metadata": {
    "execution": {
     "iopub.execute_input": "2024-07-30T16:42:12.871708Z",
     "iopub.status.busy": "2024-07-30T16:42:12.871708Z",
     "iopub.status.idle": "2024-07-30T16:42:13.090441Z",
     "shell.execute_reply": "2024-07-30T16:42:13.090441Z"
    }
   },
   "outputs": [
    {
     "name": "stdout",
     "output_type": "stream",
     "text": [
      "PyEDB INFO: EDB file release time: 0.00ms\n"
     ]
    },
    {
     "name": "stderr",
     "output_type": "stream",
     "text": [
      "--- Logging error ---\n",
      "Traceback (most recent call last):\n",
      "  File \"C:\\actions-runner\\_work\\_tool\\Python\\3.10.11\\x64\\lib\\logging\\handlers.py\", line 74, in emit\n",
      "    self.doRollover()\n",
      "  File \"C:\\actions-runner\\_work\\_tool\\Python\\3.10.11\\x64\\lib\\logging\\handlers.py\", line 179, in doRollover\n",
      "    self.rotate(self.baseFilename, dfn)\n",
      "  File \"C:\\actions-runner\\_work\\_tool\\Python\\3.10.11\\x64\\lib\\logging\\handlers.py\", line 115, in rotate\n",
      "    os.rename(source, dest)\n",
      "PermissionError: [WinError 32] The process cannot access the file because it is being used by another process: 'C:\\\\Users\\\\ansys\\\\AppData\\\\Local\\\\Temp\\\\pyedb_ansys.log' -> 'C:\\\\Users\\\\ansys\\\\AppData\\\\Local\\\\Temp\\\\pyedb_ansys.log.1'\n",
      "Call stack:\n",
      "  File \"C:\\actions-runner\\_work\\_tool\\Python\\3.10.11\\x64\\lib\\runpy.py\", line 196, in _run_module_as_main\n",
      "    return _run_code(code, main_globals, None,\n",
      "  File \"C:\\actions-runner\\_work\\_tool\\Python\\3.10.11\\x64\\lib\\runpy.py\", line 86, in _run_code\n",
      "    exec(code, run_globals)\n",
      "  File \"C:\\actions-runner\\_work\\pyedb\\pyedb\\.venv\\lib\\site-packages\\ipykernel_launcher.py\", line 18, in <module>\n",
      "    app.launch_new_instance()\n",
      "  File \"C:\\actions-runner\\_work\\pyedb\\pyedb\\.venv\\lib\\site-packages\\traitlets\\config\\application.py\", line 1075, in launch_instance\n",
      "    app.start()\n",
      "  File \"C:\\actions-runner\\_work\\pyedb\\pyedb\\.venv\\lib\\site-packages\\ipykernel\\kernelapp.py\", line 739, in start\n",
      "    self.io_loop.start()\n",
      "  File \"C:\\actions-runner\\_work\\pyedb\\pyedb\\.venv\\lib\\site-packages\\tornado\\platform\\asyncio.py\", line 205, in start\n",
      "    self.asyncio_loop.run_forever()\n",
      "  File \"C:\\actions-runner\\_work\\_tool\\Python\\3.10.11\\x64\\lib\\asyncio\\base_events.py\", line 603, in run_forever\n",
      "    self._run_once()\n",
      "  File \"C:\\actions-runner\\_work\\_tool\\Python\\3.10.11\\x64\\lib\\asyncio\\base_events.py\", line 1909, in _run_once\n",
      "    handle._run()\n",
      "  File \"C:\\actions-runner\\_work\\_tool\\Python\\3.10.11\\x64\\lib\\asyncio\\events.py\", line 80, in _run\n",
      "    self._context.run(self._callback, *self._args)\n",
      "  File \"C:\\actions-runner\\_work\\pyedb\\pyedb\\.venv\\lib\\site-packages\\ipykernel\\kernelbase.py\", line 545, in dispatch_queue\n",
      "    await self.process_one()\n",
      "  File \"C:\\actions-runner\\_work\\pyedb\\pyedb\\.venv\\lib\\site-packages\\ipykernel\\kernelbase.py\", line 534, in process_one\n",
      "    await dispatch(*args)\n",
      "  File \"C:\\actions-runner\\_work\\pyedb\\pyedb\\.venv\\lib\\site-packages\\ipykernel\\kernelbase.py\", line 437, in dispatch_shell\n",
      "    await result\n",
      "  File \"C:\\actions-runner\\_work\\pyedb\\pyedb\\.venv\\lib\\site-packages\\ipykernel\\ipkernel.py\", line 362, in execute_request\n",
      "    await super().execute_request(stream, ident, parent)\n",
      "  File \"C:\\actions-runner\\_work\\pyedb\\pyedb\\.venv\\lib\\site-packages\\ipykernel\\kernelbase.py\", line 778, in execute_request\n",
      "    reply_content = await reply_content\n",
      "  File \"C:\\actions-runner\\_work\\pyedb\\pyedb\\.venv\\lib\\site-packages\\ipykernel\\ipkernel.py\", line 449, in do_execute\n",
      "    res = shell.run_cell(\n",
      "  File \"C:\\actions-runner\\_work\\pyedb\\pyedb\\.venv\\lib\\site-packages\\ipykernel\\zmqshell.py\", line 549, in run_cell\n",
      "    return super().run_cell(*args, **kwargs)\n",
      "  File \"C:\\actions-runner\\_work\\pyedb\\pyedb\\.venv\\lib\\site-packages\\IPython\\core\\interactiveshell.py\", line 3075, in run_cell\n",
      "    result = self._run_cell(\n",
      "  File \"C:\\actions-runner\\_work\\pyedb\\pyedb\\.venv\\lib\\site-packages\\IPython\\core\\interactiveshell.py\", line 3130, in _run_cell\n",
      "    result = runner(coro)\n",
      "  File \"C:\\actions-runner\\_work\\pyedb\\pyedb\\.venv\\lib\\site-packages\\IPython\\core\\async_helpers.py\", line 128, in _pseudo_sync_runner\n",
      "    coro.send(None)\n",
      "  File \"C:\\actions-runner\\_work\\pyedb\\pyedb\\.venv\\lib\\site-packages\\IPython\\core\\interactiveshell.py\", line 3334, in run_cell_async\n",
      "    has_raised = await self.run_ast_nodes(code_ast.body, cell_name,\n",
      "  File \"C:\\actions-runner\\_work\\pyedb\\pyedb\\.venv\\lib\\site-packages\\IPython\\core\\interactiveshell.py\", line 3517, in run_ast_nodes\n",
      "    if await self.run_code(code, result, async_=asy):\n",
      "  File \"C:\\actions-runner\\_work\\pyedb\\pyedb\\.venv\\lib\\site-packages\\IPython\\core\\interactiveshell.py\", line 3577, in run_code\n",
      "    exec(code_obj, self.user_global_ns, self.user_ns)\n",
      "  File \"C:\\Users\\ansys\\AppData\\Local\\Temp\\ipykernel_8532\\3588321624.py\", line 1, in <module>\n",
      "    edb.close_edb()\n",
      "  File \"C:\\actions-runner\\_work\\pyedb\\pyedb\\.venv\\lib\\site-packages\\pyedb\\dotnet\\edb.py\", line 1353, in close_edb\n",
      "    self.logger.info(\"EDB file release time: {0:.2f}ms\".format(elapsed_time * 1000.0))\n",
      "  File \"C:\\actions-runner\\_work\\pyedb\\pyedb\\.venv\\lib\\site-packages\\pyedb\\edb_logger.py\", line 346, in info\n",
      "    return self._log_on_handler(0, msg, *args, **kwargs)\n",
      "  File \"C:\\actions-runner\\_work\\pyedb\\pyedb\\.venv\\lib\\site-packages\\pyedb\\edb_logger.py\", line 293, in _log_on_handler\n",
      "    self._global.info(message_text, *args, **kwargs)\n",
      "Message: 'EDB file release time: 0.00ms'\n",
      "Arguments: ()\n"
     ]
    },
    {
     "data": {
      "text/plain": [
       "True"
      ]
     },
     "execution_count": 8,
     "metadata": {},
     "output_type": "execute_result"
    }
   ],
   "source": [
    "edb.close_edb()"
   ]
  },
  {
   "cell_type": "markdown",
   "id": "5fdd8aa8",
   "metadata": {},
   "source": [
    "Remove all files and the temporary directory."
   ]
  },
  {
   "cell_type": "code",
   "execution_count": 9,
   "id": "a329f265",
   "metadata": {
    "execution": {
     "iopub.execute_input": "2024-07-30T16:42:13.090441Z",
     "iopub.status.busy": "2024-07-30T16:42:13.090441Z",
     "iopub.status.idle": "2024-07-30T16:42:13.106132Z",
     "shell.execute_reply": "2024-07-30T16:42:13.106132Z"
    }
   },
   "outputs": [],
   "source": [
    "temp_dir.cleanup()"
   ]
  }
 ],
 "metadata": {
  "jupytext": {
   "cell_metadata_filter": "-all",
   "main_language": "python",
   "notebook_metadata_filter": "-all",
   "text_representation": {
    "extension": ".py",
    "format_name": "light"
   }
  },
  "language_info": {
   "codemirror_mode": {
    "name": "ipython",
    "version": 3
   },
   "file_extension": ".py",
   "mimetype": "text/x-python",
   "name": "python",
   "nbconvert_exporter": "python",
   "pygments_lexer": "ipython3",
   "version": "3.10.11"
  }
 },
 "nbformat": 4,
 "nbformat_minor": 5
}
