{
 "cells": [
  {
   "cell_type": "markdown",
   "id": "1b56ae19",
   "metadata": {
    "lines_to_next_cell": 2
   },
   "source": [
    "Copyright (C) 2023 - 2024 ANSYS, Inc. and/or its affiliates.\n",
    "SPDX-License-Identifier: MIT\n",
    "\n",
    "\n",
    "Permission is hereby granted, free of charge, to any person obtaining a copy\n",
    "of this software and associated documentation files (the \"Software\"), to deal\n",
    "in the Software without restriction, including without limitation the rights\n",
    "to use, copy, modify, merge, publish, distribute, sublicense, and/or sell\n",
    "copies of the Software, and to permit persons to whom the Software is\n",
    "furnished to do so, subject to the following conditions:\n",
    "\n",
    "The above copyright notice and this permission notice shall be included in all\n",
    "copies or substantial portions of the Software.\n",
    "\n",
    "THE SOFTWARE IS PROVIDED \"AS IS\", WITHOUT WARRANTY OF ANY KIND, EXPRESS OR\n",
    "IMPLIED, INCLUDING BUT NOT LIMITED TO THE WARRANTIES OF MERCHANTABILITY,\n",
    "FITNESS FOR A PARTICULAR PURPOSE AND NONINFRINGEMENT. IN NO EVENT SHALL THE\n",
    "AUTHORS OR COPYRIGHT HOLDERS BE LIABLE FOR ANY CLAIM, DAMAGES OR OTHER\n",
    "LIABILITY, WHETHER IN AN ACTION OF CONTRACT, TORT OR OTHERWISE, ARISING FROM,\n",
    "OUT OF OR IN CONNECTION WITH THE SOFTWARE OR THE USE OR OTHER DEALINGS IN THE\n",
    "SOFTWARE."
   ]
  },
  {
   "cell_type": "markdown",
   "id": "0fd3b7ed",
   "metadata": {
    "lines_to_next_cell": 2
   },
   "source": [
    "# EDB: Rename nets and ports\n",
    "\n",
    "This example shows how you can use PyEDB to rename ports and nets."
   ]
  },
  {
   "cell_type": "markdown",
   "id": "6cc54fa2",
   "metadata": {},
   "source": [
    "## Perform required imports\n",
    "Perform required imports, which includes importing a section."
   ]
  },
  {
   "cell_type": "code",
   "execution_count": 1,
   "id": "ac1bc875",
   "metadata": {
    "execution": {
     "iopub.execute_input": "2025-01-22T08:50:04.542312Z",
     "iopub.status.busy": "2025-01-22T08:50:04.542312Z",
     "iopub.status.idle": "2025-01-22T08:50:04.573496Z",
     "shell.execute_reply": "2025-01-22T08:50:04.573496Z"
    }
   },
   "outputs": [],
   "source": [
    "from pyedb import Edb\n",
    "from pyedb.generic.general_methods import generate_unique_folder_name\n",
    "import pyedb.misc.downloads as downloads"
   ]
  },
  {
   "cell_type": "markdown",
   "id": "6a1a20bb",
   "metadata": {},
   "source": [
    "## Download ANSYS EDB\n",
    "Download ANSYS generic design from public repository."
   ]
  },
  {
   "cell_type": "code",
   "execution_count": 2,
   "id": "cace0cac",
   "metadata": {
    "execution": {
     "iopub.execute_input": "2025-01-22T08:50:04.573496Z",
     "iopub.status.busy": "2025-01-22T08:50:04.573496Z",
     "iopub.status.idle": "2025-01-22T08:50:06.255021Z",
     "shell.execute_reply": "2025-01-22T08:50:06.255021Z"
    }
   },
   "outputs": [],
   "source": [
    "temp_folder = generate_unique_folder_name()\n",
    "targetfile = downloads.download_file(\"edb/ANSYS-HSD_V1.aedb\", destination=temp_folder)"
   ]
  },
  {
   "cell_type": "markdown",
   "id": "7ddd5c1f",
   "metadata": {},
   "source": [
    "## opening EDB\n",
    "Opening EDB with ANSYS release 2024.2"
   ]
  },
  {
   "cell_type": "code",
   "execution_count": 3,
   "id": "4178c902",
   "metadata": {
    "execution": {
     "iopub.execute_input": "2025-01-22T08:50:06.255021Z",
     "iopub.status.busy": "2025-01-22T08:50:06.255021Z",
     "iopub.status.idle": "2025-01-22T08:50:19.374479Z",
     "shell.execute_reply": "2025-01-22T08:50:19.374479Z"
    }
   },
   "outputs": [
    {
     "name": "stdout",
     "output_type": "stream",
     "text": [
      "PyEDB INFO: StdOut is enabled\n"
     ]
    },
    {
     "name": "stdout",
     "output_type": "stream",
     "text": [
      "PyEDB INFO: Logger is initialized in EDB.\n"
     ]
    },
    {
     "name": "stdout",
     "output_type": "stream",
     "text": [
      "PyEDB INFO: legacy v0.35.0\n"
     ]
    },
    {
     "name": "stdout",
     "output_type": "stream",
     "text": [
      "PyEDB INFO: Python version 3.10.11 (tags/v3.10.11:7d4cc5a, Apr  5 2023, 00:38:17) [MSC v.1929 64 bit (AMD64)]\n"
     ]
    },
    {
     "name": "stderr",
     "output_type": "stream",
     "text": [
      "--- Logging error ---\n",
      "Traceback (most recent call last):\n",
      "  File \"C:\\actions-runner\\_work\\_tool\\Python\\3.10.11\\x64\\lib\\logging\\handlers.py\", line 74, in emit\n",
      "    self.doRollover()\n",
      "  File \"C:\\actions-runner\\_work\\_tool\\Python\\3.10.11\\x64\\lib\\logging\\handlers.py\", line 179, in doRollover\n",
      "    self.rotate(self.baseFilename, dfn)\n",
      "  File \"C:\\actions-runner\\_work\\_tool\\Python\\3.10.11\\x64\\lib\\logging\\handlers.py\", line 115, in rotate\n",
      "    os.rename(source, dest)\n",
      "PermissionError: [WinError 32] The process cannot access the file because it is being used by another process: 'C:\\\\Users\\\\ansys\\\\AppData\\\\Local\\\\Temp\\\\pyedb_ansys.log' -> 'C:\\\\Users\\\\ansys\\\\AppData\\\\Local\\\\Temp\\\\pyedb_ansys.log.1'\n",
      "Call stack:\n",
      "  File \"C:\\actions-runner\\_work\\_tool\\Python\\3.10.11\\x64\\lib\\runpy.py\", line 196, in _run_module_as_main\n",
      "    return _run_code(code, main_globals, None,\n",
      "  File \"C:\\actions-runner\\_work\\_tool\\Python\\3.10.11\\x64\\lib\\runpy.py\", line 86, in _run_code\n",
      "    exec(code, run_globals)\n",
      "  File \"C:\\actions-runner\\_work\\pyedb\\pyedb\\.venv\\lib\\site-packages\\ipykernel_launcher.py\", line 18, in <module>\n",
      "    app.launch_new_instance()\n",
      "  File \"C:\\actions-runner\\_work\\pyedb\\pyedb\\.venv\\lib\\site-packages\\traitlets\\config\\application.py\", line 1075, in launch_instance\n",
      "    app.start()\n",
      "  File \"C:\\actions-runner\\_work\\pyedb\\pyedb\\.venv\\lib\\site-packages\\ipykernel\\kernelapp.py\", line 739, in start\n",
      "    self.io_loop.start()\n",
      "  File \"C:\\actions-runner\\_work\\pyedb\\pyedb\\.venv\\lib\\site-packages\\tornado\\platform\\asyncio.py\", line 205, in start\n",
      "    self.asyncio_loop.run_forever()\n",
      "  File \"C:\\actions-runner\\_work\\_tool\\Python\\3.10.11\\x64\\lib\\asyncio\\base_events.py\", line 603, in run_forever\n",
      "    self._run_once()\n",
      "  File \"C:\\actions-runner\\_work\\_tool\\Python\\3.10.11\\x64\\lib\\asyncio\\base_events.py\", line 1909, in _run_once\n",
      "    handle._run()\n",
      "  File \"C:\\actions-runner\\_work\\_tool\\Python\\3.10.11\\x64\\lib\\asyncio\\events.py\", line 80, in _run\n",
      "    self._context.run(self._callback, *self._args)\n",
      "  File \"C:\\actions-runner\\_work\\pyedb\\pyedb\\.venv\\lib\\site-packages\\ipykernel\\kernelbase.py\", line 545, in dispatch_queue\n",
      "    await self.process_one()\n",
      "  File \"C:\\actions-runner\\_work\\pyedb\\pyedb\\.venv\\lib\\site-packages\\ipykernel\\kernelbase.py\", line 534, in process_one\n",
      "    await dispatch(*args)\n",
      "  File \"C:\\actions-runner\\_work\\pyedb\\pyedb\\.venv\\lib\\site-packages\\ipykernel\\kernelbase.py\", line 437, in dispatch_shell\n",
      "    await result\n",
      "  File \"C:\\actions-runner\\_work\\pyedb\\pyedb\\.venv\\lib\\site-packages\\ipykernel\\ipkernel.py\", line 362, in execute_request\n",
      "    await super().execute_request(stream, ident, parent)\n",
      "  File \"C:\\actions-runner\\_work\\pyedb\\pyedb\\.venv\\lib\\site-packages\\ipykernel\\kernelbase.py\", line 778, in execute_request\n",
      "    reply_content = await reply_content\n",
      "  File \"C:\\actions-runner\\_work\\pyedb\\pyedb\\.venv\\lib\\site-packages\\ipykernel\\ipkernel.py\", line 449, in do_execute\n",
      "    res = shell.run_cell(\n",
      "  File \"C:\\actions-runner\\_work\\pyedb\\pyedb\\.venv\\lib\\site-packages\\ipykernel\\zmqshell.py\", line 549, in run_cell\n",
      "    return super().run_cell(*args, **kwargs)\n",
      "  File \"C:\\actions-runner\\_work\\pyedb\\pyedb\\.venv\\lib\\site-packages\\IPython\\core\\interactiveshell.py\", line 3075, in run_cell\n",
      "    result = self._run_cell(\n",
      "  File \"C:\\actions-runner\\_work\\pyedb\\pyedb\\.venv\\lib\\site-packages\\IPython\\core\\interactiveshell.py\", line 3130, in _run_cell\n",
      "    result = runner(coro)\n",
      "  File \"C:\\actions-runner\\_work\\pyedb\\pyedb\\.venv\\lib\\site-packages\\IPython\\core\\async_helpers.py\", line 128, in _pseudo_sync_runner\n",
      "    coro.send(None)\n",
      "  File \"C:\\actions-runner\\_work\\pyedb\\pyedb\\.venv\\lib\\site-packages\\IPython\\core\\interactiveshell.py\", line 3334, in run_cell_async\n",
      "    has_raised = await self.run_ast_nodes(code_ast.body, cell_name,\n",
      "  File \"C:\\actions-runner\\_work\\pyedb\\pyedb\\.venv\\lib\\site-packages\\IPython\\core\\interactiveshell.py\", line 3517, in run_ast_nodes\n",
      "    if await self.run_code(code, result, async_=asy):\n",
      "  File \"C:\\actions-runner\\_work\\pyedb\\pyedb\\.venv\\lib\\site-packages\\IPython\\core\\interactiveshell.py\", line 3577, in run_code\n",
      "    exec(code_obj, self.user_global_ns, self.user_ns)\n",
      "  File \"C:\\Users\\ansys\\AppData\\Local\\Temp\\ipykernel_12908\\3629736421.py\", line 2, in <module>\n",
      "    edbapp = Edb(edbpath=targetfile, edbversion=EDB_VERSION)\n",
      "  File \"C:\\actions-runner\\_work\\pyedb\\pyedb\\.venv\\lib\\site-packages\\pyedb\\generic\\design_types.py\", line 110, in Edb\n",
      "    return app(\n",
      "  File \"C:\\actions-runner\\_work\\pyedb\\pyedb\\.venv\\lib\\site-packages\\pyedb\\dotnet\\edb.py\", line 196, in __init__\n",
      "    Database.__init__(self, edbversion=edbversion, student_version=student_version)\n",
      "  File \"C:\\actions-runner\\_work\\pyedb\\pyedb\\.venv\\lib\\site-packages\\pyedb\\dotnet\\edb_core\\dotnet\\database.py\", line 802, in __init__\n",
      "    EdbDotNet.__init__(self, edbversion=edbversion, student_version=student_version)\n",
      "  File \"C:\\actions-runner\\_work\\pyedb\\pyedb\\.venv\\lib\\site-packages\\pyedb\\dotnet\\edb_core\\dotnet\\database.py\", line 703, in __init__\n",
      "    self._logger.enable_stdout_log()\n",
      "  File \"C:\\actions-runner\\_work\\pyedb\\pyedb\\.venv\\lib\\site-packages\\pyedb\\edb_logger.py\", line 318, in enable_stdout_log\n",
      "    self.info(\"StdOut is enabled\")\n",
      "  File \"C:\\actions-runner\\_work\\pyedb\\pyedb\\.venv\\lib\\site-packages\\pyedb\\edb_logger.py\", line 346, in info\n",
      "    return self._log_on_handler(0, msg, *args, **kwargs)\n",
      "  File \"C:\\actions-runner\\_work\\pyedb\\pyedb\\.venv\\lib\\site-packages\\pyedb\\edb_logger.py\", line 293, in _log_on_handler\n",
      "    self._global.info(message_text, *args, **kwargs)\n",
      "Message: 'StdOut is enabled'\n",
      "Arguments: ()\n",
      "--- Logging error ---\n",
      "Traceback (most recent call last):\n",
      "  File \"C:\\actions-runner\\_work\\_tool\\Python\\3.10.11\\x64\\lib\\logging\\handlers.py\", line 74, in emit\n",
      "    self.doRollover()\n",
      "  File \"C:\\actions-runner\\_work\\_tool\\Python\\3.10.11\\x64\\lib\\logging\\handlers.py\", line 179, in doRollover\n",
      "    self.rotate(self.baseFilename, dfn)\n",
      "  File \"C:\\actions-runner\\_work\\_tool\\Python\\3.10.11\\x64\\lib\\logging\\handlers.py\", line 115, in rotate\n",
      "    os.rename(source, dest)\n",
      "PermissionError: [WinError 32] The process cannot access the file because it is being used by another process: 'C:\\\\Users\\\\ansys\\\\AppData\\\\Local\\\\Temp\\\\pyedb_ansys.log' -> 'C:\\\\Users\\\\ansys\\\\AppData\\\\Local\\\\Temp\\\\pyedb_ansys.log.1'\n",
      "Call stack:\n",
      "  File \"C:\\actions-runner\\_work\\_tool\\Python\\3.10.11\\x64\\lib\\runpy.py\", line 196, in _run_module_as_main\n",
      "    return _run_code(code, main_globals, None,\n",
      "  File \"C:\\actions-runner\\_work\\_tool\\Python\\3.10.11\\x64\\lib\\runpy.py\", line 86, in _run_code\n",
      "    exec(code, run_globals)\n",
      "  File \"C:\\actions-runner\\_work\\pyedb\\pyedb\\.venv\\lib\\site-packages\\ipykernel_launcher.py\", line 18, in <module>\n",
      "    app.launch_new_instance()\n",
      "  File \"C:\\actions-runner\\_work\\pyedb\\pyedb\\.venv\\lib\\site-packages\\traitlets\\config\\application.py\", line 1075, in launch_instance\n",
      "    app.start()\n",
      "  File \"C:\\actions-runner\\_work\\pyedb\\pyedb\\.venv\\lib\\site-packages\\ipykernel\\kernelapp.py\", line 739, in start\n",
      "    self.io_loop.start()\n",
      "  File \"C:\\actions-runner\\_work\\pyedb\\pyedb\\.venv\\lib\\site-packages\\tornado\\platform\\asyncio.py\", line 205, in start\n",
      "    self.asyncio_loop.run_forever()\n",
      "  File \"C:\\actions-runner\\_work\\_tool\\Python\\3.10.11\\x64\\lib\\asyncio\\base_events.py\", line 603, in run_forever\n",
      "    self._run_once()\n",
      "  File \"C:\\actions-runner\\_work\\_tool\\Python\\3.10.11\\x64\\lib\\asyncio\\base_events.py\", line 1909, in _run_once\n",
      "    handle._run()\n",
      "  File \"C:\\actions-runner\\_work\\_tool\\Python\\3.10.11\\x64\\lib\\asyncio\\events.py\", line 80, in _run\n",
      "    self._context.run(self._callback, *self._args)\n",
      "  File \"C:\\actions-runner\\_work\\pyedb\\pyedb\\.venv\\lib\\site-packages\\ipykernel\\kernelbase.py\", line 545, in dispatch_queue\n",
      "    await self.process_one()\n",
      "  File \"C:\\actions-runner\\_work\\pyedb\\pyedb\\.venv\\lib\\site-packages\\ipykernel\\kernelbase.py\", line 534, in process_one\n",
      "    await dispatch(*args)\n",
      "  File \"C:\\actions-runner\\_work\\pyedb\\pyedb\\.venv\\lib\\site-packages\\ipykernel\\kernelbase.py\", line 437, in dispatch_shell\n",
      "    await result\n",
      "  File \"C:\\actions-runner\\_work\\pyedb\\pyedb\\.venv\\lib\\site-packages\\ipykernel\\ipkernel.py\", line 362, in execute_request\n",
      "    await super().execute_request(stream, ident, parent)\n",
      "  File \"C:\\actions-runner\\_work\\pyedb\\pyedb\\.venv\\lib\\site-packages\\ipykernel\\kernelbase.py\", line 778, in execute_request\n",
      "    reply_content = await reply_content\n",
      "  File \"C:\\actions-runner\\_work\\pyedb\\pyedb\\.venv\\lib\\site-packages\\ipykernel\\ipkernel.py\", line 449, in do_execute\n",
      "    res = shell.run_cell(\n",
      "  File \"C:\\actions-runner\\_work\\pyedb\\pyedb\\.venv\\lib\\site-packages\\ipykernel\\zmqshell.py\", line 549, in run_cell\n",
      "    return super().run_cell(*args, **kwargs)\n",
      "  File \"C:\\actions-runner\\_work\\pyedb\\pyedb\\.venv\\lib\\site-packages\\IPython\\core\\interactiveshell.py\", line 3075, in run_cell\n",
      "    result = self._run_cell(\n",
      "  File \"C:\\actions-runner\\_work\\pyedb\\pyedb\\.venv\\lib\\site-packages\\IPython\\core\\interactiveshell.py\", line 3130, in _run_cell\n",
      "    result = runner(coro)\n",
      "  File \"C:\\actions-runner\\_work\\pyedb\\pyedb\\.venv\\lib\\site-packages\\IPython\\core\\async_helpers.py\", line 128, in _pseudo_sync_runner\n",
      "    coro.send(None)\n",
      "  File \"C:\\actions-runner\\_work\\pyedb\\pyedb\\.venv\\lib\\site-packages\\IPython\\core\\interactiveshell.py\", line 3334, in run_cell_async\n",
      "    has_raised = await self.run_ast_nodes(code_ast.body, cell_name,\n",
      "  File \"C:\\actions-runner\\_work\\pyedb\\pyedb\\.venv\\lib\\site-packages\\IPython\\core\\interactiveshell.py\", line 3517, in run_ast_nodes\n",
      "    if await self.run_code(code, result, async_=asy):\n",
      "  File \"C:\\actions-runner\\_work\\pyedb\\pyedb\\.venv\\lib\\site-packages\\IPython\\core\\interactiveshell.py\", line 3577, in run_code\n",
      "    exec(code_obj, self.user_global_ns, self.user_ns)\n",
      "  File \"C:\\Users\\ansys\\AppData\\Local\\Temp\\ipykernel_12908\\3629736421.py\", line 2, in <module>\n",
      "    edbapp = Edb(edbpath=targetfile, edbversion=EDB_VERSION)\n",
      "  File \"C:\\actions-runner\\_work\\pyedb\\pyedb\\.venv\\lib\\site-packages\\pyedb\\generic\\design_types.py\", line 110, in Edb\n",
      "    return app(\n",
      "  File \"C:\\actions-runner\\_work\\pyedb\\pyedb\\.venv\\lib\\site-packages\\pyedb\\dotnet\\edb.py\", line 196, in __init__\n",
      "    Database.__init__(self, edbversion=edbversion, student_version=student_version)\n",
      "  File \"C:\\actions-runner\\_work\\pyedb\\pyedb\\.venv\\lib\\site-packages\\pyedb\\dotnet\\edb_core\\dotnet\\database.py\", line 802, in __init__\n",
      "    EdbDotNet.__init__(self, edbversion=edbversion, student_version=student_version)\n",
      "  File \"C:\\actions-runner\\_work\\pyedb\\pyedb\\.venv\\lib\\site-packages\\pyedb\\dotnet\\edb_core\\dotnet\\database.py\", line 709, in __init__\n",
      "    self._logger.info(\"Logger is initialized in EDB.\")\n",
      "  File \"C:\\actions-runner\\_work\\pyedb\\pyedb\\.venv\\lib\\site-packages\\pyedb\\edb_logger.py\", line 346, in info\n",
      "    return self._log_on_handler(0, msg, *args, **kwargs)\n",
      "  File \"C:\\actions-runner\\_work\\pyedb\\pyedb\\.venv\\lib\\site-packages\\pyedb\\edb_logger.py\", line 293, in _log_on_handler\n",
      "    self._global.info(message_text, *args, **kwargs)\n",
      "Message: 'Logger is initialized in EDB.'\n",
      "Arguments: ()\n",
      "--- Logging error ---\n",
      "Traceback (most recent call last):\n",
      "  File \"C:\\actions-runner\\_work\\_tool\\Python\\3.10.11\\x64\\lib\\logging\\handlers.py\", line 74, in emit\n",
      "    self.doRollover()\n",
      "  File \"C:\\actions-runner\\_work\\_tool\\Python\\3.10.11\\x64\\lib\\logging\\handlers.py\", line 179, in doRollover\n",
      "    self.rotate(self.baseFilename, dfn)\n",
      "  File \"C:\\actions-runner\\_work\\_tool\\Python\\3.10.11\\x64\\lib\\logging\\handlers.py\", line 115, in rotate\n",
      "    os.rename(source, dest)\n",
      "PermissionError: [WinError 32] The process cannot access the file because it is being used by another process: 'C:\\\\Users\\\\ansys\\\\AppData\\\\Local\\\\Temp\\\\pyedb_ansys.log' -> 'C:\\\\Users\\\\ansys\\\\AppData\\\\Local\\\\Temp\\\\pyedb_ansys.log.1'\n",
      "Call stack:\n",
      "  File \"C:\\actions-runner\\_work\\_tool\\Python\\3.10.11\\x64\\lib\\runpy.py\", line 196, in _run_module_as_main\n",
      "    return _run_code(code, main_globals, None,\n",
      "  File \"C:\\actions-runner\\_work\\_tool\\Python\\3.10.11\\x64\\lib\\runpy.py\", line 86, in _run_code\n",
      "    exec(code, run_globals)\n",
      "  File \"C:\\actions-runner\\_work\\pyedb\\pyedb\\.venv\\lib\\site-packages\\ipykernel_launcher.py\", line 18, in <module>\n",
      "    app.launch_new_instance()\n",
      "  File \"C:\\actions-runner\\_work\\pyedb\\pyedb\\.venv\\lib\\site-packages\\traitlets\\config\\application.py\", line 1075, in launch_instance\n",
      "    app.start()\n",
      "  File \"C:\\actions-runner\\_work\\pyedb\\pyedb\\.venv\\lib\\site-packages\\ipykernel\\kernelapp.py\", line 739, in start\n",
      "    self.io_loop.start()\n",
      "  File \"C:\\actions-runner\\_work\\pyedb\\pyedb\\.venv\\lib\\site-packages\\tornado\\platform\\asyncio.py\", line 205, in start\n",
      "    self.asyncio_loop.run_forever()\n",
      "  File \"C:\\actions-runner\\_work\\_tool\\Python\\3.10.11\\x64\\lib\\asyncio\\base_events.py\", line 603, in run_forever\n",
      "    self._run_once()\n",
      "  File \"C:\\actions-runner\\_work\\_tool\\Python\\3.10.11\\x64\\lib\\asyncio\\base_events.py\", line 1909, in _run_once\n",
      "    handle._run()\n",
      "  File \"C:\\actions-runner\\_work\\_tool\\Python\\3.10.11\\x64\\lib\\asyncio\\events.py\", line 80, in _run\n",
      "    self._context.run(self._callback, *self._args)\n",
      "  File \"C:\\actions-runner\\_work\\pyedb\\pyedb\\.venv\\lib\\site-packages\\ipykernel\\kernelbase.py\", line 545, in dispatch_queue\n",
      "    await self.process_one()\n",
      "  File \"C:\\actions-runner\\_work\\pyedb\\pyedb\\.venv\\lib\\site-packages\\ipykernel\\kernelbase.py\", line 534, in process_one\n",
      "    await dispatch(*args)\n",
      "  File \"C:\\actions-runner\\_work\\pyedb\\pyedb\\.venv\\lib\\site-packages\\ipykernel\\kernelbase.py\", line 437, in dispatch_shell\n",
      "    await result\n",
      "  File \"C:\\actions-runner\\_work\\pyedb\\pyedb\\.venv\\lib\\site-packages\\ipykernel\\ipkernel.py\", line 362, in execute_request\n",
      "    await super().execute_request(stream, ident, parent)\n",
      "  File \"C:\\actions-runner\\_work\\pyedb\\pyedb\\.venv\\lib\\site-packages\\ipykernel\\kernelbase.py\", line 778, in execute_request\n",
      "    reply_content = await reply_content\n",
      "  File \"C:\\actions-runner\\_work\\pyedb\\pyedb\\.venv\\lib\\site-packages\\ipykernel\\ipkernel.py\", line 449, in do_execute\n",
      "    res = shell.run_cell(\n",
      "  File \"C:\\actions-runner\\_work\\pyedb\\pyedb\\.venv\\lib\\site-packages\\ipykernel\\zmqshell.py\", line 549, in run_cell\n",
      "    return super().run_cell(*args, **kwargs)\n",
      "  File \"C:\\actions-runner\\_work\\pyedb\\pyedb\\.venv\\lib\\site-packages\\IPython\\core\\interactiveshell.py\", line 3075, in run_cell\n",
      "    result = self._run_cell(\n",
      "  File \"C:\\actions-runner\\_work\\pyedb\\pyedb\\.venv\\lib\\site-packages\\IPython\\core\\interactiveshell.py\", line 3130, in _run_cell\n",
      "    result = runner(coro)\n",
      "  File \"C:\\actions-runner\\_work\\pyedb\\pyedb\\.venv\\lib\\site-packages\\IPython\\core\\async_helpers.py\", line 128, in _pseudo_sync_runner\n",
      "    coro.send(None)\n",
      "  File \"C:\\actions-runner\\_work\\pyedb\\pyedb\\.venv\\lib\\site-packages\\IPython\\core\\interactiveshell.py\", line 3334, in run_cell_async\n",
      "    has_raised = await self.run_ast_nodes(code_ast.body, cell_name,\n",
      "  File \"C:\\actions-runner\\_work\\pyedb\\pyedb\\.venv\\lib\\site-packages\\IPython\\core\\interactiveshell.py\", line 3517, in run_ast_nodes\n",
      "    if await self.run_code(code, result, async_=asy):\n",
      "  File \"C:\\actions-runner\\_work\\pyedb\\pyedb\\.venv\\lib\\site-packages\\IPython\\core\\interactiveshell.py\", line 3577, in run_code\n",
      "    exec(code_obj, self.user_global_ns, self.user_ns)\n",
      "  File \"C:\\Users\\ansys\\AppData\\Local\\Temp\\ipykernel_12908\\3629736421.py\", line 2, in <module>\n",
      "    edbapp = Edb(edbpath=targetfile, edbversion=EDB_VERSION)\n",
      "  File \"C:\\actions-runner\\_work\\pyedb\\pyedb\\.venv\\lib\\site-packages\\pyedb\\generic\\design_types.py\", line 110, in Edb\n",
      "    return app(\n",
      "  File \"C:\\actions-runner\\_work\\pyedb\\pyedb\\.venv\\lib\\site-packages\\pyedb\\dotnet\\edb.py\", line 196, in __init__\n",
      "    Database.__init__(self, edbversion=edbversion, student_version=student_version)\n",
      "  File \"C:\\actions-runner\\_work\\pyedb\\pyedb\\.venv\\lib\\site-packages\\pyedb\\dotnet\\edb_core\\dotnet\\database.py\", line 802, in __init__\n",
      "    EdbDotNet.__init__(self, edbversion=edbversion, student_version=student_version)\n",
      "  File \"C:\\actions-runner\\_work\\pyedb\\pyedb\\.venv\\lib\\site-packages\\pyedb\\dotnet\\edb_core\\dotnet\\database.py\", line 710, in __init__\n",
      "    self._logger.info(\"legacy v%s\", __version__)\n",
      "  File \"C:\\actions-runner\\_work\\pyedb\\pyedb\\.venv\\lib\\site-packages\\pyedb\\edb_logger.py\", line 346, in info\n",
      "    return self._log_on_handler(0, msg, *args, **kwargs)\n",
      "  File \"C:\\actions-runner\\_work\\pyedb\\pyedb\\.venv\\lib\\site-packages\\pyedb\\edb_logger.py\", line 293, in _log_on_handler\n",
      "    self._global.info(message_text, *args, **kwargs)\n",
      "Message: 'legacy v%s'\n",
      "Arguments: ('0.35.0',)\n",
      "--- Logging error ---\n",
      "Traceback (most recent call last):\n",
      "  File \"C:\\actions-runner\\_work\\_tool\\Python\\3.10.11\\x64\\lib\\logging\\handlers.py\", line 74, in emit\n",
      "    self.doRollover()\n",
      "  File \"C:\\actions-runner\\_work\\_tool\\Python\\3.10.11\\x64\\lib\\logging\\handlers.py\", line 179, in doRollover\n",
      "    self.rotate(self.baseFilename, dfn)\n",
      "  File \"C:\\actions-runner\\_work\\_tool\\Python\\3.10.11\\x64\\lib\\logging\\handlers.py\", line 115, in rotate\n",
      "    os.rename(source, dest)\n",
      "PermissionError: [WinError 32] The process cannot access the file because it is being used by another process: 'C:\\\\Users\\\\ansys\\\\AppData\\\\Local\\\\Temp\\\\pyedb_ansys.log' -> 'C:\\\\Users\\\\ansys\\\\AppData\\\\Local\\\\Temp\\\\pyedb_ansys.log.1'\n",
      "Call stack:\n",
      "  File \"C:\\actions-runner\\_work\\_tool\\Python\\3.10.11\\x64\\lib\\runpy.py\", line 196, in _run_module_as_main\n",
      "    return _run_code(code, main_globals, None,\n",
      "  File \"C:\\actions-runner\\_work\\_tool\\Python\\3.10.11\\x64\\lib\\runpy.py\", line 86, in _run_code\n",
      "    exec(code, run_globals)\n",
      "  File \"C:\\actions-runner\\_work\\pyedb\\pyedb\\.venv\\lib\\site-packages\\ipykernel_launcher.py\", line 18, in <module>\n",
      "    app.launch_new_instance()\n",
      "  File \"C:\\actions-runner\\_work\\pyedb\\pyedb\\.venv\\lib\\site-packages\\traitlets\\config\\application.py\", line 1075, in launch_instance\n",
      "    app.start()\n",
      "  File \"C:\\actions-runner\\_work\\pyedb\\pyedb\\.venv\\lib\\site-packages\\ipykernel\\kernelapp.py\", line 739, in start\n",
      "    self.io_loop.start()\n",
      "  File \"C:\\actions-runner\\_work\\pyedb\\pyedb\\.venv\\lib\\site-packages\\tornado\\platform\\asyncio.py\", line 205, in start\n",
      "    self.asyncio_loop.run_forever()\n",
      "  File \"C:\\actions-runner\\_work\\_tool\\Python\\3.10.11\\x64\\lib\\asyncio\\base_events.py\", line 603, in run_forever\n",
      "    self._run_once()\n",
      "  File \"C:\\actions-runner\\_work\\_tool\\Python\\3.10.11\\x64\\lib\\asyncio\\base_events.py\", line 1909, in _run_once\n",
      "    handle._run()\n",
      "  File \"C:\\actions-runner\\_work\\_tool\\Python\\3.10.11\\x64\\lib\\asyncio\\events.py\", line 80, in _run\n",
      "    self._context.run(self._callback, *self._args)\n",
      "  File \"C:\\actions-runner\\_work\\pyedb\\pyedb\\.venv\\lib\\site-packages\\ipykernel\\kernelbase.py\", line 545, in dispatch_queue\n",
      "    await self.process_one()\n",
      "  File \"C:\\actions-runner\\_work\\pyedb\\pyedb\\.venv\\lib\\site-packages\\ipykernel\\kernelbase.py\", line 534, in process_one\n",
      "    await dispatch(*args)\n",
      "  File \"C:\\actions-runner\\_work\\pyedb\\pyedb\\.venv\\lib\\site-packages\\ipykernel\\kernelbase.py\", line 437, in dispatch_shell\n",
      "    await result\n",
      "  File \"C:\\actions-runner\\_work\\pyedb\\pyedb\\.venv\\lib\\site-packages\\ipykernel\\ipkernel.py\", line 362, in execute_request\n",
      "    await super().execute_request(stream, ident, parent)\n",
      "  File \"C:\\actions-runner\\_work\\pyedb\\pyedb\\.venv\\lib\\site-packages\\ipykernel\\kernelbase.py\", line 778, in execute_request\n",
      "    reply_content = await reply_content\n",
      "  File \"C:\\actions-runner\\_work\\pyedb\\pyedb\\.venv\\lib\\site-packages\\ipykernel\\ipkernel.py\", line 449, in do_execute\n",
      "    res = shell.run_cell(\n",
      "  File \"C:\\actions-runner\\_work\\pyedb\\pyedb\\.venv\\lib\\site-packages\\ipykernel\\zmqshell.py\", line 549, in run_cell\n",
      "    return super().run_cell(*args, **kwargs)\n",
      "  File \"C:\\actions-runner\\_work\\pyedb\\pyedb\\.venv\\lib\\site-packages\\IPython\\core\\interactiveshell.py\", line 3075, in run_cell\n",
      "    result = self._run_cell(\n",
      "  File \"C:\\actions-runner\\_work\\pyedb\\pyedb\\.venv\\lib\\site-packages\\IPython\\core\\interactiveshell.py\", line 3130, in _run_cell\n",
      "    result = runner(coro)\n",
      "  File \"C:\\actions-runner\\_work\\pyedb\\pyedb\\.venv\\lib\\site-packages\\IPython\\core\\async_helpers.py\", line 128, in _pseudo_sync_runner\n",
      "    coro.send(None)\n",
      "  File \"C:\\actions-runner\\_work\\pyedb\\pyedb\\.venv\\lib\\site-packages\\IPython\\core\\interactiveshell.py\", line 3334, in run_cell_async\n",
      "    has_raised = await self.run_ast_nodes(code_ast.body, cell_name,\n",
      "  File \"C:\\actions-runner\\_work\\pyedb\\pyedb\\.venv\\lib\\site-packages\\IPython\\core\\interactiveshell.py\", line 3517, in run_ast_nodes\n",
      "    if await self.run_code(code, result, async_=asy):\n",
      "  File \"C:\\actions-runner\\_work\\pyedb\\pyedb\\.venv\\lib\\site-packages\\IPython\\core\\interactiveshell.py\", line 3577, in run_code\n",
      "    exec(code_obj, self.user_global_ns, self.user_ns)\n",
      "  File \"C:\\Users\\ansys\\AppData\\Local\\Temp\\ipykernel_12908\\3629736421.py\", line 2, in <module>\n",
      "    edbapp = Edb(edbpath=targetfile, edbversion=EDB_VERSION)\n",
      "  File \"C:\\actions-runner\\_work\\pyedb\\pyedb\\.venv\\lib\\site-packages\\pyedb\\generic\\design_types.py\", line 110, in Edb\n",
      "    return app(\n",
      "  File \"C:\\actions-runner\\_work\\pyedb\\pyedb\\.venv\\lib\\site-packages\\pyedb\\dotnet\\edb.py\", line 196, in __init__\n",
      "    Database.__init__(self, edbversion=edbversion, student_version=student_version)\n",
      "  File \"C:\\actions-runner\\_work\\pyedb\\pyedb\\.venv\\lib\\site-packages\\pyedb\\dotnet\\edb_core\\dotnet\\database.py\", line 802, in __init__\n",
      "    EdbDotNet.__init__(self, edbversion=edbversion, student_version=student_version)\n",
      "  File \"C:\\actions-runner\\_work\\pyedb\\pyedb\\.venv\\lib\\site-packages\\pyedb\\dotnet\\edb_core\\dotnet\\database.py\", line 711, in __init__\n",
      "    self._logger.info(\"Python version %s\", sys.version)\n",
      "  File \"C:\\actions-runner\\_work\\pyedb\\pyedb\\.venv\\lib\\site-packages\\pyedb\\edb_logger.py\", line 346, in info\n",
      "    return self._log_on_handler(0, msg, *args, **kwargs)\n",
      "  File \"C:\\actions-runner\\_work\\pyedb\\pyedb\\.venv\\lib\\site-packages\\pyedb\\edb_logger.py\", line 293, in _log_on_handler\n",
      "    self._global.info(message_text, *args, **kwargs)\n",
      "Message: 'Python version %s'\n",
      "Arguments: ('3.10.11 (tags/v3.10.11:7d4cc5a, Apr  5 2023, 00:38:17) [MSC v.1929 64 bit (AMD64)]',)\n"
     ]
    },
    {
     "name": "stdout",
     "output_type": "stream",
     "text": [
      "PyEDB INFO: Database ANSYS-HSD_V1.aedb Opened in 2024.2\n"
     ]
    },
    {
     "name": "stdout",
     "output_type": "stream",
     "text": [
      "PyEDB INFO: Cell main Opened\n"
     ]
    },
    {
     "name": "stdout",
     "output_type": "stream",
     "text": [
      "PyEDB INFO: Builder was initialized.\n"
     ]
    },
    {
     "name": "stdout",
     "output_type": "stream",
     "text": [
      "PyEDB INFO: EDB initialized.\n"
     ]
    },
    {
     "name": "stderr",
     "output_type": "stream",
     "text": [
      "--- Logging error ---\n",
      "Traceback (most recent call last):\n",
      "  File \"C:\\actions-runner\\_work\\_tool\\Python\\3.10.11\\x64\\lib\\logging\\handlers.py\", line 74, in emit\n",
      "    self.doRollover()\n",
      "  File \"C:\\actions-runner\\_work\\_tool\\Python\\3.10.11\\x64\\lib\\logging\\handlers.py\", line 179, in doRollover\n",
      "    self.rotate(self.baseFilename, dfn)\n",
      "  File \"C:\\actions-runner\\_work\\_tool\\Python\\3.10.11\\x64\\lib\\logging\\handlers.py\", line 115, in rotate\n",
      "    os.rename(source, dest)\n",
      "PermissionError: [WinError 32] The process cannot access the file because it is being used by another process: 'C:\\\\Users\\\\ansys\\\\AppData\\\\Local\\\\Temp\\\\pyedb_ansys.log' -> 'C:\\\\Users\\\\ansys\\\\AppData\\\\Local\\\\Temp\\\\pyedb_ansys.log.1'\n",
      "Call stack:\n",
      "  File \"C:\\actions-runner\\_work\\_tool\\Python\\3.10.11\\x64\\lib\\runpy.py\", line 196, in _run_module_as_main\n",
      "    return _run_code(code, main_globals, None,\n",
      "  File \"C:\\actions-runner\\_work\\_tool\\Python\\3.10.11\\x64\\lib\\runpy.py\", line 86, in _run_code\n",
      "    exec(code, run_globals)\n",
      "  File \"C:\\actions-runner\\_work\\pyedb\\pyedb\\.venv\\lib\\site-packages\\ipykernel_launcher.py\", line 18, in <module>\n",
      "    app.launch_new_instance()\n",
      "  File \"C:\\actions-runner\\_work\\pyedb\\pyedb\\.venv\\lib\\site-packages\\traitlets\\config\\application.py\", line 1075, in launch_instance\n",
      "    app.start()\n",
      "  File \"C:\\actions-runner\\_work\\pyedb\\pyedb\\.venv\\lib\\site-packages\\ipykernel\\kernelapp.py\", line 739, in start\n",
      "    self.io_loop.start()\n",
      "  File \"C:\\actions-runner\\_work\\pyedb\\pyedb\\.venv\\lib\\site-packages\\tornado\\platform\\asyncio.py\", line 205, in start\n",
      "    self.asyncio_loop.run_forever()\n",
      "  File \"C:\\actions-runner\\_work\\_tool\\Python\\3.10.11\\x64\\lib\\asyncio\\base_events.py\", line 603, in run_forever\n",
      "    self._run_once()\n",
      "  File \"C:\\actions-runner\\_work\\_tool\\Python\\3.10.11\\x64\\lib\\asyncio\\base_events.py\", line 1909, in _run_once\n",
      "    handle._run()\n",
      "  File \"C:\\actions-runner\\_work\\_tool\\Python\\3.10.11\\x64\\lib\\asyncio\\events.py\", line 80, in _run\n",
      "    self._context.run(self._callback, *self._args)\n",
      "  File \"C:\\actions-runner\\_work\\pyedb\\pyedb\\.venv\\lib\\site-packages\\ipykernel\\kernelbase.py\", line 545, in dispatch_queue\n",
      "    await self.process_one()\n",
      "  File \"C:\\actions-runner\\_work\\pyedb\\pyedb\\.venv\\lib\\site-packages\\ipykernel\\kernelbase.py\", line 534, in process_one\n",
      "    await dispatch(*args)\n",
      "  File \"C:\\actions-runner\\_work\\pyedb\\pyedb\\.venv\\lib\\site-packages\\ipykernel\\kernelbase.py\", line 437, in dispatch_shell\n",
      "    await result\n",
      "  File \"C:\\actions-runner\\_work\\pyedb\\pyedb\\.venv\\lib\\site-packages\\ipykernel\\ipkernel.py\", line 362, in execute_request\n",
      "    await super().execute_request(stream, ident, parent)\n",
      "  File \"C:\\actions-runner\\_work\\pyedb\\pyedb\\.venv\\lib\\site-packages\\ipykernel\\kernelbase.py\", line 778, in execute_request\n",
      "    reply_content = await reply_content\n",
      "  File \"C:\\actions-runner\\_work\\pyedb\\pyedb\\.venv\\lib\\site-packages\\ipykernel\\ipkernel.py\", line 449, in do_execute\n",
      "    res = shell.run_cell(\n",
      "  File \"C:\\actions-runner\\_work\\pyedb\\pyedb\\.venv\\lib\\site-packages\\ipykernel\\zmqshell.py\", line 549, in run_cell\n",
      "    return super().run_cell(*args, **kwargs)\n",
      "  File \"C:\\actions-runner\\_work\\pyedb\\pyedb\\.venv\\lib\\site-packages\\IPython\\core\\interactiveshell.py\", line 3075, in run_cell\n",
      "    result = self._run_cell(\n",
      "  File \"C:\\actions-runner\\_work\\pyedb\\pyedb\\.venv\\lib\\site-packages\\IPython\\core\\interactiveshell.py\", line 3130, in _run_cell\n",
      "    result = runner(coro)\n",
      "  File \"C:\\actions-runner\\_work\\pyedb\\pyedb\\.venv\\lib\\site-packages\\IPython\\core\\async_helpers.py\", line 128, in _pseudo_sync_runner\n",
      "    coro.send(None)\n",
      "  File \"C:\\actions-runner\\_work\\pyedb\\pyedb\\.venv\\lib\\site-packages\\IPython\\core\\interactiveshell.py\", line 3334, in run_cell_async\n",
      "    has_raised = await self.run_ast_nodes(code_ast.body, cell_name,\n",
      "  File \"C:\\actions-runner\\_work\\pyedb\\pyedb\\.venv\\lib\\site-packages\\IPython\\core\\interactiveshell.py\", line 3517, in run_ast_nodes\n",
      "    if await self.run_code(code, result, async_=asy):\n",
      "  File \"C:\\actions-runner\\_work\\pyedb\\pyedb\\.venv\\lib\\site-packages\\IPython\\core\\interactiveshell.py\", line 3577, in run_code\n",
      "    exec(code_obj, self.user_global_ns, self.user_ns)\n",
      "  File \"C:\\Users\\ansys\\AppData\\Local\\Temp\\ipykernel_12908\\3629736421.py\", line 2, in <module>\n",
      "    edbapp = Edb(edbpath=targetfile, edbversion=EDB_VERSION)\n",
      "  File \"C:\\actions-runner\\_work\\pyedb\\pyedb\\.venv\\lib\\site-packages\\pyedb\\generic\\design_types.py\", line 110, in Edb\n",
      "    return app(\n",
      "  File \"C:\\actions-runner\\_work\\pyedb\\pyedb\\.venv\\lib\\site-packages\\pyedb\\dotnet\\edb.py\", line 276, in __init__\n",
      "    self.open_edb()\n",
      "  File \"C:\\actions-runner\\_work\\pyedb\\pyedb\\.venv\\lib\\site-packages\\pyedb\\dotnet\\edb.py\", line 554, in open_edb\n",
      "    self.logger.info(\"Database {} Opened in {}\".format(os.path.split(self.edbpath)[-1], self.edbversion))\n",
      "  File \"C:\\actions-runner\\_work\\pyedb\\pyedb\\.venv\\lib\\site-packages\\pyedb\\edb_logger.py\", line 346, in info\n",
      "    return self._log_on_handler(0, msg, *args, **kwargs)\n",
      "  File \"C:\\actions-runner\\_work\\pyedb\\pyedb\\.venv\\lib\\site-packages\\pyedb\\edb_logger.py\", line 293, in _log_on_handler\n",
      "    self._global.info(message_text, *args, **kwargs)\n",
      "Message: 'Database ANSYS-HSD_V1.aedb Opened in 2024.2'\n",
      "Arguments: ()\n",
      "--- Logging error ---\n",
      "Traceback (most recent call last):\n",
      "  File \"C:\\actions-runner\\_work\\_tool\\Python\\3.10.11\\x64\\lib\\logging\\handlers.py\", line 74, in emit\n",
      "    self.doRollover()\n",
      "  File \"C:\\actions-runner\\_work\\_tool\\Python\\3.10.11\\x64\\lib\\logging\\handlers.py\", line 179, in doRollover\n",
      "    self.rotate(self.baseFilename, dfn)\n",
      "  File \"C:\\actions-runner\\_work\\_tool\\Python\\3.10.11\\x64\\lib\\logging\\handlers.py\", line 115, in rotate\n",
      "    os.rename(source, dest)\n",
      "PermissionError: [WinError 32] The process cannot access the file because it is being used by another process: 'C:\\\\Users\\\\ansys\\\\AppData\\\\Local\\\\Temp\\\\pyedb_ansys.log' -> 'C:\\\\Users\\\\ansys\\\\AppData\\\\Local\\\\Temp\\\\pyedb_ansys.log.1'\n",
      "Call stack:\n",
      "  File \"C:\\actions-runner\\_work\\_tool\\Python\\3.10.11\\x64\\lib\\runpy.py\", line 196, in _run_module_as_main\n",
      "    return _run_code(code, main_globals, None,\n",
      "  File \"C:\\actions-runner\\_work\\_tool\\Python\\3.10.11\\x64\\lib\\runpy.py\", line 86, in _run_code\n",
      "    exec(code, run_globals)\n",
      "  File \"C:\\actions-runner\\_work\\pyedb\\pyedb\\.venv\\lib\\site-packages\\ipykernel_launcher.py\", line 18, in <module>\n",
      "    app.launch_new_instance()\n",
      "  File \"C:\\actions-runner\\_work\\pyedb\\pyedb\\.venv\\lib\\site-packages\\traitlets\\config\\application.py\", line 1075, in launch_instance\n",
      "    app.start()\n",
      "  File \"C:\\actions-runner\\_work\\pyedb\\pyedb\\.venv\\lib\\site-packages\\ipykernel\\kernelapp.py\", line 739, in start\n",
      "    self.io_loop.start()\n",
      "  File \"C:\\actions-runner\\_work\\pyedb\\pyedb\\.venv\\lib\\site-packages\\tornado\\platform\\asyncio.py\", line 205, in start\n",
      "    self.asyncio_loop.run_forever()\n",
      "  File \"C:\\actions-runner\\_work\\_tool\\Python\\3.10.11\\x64\\lib\\asyncio\\base_events.py\", line 603, in run_forever\n",
      "    self._run_once()\n",
      "  File \"C:\\actions-runner\\_work\\_tool\\Python\\3.10.11\\x64\\lib\\asyncio\\base_events.py\", line 1909, in _run_once\n",
      "    handle._run()\n",
      "  File \"C:\\actions-runner\\_work\\_tool\\Python\\3.10.11\\x64\\lib\\asyncio\\events.py\", line 80, in _run\n",
      "    self._context.run(self._callback, *self._args)\n",
      "  File \"C:\\actions-runner\\_work\\pyedb\\pyedb\\.venv\\lib\\site-packages\\ipykernel\\kernelbase.py\", line 545, in dispatch_queue\n",
      "    await self.process_one()\n",
      "  File \"C:\\actions-runner\\_work\\pyedb\\pyedb\\.venv\\lib\\site-packages\\ipykernel\\kernelbase.py\", line 534, in process_one\n",
      "    await dispatch(*args)\n",
      "  File \"C:\\actions-runner\\_work\\pyedb\\pyedb\\.venv\\lib\\site-packages\\ipykernel\\kernelbase.py\", line 437, in dispatch_shell\n",
      "    await result\n",
      "  File \"C:\\actions-runner\\_work\\pyedb\\pyedb\\.venv\\lib\\site-packages\\ipykernel\\ipkernel.py\", line 362, in execute_request\n",
      "    await super().execute_request(stream, ident, parent)\n",
      "  File \"C:\\actions-runner\\_work\\pyedb\\pyedb\\.venv\\lib\\site-packages\\ipykernel\\kernelbase.py\", line 778, in execute_request\n",
      "    reply_content = await reply_content\n",
      "  File \"C:\\actions-runner\\_work\\pyedb\\pyedb\\.venv\\lib\\site-packages\\ipykernel\\ipkernel.py\", line 449, in do_execute\n",
      "    res = shell.run_cell(\n",
      "  File \"C:\\actions-runner\\_work\\pyedb\\pyedb\\.venv\\lib\\site-packages\\ipykernel\\zmqshell.py\", line 549, in run_cell\n",
      "    return super().run_cell(*args, **kwargs)\n",
      "  File \"C:\\actions-runner\\_work\\pyedb\\pyedb\\.venv\\lib\\site-packages\\IPython\\core\\interactiveshell.py\", line 3075, in run_cell\n",
      "    result = self._run_cell(\n",
      "  File \"C:\\actions-runner\\_work\\pyedb\\pyedb\\.venv\\lib\\site-packages\\IPython\\core\\interactiveshell.py\", line 3130, in _run_cell\n",
      "    result = runner(coro)\n",
      "  File \"C:\\actions-runner\\_work\\pyedb\\pyedb\\.venv\\lib\\site-packages\\IPython\\core\\async_helpers.py\", line 128, in _pseudo_sync_runner\n",
      "    coro.send(None)\n",
      "  File \"C:\\actions-runner\\_work\\pyedb\\pyedb\\.venv\\lib\\site-packages\\IPython\\core\\interactiveshell.py\", line 3334, in run_cell_async\n",
      "    has_raised = await self.run_ast_nodes(code_ast.body, cell_name,\n",
      "  File \"C:\\actions-runner\\_work\\pyedb\\pyedb\\.venv\\lib\\site-packages\\IPython\\core\\interactiveshell.py\", line 3517, in run_ast_nodes\n",
      "    if await self.run_code(code, result, async_=asy):\n",
      "  File \"C:\\actions-runner\\_work\\pyedb\\pyedb\\.venv\\lib\\site-packages\\IPython\\core\\interactiveshell.py\", line 3577, in run_code\n",
      "    exec(code_obj, self.user_global_ns, self.user_ns)\n",
      "  File \"C:\\Users\\ansys\\AppData\\Local\\Temp\\ipykernel_12908\\3629736421.py\", line 2, in <module>\n",
      "    edbapp = Edb(edbpath=targetfile, edbversion=EDB_VERSION)\n",
      "  File \"C:\\actions-runner\\_work\\pyedb\\pyedb\\.venv\\lib\\site-packages\\pyedb\\generic\\design_types.py\", line 110, in Edb\n",
      "    return app(\n",
      "  File \"C:\\actions-runner\\_work\\pyedb\\pyedb\\.venv\\lib\\site-packages\\pyedb\\dotnet\\edb.py\", line 276, in __init__\n",
      "    self.open_edb()\n",
      "  File \"C:\\actions-runner\\_work\\pyedb\\pyedb\\.venv\\lib\\site-packages\\pyedb\\dotnet\\edb.py\", line 568, in open_edb\n",
      "    self.logger.info(\"Cell %s Opened\", self._active_cell.GetName())\n",
      "  File \"C:\\actions-runner\\_work\\pyedb\\pyedb\\.venv\\lib\\site-packages\\pyedb\\edb_logger.py\", line 346, in info\n",
      "    return self._log_on_handler(0, msg, *args, **kwargs)\n",
      "  File \"C:\\actions-runner\\_work\\pyedb\\pyedb\\.venv\\lib\\site-packages\\pyedb\\edb_logger.py\", line 293, in _log_on_handler\n",
      "    self._global.info(message_text, *args, **kwargs)\n",
      "Message: 'Cell %s Opened'\n",
      "Arguments: ('main',)\n",
      "--- Logging error ---\n",
      "Traceback (most recent call last):\n",
      "  File \"C:\\actions-runner\\_work\\_tool\\Python\\3.10.11\\x64\\lib\\logging\\handlers.py\", line 74, in emit\n",
      "    self.doRollover()\n",
      "  File \"C:\\actions-runner\\_work\\_tool\\Python\\3.10.11\\x64\\lib\\logging\\handlers.py\", line 179, in doRollover\n",
      "    self.rotate(self.baseFilename, dfn)\n",
      "  File \"C:\\actions-runner\\_work\\_tool\\Python\\3.10.11\\x64\\lib\\logging\\handlers.py\", line 115, in rotate\n",
      "    os.rename(source, dest)\n",
      "PermissionError: [WinError 32] The process cannot access the file because it is being used by another process: 'C:\\\\Users\\\\ansys\\\\AppData\\\\Local\\\\Temp\\\\pyedb_ansys.log' -> 'C:\\\\Users\\\\ansys\\\\AppData\\\\Local\\\\Temp\\\\pyedb_ansys.log.1'\n",
      "Call stack:\n",
      "  File \"C:\\actions-runner\\_work\\_tool\\Python\\3.10.11\\x64\\lib\\runpy.py\", line 196, in _run_module_as_main\n",
      "    return _run_code(code, main_globals, None,\n",
      "  File \"C:\\actions-runner\\_work\\_tool\\Python\\3.10.11\\x64\\lib\\runpy.py\", line 86, in _run_code\n",
      "    exec(code, run_globals)\n",
      "  File \"C:\\actions-runner\\_work\\pyedb\\pyedb\\.venv\\lib\\site-packages\\ipykernel_launcher.py\", line 18, in <module>\n",
      "    app.launch_new_instance()\n",
      "  File \"C:\\actions-runner\\_work\\pyedb\\pyedb\\.venv\\lib\\site-packages\\traitlets\\config\\application.py\", line 1075, in launch_instance\n",
      "    app.start()\n",
      "  File \"C:\\actions-runner\\_work\\pyedb\\pyedb\\.venv\\lib\\site-packages\\ipykernel\\kernelapp.py\", line 739, in start\n",
      "    self.io_loop.start()\n",
      "  File \"C:\\actions-runner\\_work\\pyedb\\pyedb\\.venv\\lib\\site-packages\\tornado\\platform\\asyncio.py\", line 205, in start\n",
      "    self.asyncio_loop.run_forever()\n",
      "  File \"C:\\actions-runner\\_work\\_tool\\Python\\3.10.11\\x64\\lib\\asyncio\\base_events.py\", line 603, in run_forever\n",
      "    self._run_once()\n",
      "  File \"C:\\actions-runner\\_work\\_tool\\Python\\3.10.11\\x64\\lib\\asyncio\\base_events.py\", line 1909, in _run_once\n",
      "    handle._run()\n",
      "  File \"C:\\actions-runner\\_work\\_tool\\Python\\3.10.11\\x64\\lib\\asyncio\\events.py\", line 80, in _run\n",
      "    self._context.run(self._callback, *self._args)\n",
      "  File \"C:\\actions-runner\\_work\\pyedb\\pyedb\\.venv\\lib\\site-packages\\ipykernel\\kernelbase.py\", line 545, in dispatch_queue\n",
      "    await self.process_one()\n",
      "  File \"C:\\actions-runner\\_work\\pyedb\\pyedb\\.venv\\lib\\site-packages\\ipykernel\\kernelbase.py\", line 534, in process_one\n",
      "    await dispatch(*args)\n",
      "  File \"C:\\actions-runner\\_work\\pyedb\\pyedb\\.venv\\lib\\site-packages\\ipykernel\\kernelbase.py\", line 437, in dispatch_shell\n",
      "    await result\n",
      "  File \"C:\\actions-runner\\_work\\pyedb\\pyedb\\.venv\\lib\\site-packages\\ipykernel\\ipkernel.py\", line 362, in execute_request\n",
      "    await super().execute_request(stream, ident, parent)\n",
      "  File \"C:\\actions-runner\\_work\\pyedb\\pyedb\\.venv\\lib\\site-packages\\ipykernel\\kernelbase.py\", line 778, in execute_request\n",
      "    reply_content = await reply_content\n",
      "  File \"C:\\actions-runner\\_work\\pyedb\\pyedb\\.venv\\lib\\site-packages\\ipykernel\\ipkernel.py\", line 449, in do_execute\n",
      "    res = shell.run_cell(\n",
      "  File \"C:\\actions-runner\\_work\\pyedb\\pyedb\\.venv\\lib\\site-packages\\ipykernel\\zmqshell.py\", line 549, in run_cell\n",
      "    return super().run_cell(*args, **kwargs)\n",
      "  File \"C:\\actions-runner\\_work\\pyedb\\pyedb\\.venv\\lib\\site-packages\\IPython\\core\\interactiveshell.py\", line 3075, in run_cell\n",
      "    result = self._run_cell(\n",
      "  File \"C:\\actions-runner\\_work\\pyedb\\pyedb\\.venv\\lib\\site-packages\\IPython\\core\\interactiveshell.py\", line 3130, in _run_cell\n",
      "    result = runner(coro)\n",
      "  File \"C:\\actions-runner\\_work\\pyedb\\pyedb\\.venv\\lib\\site-packages\\IPython\\core\\async_helpers.py\", line 128, in _pseudo_sync_runner\n",
      "    coro.send(None)\n",
      "  File \"C:\\actions-runner\\_work\\pyedb\\pyedb\\.venv\\lib\\site-packages\\IPython\\core\\interactiveshell.py\", line 3334, in run_cell_async\n",
      "    has_raised = await self.run_ast_nodes(code_ast.body, cell_name,\n",
      "  File \"C:\\actions-runner\\_work\\pyedb\\pyedb\\.venv\\lib\\site-packages\\IPython\\core\\interactiveshell.py\", line 3517, in run_ast_nodes\n",
      "    if await self.run_code(code, result, async_=asy):\n",
      "  File \"C:\\actions-runner\\_work\\pyedb\\pyedb\\.venv\\lib\\site-packages\\IPython\\core\\interactiveshell.py\", line 3577, in run_code\n",
      "    exec(code_obj, self.user_global_ns, self.user_ns)\n",
      "  File \"C:\\Users\\ansys\\AppData\\Local\\Temp\\ipykernel_12908\\3629736421.py\", line 2, in <module>\n",
      "    edbapp = Edb(edbpath=targetfile, edbversion=EDB_VERSION)\n",
      "  File \"C:\\actions-runner\\_work\\pyedb\\pyedb\\.venv\\lib\\site-packages\\pyedb\\generic\\design_types.py\", line 110, in Edb\n",
      "    return app(\n",
      "  File \"C:\\actions-runner\\_work\\pyedb\\pyedb\\.venv\\lib\\site-packages\\pyedb\\dotnet\\edb.py\", line 276, in __init__\n",
      "    self.open_edb()\n",
      "  File \"C:\\actions-runner\\_work\\pyedb\\pyedb\\.venv\\lib\\site-packages\\pyedb\\dotnet\\edb.py\", line 571, in open_edb\n",
      "    self.logger.info(\"Builder was initialized.\")\n",
      "  File \"C:\\actions-runner\\_work\\pyedb\\pyedb\\.venv\\lib\\site-packages\\pyedb\\edb_logger.py\", line 346, in info\n",
      "    return self._log_on_handler(0, msg, *args, **kwargs)\n",
      "  File \"C:\\actions-runner\\_work\\pyedb\\pyedb\\.venv\\lib\\site-packages\\pyedb\\edb_logger.py\", line 293, in _log_on_handler\n",
      "    self._global.info(message_text, *args, **kwargs)\n",
      "Message: 'Builder was initialized.'\n",
      "Arguments: ()\n",
      "--- Logging error ---\n",
      "Traceback (most recent call last):\n",
      "  File \"C:\\actions-runner\\_work\\_tool\\Python\\3.10.11\\x64\\lib\\logging\\handlers.py\", line 74, in emit\n",
      "    self.doRollover()\n",
      "  File \"C:\\actions-runner\\_work\\_tool\\Python\\3.10.11\\x64\\lib\\logging\\handlers.py\", line 179, in doRollover\n",
      "    self.rotate(self.baseFilename, dfn)\n",
      "  File \"C:\\actions-runner\\_work\\_tool\\Python\\3.10.11\\x64\\lib\\logging\\handlers.py\", line 115, in rotate\n",
      "    os.rename(source, dest)\n",
      "PermissionError: [WinError 32] The process cannot access the file because it is being used by another process: 'C:\\\\Users\\\\ansys\\\\AppData\\\\Local\\\\Temp\\\\pyedb_ansys.log' -> 'C:\\\\Users\\\\ansys\\\\AppData\\\\Local\\\\Temp\\\\pyedb_ansys.log.1'\n",
      "Call stack:\n",
      "  File \"C:\\actions-runner\\_work\\_tool\\Python\\3.10.11\\x64\\lib\\runpy.py\", line 196, in _run_module_as_main\n",
      "    return _run_code(code, main_globals, None,\n",
      "  File \"C:\\actions-runner\\_work\\_tool\\Python\\3.10.11\\x64\\lib\\runpy.py\", line 86, in _run_code\n",
      "    exec(code, run_globals)\n",
      "  File \"C:\\actions-runner\\_work\\pyedb\\pyedb\\.venv\\lib\\site-packages\\ipykernel_launcher.py\", line 18, in <module>\n",
      "    app.launch_new_instance()\n",
      "  File \"C:\\actions-runner\\_work\\pyedb\\pyedb\\.venv\\lib\\site-packages\\traitlets\\config\\application.py\", line 1075, in launch_instance\n",
      "    app.start()\n",
      "  File \"C:\\actions-runner\\_work\\pyedb\\pyedb\\.venv\\lib\\site-packages\\ipykernel\\kernelapp.py\", line 739, in start\n",
      "    self.io_loop.start()\n",
      "  File \"C:\\actions-runner\\_work\\pyedb\\pyedb\\.venv\\lib\\site-packages\\tornado\\platform\\asyncio.py\", line 205, in start\n",
      "    self.asyncio_loop.run_forever()\n",
      "  File \"C:\\actions-runner\\_work\\_tool\\Python\\3.10.11\\x64\\lib\\asyncio\\base_events.py\", line 603, in run_forever\n",
      "    self._run_once()\n",
      "  File \"C:\\actions-runner\\_work\\_tool\\Python\\3.10.11\\x64\\lib\\asyncio\\base_events.py\", line 1909, in _run_once\n",
      "    handle._run()\n",
      "  File \"C:\\actions-runner\\_work\\_tool\\Python\\3.10.11\\x64\\lib\\asyncio\\events.py\", line 80, in _run\n",
      "    self._context.run(self._callback, *self._args)\n",
      "  File \"C:\\actions-runner\\_work\\pyedb\\pyedb\\.venv\\lib\\site-packages\\ipykernel\\kernelbase.py\", line 545, in dispatch_queue\n",
      "    await self.process_one()\n",
      "  File \"C:\\actions-runner\\_work\\pyedb\\pyedb\\.venv\\lib\\site-packages\\ipykernel\\kernelbase.py\", line 534, in process_one\n",
      "    await dispatch(*args)\n",
      "  File \"C:\\actions-runner\\_work\\pyedb\\pyedb\\.venv\\lib\\site-packages\\ipykernel\\kernelbase.py\", line 437, in dispatch_shell\n",
      "    await result\n",
      "  File \"C:\\actions-runner\\_work\\pyedb\\pyedb\\.venv\\lib\\site-packages\\ipykernel\\ipkernel.py\", line 362, in execute_request\n",
      "    await super().execute_request(stream, ident, parent)\n",
      "  File \"C:\\actions-runner\\_work\\pyedb\\pyedb\\.venv\\lib\\site-packages\\ipykernel\\kernelbase.py\", line 778, in execute_request\n",
      "    reply_content = await reply_content\n",
      "  File \"C:\\actions-runner\\_work\\pyedb\\pyedb\\.venv\\lib\\site-packages\\ipykernel\\ipkernel.py\", line 449, in do_execute\n",
      "    res = shell.run_cell(\n",
      "  File \"C:\\actions-runner\\_work\\pyedb\\pyedb\\.venv\\lib\\site-packages\\ipykernel\\zmqshell.py\", line 549, in run_cell\n",
      "    return super().run_cell(*args, **kwargs)\n",
      "  File \"C:\\actions-runner\\_work\\pyedb\\pyedb\\.venv\\lib\\site-packages\\IPython\\core\\interactiveshell.py\", line 3075, in run_cell\n",
      "    result = self._run_cell(\n",
      "  File \"C:\\actions-runner\\_work\\pyedb\\pyedb\\.venv\\lib\\site-packages\\IPython\\core\\interactiveshell.py\", line 3130, in _run_cell\n",
      "    result = runner(coro)\n",
      "  File \"C:\\actions-runner\\_work\\pyedb\\pyedb\\.venv\\lib\\site-packages\\IPython\\core\\async_helpers.py\", line 128, in _pseudo_sync_runner\n",
      "    coro.send(None)\n",
      "  File \"C:\\actions-runner\\_work\\pyedb\\pyedb\\.venv\\lib\\site-packages\\IPython\\core\\interactiveshell.py\", line 3334, in run_cell_async\n",
      "    has_raised = await self.run_ast_nodes(code_ast.body, cell_name,\n",
      "  File \"C:\\actions-runner\\_work\\pyedb\\pyedb\\.venv\\lib\\site-packages\\IPython\\core\\interactiveshell.py\", line 3517, in run_ast_nodes\n",
      "    if await self.run_code(code, result, async_=asy):\n",
      "  File \"C:\\actions-runner\\_work\\pyedb\\pyedb\\.venv\\lib\\site-packages\\IPython\\core\\interactiveshell.py\", line 3577, in run_code\n",
      "    exec(code_obj, self.user_global_ns, self.user_ns)\n",
      "  File \"C:\\Users\\ansys\\AppData\\Local\\Temp\\ipykernel_12908\\3629736421.py\", line 2, in <module>\n",
      "    edbapp = Edb(edbpath=targetfile, edbversion=EDB_VERSION)\n",
      "  File \"C:\\actions-runner\\_work\\pyedb\\pyedb\\.venv\\lib\\site-packages\\pyedb\\generic\\design_types.py\", line 110, in Edb\n",
      "    return app(\n",
      "  File \"C:\\actions-runner\\_work\\pyedb\\pyedb\\.venv\\lib\\site-packages\\pyedb\\dotnet\\edb.py\", line 278, in __init__\n",
      "    self.logger.info(\"EDB initialized.\")\n",
      "  File \"C:\\actions-runner\\_work\\pyedb\\pyedb\\.venv\\lib\\site-packages\\pyedb\\edb_logger.py\", line 346, in info\n",
      "    return self._log_on_handler(0, msg, *args, **kwargs)\n",
      "  File \"C:\\actions-runner\\_work\\pyedb\\pyedb\\.venv\\lib\\site-packages\\pyedb\\edb_logger.py\", line 293, in _log_on_handler\n",
      "    self._global.info(message_text, *args, **kwargs)\n",
      "Message: 'EDB initialized.'\n",
      "Arguments: ()\n"
     ]
    }
   ],
   "source": [
    "EDB_VERSION = \"2024.2\"\n",
    "edbapp = Edb(edbpath=targetfile, edbversion=EDB_VERSION)"
   ]
  },
  {
   "cell_type": "markdown",
   "id": "daa4dcdf",
   "metadata": {},
   "source": [
    "## Renaming all signal nets\n",
    "Using the net name setter to rename."
   ]
  },
  {
   "cell_type": "code",
   "execution_count": 4,
   "id": "3273f7e0",
   "metadata": {
    "execution": {
     "iopub.execute_input": "2025-01-22T08:50:19.374479Z",
     "iopub.status.busy": "2025-01-22T08:50:19.374479Z",
     "iopub.status.idle": "2025-01-22T08:50:19.421359Z",
     "shell.execute_reply": "2025-01-22T08:50:19.421359Z"
    }
   },
   "outputs": [],
   "source": [
    "for net_name, net in edbapp.nets.signal.items():\n",
    "    net.name = f\"{net_name}_test\""
   ]
  },
  {
   "cell_type": "markdown",
   "id": "e79f4526",
   "metadata": {},
   "source": [
    "## Creating coaxial port on component U1 and all ddr4_dqs nets\n",
    "Selecting all nets from ddr4_dqs and component U1 and create coaxial ports\n",
    "On corresponding pins."
   ]
  },
  {
   "cell_type": "code",
   "execution_count": 5,
   "id": "350c4765",
   "metadata": {
    "execution": {
     "iopub.execute_input": "2025-01-22T08:50:19.421359Z",
     "iopub.status.busy": "2025-01-22T08:50:19.421359Z",
     "iopub.status.idle": "2025-01-22T08:50:19.936990Z",
     "shell.execute_reply": "2025-01-22T08:50:19.936990Z"
    }
   },
   "outputs": [
    {
     "data": {
      "text/plain": [
       "True"
      ]
     },
     "execution_count": 5,
     "metadata": {},
     "output_type": "execute_result"
    }
   ],
   "source": [
    "comp_u1 = edbapp.components.instances[\"U1\"]\n",
    "signal_nets = [net for net in comp_u1.nets if \"ddr4_dqs\" in net.lower()]\n",
    "edbapp.hfss.create_coax_port_on_component(\"U1\", net_list=signal_nets)\n",
    "edbapp.components.set_solder_ball(component=\"U1\", sball_diam=\"0.3mm\", sball_height=\"0.3mm\")"
   ]
  },
  {
   "cell_type": "markdown",
   "id": "0b309bdc",
   "metadata": {},
   "source": [
    "## Renaming all ports\n",
    "Renaming all port with _renamed string as suffix example."
   ]
  },
  {
   "cell_type": "code",
   "execution_count": 6,
   "id": "4722a90c",
   "metadata": {
    "execution": {
     "iopub.execute_input": "2025-01-22T08:50:19.936990Z",
     "iopub.status.busy": "2025-01-22T08:50:19.936990Z",
     "iopub.status.idle": "2025-01-22T08:50:19.968271Z",
     "shell.execute_reply": "2025-01-22T08:50:19.968271Z"
    }
   },
   "outputs": [],
   "source": [
    "for port_name, port in edbapp.ports.items():\n",
    "    port.name = f\"{port_name}_renamed\""
   ]
  },
  {
   "cell_type": "markdown",
   "id": "df12f2e6",
   "metadata": {},
   "source": [
    "## Saving and closing EDB\n",
    "Once the EDB saved and closed, this can be imported in ANSYS AEDT as an HFSS 3D Layout project."
   ]
  },
  {
   "cell_type": "code",
   "execution_count": 7,
   "id": "a48f3c82",
   "metadata": {
    "execution": {
     "iopub.execute_input": "2025-01-22T08:50:19.968271Z",
     "iopub.status.busy": "2025-01-22T08:50:19.968271Z",
     "iopub.status.idle": "2025-01-22T08:50:20.186996Z",
     "shell.execute_reply": "2025-01-22T08:50:20.186996Z"
    }
   },
   "outputs": [
    {
     "data": {
      "text/plain": [
       "True"
      ]
     },
     "execution_count": 7,
     "metadata": {},
     "output_type": "execute_result"
    }
   ],
   "source": [
    "edbapp.save()\n",
    "edbapp.close()"
   ]
  }
 ],
 "metadata": {
  "jupytext": {
   "cell_metadata_filter": "-all",
   "main_language": "python",
   "notebook_metadata_filter": "-all",
   "text_representation": {
    "extension": ".py",
    "format_name": "light"
   }
  },
  "language_info": {
   "codemirror_mode": {
    "name": "ipython",
    "version": 3
   },
   "file_extension": ".py",
   "mimetype": "text/x-python",
   "name": "python",
   "nbconvert_exporter": "python",
   "pygments_lexer": "ipython3",
   "version": "3.10.11"
  }
 },
 "nbformat": 4,
 "nbformat_minor": 5
}
